<?xml version="1.0" ?>
<!-- =================================================================================== -->
<!-- |    This document was autogenerated by xacro from /home/earlaud/catkin_ws/src/prl_ur5_robot/prl_ur5_description/urdf/prl_ur5_robot.urdf.xacro | -->
<!-- |    EDITING THIS FILE BY HAND IS NOT RECOMMENDED                                 | -->
<!-- =================================================================================== -->
<robot name="prl_ur5_robot">
  <material name="onrobot/grey">
    <color rgba="0.65 0.62 0.58 1.0"/>
  </material>
  <material name="onrobot/light_grey">
    <color rgba="0.9 0.92 0.93 1.0"/>
  </material>
  <material name="onrobot/dark_grey">
    <color rgba="0.25 0.25 0.25 1.0"/>
  </material>
  <material name="aluminum">
    <color rgba="0.5 0.5 0.5 1"/>
  </material>
  <material name="plastic">
    <color rgba="0.1 0.1 0.1 1"/>
  </material>
  <!-- Including this file a second time would include 'realsense2_description/urdf/_d435i.urdf.xacro' a second time which will result in a crash related to this problem :  https://github.com/IntelRealSense/realsense-ros/issues/2338 -->
  <!-- It is assumed that this file has already been included somewhere else (e.g. in _ur5.urdf.xacro) -->
  <!-- <xacro:include filename="$(find prl_ur5_description)/urdf/_camera_sensor.urdf.xacro"/> -->
  <!-- base link -->
  <link name="prl_ur5_base"/>
  <!-- bimanual stand -->
  <link name="stand_link">
    <visual>
      <geometry>
        <mesh filename="package://ur5/data/0034_vention_tower.dae"/>
      </geometry>
      <material name="Cyan">
        <color rgba="0 1.0 1.0 1.0"/>
      </material>
    </visual>
    <collision>
      <geometry>
        <mesh filename="package://ur5/data/0020_vention_tower.stl"/>
      </geometry>
    </collision>
  </link>
  <joint name="stand_fix" type="fixed">
    <parent link="prl_ur5_base"/>
    <child link="stand_link"/>
    <origin rpy="0.0 0.0 0.0" xyz="0.0 -0.3825 0.0"/>
  </joint>
  <link name="bravo_camera_calibration_pose"/>
  <joint name="bravo_camera_calibration_pose_joint" type="fixed">
    <origin rpy="-2.099 0.002 -3.117" xyz="-0.492452 0.689076 0.379511"/>
    <parent link="prl_ur5_base"/>
    <child link="bravo_camera_calibration_pose"/>
  </joint>
  <!-- camera body, with origin at bottom screw mount -->
  <joint name="bravo_camera_joint" type="fixed">
    <origin rpy="1.5707963267948966 -1.5707963267948966 0" xyz="0.0325 0.0125 -0.0106"/>
    <parent link="bravo_camera_calibration_pose"/>
    <child link="bravo_camera_bottom_screw_frame"/>
  </joint>
  <link name="bravo_camera_bottom_screw_frame"/>
  <joint name="bravo_camera_link_joint" type="fixed">
    <origin rpy="0 0 0" xyz="0.010600000000000002 0.0175 0.0125"/>
    <parent link="bravo_camera_bottom_screw_frame"/>
    <child link="bravo_camera_link"/>
  </joint>
  <link name="bravo_camera_link">
    <visual>
      <!-- the mesh origin is at front plate in between the two infrared camera axes -->
      <origin rpy="1.5707963267948966 0 1.5707963267948966" xyz="0.0043 -0.0175 0"/>
      <geometry>
        <mesh filename="package://ur5/data/0008_d435.dae"/>
      </geometry>
    </visual>
    <collision>
      <origin rpy="0 0 0" xyz="0 -0.0175 0"/>
      <geometry>
        <box size="0.02505 0.09 0.025"/>
      </geometry>
    </collision>
    <inertial>
      <!-- The following are not reliable values, and should not be used for modeling -->
      <mass value="0.072"/>
      <origin xyz="0 0 0"/>
      <inertia ixx="0.003881243" ixy="0.0" ixz="0.0" iyy="0.000498940" iyz="0.0" izz="0.003879257"/>
    </inertial>
  </link>
  <!-- camera depth joints and links -->
  <joint name="bravo_camera_depth_joint" type="fixed">
    <origin rpy="0 0 0" xyz="0 0 0"/>
    <parent link="bravo_camera_link"/>
    <child link="bravo_camera_depth_frame"/>
  </joint>
  <link name="bravo_camera_depth_frame"/>
  <joint name="bravo_camera_depth_optical_joint" type="fixed">
    <origin rpy="-1.5707963267948966 0 -1.5707963267948966" xyz="0 0 0"/>
    <parent link="bravo_camera_depth_frame"/>
    <child link="bravo_camera_depth_optical_frame"/>
  </joint>
  <link name="bravo_camera_depth_optical_frame"/>
  <!-- camera left IR joints and links -->
  <joint name="bravo_camera_infra1_joint" type="fixed">
    <origin rpy="0 0 0" xyz="0 0.0 0"/>
    <parent link="bravo_camera_link"/>
    <child link="bravo_camera_infra1_frame"/>
  </joint>
  <link name="bravo_camera_infra1_frame"/>
  <joint name="bravo_camera_infra1_optical_joint" type="fixed">
    <origin rpy="-1.5707963267948966 0 -1.5707963267948966" xyz="0 0 0"/>
    <parent link="bravo_camera_infra1_frame"/>
    <child link="bravo_camera_infra1_optical_frame"/>
  </joint>
  <link name="bravo_camera_infra1_optical_frame"/>
  <!-- camera right IR joints and links -->
  <joint name="bravo_camera_infra2_joint" type="fixed">
    <origin rpy="0 0 0" xyz="0 -0.05 0"/>
    <parent link="bravo_camera_link"/>
    <child link="bravo_camera_infra2_frame"/>
  </joint>
  <link name="bravo_camera_infra2_frame"/>
  <joint name="bravo_camera_infra2_optical_joint" type="fixed">
    <origin rpy="-1.5707963267948966 0 -1.5707963267948966" xyz="0 0 0"/>
    <parent link="bravo_camera_infra2_frame"/>
    <child link="bravo_camera_infra2_optical_frame"/>
  </joint>
  <link name="bravo_camera_infra2_optical_frame"/>
  <!-- camera color joints and links -->
  <joint name="bravo_camera_color_joint" type="fixed">
    <origin rpy="0 0 0" xyz="0 0.015 0"/>
    <parent link="bravo_camera_link"/>
    <child link="bravo_camera_color_frame"/>
  </joint>
  <link name="bravo_camera_color_frame"/>
  <joint name="bravo_camera_color_optical_joint" type="fixed">
    <origin rpy="-1.5707963267948966 0 -1.5707963267948966" xyz="0 0 0"/>
    <parent link="bravo_camera_color_frame"/>
    <child link="bravo_camera_color_optical_frame"/>
  </joint>
  <link name="bravo_camera_color_optical_frame"/>
  <link name="bravo_camera_accel_frame"/>
  <link name="bravo_camera_accel_optical_frame"/>
  <link name="bravo_camera_gyro_frame"/>
  <link name="bravo_camera_gyro_optical_frame"/>
  <joint name="bravo_camera_accel_joint" type="fixed">
    <origin rpy="0 0 0" xyz="-0.01174 -0.00552 0.0051"/>
    <parent link="bravo_camera_link"/>
    <child link="bravo_camera_accel_frame"/>
  </joint>
  <joint name="bravo_camera_accel_optical_joint" type="fixed">
    <origin rpy="-1.5707963267948966 0 -1.5707963267948966" xyz="0 0 0"/>
    <parent link="bravo_camera_accel_frame"/>
    <child link="bravo_camera_accel_optical_frame"/>
  </joint>
  <joint name="bravo_camera_gyro_joint" type="fixed">
    <origin rpy="0 0 0" xyz="-0.01174 -0.00552 0.0051"/>
    <parent link="bravo_camera_link"/>
    <child link="bravo_camera_gyro_frame"/>
  </joint>
  <joint name="bravo_camera_gyro_optical_joint" type="fixed">
    <origin rpy="-1.5707963267948966 0 -1.5707963267948966" xyz="0 0 0"/>
    <parent link="bravo_camera_gyro_frame"/>
    <child link="bravo_camera_gyro_optical_frame"/>
  </joint>
  <gazebo reference="bravo_camera_link">
    <self_collide>1</self_collide>
    <enable_wind>0</enable_wind>
    <kinematic>0</kinematic>
    <gravity>1</gravity>
    <material>Gazebo/Grey</material>
    <!--<mu>1</mu>-->
    <mu2>1</mu2>
    <fdir1>0 0 0</fdir1>
    <!--<slip1>0</slip1>
      <slip2>0</slip2>-->
    <kp>1e+13</kp>
    <kd>1</kd>
    <!--<max_vel>0.01</max_vel>
      <min_depth>0</min_depth>-->
    <sensor name="bravo_cameracolor" type="camera">
      <camera name="bravo_camera">
        <horizontal_fov>1.2112585008840648</horizontal_fov>
        <image>
          <width>640</width>
          <height>480</height>
          <format>RGB_INT8</format>
        </image>
        <clip>
          <near>0.1</near>
          <far>100</far>
        </clip>
        <noise>
          <type>gaussian</type>
          <mean>0.0</mean>
          <stddev>0.007</stddev>
        </noise>
      </camera>
      <always_on>False</always_on>
      <update_rate>30</update_rate>
      <visualize>False</visualize>
    </sensor>
    <sensor name="bravo_cameraired1" type="camera">
      <camera name="bravo_camera">
        <horizontal_fov>1.4870205226991688</horizontal_fov>
        <image>
          <width>1280</width>
          <height>720</height>
          <format>L_INT8</format>
        </image>
        <clip>
          <near>0.1</near>
          <far>100</far>
        </clip>
        <noise>
          <type>gaussian</type>
          <mean>0.0</mean>
          <stddev>0.05</stddev>
        </noise>
      </camera>
      <always_on>0</always_on>
      <update_rate>90</update_rate>
      <visualize>0</visualize>
    </sensor>
    <sensor name="bravo_cameraired2" type="camera">
      <camera name="bravo_camera">
        <horizontal_fov>1.4870205226991688</horizontal_fov>
        <image>
          <width>1280</width>
          <height>720</height>
          <format>L_INT8</format>
        </image>
        <clip>
          <near>0.1</near>
          <far>100</far>
        </clip>
        <noise>
          <type>gaussian</type>
          <mean>0.0</mean>
          <stddev>0.05</stddev>
        </noise>
      </camera>
      <always_on>0</always_on>
      <update_rate>90</update_rate>
      <visualize>0</visualize>
    </sensor>
    <sensor name="bravo_cameradepth" type="depth">
      <camera name="bravo_camera">
        <horizontal_fov>1.4870205226991688</horizontal_fov>
        <image>
          <width>1280</width>
          <height>720</height>
        </image>
        <clip>
          <near>0.1</near>
          <far>100</far>
        </clip>
        <noise>
          <type>gaussian</type>
          <mean>0.0</mean>
          <stddev>0.100</stddev>
        </noise>
      </camera>
      <always_on>False</always_on>
      <update_rate>90</update_rate>
      <visualize>0</visualize>
    </sensor>
  </gazebo>
  <gazebo>
    <plugin filename="librealsense_gazebo_plugin.so" name="bravo_camera">
      <prefix>bravo_camera</prefix>
      <depthUpdateRate>30.0</depthUpdateRate>
      <colorUpdateRate>30.0</colorUpdateRate>
      <infraredUpdateRate>30.0</infraredUpdateRate>
      <depthTopicName>depth/image_raw</depthTopicName>
      <depthCameraInfoTopicName>depth/camera_info</depthCameraInfoTopicName>
      <colorTopicName>color/image_raw</colorTopicName>
      <colorCameraInfoTopicName>color/camera_info</colorCameraInfoTopicName>
      <infrared1TopicName>infra1/image_raw</infrared1TopicName>
      <infrared1CameraInfoTopicName>infra1/camera_info</infrared1CameraInfoTopicName>
      <infrared2TopicName>infra2/image_raw</infrared2TopicName>
      <infrared2CameraInfoTopicName>infra2/camera_info</infrared2CameraInfoTopicName>
      <colorOpticalframeName>bravo_camera_color_optical_frame</colorOpticalframeName>
      <depthOpticalframeName>bravo_camera_depth_optical_frame</depthOpticalframeName>
      <infrared1OpticalframeName>bravo_camera_left_ir_optical_frame</infrared1OpticalframeName>
      <infrared2OpticalframeName>bravo_camera_right_ir_optical_frame</infrared2OpticalframeName>
      <rangeMinDepth>0.2</rangeMinDepth>
      <rangeMaxDepth>10.0</rangeMaxDepth>
      <pointCloud>True</pointCloud>
      <pointCloudTopicName>bravo_camera_depth/color/points</pointCloudTopicName>
      <pointCloudCutoff>0.25</pointCloudCutoff>
      <pointCloudCutoffMax>9.0</pointCloudCutoffMax>
    </plugin>
  </gazebo>
  <!-- Diameter of the spherical joint supporting the camera -->
  <!-- Camera bounding box -->
  <link name="fixed_camera_0_bb">
    <visual>
      <geometry>
        <cylinder length="0.2" radius="0.125"/>
      </geometry>
      <material name="purple">
        <color rgba="0.01 0.32 0.41 0.1"/>
      </material>
    </visual>
    <collision>
      <geometry>
        <cylinder length="0.2" radius="0.125"/>
      </geometry>
    </collision>
  </link>
  <gazebo reference="fixed_camera_0_bb">
    <visual>
      <material>
        <ambient>0.1 0.5 0.5 0.2</ambient>
        <diffuse>0.1 0.5 0.1 0.2</diffuse>
        <specular>0.1 0.1 0.1 0.2</specular>
        <emissive>0.0 0.0 0.0 0.0</emissive>
      </material>
    </visual>
  </gazebo>
  <joint name="fixed_camera_0_bb_joint" type="fixed">
    <parent link="prl_ur5_base"/>
    <child link="fixed_camera_0_bb"/>
    <origin rpy="0 0 0" xyz="-0.492452 0.689076 0.379511"/>
  </joint>
  <!-- Spherical joint holding the camera -->
  <link name="fixed_camera_0_sj">
    <visual>
      <geometry>
        <cylinder length="0.16999999999999998" radius="0.06"/>
      </geometry>
      <material name="purple"/>
    </visual>
    <collision>
      <geometry>
        <cylinder length="0.16999999999999998" radius="0.06"/>
      </geometry>
    </collision>
  </link>
  <gazebo reference="fixed_camera_0_sj">
    <material>Gazebo/BlueGlow</material>
  </gazebo>
  <joint name="fixed_camera_0_sj_joint" type="fixed">
    <parent link="fixed_camera_0_bb"/>
    <child link="fixed_camera_0_sj"/>
    <origin rpy="0 0 0" xyz="0 0 -0.185"/>
  </joint>
  <!-- Vertical extrusion -->
  <link name="fixed_camera_0_vt">
    <visual>
      <geometry>
        <box size="0.105 0.105 0.355761"/>
      </geometry>
      <material name="purple"/>
    </visual>
    <collision>
      <geometry>
        <box size="0.105 0.105 0.355761"/>
      </geometry>
    </collision>
  </link>
  <gazebo reference="fixed_camera_0_vt">
    <material>Gazebo/BlueGlow</material>
  </gazebo>
  <joint name="fixed_camera_0_vt_joint" type="fixed">
    <parent link="fixed_camera_0_sj"/>
    <child link="fixed_camera_0_vt"/>
    <origin rpy="0 0 0" xyz="-0.03 -0.01 -0.0728805"/>
  </joint>
  <!-- Horizontal extrusion -->
  <link name="fixed_hr_0">
    <visual>
      <geometry>
        <box size="0.441576 0.105 0.105"/>
      </geometry>
      <material name="purple"/>
    </visual>
    <collision>
      <geometry>
        <box size="0.441576 0.105 0.105"/>
      </geometry>
    </collision>
  </link>
  <gazebo reference="fixed_hr_0">
    <material>Gazebo/BlueGlow</material>
  </gazebo>
  <joint name="fixed_hr_0_fix" type="fixed">
    <parent link="fixed_camera_0_vt"/>
    <child link="fixed_hr_0"/>
    <origin rpy="0 0 1.570796327" xyz="0 -0.16828800000000002 -0.2303805"/>
  </joint>
  <link name="charlie_camera_calibration_pose"/>
  <joint name="charlie_camera_calibration_pose_joint" type="fixed">
    <origin rpy="-2.094 -0.003 -1.568" xyz="-1.200689 0.001414 0.393254"/>
    <parent link="prl_ur5_base"/>
    <child link="charlie_camera_calibration_pose"/>
  </joint>
  <!-- camera body, with origin at bottom screw mount -->
  <joint name="charlie_camera_joint" type="fixed">
    <origin rpy="1.5707963267948966 -1.5707963267948966 0" xyz="0.0325 0.0125 -0.0106"/>
    <parent link="charlie_camera_calibration_pose"/>
    <child link="charlie_camera_bottom_screw_frame"/>
  </joint>
  <link name="charlie_camera_bottom_screw_frame"/>
  <joint name="charlie_camera_link_joint" type="fixed">
    <origin rpy="0 0 0" xyz="0.010600000000000002 0.0175 0.0125"/>
    <parent link="charlie_camera_bottom_screw_frame"/>
    <child link="charlie_camera_link"/>
  </joint>
  <link name="charlie_camera_link">
    <visual>
      <!-- the mesh origin is at front plate in between the two infrared camera axes -->
      <origin rpy="1.5707963267948966 0 1.5707963267948966" xyz="0.0043 -0.0175 0"/>
      <geometry>
        <mesh filename="package://ur5/data/0008_d435.dae"/>
      </geometry>
    </visual>
    <collision>
      <origin rpy="0 0 0" xyz="0 -0.0175 0"/>
      <geometry>
        <box size="0.02505 0.09 0.025"/>
      </geometry>
    </collision>
    <inertial>
      <!-- The following are not reliable values, and should not be used for modeling -->
      <mass value="0.072"/>
      <origin xyz="0 0 0"/>
      <inertia ixx="0.003881243" ixy="0.0" ixz="0.0" iyy="0.000498940" iyz="0.0" izz="0.003879257"/>
    </inertial>
  </link>
  <!-- camera depth joints and links -->
  <joint name="charlie_camera_depth_joint" type="fixed">
    <origin rpy="0 0 0" xyz="0 0 0"/>
    <parent link="charlie_camera_link"/>
    <child link="charlie_camera_depth_frame"/>
  </joint>
  <link name="charlie_camera_depth_frame"/>
  <joint name="charlie_camera_depth_optical_joint" type="fixed">
    <origin rpy="-1.5707963267948966 0 -1.5707963267948966" xyz="0 0 0"/>
    <parent link="charlie_camera_depth_frame"/>
    <child link="charlie_camera_depth_optical_frame"/>
  </joint>
  <link name="charlie_camera_depth_optical_frame"/>
  <!-- camera left IR joints and links -->
  <joint name="charlie_camera_infra1_joint" type="fixed">
    <origin rpy="0 0 0" xyz="0 0.0 0"/>
    <parent link="charlie_camera_link"/>
    <child link="charlie_camera_infra1_frame"/>
  </joint>
  <link name="charlie_camera_infra1_frame"/>
  <joint name="charlie_camera_infra1_optical_joint" type="fixed">
    <origin rpy="-1.5707963267948966 0 -1.5707963267948966" xyz="0 0 0"/>
    <parent link="charlie_camera_infra1_frame"/>
    <child link="charlie_camera_infra1_optical_frame"/>
  </joint>
  <link name="charlie_camera_infra1_optical_frame"/>
  <!-- camera right IR joints and links -->
  <joint name="charlie_camera_infra2_joint" type="fixed">
    <origin rpy="0 0 0" xyz="0 -0.05 0"/>
    <parent link="charlie_camera_link"/>
    <child link="charlie_camera_infra2_frame"/>
  </joint>
  <link name="charlie_camera_infra2_frame"/>
  <joint name="charlie_camera_infra2_optical_joint" type="fixed">
    <origin rpy="-1.5707963267948966 0 -1.5707963267948966" xyz="0 0 0"/>
    <parent link="charlie_camera_infra2_frame"/>
    <child link="charlie_camera_infra2_optical_frame"/>
  </joint>
  <link name="charlie_camera_infra2_optical_frame"/>
  <!-- camera color joints and links -->
  <joint name="charlie_camera_color_joint" type="fixed">
    <origin rpy="0 0 0" xyz="0 0.015 0"/>
    <parent link="charlie_camera_link"/>
    <child link="charlie_camera_color_frame"/>
  </joint>
  <link name="charlie_camera_color_frame"/>
  <joint name="charlie_camera_color_optical_joint" type="fixed">
    <origin rpy="-1.5707963267948966 0 -1.5707963267948966" xyz="0 0 0"/>
    <parent link="charlie_camera_color_frame"/>
    <child link="charlie_camera_color_optical_frame"/>
  </joint>
  <link name="charlie_camera_color_optical_frame"/>
  <link name="charlie_camera_accel_frame"/>
  <link name="charlie_camera_accel_optical_frame"/>
  <link name="charlie_camera_gyro_frame"/>
  <link name="charlie_camera_gyro_optical_frame"/>
  <joint name="charlie_camera_accel_joint" type="fixed">
    <origin rpy="0 0 0" xyz="-0.01174 -0.00552 0.0051"/>
    <parent link="charlie_camera_link"/>
    <child link="charlie_camera_accel_frame"/>
  </joint>
  <joint name="charlie_camera_accel_optical_joint" type="fixed">
    <origin rpy="-1.5707963267948966 0 -1.5707963267948966" xyz="0 0 0"/>
    <parent link="charlie_camera_accel_frame"/>
    <child link="charlie_camera_accel_optical_frame"/>
  </joint>
  <joint name="charlie_camera_gyro_joint" type="fixed">
    <origin rpy="0 0 0" xyz="-0.01174 -0.00552 0.0051"/>
    <parent link="charlie_camera_link"/>
    <child link="charlie_camera_gyro_frame"/>
  </joint>
  <joint name="charlie_camera_gyro_optical_joint" type="fixed">
    <origin rpy="-1.5707963267948966 0 -1.5707963267948966" xyz="0 0 0"/>
    <parent link="charlie_camera_gyro_frame"/>
    <child link="charlie_camera_gyro_optical_frame"/>
  </joint>
  <gazebo reference="charlie_camera_link">
    <self_collide>1</self_collide>
    <enable_wind>0</enable_wind>
    <kinematic>0</kinematic>
    <gravity>1</gravity>
    <material>Gazebo/Grey</material>
    <!--<mu>1</mu>-->
    <mu2>1</mu2>
    <fdir1>0 0 0</fdir1>
    <!--<slip1>0</slip1>
      <slip2>0</slip2>-->
    <kp>1e+13</kp>
    <kd>1</kd>
    <!--<max_vel>0.01</max_vel>
      <min_depth>0</min_depth>-->
    <sensor name="charlie_cameracolor" type="camera">
      <camera name="charlie_camera">
        <horizontal_fov>1.2112585008840648</horizontal_fov>
        <image>
          <width>640</width>
          <height>480</height>
          <format>RGB_INT8</format>
        </image>
        <clip>
          <near>0.1</near>
          <far>100</far>
        </clip>
        <noise>
          <type>gaussian</type>
          <mean>0.0</mean>
          <stddev>0.007</stddev>
        </noise>
      </camera>
      <always_on>False</always_on>
      <update_rate>30</update_rate>
      <visualize>False</visualize>
    </sensor>
    <sensor name="charlie_cameraired1" type="camera">
      <camera name="charlie_camera">
        <horizontal_fov>1.4870205226991688</horizontal_fov>
        <image>
          <width>1280</width>
          <height>720</height>
          <format>L_INT8</format>
        </image>
        <clip>
          <near>0.1</near>
          <far>100</far>
        </clip>
        <noise>
          <type>gaussian</type>
          <mean>0.0</mean>
          <stddev>0.05</stddev>
        </noise>
      </camera>
      <always_on>0</always_on>
      <update_rate>90</update_rate>
      <visualize>0</visualize>
    </sensor>
    <sensor name="charlie_cameraired2" type="camera">
      <camera name="charlie_camera">
        <horizontal_fov>1.4870205226991688</horizontal_fov>
        <image>
          <width>1280</width>
          <height>720</height>
          <format>L_INT8</format>
        </image>
        <clip>
          <near>0.1</near>
          <far>100</far>
        </clip>
        <noise>
          <type>gaussian</type>
          <mean>0.0</mean>
          <stddev>0.05</stddev>
        </noise>
      </camera>
      <always_on>0</always_on>
      <update_rate>90</update_rate>
      <visualize>0</visualize>
    </sensor>
    <sensor name="charlie_cameradepth" type="depth">
      <camera name="charlie_camera">
        <horizontal_fov>1.4870205226991688</horizontal_fov>
        <image>
          <width>1280</width>
          <height>720</height>
        </image>
        <clip>
          <near>0.1</near>
          <far>100</far>
        </clip>
        <noise>
          <type>gaussian</type>
          <mean>0.0</mean>
          <stddev>0.100</stddev>
        </noise>
      </camera>
      <always_on>False</always_on>
      <update_rate>90</update_rate>
      <visualize>0</visualize>
    </sensor>
  </gazebo>
  <gazebo>
    <plugin filename="librealsense_gazebo_plugin.so" name="charlie_camera">
      <prefix>charlie_camera</prefix>
      <depthUpdateRate>30.0</depthUpdateRate>
      <colorUpdateRate>30.0</colorUpdateRate>
      <infraredUpdateRate>30.0</infraredUpdateRate>
      <depthTopicName>depth/image_raw</depthTopicName>
      <depthCameraInfoTopicName>depth/camera_info</depthCameraInfoTopicName>
      <colorTopicName>color/image_raw</colorTopicName>
      <colorCameraInfoTopicName>color/camera_info</colorCameraInfoTopicName>
      <infrared1TopicName>infra1/image_raw</infrared1TopicName>
      <infrared1CameraInfoTopicName>infra1/camera_info</infrared1CameraInfoTopicName>
      <infrared2TopicName>infra2/image_raw</infrared2TopicName>
      <infrared2CameraInfoTopicName>infra2/camera_info</infrared2CameraInfoTopicName>
      <colorOpticalframeName>charlie_camera_color_optical_frame</colorOpticalframeName>
      <depthOpticalframeName>charlie_camera_depth_optical_frame</depthOpticalframeName>
      <infrared1OpticalframeName>charlie_camera_left_ir_optical_frame</infrared1OpticalframeName>
      <infrared2OpticalframeName>charlie_camera_right_ir_optical_frame</infrared2OpticalframeName>
      <rangeMinDepth>0.2</rangeMinDepth>
      <rangeMaxDepth>10.0</rangeMaxDepth>
      <pointCloud>True</pointCloud>
      <pointCloudTopicName>charlie_camera_depth/color/points</pointCloudTopicName>
      <pointCloudCutoff>0.25</pointCloudCutoff>
      <pointCloudCutoffMax>9.0</pointCloudCutoffMax>
    </plugin>
  </gazebo>
  <!-- Diameter of the spherical joint supporting the camera -->
  <!-- Camera bounding box -->
  <link name="fixed_camera_1_bb">
    <visual>
      <geometry>
        <cylinder length="0.2" radius="0.125"/>
      </geometry>
      <material name="purple">
        <color rgba="0.01 0.32 0.41 0.1"/>
      </material>
    </visual>
    <collision>
      <geometry>
        <cylinder length="0.2" radius="0.125"/>
      </geometry>
    </collision>
  </link>
  <gazebo reference="fixed_camera_1_bb">
    <visual>
      <material>
        <ambient>0.1 0.5 0.5 0.2</ambient>
        <diffuse>0.1 0.5 0.1 0.2</diffuse>
        <specular>0.1 0.1 0.1 0.2</specular>
        <emissive>0.0 0.0 0.0 0.0</emissive>
      </material>
    </visual>
  </gazebo>
  <joint name="fixed_camera_1_bb_joint" type="fixed">
    <parent link="prl_ur5_base"/>
    <child link="fixed_camera_1_bb"/>
    <origin rpy="0 0 0" xyz="-1.200689 0.001414 0.393254"/>
  </joint>
  <!-- Spherical joint holding the camera -->
  <link name="fixed_camera_1_sj">
    <visual>
      <geometry>
        <cylinder length="0.16999999999999998" radius="0.06"/>
      </geometry>
      <material name="purple"/>
    </visual>
    <collision>
      <geometry>
        <cylinder length="0.16999999999999998" radius="0.06"/>
      </geometry>
    </collision>
  </link>
  <gazebo reference="fixed_camera_1_sj">
    <material>Gazebo/BlueGlow</material>
  </gazebo>
  <joint name="fixed_camera_1_sj_joint" type="fixed">
    <parent link="fixed_camera_1_bb"/>
    <child link="fixed_camera_1_sj"/>
    <origin rpy="0 0 0" xyz="0 0 -0.185"/>
  </joint>
  <!-- Vertical extrusion -->
  <link name="fixed_camera_1_vt">
    <visual>
      <geometry>
        <box size="0.105 0.105 0.369504"/>
      </geometry>
      <material name="purple"/>
    </visual>
    <collision>
      <geometry>
        <box size="0.105 0.105 0.369504"/>
      </geometry>
    </collision>
  </link>
  <gazebo reference="fixed_camera_1_vt">
    <material>Gazebo/BlueGlow</material>
  </gazebo>
  <joint name="fixed_camera_1_vt_joint" type="fixed">
    <parent link="fixed_camera_1_sj"/>
    <child link="fixed_camera_1_vt"/>
    <origin rpy="0 0 0" xyz="0.01 -0.03 -0.079752"/>
  </joint>
  <!-- Horizontal extrusion -->
  <link name="fixed_hr_1">
    <visual>
      <geometry>
        <box size="0.32318899999999984 0.105 0.105"/>
      </geometry>
      <material name="purple"/>
    </visual>
    <collision>
      <geometry>
        <box size="0.32318899999999984 0.105 0.105"/>
      </geometry>
    </collision>
  </link>
  <gazebo reference="fixed_hr_1">
    <material>Gazebo/BlueGlow</material>
  </gazebo>
  <joint name="fixed_hr_1_fix" type="fixed">
    <parent link="fixed_camera_1_vt"/>
    <child link="fixed_hr_1"/>
    <origin rpy="0 0 3.1415926" xyz="0.10909449999999993 0 -0.237252"/>
  </joint>
  <link name="delta_camera_calibration_pose"/>
  <joint name="delta_camera_calibration_pose_joint" type="fixed">
    <origin rpy="-1.907 0.019 3.139" xyz="0.611561 0.518683 0.276871"/>
    <parent link="prl_ur5_base"/>
    <child link="delta_camera_calibration_pose"/>
  </joint>
  <!-- camera body, with origin at bottom screw mount -->
  <joint name="delta_camera_joint" type="fixed">
    <origin rpy="1.5707963267948966 -1.5707963267948966 0" xyz="0.0325 0.0125 -0.0106"/>
    <parent link="delta_camera_calibration_pose"/>
    <child link="delta_camera_bottom_screw_frame"/>
  </joint>
  <link name="delta_camera_bottom_screw_frame"/>
  <joint name="delta_camera_link_joint" type="fixed">
    <origin rpy="0 0 0" xyz="0.010600000000000002 0.0175 0.0125"/>
    <parent link="delta_camera_bottom_screw_frame"/>
    <child link="delta_camera_link"/>
  </joint>
  <link name="delta_camera_link">
    <visual>
      <!-- the mesh origin is at front plate in between the two infrared camera axes -->
      <origin rpy="1.5707963267948966 0 1.5707963267948966" xyz="0.0043 -0.0175 0"/>
      <geometry>
        <mesh filename="package://ur5/data/0008_d435.dae"/>
      </geometry>
    </visual>
    <collision>
      <origin rpy="0 0 0" xyz="0 -0.0175 0"/>
      <geometry>
        <box size="0.02505 0.09 0.025"/>
      </geometry>
    </collision>
    <inertial>
      <!-- The following are not reliable values, and should not be used for modeling -->
      <mass value="0.072"/>
      <origin xyz="0 0 0"/>
      <inertia ixx="0.003881243" ixy="0.0" ixz="0.0" iyy="0.000498940" iyz="0.0" izz="0.003879257"/>
    </inertial>
  </link>
  <!-- camera depth joints and links -->
  <joint name="delta_camera_depth_joint" type="fixed">
    <origin rpy="0 0 0" xyz="0 0 0"/>
    <parent link="delta_camera_link"/>
    <child link="delta_camera_depth_frame"/>
  </joint>
  <link name="delta_camera_depth_frame"/>
  <joint name="delta_camera_depth_optical_joint" type="fixed">
    <origin rpy="-1.5707963267948966 0 -1.5707963267948966" xyz="0 0 0"/>
    <parent link="delta_camera_depth_frame"/>
    <child link="delta_camera_depth_optical_frame"/>
  </joint>
  <link name="delta_camera_depth_optical_frame"/>
  <!-- camera left IR joints and links -->
  <joint name="delta_camera_infra1_joint" type="fixed">
    <origin rpy="0 0 0" xyz="0 0.0 0"/>
    <parent link="delta_camera_link"/>
    <child link="delta_camera_infra1_frame"/>
  </joint>
  <link name="delta_camera_infra1_frame"/>
  <joint name="delta_camera_infra1_optical_joint" type="fixed">
    <origin rpy="-1.5707963267948966 0 -1.5707963267948966" xyz="0 0 0"/>
    <parent link="delta_camera_infra1_frame"/>
    <child link="delta_camera_infra1_optical_frame"/>
  </joint>
  <link name="delta_camera_infra1_optical_frame"/>
  <!-- camera right IR joints and links -->
  <joint name="delta_camera_infra2_joint" type="fixed">
    <origin rpy="0 0 0" xyz="0 -0.05 0"/>
    <parent link="delta_camera_link"/>
    <child link="delta_camera_infra2_frame"/>
  </joint>
  <link name="delta_camera_infra2_frame"/>
  <joint name="delta_camera_infra2_optical_joint" type="fixed">
    <origin rpy="-1.5707963267948966 0 -1.5707963267948966" xyz="0 0 0"/>
    <parent link="delta_camera_infra2_frame"/>
    <child link="delta_camera_infra2_optical_frame"/>
  </joint>
  <link name="delta_camera_infra2_optical_frame"/>
  <!-- camera color joints and links -->
  <joint name="delta_camera_color_joint" type="fixed">
    <origin rpy="0 0 0" xyz="0 0.015 0"/>
    <parent link="delta_camera_link"/>
    <child link="delta_camera_color_frame"/>
  </joint>
  <link name="delta_camera_color_frame"/>
  <joint name="delta_camera_color_optical_joint" type="fixed">
    <origin rpy="-1.5707963267948966 0 -1.5707963267948966" xyz="0 0 0"/>
    <parent link="delta_camera_color_frame"/>
    <child link="delta_camera_color_optical_frame"/>
  </joint>
  <link name="delta_camera_color_optical_frame"/>
  <link name="delta_camera_accel_frame"/>
  <link name="delta_camera_accel_optical_frame"/>
  <link name="delta_camera_gyro_frame"/>
  <link name="delta_camera_gyro_optical_frame"/>
  <joint name="delta_camera_accel_joint" type="fixed">
    <origin rpy="0 0 0" xyz="-0.01174 -0.00552 0.0051"/>
    <parent link="delta_camera_link"/>
    <child link="delta_camera_accel_frame"/>
  </joint>
  <joint name="delta_camera_accel_optical_joint" type="fixed">
    <origin rpy="-1.5707963267948966 0 -1.5707963267948966" xyz="0 0 0"/>
    <parent link="delta_camera_accel_frame"/>
    <child link="delta_camera_accel_optical_frame"/>
  </joint>
  <joint name="delta_camera_gyro_joint" type="fixed">
    <origin rpy="0 0 0" xyz="-0.01174 -0.00552 0.0051"/>
    <parent link="delta_camera_link"/>
    <child link="delta_camera_gyro_frame"/>
  </joint>
  <joint name="delta_camera_gyro_optical_joint" type="fixed">
    <origin rpy="-1.5707963267948966 0 -1.5707963267948966" xyz="0 0 0"/>
    <parent link="delta_camera_gyro_frame"/>
    <child link="delta_camera_gyro_optical_frame"/>
  </joint>
  <gazebo reference="delta_camera_link">
    <self_collide>1</self_collide>
    <enable_wind>0</enable_wind>
    <kinematic>0</kinematic>
    <gravity>1</gravity>
    <material>Gazebo/Grey</material>
    <!--<mu>1</mu>-->
    <mu2>1</mu2>
    <fdir1>0 0 0</fdir1>
    <!--<slip1>0</slip1>
      <slip2>0</slip2>-->
    <kp>1e+13</kp>
    <kd>1</kd>
    <!--<max_vel>0.01</max_vel>
      <min_depth>0</min_depth>-->
    <sensor name="delta_cameracolor" type="camera">
      <camera name="delta_camera">
        <horizontal_fov>1.2112585008840648</horizontal_fov>
        <image>
          <width>640</width>
          <height>480</height>
          <format>RGB_INT8</format>
        </image>
        <clip>
          <near>0.1</near>
          <far>100</far>
        </clip>
        <noise>
          <type>gaussian</type>
          <mean>0.0</mean>
          <stddev>0.007</stddev>
        </noise>
      </camera>
      <always_on>False</always_on>
      <update_rate>30</update_rate>
      <visualize>False</visualize>
    </sensor>
    <sensor name="delta_cameraired1" type="camera">
      <camera name="delta_camera">
        <horizontal_fov>1.4870205226991688</horizontal_fov>
        <image>
          <width>1280</width>
          <height>720</height>
          <format>L_INT8</format>
        </image>
        <clip>
          <near>0.1</near>
          <far>100</far>
        </clip>
        <noise>
          <type>gaussian</type>
          <mean>0.0</mean>
          <stddev>0.05</stddev>
        </noise>
      </camera>
      <always_on>0</always_on>
      <update_rate>90</update_rate>
      <visualize>0</visualize>
    </sensor>
    <sensor name="delta_cameraired2" type="camera">
      <camera name="delta_camera">
        <horizontal_fov>1.4870205226991688</horizontal_fov>
        <image>
          <width>1280</width>
          <height>720</height>
          <format>L_INT8</format>
        </image>
        <clip>
          <near>0.1</near>
          <far>100</far>
        </clip>
        <noise>
          <type>gaussian</type>
          <mean>0.0</mean>
          <stddev>0.05</stddev>
        </noise>
      </camera>
      <always_on>0</always_on>
      <update_rate>90</update_rate>
      <visualize>0</visualize>
    </sensor>
    <sensor name="delta_cameradepth" type="depth">
      <camera name="delta_camera">
        <horizontal_fov>1.4870205226991688</horizontal_fov>
        <image>
          <width>1280</width>
          <height>720</height>
        </image>
        <clip>
          <near>0.1</near>
          <far>100</far>
        </clip>
        <noise>
          <type>gaussian</type>
          <mean>0.0</mean>
          <stddev>0.100</stddev>
        </noise>
      </camera>
      <always_on>False</always_on>
      <update_rate>90</update_rate>
      <visualize>0</visualize>
    </sensor>
  </gazebo>
  <gazebo>
    <plugin filename="librealsense_gazebo_plugin.so" name="delta_camera">
      <prefix>delta_camera</prefix>
      <depthUpdateRate>30.0</depthUpdateRate>
      <colorUpdateRate>30.0</colorUpdateRate>
      <infraredUpdateRate>30.0</infraredUpdateRate>
      <depthTopicName>depth/image_raw</depthTopicName>
      <depthCameraInfoTopicName>depth/camera_info</depthCameraInfoTopicName>
      <colorTopicName>color/image_raw</colorTopicName>
      <colorCameraInfoTopicName>color/camera_info</colorCameraInfoTopicName>
      <infrared1TopicName>infra1/image_raw</infrared1TopicName>
      <infrared1CameraInfoTopicName>infra1/camera_info</infrared1CameraInfoTopicName>
      <infrared2TopicName>infra2/image_raw</infrared2TopicName>
      <infrared2CameraInfoTopicName>infra2/camera_info</infrared2CameraInfoTopicName>
      <colorOpticalframeName>delta_camera_color_optical_frame</colorOpticalframeName>
      <depthOpticalframeName>delta_camera_depth_optical_frame</depthOpticalframeName>
      <infrared1OpticalframeName>delta_camera_left_ir_optical_frame</infrared1OpticalframeName>
      <infrared2OpticalframeName>delta_camera_right_ir_optical_frame</infrared2OpticalframeName>
      <rangeMinDepth>0.2</rangeMinDepth>
      <rangeMaxDepth>10.0</rangeMaxDepth>
      <pointCloud>True</pointCloud>
      <pointCloudTopicName>delta_camera_depth/color/points</pointCloudTopicName>
      <pointCloudCutoff>0.25</pointCloudCutoff>
      <pointCloudCutoffMax>9.0</pointCloudCutoffMax>
    </plugin>
  </gazebo>
  <!-- Diameter of the spherical joint supporting the camera -->
  <!-- Camera bounding box -->
  <link name="fixed_camera_2_bb">
    <visual>
      <geometry>
        <cylinder length="0.2" radius="0.125"/>
      </geometry>
      <material name="purple">
        <color rgba="0.01 0.32 0.41 0.1"/>
      </material>
    </visual>
    <collision>
      <geometry>
        <cylinder length="0.2" radius="0.125"/>
      </geometry>
    </collision>
  </link>
  <gazebo reference="fixed_camera_2_bb">
    <visual>
      <material>
        <ambient>0.1 0.5 0.5 0.2</ambient>
        <diffuse>0.1 0.5 0.1 0.2</diffuse>
        <specular>0.1 0.1 0.1 0.2</specular>
        <emissive>0.0 0.0 0.0 0.0</emissive>
      </material>
    </visual>
  </gazebo>
  <joint name="fixed_camera_2_bb_joint" type="fixed">
    <parent link="prl_ur5_base"/>
    <child link="fixed_camera_2_bb"/>
    <origin rpy="0 0 0" xyz="0.611561 0.518683 0.276871"/>
  </joint>
  <!-- Spherical joint holding the camera -->
  <link name="fixed_camera_2_sj">
    <visual>
      <geometry>
        <cylinder length="0.16999999999999998" radius="0.06"/>
      </geometry>
      <material name="purple"/>
    </visual>
    <collision>
      <geometry>
        <cylinder length="0.16999999999999998" radius="0.06"/>
      </geometry>
    </collision>
  </link>
  <gazebo reference="fixed_camera_2_sj">
    <material>Gazebo/BlueGlow</material>
  </gazebo>
  <joint name="fixed_camera_2_sj_joint" type="fixed">
    <parent link="fixed_camera_2_bb"/>
    <child link="fixed_camera_2_sj"/>
    <origin rpy="0 0 0" xyz="0 0 -0.185"/>
  </joint>
  <!-- Vertical extrusion -->
  <link name="fixed_camera_2_vt">
    <visual>
      <geometry>
        <box size="0.105 0.105 0.258121"/>
      </geometry>
      <material name="purple"/>
    </visual>
    <collision>
      <geometry>
        <box size="0.105 0.105 0.258121"/>
      </geometry>
    </collision>
  </link>
  <gazebo reference="fixed_camera_2_vt">
    <material>Gazebo/BlueGlow</material>
  </gazebo>
  <joint name="fixed_camera_2_vt_joint" type="fixed">
    <parent link="fixed_camera_2_sj"/>
    <child link="fixed_camera_2_vt"/>
    <origin rpy="0 0 0" xyz="-0.03 -0.075 -0.019060499999999994"/>
  </joint>
  <!-- Horizontal extrusion -->
  <link name="fixed_hr_2">
    <visual>
      <geometry>
        <box size="0.206183 0.105 0.105"/>
      </geometry>
      <material name="purple"/>
    </visual>
    <collision>
      <geometry>
        <box size="0.206183 0.105 0.105"/>
      </geometry>
    </collision>
  </link>
  <gazebo reference="fixed_hr_2">
    <material>Gazebo/BlueGlow</material>
  </gazebo>
  <joint name="fixed_hr_2_fix" type="fixed">
    <parent link="fixed_camera_2_vt"/>
    <child link="fixed_hr_2"/>
    <origin rpy="0 0 1.570796327" xyz="0 -0.050591500000000005 -0.18156049999999999"/>
  </joint>
  <link name="alpha_camera_calibration_pose"/>
  <joint name="alpha_camera_calibration_pose_joint" type="fixed">
    <origin rpy="-2.0 -0.042 1.608" xyz="1.123226 -0.029688 0.353876"/>
    <parent link="prl_ur5_base"/>
    <child link="alpha_camera_calibration_pose"/>
  </joint>
  <!-- camera body, with origin at bottom screw mount -->
  <joint name="alpha_camera_joint" type="fixed">
    <origin rpy="1.5707963267948966 -1.5707963267948966 0" xyz="0.0325 0.0125 -0.0106"/>
    <parent link="alpha_camera_calibration_pose"/>
    <child link="alpha_camera_bottom_screw_frame"/>
  </joint>
  <link name="alpha_camera_bottom_screw_frame"/>
  <joint name="alpha_camera_link_joint" type="fixed">
    <origin rpy="0 0 0" xyz="0.010600000000000002 0.0175 0.0125"/>
    <parent link="alpha_camera_bottom_screw_frame"/>
    <child link="alpha_camera_link"/>
  </joint>
  <link name="alpha_camera_link">
    <visual>
      <!-- the mesh origin is at front plate in between the two infrared camera axes -->
      <origin rpy="1.5707963267948966 0 1.5707963267948966" xyz="0.0043 -0.0175 0"/>
      <geometry>
        <mesh filename="package://ur5/data/0008_d435.dae"/>
      </geometry>
    </visual>
    <collision>
      <origin rpy="0 0 0" xyz="0 -0.0175 0"/>
      <geometry>
        <box size="0.02505 0.09 0.025"/>
      </geometry>
    </collision>
    <inertial>
      <!-- The following are not reliable values, and should not be used for modeling -->
      <mass value="0.072"/>
      <origin xyz="0 0 0"/>
      <inertia ixx="0.003881243" ixy="0.0" ixz="0.0" iyy="0.000498940" iyz="0.0" izz="0.003879257"/>
    </inertial>
  </link>
  <!-- camera depth joints and links -->
  <joint name="alpha_camera_depth_joint" type="fixed">
    <origin rpy="0 0 0" xyz="0 0 0"/>
    <parent link="alpha_camera_link"/>
    <child link="alpha_camera_depth_frame"/>
  </joint>
  <link name="alpha_camera_depth_frame"/>
  <joint name="alpha_camera_depth_optical_joint" type="fixed">
    <origin rpy="-1.5707963267948966 0 -1.5707963267948966" xyz="0 0 0"/>
    <parent link="alpha_camera_depth_frame"/>
    <child link="alpha_camera_depth_optical_frame"/>
  </joint>
  <link name="alpha_camera_depth_optical_frame"/>
  <!-- camera left IR joints and links -->
  <joint name="alpha_camera_infra1_joint" type="fixed">
    <origin rpy="0 0 0" xyz="0 0.0 0"/>
    <parent link="alpha_camera_link"/>
    <child link="alpha_camera_infra1_frame"/>
  </joint>
  <link name="alpha_camera_infra1_frame"/>
  <joint name="alpha_camera_infra1_optical_joint" type="fixed">
    <origin rpy="-1.5707963267948966 0 -1.5707963267948966" xyz="0 0 0"/>
    <parent link="alpha_camera_infra1_frame"/>
    <child link="alpha_camera_infra1_optical_frame"/>
  </joint>
  <link name="alpha_camera_infra1_optical_frame"/>
  <!-- camera right IR joints and links -->
  <joint name="alpha_camera_infra2_joint" type="fixed">
    <origin rpy="0 0 0" xyz="0 -0.05 0"/>
    <parent link="alpha_camera_link"/>
    <child link="alpha_camera_infra2_frame"/>
  </joint>
  <link name="alpha_camera_infra2_frame"/>
  <joint name="alpha_camera_infra2_optical_joint" type="fixed">
    <origin rpy="-1.5707963267948966 0 -1.5707963267948966" xyz="0 0 0"/>
    <parent link="alpha_camera_infra2_frame"/>
    <child link="alpha_camera_infra2_optical_frame"/>
  </joint>
  <link name="alpha_camera_infra2_optical_frame"/>
  <!-- camera color joints and links -->
  <joint name="alpha_camera_color_joint" type="fixed">
    <origin rpy="0 0 0" xyz="0 0.015 0"/>
    <parent link="alpha_camera_link"/>
    <child link="alpha_camera_color_frame"/>
  </joint>
  <link name="alpha_camera_color_frame"/>
  <joint name="alpha_camera_color_optical_joint" type="fixed">
    <origin rpy="-1.5707963267948966 0 -1.5707963267948966" xyz="0 0 0"/>
    <parent link="alpha_camera_color_frame"/>
    <child link="alpha_camera_color_optical_frame"/>
  </joint>
  <link name="alpha_camera_color_optical_frame"/>
  <link name="alpha_camera_accel_frame"/>
  <link name="alpha_camera_accel_optical_frame"/>
  <link name="alpha_camera_gyro_frame"/>
  <link name="alpha_camera_gyro_optical_frame"/>
  <joint name="alpha_camera_accel_joint" type="fixed">
    <origin rpy="0 0 0" xyz="-0.01174 -0.00552 0.0051"/>
    <parent link="alpha_camera_link"/>
    <child link="alpha_camera_accel_frame"/>
  </joint>
  <joint name="alpha_camera_accel_optical_joint" type="fixed">
    <origin rpy="-1.5707963267948966 0 -1.5707963267948966" xyz="0 0 0"/>
    <parent link="alpha_camera_accel_frame"/>
    <child link="alpha_camera_accel_optical_frame"/>
  </joint>
  <joint name="alpha_camera_gyro_joint" type="fixed">
    <origin rpy="0 0 0" xyz="-0.01174 -0.00552 0.0051"/>
    <parent link="alpha_camera_link"/>
    <child link="alpha_camera_gyro_frame"/>
  </joint>
  <joint name="alpha_camera_gyro_optical_joint" type="fixed">
    <origin rpy="-1.5707963267948966 0 -1.5707963267948966" xyz="0 0 0"/>
    <parent link="alpha_camera_gyro_frame"/>
    <child link="alpha_camera_gyro_optical_frame"/>
  </joint>
  <gazebo reference="alpha_camera_link">
    <self_collide>1</self_collide>
    <enable_wind>0</enable_wind>
    <kinematic>0</kinematic>
    <gravity>1</gravity>
    <material>Gazebo/Grey</material>
    <!--<mu>1</mu>-->
    <mu2>1</mu2>
    <fdir1>0 0 0</fdir1>
    <!--<slip1>0</slip1>
      <slip2>0</slip2>-->
    <kp>1e+13</kp>
    <kd>1</kd>
    <!--<max_vel>0.01</max_vel>
      <min_depth>0</min_depth>-->
    <sensor name="alpha_cameracolor" type="camera">
      <camera name="alpha_camera">
        <horizontal_fov>1.2112585008840648</horizontal_fov>
        <image>
          <width>640</width>
          <height>480</height>
          <format>RGB_INT8</format>
        </image>
        <clip>
          <near>0.1</near>
          <far>100</far>
        </clip>
        <noise>
          <type>gaussian</type>
          <mean>0.0</mean>
          <stddev>0.007</stddev>
        </noise>
      </camera>
      <always_on>False</always_on>
      <update_rate>30</update_rate>
      <visualize>False</visualize>
    </sensor>
    <sensor name="alpha_cameraired1" type="camera">
      <camera name="alpha_camera">
        <horizontal_fov>1.4870205226991688</horizontal_fov>
        <image>
          <width>1280</width>
          <height>720</height>
          <format>L_INT8</format>
        </image>
        <clip>
          <near>0.1</near>
          <far>100</far>
        </clip>
        <noise>
          <type>gaussian</type>
          <mean>0.0</mean>
          <stddev>0.05</stddev>
        </noise>
      </camera>
      <always_on>0</always_on>
      <update_rate>90</update_rate>
      <visualize>0</visualize>
    </sensor>
    <sensor name="alpha_cameraired2" type="camera">
      <camera name="alpha_camera">
        <horizontal_fov>1.4870205226991688</horizontal_fov>
        <image>
          <width>1280</width>
          <height>720</height>
          <format>L_INT8</format>
        </image>
        <clip>
          <near>0.1</near>
          <far>100</far>
        </clip>
        <noise>
          <type>gaussian</type>
          <mean>0.0</mean>
          <stddev>0.05</stddev>
        </noise>
      </camera>
      <always_on>0</always_on>
      <update_rate>90</update_rate>
      <visualize>0</visualize>
    </sensor>
    <sensor name="alpha_cameradepth" type="depth">
      <camera name="alpha_camera">
        <horizontal_fov>1.4870205226991688</horizontal_fov>
        <image>
          <width>1280</width>
          <height>720</height>
        </image>
        <clip>
          <near>0.1</near>
          <far>100</far>
        </clip>
        <noise>
          <type>gaussian</type>
          <mean>0.0</mean>
          <stddev>0.100</stddev>
        </noise>
      </camera>
      <always_on>False</always_on>
      <update_rate>90</update_rate>
      <visualize>0</visualize>
    </sensor>
  </gazebo>
  <gazebo>
    <plugin filename="librealsense_gazebo_plugin.so" name="alpha_camera">
      <prefix>alpha_camera</prefix>
      <depthUpdateRate>30.0</depthUpdateRate>
      <colorUpdateRate>30.0</colorUpdateRate>
      <infraredUpdateRate>30.0</infraredUpdateRate>
      <depthTopicName>depth/image_raw</depthTopicName>
      <depthCameraInfoTopicName>depth/camera_info</depthCameraInfoTopicName>
      <colorTopicName>color/image_raw</colorTopicName>
      <colorCameraInfoTopicName>color/camera_info</colorCameraInfoTopicName>
      <infrared1TopicName>infra1/image_raw</infrared1TopicName>
      <infrared1CameraInfoTopicName>infra1/camera_info</infrared1CameraInfoTopicName>
      <infrared2TopicName>infra2/image_raw</infrared2TopicName>
      <infrared2CameraInfoTopicName>infra2/camera_info</infrared2CameraInfoTopicName>
      <colorOpticalframeName>alpha_camera_color_optical_frame</colorOpticalframeName>
      <depthOpticalframeName>alpha_camera_depth_optical_frame</depthOpticalframeName>
      <infrared1OpticalframeName>alpha_camera_left_ir_optical_frame</infrared1OpticalframeName>
      <infrared2OpticalframeName>alpha_camera_right_ir_optical_frame</infrared2OpticalframeName>
      <rangeMinDepth>0.2</rangeMinDepth>
      <rangeMaxDepth>10.0</rangeMaxDepth>
      <pointCloud>True</pointCloud>
      <pointCloudTopicName>alpha_camera_depth/color/points</pointCloudTopicName>
      <pointCloudCutoff>0.25</pointCloudCutoff>
      <pointCloudCutoffMax>9.0</pointCloudCutoffMax>
    </plugin>
  </gazebo>
  <!-- Diameter of the spherical joint supporting the camera -->
  <!-- Camera bounding box -->
  <link name="fixed_camera_3_bb">
    <visual>
      <geometry>
        <cylinder length="0.2" radius="0.125"/>
      </geometry>
      <material name="purple">
        <color rgba="0.01 0.32 0.41 0.1"/>
      </material>
    </visual>
    <collision>
      <geometry>
        <cylinder length="0.2" radius="0.125"/>
      </geometry>
    </collision>
  </link>
  <gazebo reference="fixed_camera_3_bb">
    <visual>
      <material>
        <ambient>0.1 0.5 0.5 0.2</ambient>
        <diffuse>0.1 0.5 0.1 0.2</diffuse>
        <specular>0.1 0.1 0.1 0.2</specular>
        <emissive>0.0 0.0 0.0 0.0</emissive>
      </material>
    </visual>
  </gazebo>
  <joint name="fixed_camera_3_bb_joint" type="fixed">
    <parent link="prl_ur5_base"/>
    <child link="fixed_camera_3_bb"/>
    <origin rpy="0 0 0" xyz="1.123226 -0.029688 0.353876"/>
  </joint>
  <!-- Spherical joint holding the camera -->
  <link name="fixed_camera_3_sj">
    <visual>
      <geometry>
        <cylinder length="0.16999999999999998" radius="0.06"/>
      </geometry>
      <material name="purple"/>
    </visual>
    <collision>
      <geometry>
        <cylinder length="0.16999999999999998" radius="0.06"/>
      </geometry>
    </collision>
  </link>
  <gazebo reference="fixed_camera_3_sj">
    <material>Gazebo/BlueGlow</material>
  </gazebo>
  <joint name="fixed_camera_3_sj_joint" type="fixed">
    <parent link="fixed_camera_3_bb"/>
    <child link="fixed_camera_3_sj"/>
    <origin rpy="0 0 0" xyz="0 0 -0.185"/>
  </joint>
  <!-- Vertical extrusion -->
  <link name="fixed_camera_3_vt">
    <visual>
      <geometry>
        <box size="0.105 0.105 0.33012600000000003"/>
      </geometry>
      <material name="purple"/>
    </visual>
    <collision>
      <geometry>
        <box size="0.105 0.105 0.33012600000000003"/>
      </geometry>
    </collision>
  </link>
  <gazebo reference="fixed_camera_3_vt">
    <material>Gazebo/BlueGlow</material>
  </gazebo>
  <joint name="fixed_camera_3_vt_joint" type="fixed">
    <parent link="fixed_camera_3_sj"/>
    <child link="fixed_camera_3_vt"/>
    <origin rpy="0 0 0" xyz="0.08 -0.02 -0.06006300000000002"/>
  </joint>
  <!-- Horizontal extrusion -->
  <link name="fixed_hr_3">
    <visual>
      <geometry>
        <box size="0.3357260000000001 0.105 0.105"/>
      </geometry>
      <material name="purple"/>
    </visual>
    <collision>
      <geometry>
        <box size="0.3357260000000001 0.105 0.105"/>
      </geometry>
    </collision>
  </link>
  <gazebo reference="fixed_hr_3">
    <material>Gazebo/BlueGlow</material>
  </gazebo>
  <joint name="fixed_hr_3_fix" type="fixed">
    <parent link="fixed_camera_3_vt"/>
    <child link="fixed_hr_3"/>
    <origin rpy="0 0 0" xyz="-0.11536300000000005 0 -0.217563"/>
  </joint>
  <link name="backwall_link">
    <visual>
      <geometry>
        <box size="3 0.1 2.5"/>
      </geometry>
      <material name="grey">
        <color rgba="0.8 0.8 0.8 0.2"/>
      </material>
    </visual>
    <collision>
      <geometry>
        <box size="3 0.1 2.5"/>
      </geometry>
    </collision>
  </link>
  <joint name="backwall_fix" type="fixed">
    <parent link="prl_ur5_base"/>
    <child link="backwall_link"/>
    <origin rpy="0.0 0.0 0.0" xyz="0 -1.05 0.5"/>
  </joint>
  <link name="ceiling_link">
    <visual>
      <geometry>
        <box size="3 1.95 0.1"/>
      </geometry>
      <material name="grey">
        <color rgba="0.8 0.8 0.8 0.1"/>
      </material>
    </visual>
    <collision>
      <geometry>
        <box size="3 1.95 0.1"/>
      </geometry>
    </collision>
  </link>
  <joint name="ceiling_fix" type="fixed">
    <parent link="prl_ur5_base"/>
    <child link="ceiling_link"/>
    <origin rpy="0.0 0.0 0.0" xyz="0 0 1.3"/>
  </joint>
  <!--
    Base UR robot series xacro macro.

    NOTE: this is NOT a URDF. It cannot directly be loaded by consumers
    expecting a flattened '.urdf' file. See the top-level '.xacro' for that
    (but note: that .xacro must still be processed by the xacro command).

    For use in '.launch' files: use one of the 'load_urX.launch' convenience
    launch files.

    This file models the base kinematic chain of a UR robot, which then gets
    parameterised by various configuration files to convert it into a UR3(e),
    UR5(e), UR10(e) or UR16e.

    NOTE: the default kinematic parameters (ie: link lengths, frame locations,
    offets, etc) do not correspond to any particular robot. They are defaults
    only. There WILL be non-zero offsets between the Forward Kinematics results
    in TF (ie: robot_state_publisher) and the values reported by the Teach
    Pendant.

    For accurate (and robot-specific) transforms, the 'kinematics_parameters_file'
    parameter MUST point to a .yaml file containing the appropriate values for
    the targetted robot.

    If using the UniversalRobots/Universal_Robots_ROS_Driver, follow the steps
    described in the readme of that repository to extract the kinematic
    calibration from the controller and generate the required .yaml file.

    Main author of the migration to yaml configs: Ludovic Delval.

    Contributors to previous versions (in no particular order):

     - Felix Messmer
     - Kelsey Hawkins
     - Wim Meeussen
     - Shaun Edwards
     - Nadia Hammoudeh Garcia
     - Dave Hershberger
     - G. vd. Hoorn
     - Philip Long
     - Dave Coleman
     - Miguel Prada
     - Mathias Luedtke
     - Marcel Schnirring
     - Felix von Drigalski
     - Felix Exner
     - Jimmy Da Silva
     - Ajit Krisshna N L
     - Muhammad Asif Rana
  -->
  <!--
    NOTE: the macro defined in this file is NOT part of the public API of this
          package. Users CANNOT rely on this file being available, or stored in
          this location. Nor can they rely on the existence of the macro.
  -->
  <transmission name="left_shoulder_pan_trans">
    <type>transmission_interface/SimpleTransmission</type>
    <joint name="left_shoulder_pan_joint">
      <hardwareInterface>hardware_interface/PositionJointInterface</hardwareInterface>
    </joint>
    <actuator name="left_shoulder_pan_motor">
      <mechanicalReduction>1</mechanicalReduction>
    </actuator>
  </transmission>
  <transmission name="left_shoulder_lift_trans">
    <type>transmission_interface/SimpleTransmission</type>
    <joint name="left_shoulder_lift_joint">
      <hardwareInterface>hardware_interface/PositionJointInterface</hardwareInterface>
    </joint>
    <actuator name="left_shoulder_lift_motor">
      <mechanicalReduction>1</mechanicalReduction>
    </actuator>
  </transmission>
  <transmission name="left_elbow_trans">
    <type>transmission_interface/SimpleTransmission</type>
    <joint name="left_elbow_joint">
      <hardwareInterface>hardware_interface/PositionJointInterface</hardwareInterface>
    </joint>
    <actuator name="left_elbow_motor">
      <mechanicalReduction>1</mechanicalReduction>
    </actuator>
  </transmission>
  <transmission name="left_wrist_1_trans">
    <type>transmission_interface/SimpleTransmission</type>
    <joint name="left_wrist_1_joint">
      <hardwareInterface>hardware_interface/PositionJointInterface</hardwareInterface>
    </joint>
    <actuator name="left_wrist_1_motor">
      <mechanicalReduction>1</mechanicalReduction>
    </actuator>
  </transmission>
  <transmission name="left_wrist_2_trans">
    <type>transmission_interface/SimpleTransmission</type>
    <joint name="left_wrist_2_joint">
      <hardwareInterface>hardware_interface/PositionJointInterface</hardwareInterface>
    </joint>
    <actuator name="left_wrist_2_motor">
      <mechanicalReduction>1</mechanicalReduction>
    </actuator>
  </transmission>
  <transmission name="left_wrist_3_trans">
    <type>transmission_interface/SimpleTransmission</type>
    <joint name="left_wrist_3_joint">
      <hardwareInterface>hardware_interface/PositionJointInterface</hardwareInterface>
    </joint>
    <actuator name="left_wrist_3_motor">
      <mechanicalReduction>1</mechanicalReduction>
    </actuator>
  </transmission>
  <!-- links: main serial chain -->
  <link name="left_base_link"/>
  <link name="left_base_link_inertia">
    <visual>
      <origin rpy="0 0 3.141592653589793" xyz="0 0 0"/>
      <geometry>
        <mesh filename="package://ur5/data/0037_base.dae"/>
      </geometry>
      <material name="LightGrey">
        <color rgba="0.7 0.7 0.7 1.0"/>
      </material>
    </visual>
    <collision>
      <origin rpy="0 0 3.141592653589793" xyz="0 0 0"/>
      <geometry>
        <mesh filename="package://ur5/data/0014_base.stl"/>
      </geometry>
    </collision>
    <inertial>
      <mass value="4.0"/>
      <origin rpy="0 0 0" xyz="0 0 0"/>
      <inertia ixx="0.00443333156" ixy="0.0" ixz="0.0" iyy="0.00443333156" iyz="0.0" izz="0.0072"/>
    </inertial>
  </link>
  <link name="left_shoulder_link">
    <visual>
      <origin rpy="0 0 3.141592653589793" xyz="0 0 0"/>
      <geometry>
        <mesh filename="package://ur5/data/0006_shoulder.dae"/>
      </geometry>
      <material name="LightGrey">
        <color rgba="0.7 0.7 0.7 1.0"/>
      </material>
    </visual>
    <collision>
      <origin rpy="0 0 3.141592653589793" xyz="0 0 0"/>
      <geometry>
        <mesh filename="package://ur5/data/0023_shoulder.stl"/>
      </geometry>
    </collision>
    <inertial>
      <mass value="3.7"/>
      <origin rpy="0 0 0" xyz="0 0 0"/>
      <inertia ixx="0.014972352344389999" ixy="0.0" ixz="0.0" iyy="0.014972352344389999" iyz="0.0" izz="0.01040625"/>
    </inertial>
  </link>
  <link name="left_upper_arm_link">
    <visual>
      <origin rpy="1.5707963267948966 0 -1.5707963267948966" xyz="0 0 0.13585"/>
      <geometry>
        <mesh filename="package://ur5/data/0035_upperarm.dae"/>
      </geometry>
      <material name="LightGrey">
        <color rgba="0.7 0.7 0.7 1.0"/>
      </material>
    </visual>
    <collision>
      <origin rpy="1.5707963267948966 0 -1.5707963267948966" xyz="0 0 0.13585"/>
      <geometry>
        <mesh filename="package://ur5/data/0013_upperarm.stl"/>
      </geometry>
    </collision>
    <inertial>
      <mass value="8.393"/>
      <origin rpy="0 1.5707963267948966 0" xyz="-0.2125 0.0 0.136"/>
      <inertia ixx="0.1338857818623325" ixy="0.0" ixz="0.0" iyy="0.1338857818623325" iyz="0.0" izz="0.0151074"/>
    </inertial>
  </link>
  <link name="left_forearm_link">
    <visual>
      <origin rpy="1.5707963267948966 0 -1.5707963267948966" xyz="0 0 0.0165"/>
      <geometry>
        <mesh filename="package://ur5/data/0036_forearm.dae"/>
      </geometry>
      <material name="LightGrey">
        <color rgba="0.7 0.7 0.7 1.0"/>
      </material>
    </visual>
    <collision>
      <origin rpy="1.5707963267948966 0 -1.5707963267948966" xyz="0 0 0.0165"/>
      <geometry>
        <mesh filename="package://ur5/data/0017_forearm.stl"/>
      </geometry>
    </collision>
    <inertial>
      <mass value="2.275"/>
      <origin rpy="0 1.5707963267948966 0" xyz="-0.196125 0.0 0.0165"/>
      <inertia ixx="0.03121679102890359" ixy="0.0" ixz="0.0" iyy="0.03121679102890359" iyz="0.0" izz="0.004095"/>
    </inertial>
  </link>
  <link name="left_wrist_1_link">
    <visual>
      <!-- TODO: Move this to a parameter -->
      <origin rpy="1.5707963267948966 0 0" xyz="0 0 -0.093"/>
      <geometry>
        <mesh filename="package://ur5/data/0002_wrist1.dae"/>
      </geometry>
      <material name="LightGrey">
        <color rgba="0.7 0.7 0.7 1.0"/>
      </material>
    </visual>
    <collision>
      <origin rpy="1.5707963267948966 0 0" xyz="0 0 -0.093"/>
      <geometry>
        <mesh filename="package://ur5/data/0031_wrist1.stl"/>
      </geometry>
    </collision>
    <inertial>
      <mass value="1.219"/>
      <origin rpy="0 0 0" xyz="0 0 0"/>
      <inertia ixx="0.0020138887777775" ixy="0.0" ixz="0.0" iyy="0.0020138887777775" iyz="0.0" izz="0.0021942"/>
    </inertial>
  </link>
  <link name="left_wrist_2_link">
    <visual>
      <origin rpy="0 0 0" xyz="0 0 -0.095"/>
      <geometry>
        <mesh filename="package://ur5/data/0015_wrist2.dae"/>
      </geometry>
      <material name="LightGrey">
        <color rgba="0.7 0.7 0.7 1.0"/>
      </material>
    </visual>
    <collision>
      <origin rpy="0 0 0" xyz="0 0 -0.095"/>
      <geometry>
        <mesh filename="package://ur5/data/0019_wrist2.stl"/>
      </geometry>
    </collision>
    <inertial>
      <mass value="1.219"/>
      <origin rpy="0 0 0" xyz="0 0 0"/>
      <inertia ixx="0.0018310388509175" ixy="0.0" ixz="0.0" iyy="0.0018310388509175" iyz="0.0" izz="0.0021942"/>
    </inertial>
  </link>
  <link name="left_wrist_3_link">
    <visual>
      <origin rpy="1.5707963267948966 0 0" xyz="0 0 -0.0818"/>
      <geometry>
        <mesh filename="package://ur5/data/0022_wrist3.dae"/>
      </geometry>
      <material name="LightGrey">
        <color rgba="0.7 0.7 0.7 1.0"/>
      </material>
    </visual>
    <collision>
      <origin rpy="1.5707963267948966 0 0" xyz="0 0 -0.0818"/>
      <geometry>
        <mesh filename="package://ur5/data/0007_wrist3.stl"/>
      </geometry>
    </collision>
    <inertial>
      <mass value="0.1879"/>
      <origin rpy="0 0 0" xyz="0.0 0.0 -0.01525"/>
      <inertia ixx="8.062472608343e-05" ixy="0.0" ixz="0.0" iyy="8.062472608343e-05" iyz="0.0" izz="0.0001321171875"/>
    </inertial>
  </link>
  <!-- joints: main serial chain -->
  <joint name="left_base_link-base_link_inertia" type="fixed">
    <parent link="left_base_link"/>
    <child link="left_base_link_inertia"/>
    <!-- 'base_link' is REP-103 aligned (so X+ forward), while the internal
           frames of the robot/controller have X+ pointing backwards.
           Use the joint between 'base_link' and 'base_link_inertia' (a dummy
           link/frame) to introduce the necessary rotation over Z (of pi rad).
      -->
    <origin rpy="0 0 3.141592653589793" xyz="0 0 0"/>
  </joint>
  <joint name="left_shoulder_pan_joint" type="revolute">
    <parent link="left_base_link_inertia"/>
    <child link="left_shoulder_link"/>
    <origin rpy="0 0 -2.749502368353233e-06" xyz="0 0 0.08918501667510044"/>
    <axis xyz="0 0 1"/>
    <limit effort="150.0" lower="-3.141592653589793" upper="3.141592653589793" velocity="3.141592653589793"/>
    <dynamics damping="0" friction="0"/>
  </joint>
  <joint name="left_shoulder_lift_joint" type="revolute">
    <parent link="left_shoulder_link"/>
    <child link="left_upper_arm_link"/>
    <origin rpy="1.570525232048461 0 1.921977645271288e-05" xyz="0.000107269917097091 0 0"/>
    <axis xyz="0 0 1"/>
    <limit effort="150.0" lower="-3.141592653589793" upper="3.141592653589793" velocity="3.141592653589793"/>
    <dynamics damping="0" friction="0"/>
  </joint>
  <joint name="left_elbow_joint" type="revolute">
    <parent link="left_upper_arm_link"/>
    <child link="left_forearm_link"/>
    <origin rpy="0.000369043097955391 0.0005901088854669997 5.099356470552253e-05" xyz="-0.4254954077228868 0 0"/>
    <axis xyz="0 0 1"/>
    <limit effort="150.0" lower="-3.141592653589793" upper="3.141592653589793" velocity="3.141592653589793"/>
    <dynamics damping="0" friction="0"/>
  </joint>
  <joint name="left_wrist_1_joint" type="revolute">
    <parent link="left_forearm_link"/>
    <child link="left_wrist_1_link"/>
    <origin rpy="0.007357465532194211 0.001366817683118754 5.507031446329021e-05" xyz="-0.3924103068549387 -0.0008152208483887941 0.1107998582993478"/>
    <axis xyz="0 0 1"/>
    <limit effort="28.0" lower="-3.141592653589793" upper="3.141592653589793" velocity="3.141592653589793"/>
    <dynamics damping="0" friction="0"/>
  </joint>
  <joint name="left_wrist_2_joint" type="revolute">
    <parent link="left_wrist_1_link"/>
    <child link="left_wrist_2_link"/>
    <origin rpy="1.569689148919446 0 -3.884674228365137e-06" xyz="1.88989034199928e-05 -0.09486007969995007 0.000105027024422771"/>
    <axis xyz="0 0 1"/>
    <limit effort="28.0" lower="-3.141592653589793" upper="3.141592653589793" velocity="3.141592653589793"/>
    <dynamics damping="0" friction="0"/>
  </joint>
  <joint name="left_wrist_3_joint" type="revolute">
    <parent link="left_wrist_2_link"/>
    <child link="left_wrist_3_link"/>
    <origin rpy="1.571563236607506 3.141592653589793 3.141560506388899" xyz="8.727327772039603e-05 0.08253620113769419 6.32978349575522e-05"/>
    <axis xyz="0 0 1"/>
    <limit effort="28.0" lower="-3.141592653589793" upper="3.141592653589793" velocity="3.141592653589793"/>
    <dynamics damping="0" friction="0"/>
  </joint>
  <!-- ROS-Industrial 'base' frame: base_link to UR 'Base' Coordinates transform -->
  <link name="left_base"/>
  <joint name="left_base_link-base_fixed_joint" type="fixed">
    <!-- Note the rotation over Z of pi radians: as base_link is REP-103
           aligned (ie: has X+ forward, Y+ left and Z+ up), this is needed
           to correctly align 'base' with the 'Base' coordinate system of
           the UR controller.
      -->
    <origin rpy="0 0 3.141592653589793" xyz="0 0 0"/>
    <parent link="left_base_link"/>
    <child link="left_base"/>
  </joint>
  <!-- ROS-Industrial 'flange' frame: attachment point for EEF models -->
  <link name="left_flange"/>
  <joint name="left_wrist_3-flange" type="fixed">
    <parent link="left_wrist_3_link"/>
    <child link="left_flange"/>
    <origin rpy="0 -1.5707963267948966 -1.5707963267948966" xyz="0 0 0"/>
  </joint>
  <!-- ROS-Industrial 'tool0' frame: all-zeros tool frame -->
  <link name="left_tool0"/>
  <joint name="left_flange-tool0" type="fixed">
    <!-- default toolframe: X+ left, Y+ up, Z+ front -->
    <origin rpy="1.5707963267948966 0 1.5707963267948966" xyz="0 0 0"/>
    <parent link="left_flange"/>
    <child link="left_tool0"/>
  </joint>
  <joint name="left_base_joint" type="fixed">
    <origin rpy="3.1392474585649786 -0.7832185966785736 3.1383051269108933" xyz="-0.17469280010643373 -0.0042453758457910995 0.7900226386441459"/>
    <parent link="stand_link"/>
    <child link="left_base_link"/>
  </joint>
  <!-- mount the fts to the robot -->
  <joint name="left_ft300_fix" type="fixed">
    <origin rpy="0 0 -1.5707963267948966" xyz="0 0 -0.004"/>
    <parent link="left_tool0"/>
    <child link="left_ft300_mounting_plate"/>
  </joint>
  <!-- Link representing the FT300 force-torque sensor -->
  <link name="left_ft300_sensor">
    <inertial>
      <origin rpy="0 0 0" xyz="0 0 -0.017"/>
      <mass value="0.300"/>
      <inertia ixx="0.000262" ixy="0" ixz="1e-06" iyx="0" iyy="0.000265" iyz="1e-06" izx="-1e-06" izy="1e-06" izz="0.000219"/>
    </inertial>
    <visual>
      <origin rpy="0 0 0" xyz="0 0 0"/>
      <geometry>
        <mesh filename="package://ur5/data/0025_robotiq_ft300.STL"/>
      </geometry>
      <material name="Robotiq-Black">
        <color rgba="0.2 0.2 0.2 1.0"/>
      </material>
    </visual>
    <collision>
      <origin rpy="0 0 0" xyz="0 0 0"/>
      <geometry>
        <mesh filename="package://ur5/data/0005_robotiq_ft300.STL"/>
      </geometry>
    </collision>
  </link>
  <!-- Link representing the FT300 mounting plate -->
  <link name="left_ft300_mounting_plate">
    <visual>
      <origin rpy="0 0 0" xyz="0 0 0"/>
      <geometry>
        <mesh filename="package://ur5/data/0004_robotiq_ft300-G-062-COUPLING_G-50-4M6-1D6_20181119.STL"/>
      </geometry>
      <material name="Robotiq-Grey">
        <color rgba="0.4 0.4 0.4 1.0"/>
      </material>
    </visual>
    <collision>
      <origin rpy="0 0 0" xyz="0 0 0"/>
      <geometry>
        <mesh filename="package://ur5/data/0027_robotiq_ft300-G-062-COUPLING_G-50-4M6-1D6_20181119.STL"/>
      </geometry>
    </collision>
  </link>
  <!-- Connect force sensor with mounting/coupling plate -->
  <joint name="left_ft300_mounting_plate_joint" type="fixed">
    <origin rpy="0 3.141592653589793 0" xyz="0 0 0.0415"/>
    <parent link="left_ft300_mounting_plate"/>
    <child link="left_ft300_sensor"/>
  </joint>
  <!-- FORCE REFERENCE FRAME _______________________________________________________________________________
            As specified in the documentation:
            - The Z axis passes through the center of the depression with positive direction in the tool direction.
            - The X axis traces a symmetric line centered on the connector; the positive direction
                points the opposite way away from the connector.
            - The Y axis uses the right hand thumb rule according to X-Z. -->
  <joint name="left_measurment_joint" type="fixed">
    <origin rpy="0 3.141592653589793 -1.5707963267948966" xyz="0 0 0"/>
    <parent link="left_ft300_sensor"/>
    <child link="left_robotiq_ft_frame_id"/>
  </joint>
  <link name="left_robotiq_ft_frame_id"/>
  <!-- enable force_torque sensor -->
  <gazebo reference="left_measurment_joint">
    <preserveFixedJoint>true</preserveFixedJoint>
    <sensor name="left_force_torque" type="force_torque">
      <always_on>0</always_on>
      <update_rate>100.0</update_rate>
      <visualize>False</visualize>
      <force_torque>
        <frame>left_robotiq_ft_frame_id</frame>
        <measure_direction>child_to_parent</measure_direction>
      </force_torque>
    </sensor>
  </gazebo>
  <!-- ft_sensor plugin -->
  <gazebo>
    <plugin filename="libgazebo_ros_ft_sensor.so" name="left_ft_sensor">
      <updateRate>100.0</updateRate>
      <topicName>left_ft_wrench</topicName>
      <jointName>left_measurment_joint</jointName>
      <noise>
        <type>gaussian</type>
        <mean>0.0</mean>
        <stddev>0.003</stddev>
      </noise>
    </plugin>
  </gazebo>
  <!-- override link properties -->
  <gazebo reference="left_ft300_sensor">
    <material>Gazebo/Black</material>
    <selfCollide>true</selfCollide>
  </gazebo>
  <gazebo reference="left_ft300_mounting_plate">
    <material>Gazebo/Black</material>
    <selfCollide>true</selfCollide>
  </gazebo>
  <!-- tool frame -->
  <link name="left_tool"/>
  <joint name="left_tool_joint" type="fixed">
    <origin rpy="0 0 -3.141592653589793" xyz="0 0 0"/>
    <parent link="left_robotiq_ft_frame_id"/>
    <child link="left_tool"/>
  </joint>
  <!-- bracket -->
  <link name="left_gripper_bracket">
    <visual>
      <geometry>
        <mesh filename="package://ur5/data/0033_single_bracket.stl"/>
      </geometry>
      <material name="onrobot/grey"/>
    </visual>
    <collision>
      <geometry>
        <mesh filename="package://ur5/data/0032_single_bracket.stl"/>
      </geometry>
    </collision>
    <inertial>
      <mass value="0.001"/>
      <inertia ixx="0.001" ixy="0.0" ixz="0.0" iyy="0.001" iyz="0.0" izz="0.001"/>
    </inertial>
  </link>
  <joint name="left_gripper_bracket_joint" type="fixed">
    <parent link="left_tool"/>
    <child link="left_gripper_bracket"/>
    <origin rpy="0.0 0.0 0.0" xyz="0.0 0.0 0.0"/>
  </joint>
  <!-- body -->
  <link name="left_gripper_body">
    <visual>
      <geometry>
        <mesh filename="package://ur5/data/0018_body.stl"/>
      </geometry>
      <material name="onrobot/light_grey"/>
    </visual>
    <collision>
      <geometry>
        <mesh filename="package://ur5/data/0024_body.stl"/>
      </geometry>
    </collision>
    <inertial>
      <mass value="0.78"/>
      <inertia ixx="0.001" ixy="0.0" ixz="0.0" iyy="0.001" iyz="0.0" izz="0.001"/>
    </inertial>
  </link>
  <joint name="left_gripper_body_joint" type="fixed">
    <parent link="left_gripper_bracket"/>
    <child link="left_gripper_body"/>
    <origin rpy="0.0 0.0 0.0" xyz="0.0 0.0 0.051"/>
  </joint>
  <!-- grasp frame -->
  <link name="left_gripper_grasp_frame"/>
  <joint name="left_gripper_grasp_frame_joint" type="fixed">
    <parent link="left_gripper_body"/>
    <child link="left_gripper_grasp_frame"/>
    <origin rpy="0.0 0.0 0.0" xyz="0.0 0.0 0.19"/>
  </joint>
  <!-- origin frame -->
  <link name="left_gripper_finger_1_origin">
    <inertial>
      <mass value="0.001"/>
      <inertia ixx="0.00001" ixy="0.0" ixz="0.0" iyy="0.00001" iyz="0.0" izz="0.00001"/>
    </inertial>
  </link>
  <joint name="left_gripper_finger_1_origin_joint" type="fixed">
    <parent link="left_gripper_body"/>
    <child link="left_gripper_finger_1_origin"/>
    <origin rpy="0 0 0" xyz="0 0 0"/>
  </joint>
  <!-- moment bar -->
  <link name="left_gripper_finger_1_moment_arm">
    <visual>
      <geometry>
        <mesh filename="package://ur5/data/0009_moment_arm.stl"/>
      </geometry>
      <material name="onrobot/light_grey"/>
    </visual>
    <collision>
      <geometry>
        <mesh filename="package://ur5/data/0021_moment_arm.stl"/>
      </geometry>
    </collision>
    <inertial>
      <mass value="0.001"/>
      <inertia ixx="0.001" ixy="0.0" ixz="0.0" iyy="0.001" iyz="0.0" izz="0.001"/>
    </inertial>
  </link>
  <joint name="left_gripper_joint" type="revolute">
    <parent link="left_gripper_finger_1_origin"/>
    <child link="left_gripper_finger_1_moment_arm"/>
    <axis xyz="0 1 0"/>
    <origin rpy="0.0 -0.49 0.0" xyz="-0.0238 0.0 0.066"/>
    <limit effort="10.0" lower="0.0" upper="1.3" velocity="2.4"/>
    <dynamics damping="0.5"/>
  </joint>
  <!-- truss bar -->
  <link name="left_gripper_finger_1_truss_arm">
    <visual>
      <geometry>
        <mesh filename="package://ur5/data/0003_truss_arm.stl"/>
      </geometry>
      <material name="onrobot/light_grey"/>
    </visual>
    <collision>
      <geometry>
        <mesh filename="package://ur5/data/0012_truss_arm.stl"/>
      </geometry>
    </collision>
    <inertial>
      <mass value="0.001"/>
      <inertia ixx="0.001" ixy="0.0" ixz="0.0" iyy="0.001" iyz="0.0" izz="0.001"/>
    </inertial>
  </link>
  <joint name="left_gripper_finger_1_truss_arm_joint" type="revolute">
    <parent link="left_gripper_finger_1_origin"/>
    <child link="left_gripper_finger_1_truss_arm"/>
    <axis xyz="0 1 0"/>
    <origin rpy="0.0 -0.49 0.0" xyz="-0.0105 0.0 0.0891"/>
    <limit effort="10.0" lower="0.0" upper="1.3" velocity="2.4"/>
    <mimic joint="left_gripper_joint" multiplier="1" offset="0"/>
  </joint>
  <link name="left_gripper_finger_1_safety_shield">
    <visual>
      <geometry>
        <mesh filename="package://ur5/data/0016_safety_shield.stl"/>
      </geometry>
      <material name="onrobot/dark_grey"/>
    </visual>
    <collision>
      <geometry>
        <!-- <mesh filename="package://ur5/data/0028_safety_shield.stl"/> -->
        <box size="0.0 0.0 0.0"/>
      </geometry>
    </collision>
    <inertial>
      <mass value="0.001"/>
      <inertia ixx="0.001" ixy="0.0" ixz="0.0" iyy="0.001" iyz="0.0" izz="0.001"/>
    </inertial>
  </link>
  <joint name="left_gripper_finger_1_safety_shield_joint" type="revolute">
    <parent link="left_gripper_finger_1_finger_tip"/>
    <child link="left_gripper_finger_1_safety_shield"/>
    <axis xyz="0 1 0"/>
    <origin rpy="0.0 -0.49 0.0" xyz="-0.00665 0.0 -0.01155"/>
    <limit effort="10.0" lower="0.0" upper="1.3" velocity="2.4"/>
    <mimic joint="left_gripper_joint" multiplier="1" offset="0"/>
  </joint>
  <!-- finger tip -->
  <link name="left_gripper_finger_1_finger_tip">
    <visual>
      <geometry>
        <mesh filename="package://ur5/data/0001_finger_tip.stl"/>
      </geometry>
      <material name="onrobot/light_grey"/>
    </visual>
    <collision>
      <geometry>
        <mesh filename="package://ur5/data/0030_finger_tip_1.stl"/>
      </geometry>
    </collision>
    <collision>
      <geometry>
        <mesh filename="package://ur5/data/0010_finger_tip_2.stl"/>
      </geometry>
    </collision>
    <inertial>
      <mass value="0.001"/>
      <inertia ixx="0.001" ixy="0.0" ixz="0.0" iyy="0.001" iyz="0.0" izz="0.001"/>
    </inertial>
  </link>
  <joint name="left_gripper_finger_1_finger_tip_joint" type="revolute">
    <parent link="left_gripper_finger_1_truss_arm"/>
    <child link="left_gripper_finger_1_finger_tip"/>
    <axis xyz="0 -1 0"/>
    <origin rpy="0.0 0.49 0.0" xyz="-0.05503 0.0 0.05807"/>
    <limit effort="10.0" lower="0.0" upper="1.3" velocity="2.4"/>
    <mimic joint="left_gripper_joint" multiplier="1" offset="0"/>
  </joint>
  <!-- flex finger -->
  <link name="left_gripper_finger_1_flex_finger">
    <visual>
      <geometry>
        <mesh filename="package://ur5/data/0029_flex_finger.stl"/>
      </geometry>
      <material name="onrobot/dark_grey"/>
    </visual>
    <collision>
      <geometry>
        <mesh filename="package://ur5/data/0026_flex_finger.stl"/>
      </geometry>
    </collision>
    <inertial>
      <mass value="0.001"/>
      <inertia ixx="0.001" ixy="0.0" ixz="0.0" iyy="0.001" iyz="0.0" izz="0.001"/>
    </inertial>
  </link>
  <joint name="left_gripper_finger_1_flex_finger_joint" type="fixed">
    <parent link="left_gripper_finger_1_finger_tip"/>
    <child link="left_gripper_finger_1_flex_finger"/>
    <origin rpy="0.0 0.0 0.0" xyz="0.0098 0.0 0.0218"/>
  </joint>
  <!-- origin frame -->
  <link name="left_gripper_finger_2_origin">
    <inertial>
      <mass value="0.001"/>
      <inertia ixx="0.00001" ixy="0.0" ixz="0.0" iyy="0.00001" iyz="0.0" izz="0.00001"/>
    </inertial>
  </link>
  <joint name="left_gripper_finger_2_origin_joint" type="fixed">
    <parent link="left_gripper_body"/>
    <child link="left_gripper_finger_2_origin"/>
    <origin rpy="0 0 3.141592653589793" xyz="0 0 0"/>
  </joint>
  <!-- moment bar -->
  <link name="left_gripper_finger_2_moment_arm">
    <visual>
      <geometry>
        <mesh filename="package://ur5/data/0009_moment_arm.stl"/>
      </geometry>
      <material name="onrobot/light_grey"/>
    </visual>
    <collision>
      <geometry>
        <mesh filename="package://ur5/data/0021_moment_arm.stl"/>
      </geometry>
    </collision>
    <inertial>
      <mass value="0.001"/>
      <inertia ixx="0.001" ixy="0.0" ixz="0.0" iyy="0.001" iyz="0.0" izz="0.001"/>
    </inertial>
  </link>
  <joint name="left_gripper_mirror_joint" type="revolute">
    <parent link="left_gripper_finger_2_origin"/>
    <child link="left_gripper_finger_2_moment_arm"/>
    <axis xyz="0 1 0"/>
    <origin rpy="0.0 -0.49 0.0" xyz="-0.0238 0.0 0.066"/>
    <limit effort="10.0" lower="0.0" upper="1.3" velocity="2.4"/>
    <dynamics damping="0.5"/>
    <mimic joint="left_gripper_joint" multiplier="1" offset="0"/>
  </joint>
  <!-- truss bar -->
  <link name="left_gripper_finger_2_truss_arm">
    <visual>
      <geometry>
        <mesh filename="package://ur5/data/0003_truss_arm.stl"/>
      </geometry>
      <material name="onrobot/light_grey"/>
    </visual>
    <collision>
      <geometry>
        <mesh filename="package://ur5/data/0012_truss_arm.stl"/>
      </geometry>
    </collision>
    <inertial>
      <mass value="0.001"/>
      <inertia ixx="0.001" ixy="0.0" ixz="0.0" iyy="0.001" iyz="0.0" izz="0.001"/>
    </inertial>
  </link>
  <joint name="left_gripper_finger_2_truss_arm_joint" type="revolute">
    <parent link="left_gripper_finger_2_origin"/>
    <child link="left_gripper_finger_2_truss_arm"/>
    <axis xyz="0 1 0"/>
    <origin rpy="0.0 -0.49 0.0" xyz="-0.0105 0.0 0.0891"/>
    <limit effort="10.0" lower="0.0" upper="1.3" velocity="2.4"/>
    <mimic joint="left_gripper_joint" multiplier="1" offset="0"/>
  </joint>
  <link name="left_gripper_finger_2_safety_shield">
    <visual>
      <geometry>
        <mesh filename="package://ur5/data/0016_safety_shield.stl"/>
      </geometry>
      <material name="onrobot/dark_grey"/>
    </visual>
    <collision>
      <geometry>
        <!-- <mesh filename="package://ur5/data/0028_safety_shield.stl"/> -->
        <box size="0.0 0.0 0.0"/>
      </geometry>
    </collision>
    <inertial>
      <mass value="0.001"/>
      <inertia ixx="0.001" ixy="0.0" ixz="0.0" iyy="0.001" iyz="0.0" izz="0.001"/>
    </inertial>
  </link>
  <joint name="left_gripper_finger_2_safety_shield_joint" type="revolute">
    <parent link="left_gripper_finger_2_finger_tip"/>
    <child link="left_gripper_finger_2_safety_shield"/>
    <axis xyz="0 1 0"/>
    <origin rpy="0.0 -0.49 0.0" xyz="-0.00665 0.0 -0.01155"/>
    <limit effort="10.0" lower="0.0" upper="1.3" velocity="2.4"/>
    <mimic joint="left_gripper_joint" multiplier="1" offset="0"/>
  </joint>
  <!-- finger tip -->
  <link name="left_gripper_finger_2_finger_tip">
    <visual>
      <geometry>
        <mesh filename="package://ur5/data/0001_finger_tip.stl"/>
      </geometry>
      <material name="onrobot/light_grey"/>
    </visual>
    <collision>
      <geometry>
        <mesh filename="package://ur5/data/0030_finger_tip_1.stl"/>
      </geometry>
    </collision>
    <collision>
      <geometry>
        <mesh filename="package://ur5/data/0010_finger_tip_2.stl"/>
      </geometry>
    </collision>
    <inertial>
      <mass value="0.001"/>
      <inertia ixx="0.001" ixy="0.0" ixz="0.0" iyy="0.001" iyz="0.0" izz="0.001"/>
    </inertial>
  </link>
  <joint name="left_gripper_finger_2_finger_tip_joint" type="revolute">
    <parent link="left_gripper_finger_2_truss_arm"/>
    <child link="left_gripper_finger_2_finger_tip"/>
    <axis xyz="0 -1 0"/>
    <origin rpy="0.0 0.49 0.0" xyz="-0.05503 0.0 0.05807"/>
    <limit effort="10.0" lower="0.0" upper="1.3" velocity="2.4"/>
    <mimic joint="left_gripper_joint" multiplier="1" offset="0"/>
  </joint>
  <!-- flex finger -->
  <link name="left_gripper_finger_2_flex_finger">
    <visual>
      <geometry>
        <mesh filename="package://ur5/data/0029_flex_finger.stl"/>
      </geometry>
      <material name="onrobot/dark_grey"/>
    </visual>
    <collision>
      <geometry>
        <mesh filename="package://ur5/data/0026_flex_finger.stl"/>
      </geometry>
    </collision>
    <inertial>
      <mass value="0.001"/>
      <inertia ixx="0.001" ixy="0.0" ixz="0.0" iyy="0.001" iyz="0.0" izz="0.001"/>
    </inertial>
  </link>
  <joint name="left_gripper_finger_2_flex_finger_joint" type="fixed">
    <parent link="left_gripper_finger_2_finger_tip"/>
    <child link="left_gripper_finger_2_flex_finger"/>
    <origin rpy="0.0 0.0 0.0" xyz="0.0098 0.0 0.0218"/>
  </joint>
  <!-- <transmission name="${prefix}_joint_trans">
      <type>transmission_interface/SimpleTransmission</type>
      <joint name="${prefix}_joint">
        <hardwareInterface>${hw_interface}</hardwareInterface>
      </joint>
      <actuator name="${prefix}_joint_motor">
        <hardwareInterface>${hw_interface}</hardwareInterface>
        <mechanicalReduction>1</mechanicalReduction>
      </actuator>
    </transmission> -->
  <!-- load "onrobot_gripper_plugin" plugin -->
  <gazebo>
    <plugin filename="libonrobot_gripper_plugin.so" name="left_gripper_plugin">
      <robotNamespace>/left_gripper</robotNamespace>
      <jointName>left_gripper_joint, left_gripper_mirror_joint</jointName>
      <tipName>left_gripper_finger_1_finger_tip, left_gripper_finger_2_finger_tip</tipName>
      <palmName>left_gripper_body</palmName>
      <mimicName>left_gripper_finger_1_safety_shield_joint, left_gripper_finger_2_safety_shield_joint</mimicName>
      <maxEffort>0.5</maxEffort>
    </plugin>
  </gazebo>
  <gazebo>
    <joint name="left_gripper_finger_1_close_loop_joint" type="revolute">
      <parent>left_gripper_finger_1_moment_arm</parent>
      <child>left_gripper_finger_1_finger_tip</child>
      <pose frame="">-0.013300000000000001 0.0 -0.023099999999999996 0 0 0</pose>
      <axis>
        <xyz>0 -1 0</xyz>
        <use_parent_model_frame>0</use_parent_model_frame>
      </axis>
    </joint>
    <joint name="left_gripper_finger_2_close_loop_joint" type="revolute">
      <parent>left_gripper_finger_2_moment_arm</parent>
      <child>left_gripper_finger_2_finger_tip</child>
      <pose frame="">-0.013300000000000001 0.0 -0.023099999999999996 0 0 0</pose>
      <axis>
        <xyz>0 -1 0</xyz>
        <use_parent_model_frame>0</use_parent_model_frame>
      </axis>
    </joint>
  </gazebo>
  <gazebo reference="left_gripper_finger_1_flex_finger">
    <mu1>100</mu1>
    <mu2>100</mu2>
    <fdir1>0 0 1</fdir1>
    <kp>100000</kp>
    <kd>10</kd>
    <collision name="left_gripper_finger_1_flex_finger_collision">
      <surface>
        <friction>
          <torsional>
            <coefficient>0.456</coefficient>
            <use_patch_radius>true</use_patch_radius>
            <patch_radius>0.05</patch_radius>
          </torsional>
        </friction>
      </surface>
    </collision>
  </gazebo>
  <gazebo reference="left_gripper_finger_2_flex_finger">
    <mu1>100</mu1>
    <mu2>100</mu2>
    <fdir1>0 0 1</fdir1>
    <kp>100000</kp>
    <kd>10</kd>
    <collision name="left_gripper_finger_2_flex_finger_collision">
      <surface>
        <friction>
          <torsional>
            <coefficient>0.456</coefficient>
            <use_patch_radius>true</use_patch_radius>
            <patch_radius>0.05</patch_radius>
          </torsional>
        </friction>
      </surface>
    </collision>
  </gazebo>
  <!-- enable self collision -->
  <gazebo reference="left_gripper_bracket">
    <selfCollide>true</selfCollide>
  </gazebo>
  <gazebo reference="left_gripper_body">
    <selfCollide>true</selfCollide>
  </gazebo>
  <gazebo reference="left_gripper_finger_1_truss_arm">
    <selfCollide>true</selfCollide>
  </gazebo>
  <gazebo reference="left_gripper_finger_1_moment_arm">
    <selfCollide>true</selfCollide>
  </gazebo>
  <gazebo reference="left_gripper_finger_1_finger_tip">
    <selfCollide>true</selfCollide>
  </gazebo>
  <gazebo reference="left_gripper_finger_1_flex_finger">
    <selfCollide>true</selfCollide>
  </gazebo>
  <gazebo reference="left_gripper_finger_2_truss_arm">
    <selfCollide>true</selfCollide>
  </gazebo>
  <gazebo reference="left_gripper_finger_2_moment_arm">
    <selfCollide>true</selfCollide>
  </gazebo>
  <gazebo reference="left_gripper_finger_2_finger_tip">
    <selfCollide>true</selfCollide>
  </gazebo>
  <gazebo reference="left_gripper_finger_2_flex_finger">
    <selfCollide>true</selfCollide>
  </gazebo>
  <!-- Right angle connector -->
  <link name="left_wrist_connector_link">
    <visual>
      <geometry>
        <mesh filename="package://ur5/data/0000_RG_connector_simple.stl"/>
      </geometry>
      <material name="connector_green">
        <color rgba="0.2 0.8 0 1"/>
      </material>
    </visual>
    <collision>
      <geometry>
        <mesh filename="package://ur5/data/0000_RG_connector_simple.stl"/>
      </geometry>
    </collision>
  </link>
  <joint name="left_wrist_connector" type="fixed">
    <origin rpy="1.5708 0 0" xyz="0 -0.0375 -0.02"/>
    <parent link="left_wrist_3_link"/>
    <child link="left_wrist_connector_link"/>
  </joint>
  <!-- camera body, with origin at bottom screw mount -->
  <joint name="left_camera_joint" type="fixed">
    <origin rpy="2.8041477875085317 -1.5592828100772942 1.9010370316589085" xyz="0.0014664225137346124 0.014491056527151769 0.13148527149329517"/>
    <parent link="left_tool"/>
    <child link="left_camera_bottom_screw_frame"/>
  </joint>
  <link name="left_camera_bottom_screw_frame"/>
  <joint name="left_camera_link_joint" type="fixed">
    <origin rpy="0 0 0" xyz="0.010600000000000002 0.0175 0.0125"/>
    <parent link="left_camera_bottom_screw_frame"/>
    <child link="left_camera_link"/>
  </joint>
  <link name="left_camera_link">
    <visual>
      <!-- the mesh origin is at front plate in between the two infrared camera axes -->
      <origin rpy="1.5707963267948966 0 1.5707963267948966" xyz="0.0043 -0.0175 0"/>
      <geometry>
        <mesh filename="package://ur5/data/0008_d435.dae"/>
      </geometry>
    </visual>
    <collision>
      <origin rpy="0 0 0" xyz="0 -0.0175 0"/>
      <geometry>
        <box size="0.02505 0.09 0.025"/>
      </geometry>
    </collision>
    <inertial>
      <!-- The following are not reliable values, and should not be used for modeling -->
      <mass value="0.072"/>
      <origin xyz="0 0 0"/>
      <inertia ixx="0.003881243" ixy="0.0" ixz="0.0" iyy="0.000498940" iyz="0.0" izz="0.003879257"/>
    </inertial>
  </link>
  <!-- camera depth joints and links -->
  <joint name="left_camera_depth_joint" type="fixed">
    <origin rpy="0 0 0" xyz="0 0 0"/>
    <parent link="left_camera_link"/>
    <child link="left_camera_depth_frame"/>
  </joint>
  <link name="left_camera_depth_frame"/>
  <joint name="left_camera_depth_optical_joint" type="fixed">
    <origin rpy="-1.5707963267948966 0 -1.5707963267948966" xyz="0 0 0"/>
    <parent link="left_camera_depth_frame"/>
    <child link="left_camera_depth_optical_frame"/>
  </joint>
  <link name="left_camera_depth_optical_frame"/>
  <!-- camera left IR joints and links -->
  <joint name="left_camera_infra1_joint" type="fixed">
    <origin rpy="0 0 0" xyz="0 0.0 0"/>
    <parent link="left_camera_link"/>
    <child link="left_camera_infra1_frame"/>
  </joint>
  <link name="left_camera_infra1_frame"/>
  <joint name="left_camera_infra1_optical_joint" type="fixed">
    <origin rpy="-1.5707963267948966 0 -1.5707963267948966" xyz="0 0 0"/>
    <parent link="left_camera_infra1_frame"/>
    <child link="left_camera_infra1_optical_frame"/>
  </joint>
  <link name="left_camera_infra1_optical_frame"/>
  <!-- camera right IR joints and links -->
  <joint name="left_camera_infra2_joint" type="fixed">
    <origin rpy="0 0 0" xyz="0 -0.05 0"/>
    <parent link="left_camera_link"/>
    <child link="left_camera_infra2_frame"/>
  </joint>
  <link name="left_camera_infra2_frame"/>
  <joint name="left_camera_infra2_optical_joint" type="fixed">
    <origin rpy="-1.5707963267948966 0 -1.5707963267948966" xyz="0 0 0"/>
    <parent link="left_camera_infra2_frame"/>
    <child link="left_camera_infra2_optical_frame"/>
  </joint>
  <link name="left_camera_infra2_optical_frame"/>
  <!-- camera color joints and links -->
  <joint name="left_camera_color_joint" type="fixed">
    <origin rpy="0 0 0" xyz="0 0.015 0"/>
    <parent link="left_camera_link"/>
    <child link="left_camera_color_frame"/>
  </joint>
  <link name="left_camera_color_frame"/>
  <joint name="left_camera_color_optical_joint" type="fixed">
    <origin rpy="-1.5707963267948966 0 -1.5707963267948966" xyz="0 0 0"/>
    <parent link="left_camera_color_frame"/>
    <child link="left_camera_color_optical_frame"/>
  </joint>
  <link name="left_camera_color_optical_frame"/>
  <link name="left_camera_accel_frame"/>
  <link name="left_camera_accel_optical_frame"/>
  <link name="left_camera_gyro_frame"/>
  <link name="left_camera_gyro_optical_frame"/>
  <joint name="left_camera_accel_joint" type="fixed">
    <origin rpy="0 0 0" xyz="-0.01174 -0.00552 0.0051"/>
    <parent link="left_camera_link"/>
    <child link="left_camera_accel_frame"/>
  </joint>
  <joint name="left_camera_accel_optical_joint" type="fixed">
    <origin rpy="-1.5707963267948966 0 -1.5707963267948966" xyz="0 0 0"/>
    <parent link="left_camera_accel_frame"/>
    <child link="left_camera_accel_optical_frame"/>
  </joint>
  <joint name="left_camera_gyro_joint" type="fixed">
    <origin rpy="0 0 0" xyz="-0.01174 -0.00552 0.0051"/>
    <parent link="left_camera_link"/>
    <child link="left_camera_gyro_frame"/>
  </joint>
  <joint name="left_camera_gyro_optical_joint" type="fixed">
    <origin rpy="-1.5707963267948966 0 -1.5707963267948966" xyz="0 0 0"/>
    <parent link="left_camera_gyro_frame"/>
    <child link="left_camera_gyro_optical_frame"/>
  </joint>
  <gazebo reference="left_camera_link">
    <self_collide>1</self_collide>
    <enable_wind>0</enable_wind>
    <kinematic>0</kinematic>
    <gravity>1</gravity>
    <material>Gazebo/Grey</material>
    <!--<mu>1</mu>-->
    <mu2>1</mu2>
    <fdir1>0 0 0</fdir1>
    <!--<slip1>0</slip1>
      <slip2>0</slip2>-->
    <kp>1e+13</kp>
    <kd>1</kd>
    <!--<max_vel>0.01</max_vel>
      <min_depth>0</min_depth>-->
    <sensor name="left_cameracolor" type="camera">
      <camera name="left_camera">
        <horizontal_fov>1.2112585008840648</horizontal_fov>
        <image>
          <width>640</width>
          <height>480</height>
          <format>RGB_INT8</format>
        </image>
        <clip>
          <near>0.1</near>
          <far>100</far>
        </clip>
        <noise>
          <type>gaussian</type>
          <mean>0.0</mean>
          <stddev>0.007</stddev>
        </noise>
      </camera>
      <always_on>False</always_on>
      <update_rate>30</update_rate>
      <visualize>False</visualize>
    </sensor>
    <sensor name="left_cameraired1" type="camera">
      <camera name="left_camera">
        <horizontal_fov>1.4870205226991688</horizontal_fov>
        <image>
          <width>1280</width>
          <height>720</height>
          <format>L_INT8</format>
        </image>
        <clip>
          <near>0.1</near>
          <far>100</far>
        </clip>
        <noise>
          <type>gaussian</type>
          <mean>0.0</mean>
          <stddev>0.05</stddev>
        </noise>
      </camera>
      <always_on>0</always_on>
      <update_rate>90</update_rate>
      <visualize>0</visualize>
    </sensor>
    <sensor name="left_cameraired2" type="camera">
      <camera name="left_camera">
        <horizontal_fov>1.4870205226991688</horizontal_fov>
        <image>
          <width>1280</width>
          <height>720</height>
          <format>L_INT8</format>
        </image>
        <clip>
          <near>0.1</near>
          <far>100</far>
        </clip>
        <noise>
          <type>gaussian</type>
          <mean>0.0</mean>
          <stddev>0.05</stddev>
        </noise>
      </camera>
      <always_on>0</always_on>
      <update_rate>90</update_rate>
      <visualize>0</visualize>
    </sensor>
    <sensor name="left_cameradepth" type="depth">
      <camera name="left_camera">
        <horizontal_fov>1.4870205226991688</horizontal_fov>
        <image>
          <width>1280</width>
          <height>720</height>
        </image>
        <clip>
          <near>0.1</near>
          <far>100</far>
        </clip>
        <noise>
          <type>gaussian</type>
          <mean>0.0</mean>
          <stddev>0.100</stddev>
        </noise>
      </camera>
      <always_on>False</always_on>
      <update_rate>90</update_rate>
      <visualize>0</visualize>
    </sensor>
  </gazebo>
  <gazebo>
    <plugin filename="librealsense_gazebo_plugin.so" name="left_camera">
      <prefix>left_camera</prefix>
      <depthUpdateRate>30.0</depthUpdateRate>
      <colorUpdateRate>30.0</colorUpdateRate>
      <infraredUpdateRate>30.0</infraredUpdateRate>
      <depthTopicName>depth/image_raw</depthTopicName>
      <depthCameraInfoTopicName>depth/camera_info</depthCameraInfoTopicName>
      <colorTopicName>color/image_raw</colorTopicName>
      <colorCameraInfoTopicName>color/camera_info</colorCameraInfoTopicName>
      <infrared1TopicName>infra1/image_raw</infrared1TopicName>
      <infrared1CameraInfoTopicName>infra1/camera_info</infrared1CameraInfoTopicName>
      <infrared2TopicName>infra2/image_raw</infrared2TopicName>
      <infrared2CameraInfoTopicName>infra2/camera_info</infrared2CameraInfoTopicName>
      <colorOpticalframeName>left_camera_color_optical_frame</colorOpticalframeName>
      <depthOpticalframeName>left_camera_depth_optical_frame</depthOpticalframeName>
      <infrared1OpticalframeName>left_camera_left_ir_optical_frame</infrared1OpticalframeName>
      <infrared2OpticalframeName>left_camera_right_ir_optical_frame</infrared2OpticalframeName>
      <rangeMinDepth>0.2</rangeMinDepth>
      <rangeMaxDepth>10.0</rangeMaxDepth>
      <pointCloud>True</pointCloud>
      <pointCloudTopicName>left_camera_depth/color/points</pointCloudTopicName>
      <pointCloudCutoff>0.25</pointCloudCutoff>
      <pointCloudCutoffMax>9.0</pointCloudCutoffMax>
    </plugin>
  </gazebo>
  <!--
    Base UR robot series xacro macro.

    NOTE: this is NOT a URDF. It cannot directly be loaded by consumers
    expecting a flattened '.urdf' file. See the top-level '.xacro' for that
    (but note: that .xacro must still be processed by the xacro command).

    For use in '.launch' files: use one of the 'load_urX.launch' convenience
    launch files.

    This file models the base kinematic chain of a UR robot, which then gets
    parameterised by various configuration files to convert it into a UR3(e),
    UR5(e), UR10(e) or UR16e.

    NOTE: the default kinematic parameters (ie: link lengths, frame locations,
    offets, etc) do not correspond to any particular robot. They are defaults
    only. There WILL be non-zero offsets between the Forward Kinematics results
    in TF (ie: robot_state_publisher) and the values reported by the Teach
    Pendant.

    For accurate (and robot-specific) transforms, the 'kinematics_parameters_file'
    parameter MUST point to a .yaml file containing the appropriate values for
    the targetted robot.

    If using the UniversalRobots/Universal_Robots_ROS_Driver, follow the steps
    described in the readme of that repository to extract the kinematic
    calibration from the controller and generate the required .yaml file.

    Main author of the migration to yaml configs: Ludovic Delval.

    Contributors to previous versions (in no particular order):

     - Felix Messmer
     - Kelsey Hawkins
     - Wim Meeussen
     - Shaun Edwards
     - Nadia Hammoudeh Garcia
     - Dave Hershberger
     - G. vd. Hoorn
     - Philip Long
     - Dave Coleman
     - Miguel Prada
     - Mathias Luedtke
     - Marcel Schnirring
     - Felix von Drigalski
     - Felix Exner
     - Jimmy Da Silva
     - Ajit Krisshna N L
     - Muhammad Asif Rana
  -->
  <!--
    NOTE: the macro defined in this file is NOT part of the public API of this
          package. Users CANNOT rely on this file being available, or stored in
          this location. Nor can they rely on the existence of the macro.
  -->
  <transmission name="right_shoulder_pan_trans">
    <type>transmission_interface/SimpleTransmission</type>
    <joint name="right_shoulder_pan_joint">
      <hardwareInterface>hardware_interface/PositionJointInterface</hardwareInterface>
    </joint>
    <actuator name="right_shoulder_pan_motor">
      <mechanicalReduction>1</mechanicalReduction>
    </actuator>
  </transmission>
  <transmission name="right_shoulder_lift_trans">
    <type>transmission_interface/SimpleTransmission</type>
    <joint name="right_shoulder_lift_joint">
      <hardwareInterface>hardware_interface/PositionJointInterface</hardwareInterface>
    </joint>
    <actuator name="right_shoulder_lift_motor">
      <mechanicalReduction>1</mechanicalReduction>
    </actuator>
  </transmission>
  <transmission name="right_elbow_trans">
    <type>transmission_interface/SimpleTransmission</type>
    <joint name="right_elbow_joint">
      <hardwareInterface>hardware_interface/PositionJointInterface</hardwareInterface>
    </joint>
    <actuator name="right_elbow_motor">
      <mechanicalReduction>1</mechanicalReduction>
    </actuator>
  </transmission>
  <transmission name="right_wrist_1_trans">
    <type>transmission_interface/SimpleTransmission</type>
    <joint name="right_wrist_1_joint">
      <hardwareInterface>hardware_interface/PositionJointInterface</hardwareInterface>
    </joint>
    <actuator name="right_wrist_1_motor">
      <mechanicalReduction>1</mechanicalReduction>
    </actuator>
  </transmission>
  <transmission name="right_wrist_2_trans">
    <type>transmission_interface/SimpleTransmission</type>
    <joint name="right_wrist_2_joint">
      <hardwareInterface>hardware_interface/PositionJointInterface</hardwareInterface>
    </joint>
    <actuator name="right_wrist_2_motor">
      <mechanicalReduction>1</mechanicalReduction>
    </actuator>
  </transmission>
  <transmission name="right_wrist_3_trans">
    <type>transmission_interface/SimpleTransmission</type>
    <joint name="right_wrist_3_joint">
      <hardwareInterface>hardware_interface/PositionJointInterface</hardwareInterface>
    </joint>
    <actuator name="right_wrist_3_motor">
      <mechanicalReduction>1</mechanicalReduction>
    </actuator>
  </transmission>
  <!-- links: main serial chain -->
  <link name="right_base_link"/>
  <link name="right_base_link_inertia">
    <visual>
      <origin rpy="0 0 3.141592653589793" xyz="0 0 0"/>
      <geometry>
        <mesh filename="package://ur5/data/0037_base.dae"/>
      </geometry>
      <material name="LightGrey">
        <color rgba="0.7 0.7 0.7 1.0"/>
      </material>
    </visual>
    <collision>
      <origin rpy="0 0 3.141592653589793" xyz="0 0 0"/>
      <geometry>
        <mesh filename="package://ur5/data/0014_base.stl"/>
      </geometry>
    </collision>
    <inertial>
      <mass value="4.0"/>
      <origin rpy="0 0 0" xyz="0 0 0"/>
      <inertia ixx="0.00443333156" ixy="0.0" ixz="0.0" iyy="0.00443333156" iyz="0.0" izz="0.0072"/>
    </inertial>
  </link>
  <link name="right_shoulder_link">
    <visual>
      <origin rpy="0 0 3.141592653589793" xyz="0 0 0"/>
      <geometry>
        <mesh filename="package://ur5/data/0006_shoulder.dae"/>
      </geometry>
      <material name="LightGrey">
        <color rgba="0.7 0.7 0.7 1.0"/>
      </material>
    </visual>
    <collision>
      <origin rpy="0 0 3.141592653589793" xyz="0 0 0"/>
      <geometry>
        <mesh filename="package://ur5/data/0023_shoulder.stl"/>
      </geometry>
    </collision>
    <inertial>
      <mass value="3.7"/>
      <origin rpy="0 0 0" xyz="0 0 0"/>
      <inertia ixx="0.014972352344389999" ixy="0.0" ixz="0.0" iyy="0.014972352344389999" iyz="0.0" izz="0.01040625"/>
    </inertial>
  </link>
  <link name="right_upper_arm_link">
    <visual>
      <origin rpy="1.5707963267948966 0 -1.5707963267948966" xyz="0 0 0.13585"/>
      <geometry>
        <mesh filename="package://ur5/data/0035_upperarm.dae"/>
      </geometry>
      <material name="LightGrey">
        <color rgba="0.7 0.7 0.7 1.0"/>
      </material>
    </visual>
    <collision>
      <origin rpy="1.5707963267948966 0 -1.5707963267948966" xyz="0 0 0.13585"/>
      <geometry>
        <mesh filename="package://ur5/data/0013_upperarm.stl"/>
      </geometry>
    </collision>
    <inertial>
      <mass value="8.393"/>
      <origin rpy="0 1.5707963267948966 0" xyz="-0.2125 0.0 0.136"/>
      <inertia ixx="0.1338857818623325" ixy="0.0" ixz="0.0" iyy="0.1338857818623325" iyz="0.0" izz="0.0151074"/>
    </inertial>
  </link>
  <link name="right_forearm_link">
    <visual>
      <origin rpy="1.5707963267948966 0 -1.5707963267948966" xyz="0 0 0.0165"/>
      <geometry>
        <mesh filename="package://ur5/data/0036_forearm.dae"/>
      </geometry>
      <material name="LightGrey">
        <color rgba="0.7 0.7 0.7 1.0"/>
      </material>
    </visual>
    <collision>
      <origin rpy="1.5707963267948966 0 -1.5707963267948966" xyz="0 0 0.0165"/>
      <geometry>
        <mesh filename="package://ur5/data/0017_forearm.stl"/>
      </geometry>
    </collision>
    <inertial>
      <mass value="2.275"/>
      <origin rpy="0 1.5707963267948966 0" xyz="-0.196125 0.0 0.0165"/>
      <inertia ixx="0.03121679102890359" ixy="0.0" ixz="0.0" iyy="0.03121679102890359" iyz="0.0" izz="0.004095"/>
    </inertial>
  </link>
  <link name="right_wrist_1_link">
    <visual>
      <!-- TODO: Move this to a parameter -->
      <origin rpy="1.5707963267948966 0 0" xyz="0 0 -0.093"/>
      <geometry>
        <mesh filename="package://ur5/data/0002_wrist1.dae"/>
      </geometry>
      <material name="LightGrey">
        <color rgba="0.7 0.7 0.7 1.0"/>
      </material>
    </visual>
    <collision>
      <origin rpy="1.5707963267948966 0 0" xyz="0 0 -0.093"/>
      <geometry>
        <mesh filename="package://ur5/data/0031_wrist1.stl"/>
      </geometry>
    </collision>
    <inertial>
      <mass value="1.219"/>
      <origin rpy="0 0 0" xyz="0 0 0"/>
      <inertia ixx="0.0020138887777775" ixy="0.0" ixz="0.0" iyy="0.0020138887777775" iyz="0.0" izz="0.0021942"/>
    </inertial>
  </link>
  <link name="right_wrist_2_link">
    <visual>
      <origin rpy="0 0 0" xyz="0 0 -0.095"/>
      <geometry>
        <mesh filename="package://ur5/data/0015_wrist2.dae"/>
      </geometry>
      <material name="LightGrey">
        <color rgba="0.7 0.7 0.7 1.0"/>
      </material>
    </visual>
    <collision>
      <origin rpy="0 0 0" xyz="0 0 -0.095"/>
      <geometry>
        <mesh filename="package://ur5/data/0019_wrist2.stl"/>
      </geometry>
    </collision>
    <inertial>
      <mass value="1.219"/>
      <origin rpy="0 0 0" xyz="0 0 0"/>
      <inertia ixx="0.0018310388509175" ixy="0.0" ixz="0.0" iyy="0.0018310388509175" iyz="0.0" izz="0.0021942"/>
    </inertial>
  </link>
  <link name="right_wrist_3_link">
    <visual>
      <origin rpy="1.5707963267948966 0 0" xyz="0 0 -0.0818"/>
      <geometry>
        <mesh filename="package://ur5/data/0022_wrist3.dae"/>
      </geometry>
      <material name="LightGrey">
        <color rgba="0.7 0.7 0.7 1.0"/>
      </material>
    </visual>
    <collision>
      <origin rpy="1.5707963267948966 0 0" xyz="0 0 -0.0818"/>
      <geometry>
        <mesh filename="package://ur5/data/0007_wrist3.stl"/>
      </geometry>
    </collision>
    <inertial>
      <mass value="0.1879"/>
      <origin rpy="0 0 0" xyz="0.0 0.0 -0.01525"/>
      <inertia ixx="8.062472608343e-05" ixy="0.0" ixz="0.0" iyy="8.062472608343e-05" iyz="0.0" izz="0.0001321171875"/>
    </inertial>
  </link>
  <!-- joints: main serial chain -->
  <joint name="right_base_link-base_link_inertia" type="fixed">
    <parent link="right_base_link"/>
    <child link="right_base_link_inertia"/>
    <!-- 'base_link' is REP-103 aligned (so X+ forward), while the internal
           frames of the robot/controller have X+ pointing backwards.
           Use the joint between 'base_link' and 'base_link_inertia' (a dummy
           link/frame) to introduce the necessary rotation over Z (of pi rad).
      -->
    <origin rpy="0 0 3.141592653589793" xyz="0 0 0"/>
  </joint>
  <joint name="right_shoulder_pan_joint" type="revolute">
    <parent link="right_base_link_inertia"/>
    <child link="right_shoulder_link"/>
    <origin rpy="0 0 6.935093637945505e-05" xyz="0 0 0.08949928559905179"/>
    <axis xyz="0 0 1"/>
    <limit effort="150.0" lower="-3.141592653589793" upper="3.141592653589793" velocity="3.141592653589793"/>
    <dynamics damping="0" friction="0"/>
  </joint>
  <joint name="right_shoulder_lift_joint" type="revolute">
    <parent link="right_shoulder_link"/>
    <child link="right_upper_arm_link"/>
    <origin rpy="1.569776430478979 0 -1.899595783444728e-05" xyz="-4.453187360131969e-05 0 0"/>
    <axis xyz="0 0 1"/>
    <limit effort="150.0" lower="-3.141592653589793" upper="3.141592653589793" velocity="3.141592653589793"/>
    <dynamics damping="0" friction="0"/>
  </joint>
  <joint name="right_elbow_joint" type="revolute">
    <parent link="right_upper_arm_link"/>
    <child link="right_forearm_link"/>
    <origin rpy="0.003664895000787752 0.003110587533505237 -1.094175347315775e-05" xyz="-0.4255955178735976 0 0"/>
    <axis xyz="0 0 1"/>
    <limit effort="150.0" lower="-3.141592653589793" upper="3.141592653589793" velocity="3.141592653589793"/>
    <dynamics damping="0" friction="0"/>
  </joint>
  <joint name="right_wrist_1_joint" type="revolute">
    <parent link="right_forearm_link"/>
    <child link="right_wrist_1_link"/>
    <origin rpy="0.005347748217401119 0.0006785171055329065 -2.742538745494148e-05" xyz="-0.3924311684839673 -0.0005944496110317049 0.1111578032629135"/>
    <axis xyz="0 0 1"/>
    <limit effort="28.0" lower="-3.141592653589793" upper="3.141592653589793" velocity="3.141592653589793"/>
    <dynamics damping="0" friction="0"/>
  </joint>
  <joint name="right_wrist_2_joint" type="revolute">
    <parent link="right_wrist_1_link"/>
    <child link="right_wrist_2_link"/>
    <origin rpy="1.569468403067662 0 -9.542494196330857e-05" xyz="2.941862599780075e-05 -0.09489788806426759 0.0001260172312971319"/>
    <axis xyz="0 0 1"/>
    <limit effort="28.0" lower="-3.141592653589793" upper="3.141592653589793" velocity="3.141592653589793"/>
    <dynamics damping="0" friction="0"/>
  </joint>
  <joint name="right_wrist_3_joint" type="revolute">
    <parent link="right_wrist_2_link"/>
    <child link="right_wrist_3_link"/>
    <origin rpy="1.572087084765102 3.141592653589793 3.141548784260287" xyz="2.687562318826077e-05 0.0824693622601854 0.0001064480457512508"/>
    <axis xyz="0 0 1"/>
    <limit effort="28.0" lower="-3.141592653589793" upper="3.141592653589793" velocity="3.141592653589793"/>
    <dynamics damping="0" friction="0"/>
  </joint>
  <!-- ROS-Industrial 'base' frame: base_link to UR 'Base' Coordinates transform -->
  <link name="right_base"/>
  <joint name="right_base_link-base_fixed_joint" type="fixed">
    <!-- Note the rotation over Z of pi radians: as base_link is REP-103
           aligned (ie: has X+ forward, Y+ left and Z+ up), this is needed
           to correctly align 'base' with the 'Base' coordinate system of
           the UR controller.
      -->
    <origin rpy="0 0 3.141592653589793" xyz="0 0 0"/>
    <parent link="right_base_link"/>
    <child link="right_base"/>
  </joint>
  <!-- ROS-Industrial 'flange' frame: attachment point for EEF models -->
  <link name="right_flange"/>
  <joint name="right_wrist_3-flange" type="fixed">
    <parent link="right_wrist_3_link"/>
    <child link="right_flange"/>
    <origin rpy="0 -1.5707963267948966 -1.5707963267948966" xyz="0 0 0"/>
  </joint>
  <!-- ROS-Industrial 'tool0' frame: all-zeros tool frame -->
  <link name="right_tool0"/>
  <joint name="right_flange-tool0" type="fixed">
    <!-- default toolframe: X+ left, Y+ up, Z+ front -->
    <origin rpy="1.5707963267948966 0 1.5707963267948966" xyz="0 0 0"/>
    <parent link="right_flange"/>
    <child link="right_tool0"/>
  </joint>
  <joint name="right_base_joint" type="fixed">
    <origin rpy="0.0 2.356194490192345 0.0" xyz="0.17906 0.0 0.78936"/>
    <parent link="stand_link"/>
    <child link="right_base_link"/>
  </joint>
  <!-- mount the fts to the robot -->
  <joint name="right_ft300_fix" type="fixed">
    <origin rpy="0 0 -1.5707963267948966" xyz="0 0 -0.004"/>
    <parent link="right_tool0"/>
    <child link="right_ft300_mounting_plate"/>
  </joint>
  <!-- Link representing the FT300 force-torque sensor -->
  <link name="right_ft300_sensor">
    <inertial>
      <origin rpy="0 0 0" xyz="0 0 -0.017"/>
      <mass value="0.300"/>
      <inertia ixx="0.000262" ixy="0" ixz="1e-06" iyx="0" iyy="0.000265" iyz="1e-06" izx="-1e-06" izy="1e-06" izz="0.000219"/>
    </inertial>
    <visual>
      <origin rpy="0 0 0" xyz="0 0 0"/>
      <geometry>
        <mesh filename="package://ur5/data/0025_robotiq_ft300.STL"/>
      </geometry>
      <material name="Robotiq-Black">
        <color rgba="0.2 0.2 0.2 1.0"/>
      </material>
    </visual>
    <collision>
      <origin rpy="0 0 0" xyz="0 0 0"/>
      <geometry>
        <mesh filename="package://ur5/data/0005_robotiq_ft300.STL"/>
      </geometry>
    </collision>
  </link>
  <!-- Link representing the FT300 mounting plate -->
  <link name="right_ft300_mounting_plate">
    <visual>
      <origin rpy="0 0 0" xyz="0 0 0"/>
      <geometry>
        <mesh filename="package://ur5/data/0004_robotiq_ft300-G-062-COUPLING_G-50-4M6-1D6_20181119.STL"/>
      </geometry>
      <material name="Robotiq-Grey">
        <color rgba="0.4 0.4 0.4 1.0"/>
      </material>
    </visual>
    <collision>
      <origin rpy="0 0 0" xyz="0 0 0"/>
      <geometry>
        <mesh filename="package://ur5/data/0027_robotiq_ft300-G-062-COUPLING_G-50-4M6-1D6_20181119.STL"/>
      </geometry>
    </collision>
  </link>
  <!-- Connect force sensor with mounting/coupling plate -->
  <joint name="right_ft300_mounting_plate_joint" type="fixed">
    <origin rpy="0 3.141592653589793 0" xyz="0 0 0.0415"/>
    <parent link="right_ft300_mounting_plate"/>
    <child link="right_ft300_sensor"/>
  </joint>
  <!-- FORCE REFERENCE FRAME _______________________________________________________________________________
            As specified in the documentation:
            - The Z axis passes through the center of the depression with positive direction in the tool direction.
            - The X axis traces a symmetric line centered on the connector; the positive direction
                points the opposite way away from the connector.
            - The Y axis uses the right hand thumb rule according to X-Z. -->
  <joint name="right_measurment_joint" type="fixed">
    <origin rpy="0 3.141592653589793 -1.5707963267948966" xyz="0 0 0"/>
    <parent link="right_ft300_sensor"/>
    <child link="right_robotiq_ft_frame_id"/>
  </joint>
  <link name="right_robotiq_ft_frame_id"/>
  <!-- enable force_torque sensor -->
  <gazebo reference="right_measurment_joint">
    <preserveFixedJoint>true</preserveFixedJoint>
    <sensor name="right_force_torque" type="force_torque">
      <always_on>0</always_on>
      <update_rate>100.0</update_rate>
      <visualize>False</visualize>
      <force_torque>
        <frame>right_robotiq_ft_frame_id</frame>
        <measure_direction>child_to_parent</measure_direction>
      </force_torque>
    </sensor>
  </gazebo>
  <!-- ft_sensor plugin -->
  <gazebo>
    <plugin filename="libgazebo_ros_ft_sensor.so" name="right_ft_sensor">
      <updateRate>100.0</updateRate>
      <topicName>right_ft_wrench</topicName>
      <jointName>right_measurment_joint</jointName>
      <noise>
        <type>gaussian</type>
        <mean>0.0</mean>
        <stddev>0.003</stddev>
      </noise>
    </plugin>
  </gazebo>
  <!-- override link properties -->
  <gazebo reference="right_ft300_sensor">
    <material>Gazebo/Black</material>
    <selfCollide>true</selfCollide>
  </gazebo>
  <gazebo reference="right_ft300_mounting_plate">
    <material>Gazebo/Black</material>
    <selfCollide>true</selfCollide>
  </gazebo>
  <!-- tool frame -->
  <link name="right_tool"/>
  <joint name="right_tool_joint" type="fixed">
    <origin rpy="0 0 -3.141592653589793" xyz="0 0 0"/>
    <parent link="right_robotiq_ft_frame_id"/>
    <child link="right_tool"/>
  </joint>
  <link name="right_gripper_base"/>
  <joint name="right_gripper_base_joint" type="fixed">
    <parent link="right_tool"/>
    <child link="right_gripper_base"/>
    <origin rpy="0.0 0.0 0.0" xyz="0.0 0.0 0.0"/>
  </joint>
  <!-- body -->
  <link name="right_gripper_body">
    <visual>
      <geometry>
        <mesh filename="package://ur5/data/0011_cylinder_tool.stl" scale="0.001 0.001 0.001"/>
      </geometry>
      <material name="Grey">
        <color rgba="0.8 0.8 0.8 1.0"/>
      </material>
    </visual>
    <collision>
      <geometry>
        <mesh filename="package://ur5/data/0011_cylinder_tool.stl" scale="0.001 0.001 0.001"/>
      </geometry>
    </collision>
    <inertial>
      <mass value="0.2"/>
      <inertia ixx="0.0001" ixy="0.0" ixz="0.0" iyy="0.0001" iyz="0.0" izz="0.0001"/>
    </inertial>
  </link>
  <joint name="right_gripper_body_joint" type="fixed">
    <parent link="right_gripper_base"/>
    <child link="right_gripper_body"/>
    <origin rpy="3.141592653589793 0 0" xyz="0 0 0.0041"/>
  </joint>
  <!-- grasp frame -->
  <link name="right_gripper_grasp_frame"/>
  <joint name="right_gripper_grasp_frame_joint" type="fixed">
    <parent link="right_gripper_base"/>
    <child link="right_gripper_grasp_frame"/>
    <origin rpy="0 0 0" xyz="0 0 0.154"/>
  </joint>
  <!-- tip -->
  <link name="right_gripper_finger_1_finger_tip">
    <inertial>
      <mass value="0.001"/>
      <inertia ixx="0.0" ixy="0.0" ixz="0.0" iyy="0.0" iyz="0.0" izz="0.0"/>
    </inertial>
  </link>
  <!-- Actuated joint -->
  <joint name="right_gripper_joint" type="revolute">
    <parent link="right_gripper_body"/>
    <child link="right_gripper_finger_1_finger_tip"/>
    <axis xyz="0 1 0"/>
    <origin rpy="0 0 0" xyz="0 0 0"/>
    <limit effort="1" lower="-.1" upper="1.4" velocity="1"/>
  </joint>
  <!-- tip -->
  <link name="right_gripper_finger_2_finger_tip">
    <inertial>
      <mass value="0.001"/>
      <inertia ixx="0.0" ixy="0.0" ixz="0.0" iyy="0.0" iyz="0.0" izz="0.0"/>
    </inertial>
  </link>
  <!-- Actuated joint -->
  <joint name="right_gripper_mirror_joint" type="revolute">
    <parent link="right_gripper_body"/>
    <child link="right_gripper_finger_2_finger_tip"/>
    <axis xyz="0 1 0"/>
    <origin rpy="0 0 0" xyz="0 0 0"/>
    <limit effort="1" lower="-.1" upper="1.4" velocity="1"/>
    <mimic joint="right_gripper_joint" multiplier="1" offset="0"/>
  </joint>
  <gazebo>
    <plugin filename="libonrobot_gripper_plugin.so" name="right_gripper_plugin">
      <robotNamespace>/right_gripper</robotNamespace>
      <jointName>right_gripper_joint, right_gripper_mirror_joint</jointName>
      <tipName>right_gripper_finger_1_finger_tip, right_gripper_finger_2_finger_tip</tipName>
      <palmName>right_gripper_body</palmName>
      <maxEffort>0.5</maxEffort>
    </plugin>
  </gazebo>
  <!-- Right angle connector -->
  <link name="right_wrist_connector_link">
    <visual>
      <geometry>
        <mesh filename="package://ur5/data/0000_RG_connector_simple.stl"/>
      </geometry>
      <material name="connector_green">
        <color rgba="0.2 0.8 0 1"/>
      </material>
    </visual>
    <collision>
      <geometry>
        <mesh filename="package://ur5/data/0000_RG_connector_simple.stl"/>
      </geometry>
    </collision>
  </link>
  <joint name="right_wrist_connector" type="fixed">
    <origin rpy="1.5708 0 0" xyz="0 -0.0375 -0.02"/>
    <parent link="right_wrist_3_link"/>
    <child link="right_wrist_connector_link"/>
  </joint>
  <gazebo>
    <!-- enable ros_control loop -->
    <plugin filename="libgazebo_ros_control.so" name="ros_control"/>
    <!-- gravity compensation -->
    <plugin filename="libGravityCompensationPlugin.so" name="gravity_compensation">
      <uri>model://prl_ur5_robot</uri>
    </plugin>
    <!-- fix base in Gazebo -->
    <joint name="fixed" type="fixed">
      <parent>world</parent>
      <child>prl_ur5_base</child>
    </joint>
  </gazebo>
</robot>

