<?xml version="1.0" encoding="utf-8"?>
<!-- =================================================================================== -->
<!-- |    This document was autogenerated by xacro from canopies_arm_bench.urdf.xacro  | -->
<!-- |    EDITING THIS FILE BY HAND IS NOT RECOMMENDED                                 | -->
<!-- =================================================================================== -->
<robot name="canopies_arm_bench">
  <!-- Constants -->
  <gazebo>
    <plugin filename="libgazebo_ros_control.so" name="gazebo_ros_control">
      <ns/>
      <robotSimType>pal_hardware_gazebo/PalHardwareGazebo</robotSimType>
      <robotNamespace/>
      <controlPeriod>0.001</controlPeriod>
    </plugin>
    <plugin filename="libgazebo_ros_p3d.so" name="gazebo_ros_p3d">
      <bodyName>base_footprint</bodyName>
      <topicName>ground_truth_odom</topicName>
      <alwaysOn>true</alwaysOn>
      <updateRate>100.0</updateRate>
    </plugin>
  </gazebo>
  <gazebo>
    <plugin filename="libgazebo_world_odometry.so" name="gazebo_ros_odometry">
      <frameName>base_footprint</frameName>
      <topicName>floating_base_pose_simulated</topicName>
    </plugin>
  </gazebo>
  <gazebo reference="base_imu_link">
    <!-- this is expected to be reparented to pelvis with appropriate offset
         when imu_link is reduced by fixed joint reduction -->
    <!-- todo: this is working with gazebo 1.4, need to write a unit test -->
    <sensor name="imu_sensor" type="imu">
      <always_on>1</always_on>
      <update_rate>1000.0</update_rate>
      <imu>
        <noise>
          <type>gaussian</type>
          <!-- Noise parameters from Boston Dynamics
               (http://gazebosim.org/wiki/Sensor_noise):
                 rates (rad/s): mean=0, stddev=2e-4
                 accels (m/s/s): mean=0, stddev=1.7e-2
                 rate bias (rad/s): 5e-6 - 1e-5
                 accel bias (m/s/s): 1e-1
               Experimentally, simulation provide rates with noise of
               about 1e-3 rad/s and accels with noise of about 1e-1 m/s/s.
               So we don't expect to see the noise unless number of inner iterations
               are increased.

               We will add bias.  In this model, bias is sampled once for rates
               and once for accels at startup; the sign (negative or positive)
               of each bias is then switched with equal probability.  Thereafter,
               the biases are fixed additive offsets.  We choose
               bias means and stddevs to produce biases close to the provided
               data. -->
          <rate>
            <mean>0.0</mean>
            <stddev>2e-4</stddev>
            <bias_mean>0.0000075</bias_mean>
            <bias_stddev>0.0000008</bias_stddev>
          </rate>
          <accel>
            <mean>0.0</mean>
            <stddev>1.7e-2</stddev>
            <bias_mean>0.1</bias_mean>
            <bias_stddev>0.001</bias_stddev>
          </accel>
        </noise>
      </imu>
    </sensor>
  </gazebo>
  <!-- Base link -->
  <link name="base_link">
    <inertial>
      <origin rpy="0 0 0" xyz="0. 0. 0."/>
      <mass value="1e-6"/>
      <inertia ixx="1e-6" ixy="0.0" ixz="0.0" iyy="1e-6" iyz="0.0" izz="1e-6"/>
    </inertial>
    <visual>
      <origin rpy="0 0 0" xyz="0 0 0"/>
      <geometry>
        <box size="0.1 0.1 0.1"/>
      </geometry>
      <material name="">
        <color rgba="0.752941176470588 0.752941176470588 0.752941176470588 1"/>
      </material>
    </visual>
  </link>
  <!-- Base footprint -->
  <link name="base_footprint"/>
  <joint name="base_footprint_joint" type="fixed">
    <origin rpy="0 0 0" xyz="0 0 0.8"/>
    <child link="base_link"/>
    <parent link="base_footprint"/>
  </joint>
  <!-- gazebo parameters are given here for base_link thru base_footprint -->
  <gazebo reference="base_footprint">
    <kp>100000000.0</kp>
    <kd>10.0</kd>
    <mu1>0.1</mu1>
    <mu2>0.1</mu2>
    <fdir1>1 0 0</fdir1>
    <maxVel>10.0</maxVel>
    <minDepth>0.0005</minDepth>
    <laserRetro>0</laserRetro>
  </gazebo>
  <link name="arm_right_1_link">
    <inertial>
      <origin rpy="0 0 0" xyz="0.104590177873438 -0.0135580162788852 -0.0309966654078049"/>
      <mass value="0.876973685013"/>
      <inertia ixx="0.000601489961747" ixy="8.34336374218e-05" ixz="0.000317156454887" iyy="0.00185108820021" iyz="-2.48712752724e-05" izz="0.00165524533455"/>
    </inertial>
    <visual>
      <origin rpy="0 0 0" xyz="0 0 0"/>
      <geometry>
        <mesh filename="package://canopies_description/meshes/arm_right_1_link.STL"/>
      </geometry>
      <material name="">
        <color rgba="0.752941176470588 0.752941176470588 0.752941176470588 1"/>
      </material>
    </visual>
    <collision>
      <origin rpy="0 0 0" xyz="0 0 0"/>
      <geometry>
        <mesh filename="package://canopies_description/meshes/arm_right_1_link_convex.STL"/>
      </geometry>
    </collision>
  </link>
  <joint name="arm_right_1_joint" type="revolute">
    <origin rpy="0 0 -1.5708" xyz="0.18155 -0.203 -0.0151"/>
    <parent link="base_link"/>
    <child link="arm_right_1_link"/>
    <axis xyz="0 0 1"/>
    <limit effort="50" lower="-1.1854" upper="1.5708" velocity="2"/>
  </joint>
  <link name="arm_right_2_link">
    <inertial>
      <origin rpy="0 0 0" xyz="-0.103229215921456 -6.62803677657919E-05 0.040391671720359"/>
      <mass value="0.794071310034"/>
      <inertia ixx="0.000785583237145" ixy="-2.0052022231e-07" ixz="-0.000281390136283" iyy="0.00123739549319" iyz="-9.50161622259e-07" izz="0.00128756739474"/>
    </inertial>
    <visual>
      <origin rpy="0 0 0" xyz="0 0 0"/>
      <geometry>
        <mesh filename="package://canopies_description/meshes/arm_right_2_link.STL"/>
      </geometry>
      <material name="">
        <color rgba="0.752941176470588 0.752941176470588 0.752941176470588 1"/>
      </material>
    </visual>
    <collision>
      <origin rpy="0 0 0" xyz="0 0 0"/>
      <geometry>
        <mesh filename="package://canopies_description/meshes/arm_right_2_link_convex.STL"/>
      </geometry>
    </collision>
  </link>
  <joint name="arm_right_2_joint" type="revolute">
    <origin rpy="1.5707963267949 0 3.14159265358979" xyz="0.130000000000049 -0.0482999996185306 -0.0399999999998413"/>
    <parent link="arm_right_1_link"/>
    <child link="arm_right_2_link"/>
    <axis xyz="0 0 1"/>
    <limit effort="50" lower="-1.5708" upper="1.5708" velocity="2"/>
  </joint>
  <link name="arm_right_3_link">
    <inertial>
      <origin rpy="0 0 0" xyz="0.0141106542132395 0.0147731157720475 -0.129722816418797"/>
      <mass value="0.926307323067"/>
      <inertia ixx="0.00268729618779" ixy="5.93138944713e-06" ixz="6.98081651e-05" iyy="0.0022624306041" iyz="0.000217390694395" izz="0.000728199500067"/>
    </inertial>
    <visual>
      <origin rpy="0 0 0" xyz="0 0 0"/>
      <geometry>
        <mesh filename="package://canopies_description/meshes/arm_right_3_link.STL"/>
      </geometry>
      <material name="">
        <color rgba="0.752941176470588 0.752941176470588 0.752941176470588 1"/>
      </material>
    </visual>
    <collision>
      <origin rpy="0 0 0" xyz="0 0 0"/>
      <geometry>
        <mesh filename="package://canopies_description/meshes/arm_right_3_link_convex.STL"/>
      </geometry>
    </collision>
  </link>
  <joint name="arm_right_3_joint" type="revolute">
    <origin rpy="0 1.5707963267949 0" xyz="-0.154945006346293 0 0.0500038538537946"/>
    <parent link="arm_right_2_link"/>
    <child link="arm_right_3_link"/>
    <axis xyz="0 0 1"/>
    <limit effort="50" lower="-2.4435" upper="2.4435" velocity="2"/>
  </joint>
  <link name="arm_right_4_link">
    <inertial>
      <origin rpy="0 0 0" xyz="-0.0270943216353722 -0.0988821520517052 0.0405150394017644"/>
      <mass value="0.82292797291"/>
      <inertia ixx="0.00134281613791" ixy="0.000105745458534" ixz="8.84774161323e-05" iyy="0.000825129978916" iyz="0.000306718405566" izz="0.00139879333095"/>
    </inertial>
    <visual>
      <origin rpy="0 0 0" xyz="0 0 0"/>
      <geometry>
        <mesh filename="package://canopies_description/meshes/arm_right_4_link.STL"/>
      </geometry>
      <material name="">
        <color rgba="0.752941176470588 0.752941176470588 0.752941176470588 1"/>
      </material>
    </visual>
    <collision>
      <origin rpy="0 0 0" xyz="0 0 0"/>
      <geometry>
        <mesh filename="package://canopies_description/meshes/arm_right_4_link_convex.STL"/>
      </geometry>
    </collision>
  </link>
  <joint name="arm_right_4_joint" type="revolute">
    <origin rpy="1.5707963267949 -0.436332316595644 -1.5707963267949" xyz="0.049993121155 0.0199999999949542 -0.165099999970051"/>
    <parent link="arm_right_3_link"/>
    <child link="arm_right_4_link"/>
    <axis xyz="0 0 -1"/>
    <limit effort="50" lower="-1.5708" upper="2.3562" velocity="2"/>
  </joint>
  <link name="arm_right_5_link">
    <inertial>
      <origin rpy="0 0 0" xyz="4.30740072904223E-05 -0.00848243416126348 -0.122150591344461"/>
      <mass value="0.748930343342"/>
      <inertia ixx="0.00165448487772" ixy="7.13153097641e-08" ixz="5.94335178566e-07" iyy="0.0018865698396" iyz="-1.99881659135e-05" izz="0.000485154620181"/>
    </inertial>
    <visual>
      <origin rpy="0 0 0" xyz="0 0 0"/>
      <geometry>
        <mesh filename="package://canopies_description/meshes/arm_right_5_link.STL"/>
      </geometry>
      <material name="">
        <color rgba="0.752941176470588 0.752941176470588 0.752941176470588 1"/>
      </material>
    </visual>
    <collision>
      <origin rpy="0 0 0" xyz="0 0 0"/>
      <geometry>
        <mesh filename="package://canopies_description/meshes/arm_right_5_link_convex.STL"/>
      </geometry>
    </collision>
  </link>
  <joint name="arm_right_5_joint" type="revolute">
    <origin rpy="1.57079632679489 0 2.70526034059123" xyz="-0.0473796779453546 -0.148930079190456 0.0500006723402781"/>
    <parent link="arm_right_4_link"/>
    <child link="arm_right_5_link"/>
    <axis xyz="0 0 1"/>
    <limit effort="50" lower="-2.4435" upper="2.4435" velocity="2"/>
  </joint>
  <link name="arm_right_6_link">
    <inertial>
      <origin rpy="0 0 0" xyz="2.67981412671592E-05 -0.0996444474227959 0.0324891780507251"/>
      <mass value="0.574499982762"/>
      <inertia ixx="0.0006497241529" ixy="-2.88560094495e-07" ixz="7.26158980543e-07" iyy="0.00035431768666" iyz="0.000130103098394" izz="0.000674307517909"/>
    </inertial>
    <visual>
      <origin rpy="0 0 0" xyz="0 0 0"/>
      <geometry>
        <mesh filename="package://canopies_description/meshes/arm_right_6_link.STL"/>
      </geometry>
      <material name="">
        <color rgba="0.752941176470588 0.752941176470588 0.752941176470588 1"/>
      </material>
    </visual>
    <collision>
      <origin rpy="0 0 0" xyz="0 0 0"/>
      <geometry>
        <mesh filename="package://canopies_description/meshes/arm_right_6_link_convex.STL"/>
      </geometry>
    </collision>
  </link>
  <joint name="arm_right_6_joint" type="revolute">
    <origin rpy="1.57079225562289 0 3.14159265358979" xyz="0 -0.0394965876541469 -0.165050003051757"/>
    <parent link="arm_right_5_link"/>
    <child link="arm_right_6_link"/>
    <axis xyz="0 0 -1"/>
    <limit effort="50" lower="-2.0944" upper="2.0944" velocity="2"/>
  </joint>
  <link name="arm_right_7_link">
    <inertial>
      <origin rpy="0 0 0" xyz="8.56652769554156E-12 1.39648292929451E-11 0.00740178372048539"/>
      <mass value="0.04645419506"/>
      <inertia ixx="1.50415963926e-05" ixy="1.85363213141e-15" ixz="1.20426857767e-14" iyy="1.5041596398e-05" iyz="-2.32028280159e-14" izz="1.40885078823e-05"/>
    </inertial>
    <visual>
      <origin rpy="0 0 0" xyz="0 0 0"/>
      <geometry>
        <mesh filename="package://canopies_description/meshes/arm_right_7_link.STL"/>
      </geometry>
      <material name="">
        <color rgba="0.752941176470588 0.752941176470588 0.752941176470588 1"/>
      </material>
    </visual>
    <collision>
      <origin rpy="0 0 0" xyz="0 0 0"/>
      <geometry>
        <mesh filename="package://canopies_description/meshes/arm_right_7_link_convex.STL"/>
      </geometry>
    </collision>
  </link>
  <joint name="arm_right_7_joint" type="revolute">
    <origin rpy="0 1.57079225564058 1.57079632319904" xyz="0 -0.146000162750523 0.0390015522533293"/>
    <parent link="arm_right_6_link"/>
    <child link="arm_right_7_link"/>
    <axis xyz="0 0 1"/>
    <limit effort="50" lower="-2.4435" upper="2.4435" velocity="2"/>
  </joint>
  <!-- Gazebo tags -->
  <gazebo reference="arm_right_1_link">
    <mu1>0.9</mu1>
    <mu2>0.9</mu2>
    <material>Gazebo/DarkGrey</material>
  </gazebo>
  <gazebo reference="arm_right_2_link">
    <mu1>0.9</mu1>
    <mu2>0.9</mu2>
    <material>Gazebo/DarkGrey</material>
  </gazebo>
  <gazebo reference="arm_right_3_link">
    <mu1>0.9</mu1>
    <mu2>0.9</mu2>
    <material>Gazebo/DarkGrey</material>
  </gazebo>
  <gazebo reference="arm_right_4_link">
    <mu1>0.9</mu1>
    <mu2>0.9</mu2>
    <material>Gazebo/DarkGrey</material>
  </gazebo>
  <gazebo reference="arm_right_5_link">
    <mu1>0.9</mu1>
    <mu2>0.9</mu2>
    <material>Gazebo/DarkGrey</material>
  </gazebo>
  <gazebo reference="arm_right_6_link">
    <mu1>0.9</mu1>
    <mu2>0.9</mu2>
    <material>Gazebo/DarkGrey</material>
  </gazebo>
  <gazebo reference="arm_right_7_link">
    <mu1>0.9</mu1>
    <mu2>0.9</mu2>
    <material>Gazebo/DarkGrey</material>
  </gazebo>
  <gazebo reference="arm_right_1_joint">
    <implicitSpringDamper>1</implicitSpringDamper>
  </gazebo>
  <gazebo reference="arm_right_2_joint">
    <implicitSpringDamper>1</implicitSpringDamper>
  </gazebo>
  <gazebo reference="arm_right_3_joint">
    <implicitSpringDamper>1</implicitSpringDamper>
  </gazebo>
  <gazebo reference="arm_right_4_joint">
    <implicitSpringDamper>1</implicitSpringDamper>
  </gazebo>
  <gazebo reference="arm_right_5_joint">
    <implicitSpringDamper>1</implicitSpringDamper>
  </gazebo>
  <gazebo reference="arm_right_6_joint">
    <implicitSpringDamper>1</implicitSpringDamper>
  </gazebo>
  <gazebo reference="arm_right_7_joint">
    <implicitSpringDamper>1</implicitSpringDamper>
  </gazebo>
  <transmission name="arm_right_1_trans">
    <type>transmission_interface/SimpleTransmission</type>
    <actuator name="arm_right_1_motor">
      <mechanicalReduction>1.0</mechanicalReduction>
    </actuator>
    <joint name="arm_right_1_joint">
      <offset>0</offset>
      <hardwareInterface>hardware_interface/PositionJointInterface</hardwareInterface>
      <hardwareInterface>hardware_interface/EffortJointInterface</hardwareInterface>
      <hardwareInterface>hardware_interface/VelocityJointInterface</hardwareInterface>
      <hardwareInterface>hardware_interface/JointStateInterface</hardwareInterface>
    </joint>
  </transmission>
  <transmission name="arm_right_2_trans">
    <type>transmission_interface/SimpleTransmission</type>
    <actuator name="arm_right_2_motor">
      <mechanicalReduction>1.0</mechanicalReduction>
    </actuator>
    <joint name="arm_right_2_joint">
      <offset>0</offset>
      <hardwareInterface>hardware_interface/PositionJointInterface</hardwareInterface>
      <hardwareInterface>hardware_interface/EffortJointInterface</hardwareInterface>
      <hardwareInterface>hardware_interface/VelocityJointInterface</hardwareInterface>
      <hardwareInterface>hardware_interface/JointStateInterface</hardwareInterface>
    </joint>
  </transmission>
  <transmission name="arm_right_3_trans">
    <type>transmission_interface/SimpleTransmission</type>
    <actuator name="arm_right_3_motor">
      <mechanicalReduction>1.0</mechanicalReduction>
    </actuator>
    <joint name="arm_right_3_joint">
      <offset>0</offset>
      <hardwareInterface>hardware_interface/PositionJointInterface</hardwareInterface>
      <hardwareInterface>hardware_interface/EffortJointInterface</hardwareInterface>
      <hardwareInterface>hardware_interface/VelocityJointInterface</hardwareInterface>
      <hardwareInterface>hardware_interface/JointStateInterface</hardwareInterface>
    </joint>
  </transmission>
  <transmission name="arm_right_4_trans">
    <type>transmission_interface/SimpleTransmission</type>
    <actuator name="arm_right_4_motor">
      <mechanicalReduction>1.0</mechanicalReduction>
    </actuator>
    <joint name="arm_right_4_joint">
      <offset>0</offset>
      <hardwareInterface>hardware_interface/PositionJointInterface</hardwareInterface>
      <hardwareInterface>hardware_interface/EffortJointInterface</hardwareInterface>
      <hardwareInterface>hardware_interface/VelocityJointInterface</hardwareInterface>
      <hardwareInterface>hardware_interface/JointStateInterface</hardwareInterface>
    </joint>
  </transmission>
  <transmission name="arm_right_5_trans">
    <type>transmission_interface/SimpleTransmission</type>
    <actuator name="arm_right_5_motor">
      <mechanicalReduction>1.0</mechanicalReduction>
    </actuator>
    <joint name="arm_right_5_joint">
      <offset>0</offset>
      <hardwareInterface>hardware_interface/PositionJointInterface</hardwareInterface>
      <hardwareInterface>hardware_interface/EffortJointInterface</hardwareInterface>
      <hardwareInterface>hardware_interface/VelocityJointInterface</hardwareInterface>
      <hardwareInterface>hardware_interface/JointStateInterface</hardwareInterface>
    </joint>
  </transmission>
  <transmission name="arm_right_6_trans">
    <type>transmission_interface/SimpleTransmission</type>
    <actuator name="arm_right_6_motor">
      <mechanicalReduction>1.0</mechanicalReduction>
    </actuator>
    <joint name="arm_right_6_joint">
      <offset>0</offset>
      <hardwareInterface>hardware_interface/PositionJointInterface</hardwareInterface>
      <hardwareInterface>hardware_interface/EffortJointInterface</hardwareInterface>
      <hardwareInterface>hardware_interface/VelocityJointInterface</hardwareInterface>
      <hardwareInterface>hardware_interface/JointStateInterface</hardwareInterface>
    </joint>
  </transmission>
  <transmission name="arm_right_7_trans">
    <type>transmission_interface/SimpleTransmission</type>
    <actuator name="arm_right_7_motor">
      <mechanicalReduction>1.0</mechanicalReduction>
    </actuator>
    <joint name="arm_right_7_joint">
      <offset>0</offset>
      <hardwareInterface>hardware_interface/PositionJointInterface</hardwareInterface>
      <hardwareInterface>hardware_interface/EffortJointInterface</hardwareInterface>
      <hardwareInterface>hardware_interface/VelocityJointInterface</hardwareInterface>
      <hardwareInterface>hardware_interface/JointStateInterface</hardwareInterface>
    </joint>
  </transmission>
</robot>
