<?xml version="1.0" encoding="utf-8"?>
<!-- =================================================================================== -->
<!-- |    This document was autogenerated by xacro from canopies.urdf.xacro            | -->
<!-- |    EDITING THIS FILE BY HAND IS NOT RECOMMENDED                                 | -->
<!-- =================================================================================== -->
<robot name="canopies">
  <!-- Constants -->
  <gazebo>
    <plugin filename="libgazebo_ros_control.so" name="gazebo_ros_control">
      <ns/>
      <robotSimType>pal_hardware_gazebo/PalHardwareGazebo</robotSimType>
      <robotNamespace/>
      <controlPeriod>0.001</controlPeriod>
    </plugin>
    <plugin filename="libgazebo_ros_p3d.so" name="gazebo_ros_p3d">
      <bodyName>base_footprint</bodyName>
      <topicName>ground_truth_odom</topicName>
      <alwaysOn>true</alwaysOn>
      <updateRate>100.0</updateRate>
    </plugin>
  </gazebo>
  <gazebo>
    <plugin filename="libgazebo_world_odometry.so" name="gazebo_ros_odometry">
      <frameName>base_footprint</frameName>
      <topicName>floating_base_pose_simulated</topicName>
    </plugin>
  </gazebo>
  <gazebo reference="base_imu_link">
    <!-- this is expected to be reparented to pelvis with appropriate offset
         when imu_link is reduced by fixed joint reduction -->
    <!-- todo: this is working with gazebo 1.4, need to write a unit test -->
    <sensor name="imu_sensor" type="imu">
      <always_on>1</always_on>
      <update_rate>1000.0</update_rate>
      <imu>
        <noise>
          <type>gaussian</type>
          <!-- Noise parameters from Boston Dynamics
               (http://gazebosim.org/wiki/Sensor_noise):
                 rates (rad/s): mean=0, stddev=2e-4
                 accels (m/s/s): mean=0, stddev=1.7e-2
                 rate bias (rad/s): 5e-6 - 1e-5
                 accel bias (m/s/s): 1e-1
               Experimentally, simulation provide rates with noise of
               about 1e-3 rad/s and accels with noise of about 1e-1 m/s/s.
               So we don't expect to see the noise unless number of inner iterations
               are increased.

               We will add bias.  In this model, bias is sampled once for rates
               and once for accels at startup; the sign (negative or positive)
               of each bias is then switched with equal probability.  Thereafter,
               the biases are fixed additive offsets.  We choose
               bias means and stddevs to produce biases close to the provided
               data. -->
          <rate>
            <mean>0.0</mean>
            <stddev>2e-4</stddev>
            <bias_mean>0.0000075</bias_mean>
            <bias_stddev>0.0000008</bias_stddev>
          </rate>
          <accel>
            <mean>0.0</mean>
            <stddev>1.7e-2</stddev>
            <bias_mean>0.1</bias_mean>
            <bias_stddev>0.001</bias_stddev>
          </accel>
        </noise>
      </imu>
    </sensor>
  </gazebo>
  <material name="silver_default">
    <color rgba="0.700 0.700 0.700 1.000"/>
  </material>
  <material name="powder_coat_rough_black">
    <color rgba="0.09803921568627451 0.09803921568627451 0.09803921568627451 1.0"/>
  </material>
  <material name="steel_cast">
    <color rgba="0.6274509803921569 0.6274509803921569 0.6274509803921569 1.0"/>
  </material>
  <material name="stainless_steel_cast">
    <color rgba="0.796078431372549 0.796078431372549 0.796078431372549 1.0"/>
  </material>
  <material name="paint_metallic_silver">
    <color rgba="0.984313725490196 0.9803921568627451 0.9607843137254902 1.0"/>
  </material>
  <material name="paint_enamel_glossy_yellow">
    <color rgba="1.0 1.0 0.0 1.0"/>
  </material>
  <material name="conveyor_material">
    <color rgba="0.09803921568627451 0.09803921568627451 0.09803921568627451 1.0"/>
  </material>
  <material name="bem_frame_material">
    <color rgba="0.984313725490196 0.9803921568627451 0.9607843137254902 1.0"/>
  </material>
  <!-- false, true-->
  <!-- Base footprint -->
  <link name="base_footprint"/>
  <gazebo reference="base_footprint">
    <kp>100000000.0</kp>
    <kd>10.0</kd>
    <mu1>0.1</mu1>
    <mu2>0.1</mu2>
    <fdir1>1 0 0</fdir1>
    <maxVel>10.0</maxVel>
    <minDepth>0.0005</minDepth>
    <laserRetro>0</laserRetro>
  </gazebo>
  <joint name="base_footprint_joint" type="fixed">
    <origin rpy="0 0 0" xyz="0 0 0.17"/>
    <child link="base_link"/>
    <parent link="base_footprint"/>
  </joint>
  <!-- Base -->
  <link name="base_link">
    <inertial>
      <origin rpy="0 0 0" xyz="0 0 0"/>
      <mass value="0.001"/>
      <inertia ixx="1e-6" ixy="0" ixz="0" iyy="1e-6" iyz="0" izz="1e-6"/>
    </inertial>
  </link>
  <gazebo reference="base_link">
    <turnGravityOff>false</turnGravityOff>
  </gazebo>
  <!-- Yellow chassis -->
  <link name="base_chassis_yellow_link">
    <inertial>
      <origin rpy="0 0 0" xyz="0.33 0 0.18373503481265221"/>
      <mass value="10"/>
      <inertia ixx="0.229666666667" ixy="0.0" ixz="0.0" iyy="1.50466666667" iyz="0.0" izz="1.54166666667"/>
    </inertial>
    <visual>
      <origin rpy="0 0 0" xyz="0 0 0"/>
      <geometry>
        <mesh filename="package://alitrak_description/meshes/base/chassis_yellow.stl" scale="0.001 0.001 0.001"/>
      </geometry>
      <material name="paint_enamel_glossy_yellow"/>
    </visual>
    <collision>
      <origin rpy="0 0 0" xyz="-0.08 0 0.09"/>
      <geometry>
        <box size="1.3 0.4 0.34"/>
      </geometry>
    </collision>
  </link>
  <gazebo reference="base_chassis_yellow_link">
    <turnGravityOff>false</turnGravityOff>
    <material>Gazebo/Yellow</material>
    <selfCollide>false</selfCollide>
  </gazebo>
  <joint name="base_chassis_yellow_joint" type="fixed">
    <origin rpy="0 0 0" xyz="0 0 0"/>
    <parent link="base_link"/>
    <child link="base_chassis_yellow_link"/>
  </joint>
  <!-- Grey chassis -->
  <link name="base_chassis_grey_link">
    <inertial>
      <origin rpy="0 0 0" xyz="0 0 0"/>
      <mass value="1e-5"/>
      <inertia ixx="1e-6" ixy="0" ixz="0" iyy="1e-6" iyz="0" izz="1e-6"/>
    </inertial>
    <visual>
      <origin rpy="0 0 0" xyz="0 0 0"/>
      <geometry>
        <mesh filename="package://alitrak_description/meshes/base/chassis_grey.stl" scale="0.001 0.001 0.001"/>
      </geometry>
      <material name="paint_metallic_silver"/>
    </visual>
  </link>
  <gazebo reference="base_chassis_grey_link">
    <turnGravityOff>false</turnGravityOff>
    <material>Gazebo/Gray</material>
    <selfCollide>false</selfCollide>
  </gazebo>
  <joint name="base_chassis_grey_joint" type="fixed">
    <origin rpy="0 0 0" xyz="0 0 0"/>
    <parent link="base_chassis_yellow_link"/>
    <child link="base_chassis_grey_link"/>
  </joint>
  <!-- Top plate -->
  <link name="base_top_plate_link">
    <inertial>
      <mass value="1e-5"/>
      <origin rpy="0 0 0" xyz="0 0 0"/>
      <inertia ixx="1e-6" ixy="0" ixz="0" iyy="1e-6" iyz="0" izz="1e-6"/>
    </inertial>
    <visual>
      <origin rpy="0 0 0" xyz="0 0 0"/>
      <geometry>
        <mesh filename="package://alitrak_description/meshes/base/top_plate.stl" scale="0.001 0.001 0.001"/>
      </geometry>
      <material name="silver_default"/>
    </visual>
    <collision>
      <origin rpy="0 0 0" xyz="0 0 0"/>
      <geometry>
        <box size="1.4 0.75 0.01"/>
      </geometry>
    </collision>
  </link>
  <gazebo reference="base_top_plate_link">
    <turnGravityOff>false</turnGravityOff>
    <material>Gazebo/Gray</material>
    <selfCollide>false</selfCollide>
  </gazebo>
  <joint name="base_top_plate_joint" type="fixed">
    <origin rpy="0 0 0" xyz="0 0 0.262902"/>
    <parent link="base_chassis_yellow_link"/>
    <child link="base_top_plate_link"/>
  </joint>
  <!-- Torso -->
  <link name="base_attachment_link">
    <inertial>
      <origin rpy="0 0 0" xyz="0 0 0"/>
      <mass value="0.001"/>
      <inertia ixx="1e-6" ixy="0" ixz="0" iyy="1e-6" iyz="0" izz="1e-6"/>
    </inertial>
  </link>
  <gazebo reference="base_link">
    <turnGravityOff>false</turnGravityOff>
  </gazebo>
  <joint name="base_attachment_joint" type="fixed">
    <origin rpy="0 0 0" xyz="-0.338 0.0 0.0749"/>
    <parent link="base_link"/>
    <child link="base_attachment_link"/>
  </joint>
  <!-- Bem -->
  <link name="base_bem_attachment_link">
    <inertial>
      <origin rpy="0 0 0" xyz="0.0 0.0 0.0"/>
      <mass value="0.1"/>
      <inertia ixx="0.01" ixy="0.0" ixz="0.0" iyy="0.01" iyz="0.0" izz="0.01"/>
    </inertial>
  </link>
  <joint name="base_bem_attachment_joint" type="fixed">
    <origin rpy="0 0 0" xyz="0.3 0.0 0.0"/>
    <parent link="base_top_plate_link"/>
    <child link="base_bem_attachment_link"/>
  </joint>
  <link name="track_motor_body_right_link">
    <inertial>
      <mass value="1e-5"/>
      <origin rpy="0 0 0" xyz="0 0 0"/>
      <inertia ixx="1e-6" ixy="0" ixz="0" iyy="1e-6" iyz="0" izz="1e-6"/>
    </inertial>
    <visual>
      <origin rpy="0 0 0" xyz="0.0 -0.0 -0.0"/>
      <geometry>
        <mesh filename="package://alitrak_description/meshes/wheels/motor_body.stl" scale="0.001 -0.001 0.001"/>
      </geometry>
      <material name="steel_cast"/>
    </visual>
  </link>
  <gazebo reference="track_motor_body_right_link">
    <turnGravityOff>false</turnGravityOff>
    <material>Gazebo/DarkGray</material>
    <selfCollide>false</selfCollide>
  </gazebo>
  <joint name="track_motor_body_right_joint" type="fixed">
    <origin rpy="0 0 0" xyz="-0.4855 -0.305 0"/>
    <parent link="base_link"/>
    <child link="track_motor_body_right_link"/>
  </joint>
  <link name="track_right_link">
    <inertial>
      <mass value="1e-5"/>
      <origin rpy="0 0 0" xyz="0 0 0"/>
      <inertia ixx="1e-6" ixy="0" ixz="0" iyy="1e-6" iyz="0" izz="1e-6"/>
    </inertial>
    <visual>
      <origin rpy="0 0 0" xyz="0 0 0"/>
      <geometry>
        <mesh filename="package://alitrak_description/meshes/wheels/track.stl" scale="0.001 0.001 0.001"/>
      </geometry>
      <material name="powder_coat_rough_black"/>
    </visual>
    <collision>
      <origin rpy="0 0 0" xyz="0 0 0"/>
      <geometry>
        <mesh filename="package://alitrak_description/meshes/wheels/track.stl" scale="0.001 0.001 0.001"/>
      </geometry>
    </collision>
  </link>
  <gazebo reference="track_right_link">
    <turnGravityOff>false</turnGravityOff>
    <material>Gazebo/FlatBlack</material>
    <selfCollide>false</selfCollide>
  </gazebo>
  <joint name="track_right_joint" type="fixed">
    <origin rpy="0.0 0.0 0.0" xyz="-0.0 -0.305 0.0"/>
    <parent link="base_link"/>
    <child link="track_right_link"/>
  </joint>
  <link name="track_wheel_right_link">
    <inertial>
      <mass value="1e-5"/>
      <origin rpy="0 0 0" xyz="0 0 0"/>
      <inertia ixx="1e-6" ixy="0" ixz="0" iyy="1e-6" iyz="0" izz="1e-6"/>
    </inertial>
    <visual>
      <origin rpy="0 0 0" xyz="0 0 0"/>
      <geometry>
        <mesh filename="package://alitrak_description/meshes/wheels/motor_gear_wheel.stl" scale="0.001 0.001 0.001"/>
      </geometry>
      <material name="stainless_steel_cast"/>
    </visual>
    <collision>
      <origin rpy="0 1.57079632679 1.57079632679" xyz="0.0 0.0 0.0"/>
      <geometry>
        <cylinder length="0.18" radius="0.175"/>
      </geometry>
    </collision>
  </link>
  <joint name="track_wheel_right_joint" type="fixed">
    <origin rpy="0 0 0" xyz="0 0 0"/>
    <parent link="track_motor_body_right_link"/>
    <child link="track_wheel_right_link"/>
    <axis xyz="0 1 0"/>
  </joint>
  <!-- Transmission -->
  <!--     <xacro:wheel_transmission name="${name}_wheel" side="${side}"/>-->
  <!-- Gazebo extensions -->
  <!-- <xacro:wheel_gazebo name="${name}_wheel" side="${side}"/> -->
  <link name="track_motor_body_left_link">
    <inertial>
      <mass value="1e-5"/>
      <origin rpy="0 0 0" xyz="0 0 0"/>
      <inertia ixx="1e-6" ixy="0" ixz="0" iyy="1e-6" iyz="0" izz="1e-6"/>
    </inertial>
    <visual>
      <origin rpy="0 0 0" xyz="0.0 -0.0 -0.0"/>
      <geometry>
        <mesh filename="package://alitrak_description/meshes/wheels/motor_body.stl" scale="0.001 0.001 0.001"/>
      </geometry>
      <material name="steel_cast"/>
    </visual>
  </link>
  <gazebo reference="track_motor_body_left_link">
    <turnGravityOff>false</turnGravityOff>
    <material>Gazebo/DarkGray</material>
    <selfCollide>false</selfCollide>
  </gazebo>
  <joint name="track_motor_body_left_joint" type="fixed">
    <origin rpy="0 0 0" xyz="-0.4855 0.305 0"/>
    <parent link="base_link"/>
    <child link="track_motor_body_left_link"/>
  </joint>
  <link name="track_left_link">
    <inertial>
      <mass value="1e-5"/>
      <origin rpy="0 0 0" xyz="0 0 0"/>
      <inertia ixx="1e-6" ixy="0" ixz="0" iyy="1e-6" iyz="0" izz="1e-6"/>
    </inertial>
    <visual>
      <origin rpy="0 0 0" xyz="0 0 0"/>
      <geometry>
        <mesh filename="package://alitrak_description/meshes/wheels/track.stl" scale="0.001 -0.001 0.001"/>
      </geometry>
      <material name="powder_coat_rough_black"/>
    </visual>
    <collision>
      <origin rpy="0 0 0" xyz="0 0 0"/>
      <geometry>
        <mesh filename="package://alitrak_description/meshes/wheels/track.stl" scale="0.001 -0.001 0.001"/>
      </geometry>
    </collision>
  </link>
  <gazebo reference="track_left_link">
    <turnGravityOff>false</turnGravityOff>
    <material>Gazebo/FlatBlack</material>
    <selfCollide>false</selfCollide>
  </gazebo>
  <joint name="track_left_joint" type="fixed">
    <origin rpy="0.0 0.0 0.0" xyz="-0.0 0.305 0.0"/>
    <parent link="base_link"/>
    <child link="track_left_link"/>
  </joint>
  <link name="track_wheel_left_link">
    <inertial>
      <mass value="1e-5"/>
      <origin rpy="0 0 0" xyz="0 0 0"/>
      <inertia ixx="1e-6" ixy="0" ixz="0" iyy="1e-6" iyz="0" izz="1e-6"/>
    </inertial>
    <visual>
      <origin rpy="0 0 0" xyz="0 0 0"/>
      <geometry>
        <mesh filename="package://alitrak_description/meshes/wheels/motor_gear_wheel.stl" scale="0.001 -0.001 0.001"/>
      </geometry>
      <material name="stainless_steel_cast"/>
    </visual>
    <collision>
      <origin rpy="0 1.57079632679 1.57079632679" xyz="0.0 0.0 0.0"/>
      <geometry>
        <cylinder length="0.18" radius="0.175"/>
      </geometry>
    </collision>
  </link>
  <joint name="track_wheel_left_joint" type="fixed">
    <origin rpy="0 0 0" xyz="0 0 0"/>
    <parent link="track_motor_body_left_link"/>
    <child link="track_wheel_left_link"/>
    <axis xyz="0 1 0"/>
  </joint>
  <!-- Transmission -->
  <!--     <xacro:wheel_transmission name="${name}_wheel" side="${side}"/>-->
  <!-- Gazebo extensions -->
  <!-- <xacro:wheel_gazebo name="${name}_wheel" side="${side}"/> -->
  <link name="base_imu_link">
    <inertial>
      <mass value="1e-5"/>
      <origin rpy="0 0 0" xyz="0 0 0"/>
      <inertia ixx="1e-6" ixy="0" ixz="0" iyy="1e-6" iyz="0" izz="1e-6"/>
    </inertial>
  </link>
  <joint name="base_imu_joint" type="fixed">
    <parent link="base_top_plate_link"/>
    <child link="base_imu_link"/>
    <origin rpy="0 0 0" xyz="-0.0425 0 0.167"/>
  </joint>
  <gazebo reference="base_imu_link">
    <gravity>true</gravity>
    <sensor name="base_imu_sensor" type="imu">
      <always_on>true</always_on>
      <update_rate>100</update_rate>
      <visualize>true</visualize>
      <topic>__default_topic__</topic>
      <plugin filename="libgazebo_ros_imu_sensor.so" name="imu_plugin">
        <topicName>imu</topicName>
        <bodyName>base_imu_link</bodyName>
        <updateRateHZ>100.0</updateRateHZ>
        <gaussianNoise>0.0</gaussianNoise>
        <xyzOffset>0 0 0</xyzOffset>
        <rpyOffset>0 0 0</rpyOffset>
        <frameName>imu_link</frameName>
        <initialOrientationAsReference>false</initialOrientationAsReference>
      </plugin>
      <pose>0 0 0 0 0 0</pose>
    </sensor>
  </gazebo>
  <link name="base_gnss_left_link">
    <inertial>
      <mass value="1e-5"/>
      <origin rpy="0 0 0" xyz="0 0 0"/>
      <inertia ixx="1e-6" ixy="0" ixz="0" iyy="1e-6" iyz="0" izz="1e-6"/>
    </inertial>
  </link>
  <joint name="base_gnss_left_joint" type="fixed">
    <parent link="base_top_plate_link"/>
    <child link="base_gnss_left_link"/>
    <origin rpy="0 0 0" xyz="-0.0425 0.325 0.25"/>
  </joint>
  <link name="base_gnss_right_link">
    <inertial>
      <mass value="1e-5"/>
      <origin rpy="0 0 0" xyz="0 0 0"/>
      <inertia ixx="1e-6" ixy="0" ixz="0" iyy="1e-6" iyz="0" izz="1e-6"/>
    </inertial>
  </link>
  <joint name="base_gnss_right_joint" type="fixed">
    <parent link="base_top_plate_link"/>
    <child link="base_gnss_right_link"/>
    <origin rpy="0 0 0" xyz="-0.0425 -0.325 0.25"/>
  </joint>
  <link name="lidar_front_link">
    <inertial>
      <mass value="1e-5"/>
      <origin rpy="0 0 0" xyz="0 0 0"/>
      <inertia ixx="1e-6" ixy="0" ixz="0" iyy="1e-6" iyz="0" izz="1e-6"/>
    </inertial>
  </link>
  <joint name="lidar_front_joint" type="fixed">
    <parent link="base_top_plate_link"/>
    <child link="lidar_front_link"/>
    <origin rpy="0 0 0" xyz="0.6275 -0.3 0.05"/>
  </joint>
  <link name="lidar_rear_link">
    <inertial>
      <mass value="1e-5"/>
      <origin rpy="0 0 0" xyz="0 0 0"/>
      <inertia ixx="1e-6" ixy="0" ixz="0" iyy="1e-6" iyz="0" izz="1e-6"/>
    </inertial>
  </link>
  <joint name="lidar_rear_joint" type="fixed">
    <parent link="base_top_plate_link"/>
    <child link="lidar_rear_link"/>
    <origin rpy="0 0 3.14159265359" xyz="-0.5925 0.3 0.05"/>
  </joint>
  <!-- Base link -->
  <link name="torso_base_link">
    <inertial>
      <origin rpy="0 0 0" xyz="0.0794971333361958 -0.0197312459015459 0.0498840944438262"/>
      <mass value="39.1190104209384"/>
      <inertia ixx="0.463390325482616" ixy="0.000800209490041979" ixz="0.0038269247621744" iyy="0.537783416757447" iyz="-0.00015991644650722" izz="0.931001593088985"/>
    </inertial>
    <visual>
      <origin rpy="0 0 0" xyz="0 0 0"/>
      <geometry>
        <mesh filename="package://canopies_description/meshes/torso/torso_base.STL"/>
      </geometry>
      <material name="">
        <color rgba="0.752941176470588 0.752941176470588 0.752941176470588 1"/>
      </material>
    </visual>
    <collision>
      <origin rpy="0 0 0" xyz="0 0 0"/>
      <geometry>
        <mesh filename="package://canopies_description/meshes/torso/torso_base_convex.STL"/>
      </geometry>
    </collision>
  </link>
  <joint name="torso_base_joint" type="fixed">
    <origin rpy="0 0 0" xyz="-0.4 0 0.277902"/>
    <child link="torso_base_link"/>
    <parent link="base_link"/>
  </joint>
  <!-- Torso yaw -->
  <link name="torso_yaw_link">
    <inertial>
      <origin rpy="0 0 0" xyz="-2.65609177871329E-05 -0.000435786406406857 0.00668095998040263"/>
      <mass value="3.08062751553524"/>
      <inertia ixx="0.0118287754267984" ixy="-7.53330500953443E-06" ixz="1.67448680288092E-07" iyy="0.0118749837139915" iyz="-1.81778403003434E-07" izz="0.0235557708250256"/>
    </inertial>
    <visual>
      <origin rpy="0 0 0" xyz="0 0 0"/>
      <geometry>
        <mesh filename="package://canopies_description/meshes/torso/torso_yaw.STL"/>
      </geometry>
      <material name="">
        <color rgba="0.752941176470588 0.752941176470588 0.752941176470588 1"/>
      </material>
    </visual>
    <collision>
      <origin rpy="0 0 0" xyz="0 0 0"/>
      <geometry>
        <mesh filename="package://canopies_description/meshes/torso/torso_yaw_convex.STL"/>
      </geometry>
    </collision>
  </link>
  <joint name="torso_yaw_joint" type="revolute">
    <origin rpy="0 0 0" xyz="0 0 0.144"/>
    <parent link="torso_base_link"/>
    <child link="torso_yaw_link"/>
    <axis xyz="0 0 1"/>
    <limit effort="2000" lower="-3.0107" upper="3.0107" velocity="0.8"/>
  </joint>
  <!-- Torso fix -->
  <link name="torso_fix_link">
    <inertial>
      <origin rpy="0 0 0" xyz="0.0252969404404609 -0.0103776216172753 0.20112908638825"/>
      <mass value="11.1069753304074"/>
      <inertia ixx="0.163309283241266" ixy="5.03933214554739E-05" ixz="-0.0040119335221245" iyy="0.161417347213433" iyz="-0.000559120248100301" izz="0.0394165396913767"/>
    </inertial>
    <visual>
      <origin rpy="0 0 0" xyz="0 0 0"/>
      <geometry>
        <mesh filename="package://canopies_description/meshes/torso/torso_fix.STL"/>
      </geometry>
      <material name="">
        <color rgba="0.752941176470588 0.752941176470588 0.752941176470588 1"/>
      </material>
    </visual>
    <collision>
      <origin rpy="0 0 0" xyz="0 0 0"/>
      <geometry>
        <mesh filename="package://canopies_description/meshes/torso/torso_fix_convex.STL"/>
      </geometry>
    </collision>
  </link>
  <joint name="torso_fix_joint" type="fixed">
    <origin rpy="0 0 0" xyz="0 0 0.0165"/>
    <parent link="torso_yaw_link"/>
    <child link="torso_fix_link"/>
    <axis xyz="0 0 0"/>
  </joint>
  <!-- Middle extending  -->
  <link name="torso_fixed_column_link">
    <inertial>
      <origin rpy="0 0 0" xyz="0 0 0"/>
      <mass value="0.01"/>
      <inertia ixx="0.000001" ixy="0" ixz="0" iyy="0.000001" iyz="0" izz="0.000001"/>
    </inertial>
    <visual>
      <origin rpy="0 0 0" xyz="0 0 0.275"/>
      <geometry>
        <box size="0.18 0.2 0.45"/>
      </geometry>
      <material name="DarkGrey"/>
    </visual>
    <collision>
      <origin rpy="0 0 0" xyz="0 0 0.275"/>
      <geometry>
        <box size="0.23 0.23 0.45"/>
      </geometry>
      <material name="DarkGrey"/>
    </collision>
  </link>
  <gazebo reference="torso_fixed_column_link">
    <material>Gazebo/DarkGrey</material>
  </gazebo>
  <joint name="torso_fixed_column_joint" type="fixed">
    <origin rpy="0 0 0" xyz="0.025 0 0.085"/>
    <parent link="torso_yaw_link"/>
    <child link="torso_fixed_column_link"/>
    <axis xyz="0 0 0"/>
  </joint>
  <!-- Torso lift -->
  <link name="torso_lift_link">
    <inertial>
      <origin rpy="0 0 0" xyz="0.101990394145162 0.000680984177382946 -0.115643554033635"/>
      <mass value="10.1808989814849"/>
      <inertia ixx="0.146245909179038" ixy="-1.46847178715372E-05" ixz="-0.00560071984192646" iyy="0.126819752699149" iyz="-0.000566234960303349" izz="0.058050729772705"/>
    </inertial>
    <visual>
      <origin rpy="0 0 0" xyz="0 0 0"/>
      <geometry>
        <mesh filename="package://canopies_description/meshes/torso/torso_lift.STL"/>
      </geometry>
      <material name="">
        <color rgba="0.792156862745098 0.819607843137255 0.933333333333333 1"/>
      </material>
    </visual>
    <collision>
      <origin rpy="0 0 0" xyz="0 0 0"/>
      <geometry>
        <mesh filename="package://canopies_description/meshes/torso/torso_lift_convex.STL"/>
      </geometry>
    </collision>
  </link>
  <joint name="torso_lift_joint" type="prismatic">
    <origin rpy="0 0 0" xyz="0 0 0.606"/>
    <parent link="torso_fix_link"/>
    <child link="torso_lift_link"/>
    <axis xyz="0 0 1"/>
    <limit effort="2000" lower="0" upper="0.35" velocity="0.07"/>
  </joint>
  <transmission name="torso_yaw_trans">
    <type>transmission_interface/SimpleTransmission</type>
    <actuator name="torso_yaw_motor">
      <mechanicalReduction>1.0</mechanicalReduction>
    </actuator>
    <joint name="torso_yaw_joint">
      <hardwareInterface>hardware_interface/PositionJointInterface</hardwareInterface>
      <hardwareInterface>hardware_interface/VelocityJointInterface</hardwareInterface>
      <hardwareInterface>hardware_interface/EffortJointInterface</hardwareInterface>
      <hardwareInterface>hardware_interface/JointStateInterface</hardwareInterface>
    </joint>
  </transmission>
  <transmission name="torso_lift_trans">
    <type>transmission_interface/SimpleTransmission</type>
    <actuator name="torso_lift_motor">
      <mechanicalReduction>1.0</mechanicalReduction>
    </actuator>
    <joint name="torso_lift_joint">
      <hardwareInterface>hardware_interface/PositionJointInterface</hardwareInterface>
      <hardwareInterface>hardware_interface/VelocityJointInterface</hardwareInterface>
      <hardwareInterface>hardware_interface/EffortJointInterface</hardwareInterface>
      <hardwareInterface>hardware_interface/JointStateInterface</hardwareInterface>
    </joint>
  </transmission>
  <link name="arm_right_1_link">
    <inertial>
      <origin rpy="0 0 0" xyz="0.104590177873438 -0.0135580162788852 -0.0309966654078049"/>
      <mass value="0.876973685013"/>
      <inertia ixx="0.000601489961747" ixy="8.34336374218e-05" ixz="0.000317156454887" iyy="0.00185108820021" iyz="-2.48712752724e-05" izz="0.00165524533455"/>
    </inertial>
    <visual>
      <origin rpy="0 0 0" xyz="0 0 0"/>
      <geometry>
        <mesh filename="package://canopies_description/meshes/arm/arm_right_1_link.STL"/>
      </geometry>
      <material name="">
        <color rgba="0.752941176470588 0.752941176470588 0.752941176470588 1"/>
      </material>
    </visual>
    <collision>
      <origin rpy="0 0 0" xyz="0 0 0"/>
      <geometry>
        <mesh filename="package://canopies_description/meshes/arm/arm_right_1_link_convex.STL"/>
      </geometry>
    </collision>
  </link>
  <joint name="arm_right_1_joint" type="revolute">
    <origin rpy="0 0 -1.5708" xyz="0.181558781082121 -0.203000000000049 -0.0441000000002132"/>
    <parent link="torso_lift_link"/>
    <child link="arm_right_1_link"/>
    <axis xyz="0 0 1"/>
    <limit effort="50" lower="-0.848" upper="1.5639" velocity="1.95"/>
    <safety_controller k_position="20" k_velocity="20" soft_lower_limit="-0.778" soft_upper_limit="1.4939"/>
  </joint>
  <link name="arm_right_2_link">
    <inertial>
      <origin rpy="0 0 0" xyz="-0.103229215921456 -6.62803677657919E-05 0.040391671720359"/>
      <mass value="0.794071310034"/>
      <inertia ixx="0.000785583237145" ixy="-2.0052022231e-07" ixz="-0.000281390136283" iyy="0.00123739549319" iyz="-9.50161622259e-07" izz="0.00128756739474"/>
    </inertial>
    <visual>
      <origin rpy="0 0 0" xyz="0 0 0"/>
      <geometry>
        <mesh filename="package://canopies_description/meshes/arm/arm_right_2_link.STL"/>
      </geometry>
      <material name="">
        <color rgba="0.752941176470588 0.752941176470588 0.752941176470588 1"/>
      </material>
    </visual>
    <collision>
      <origin rpy="0 0 0" xyz="0 0 0"/>
      <geometry>
        <mesh filename="package://canopies_description/meshes/arm/arm_right_2_link_convex.STL"/>
      </geometry>
    </collision>
  </link>
  <joint name="arm_right_2_joint" type="revolute">
    <origin rpy="1.5707963267949 0 3.14159265358979" xyz="0.130000000000049 -0.0482999996185306 -0.0399999999998413"/>
    <parent link="arm_right_1_link"/>
    <child link="arm_right_2_link"/>
    <axis xyz="0 0 1"/>
    <limit effort="50" lower="-1.5922" upper="1.5922" velocity="1.95"/>
    <safety_controller k_position="20" k_velocity="20" soft_lower_limit="-1.5222" soft_upper_limit="1.5222"/>
  </joint>
  <link name="arm_right_3_link">
    <inertial>
      <origin rpy="0 0 0" xyz="0.0141106542132395 0.0147731157720475 -0.129722816418797"/>
      <mass value="0.926307323067"/>
      <inertia ixx="0.00268729618779" ixy="5.93138944713e-06" ixz="6.98081651e-05" iyy="0.0022624306041" iyz="0.000217390694395" izz="0.000728199500067"/>
    </inertial>
    <visual>
      <origin rpy="0 0 0" xyz="0 0 0"/>
      <geometry>
        <mesh filename="package://canopies_description/meshes/arm/arm_right_3_link.STL"/>
      </geometry>
      <material name="">
        <color rgba="0.752941176470588 0.752941176470588 0.752941176470588 1"/>
      </material>
    </visual>
    <collision>
      <origin rpy="0 0 0" xyz="0 0 0"/>
      <geometry>
        <mesh filename="package://canopies_description/meshes/arm/arm_right_3_link_convex.STL"/>
      </geometry>
    </collision>
  </link>
  <joint name="arm_right_3_joint" type="revolute">
    <origin rpy="0 1.5707963267949 0" xyz="-0.154945006346293 0 0.0500038538537946"/>
    <parent link="arm_right_2_link"/>
    <child link="arm_right_3_link"/>
    <axis xyz="0 0 -1"/>
    <limit effort="50" lower="-2.53135" upper="2.53135" velocity="1.95"/>
    <safety_controller k_position="20" k_velocity="20" soft_lower_limit="-2.46135" soft_upper_limit="2.46135"/>
  </joint>
  <link name="arm_right_4_link">
    <inertial>
      <origin rpy="0 0 0" xyz="-0.0270943216353722 -0.0988821520517052 0.0405150394017644"/>
      <mass value="0.82292797291"/>
      <inertia ixx="0.00134281613791" ixy="0.000105745458534" ixz="8.84774161323e-05" iyy="0.000825129978916" iyz="0.000306718405566" izz="0.00139879333095"/>
    </inertial>
    <visual>
      <origin rpy="0 0 0" xyz="0 0 0"/>
      <geometry>
        <mesh filename="package://canopies_description/meshes/arm/arm_right_4_link.STL"/>
      </geometry>
      <material name="">
        <color rgba="0.752941176470588 0.752941176470588 0.752941176470588 1"/>
      </material>
    </visual>
    <collision>
      <origin rpy="0 0 0" xyz="0 0 0"/>
      <geometry>
        <mesh filename="package://canopies_description/meshes/arm/arm_right_4_link_convex.STL"/>
      </geometry>
    </collision>
  </link>
  <joint name="arm_right_4_joint" type="revolute">
    <origin rpy="1.5707963267949 -0.436332316595644 -1.5707963267949" xyz="0.049993121155 0.0199999999949542 -0.165099999970051"/>
    <parent link="arm_right_3_link"/>
    <child link="arm_right_4_link"/>
    <axis xyz="0 0 1"/>
    <limit effort="50" lower="-2.41302" upper="1.60868" velocity="1.95"/>
    <safety_controller k_position="20" k_velocity="20" soft_lower_limit="-2.34302" soft_upper_limit="1.53868"/>
  </joint>
  <link name="arm_right_5_link">
    <inertial>
      <origin rpy="0 0 0" xyz="4.30740072904223E-05 -0.00848243416126348 -0.122150591344461"/>
      <mass value="0.748930343342"/>
      <inertia ixx="0.00165448487772" ixy="7.13153097641e-08" ixz="5.94335178566e-07" iyy="0.0018865698396" iyz="-1.99881659135e-05" izz="0.000485154620181"/>
    </inertial>
    <visual>
      <origin rpy="0 0 0" xyz="0 0 0"/>
      <geometry>
        <mesh filename="package://canopies_description/meshes/arm/arm_right_5_link.STL"/>
      </geometry>
      <material name="">
        <color rgba="0.752941176470588 0.752941176470588 0.752941176470588 1"/>
      </material>
    </visual>
    <collision>
      <origin rpy="0 0 0" xyz="0 0 0"/>
      <geometry>
        <mesh filename="package://canopies_description/meshes/arm/arm_right_5_link_convex.STL"/>
      </geometry>
    </collision>
  </link>
  <joint name="arm_right_5_joint" type="revolute">
    <origin rpy="1.57079632679489 0 2.70526034059123" xyz="-0.0473796779453546 -0.148930079190456 0.0500006723402781"/>
    <parent link="arm_right_4_link"/>
    <child link="arm_right_5_link"/>
    <axis xyz="0 0 -1"/>
    <limit effort="50" lower="-2.54185" upper="2.54185" velocity="1.95"/>
    <safety_controller k_position="20" k_velocity="20" soft_lower_limit="-2.47185" soft_upper_limit="2.47185"/>
  </joint>
  <link name="arm_right_6_link">
    <inertial>
      <origin rpy="0 0 0" xyz="2.67981412671592E-05 -0.0996444474227959 0.0324891780507251"/>
      <mass value="0.574499982762"/>
      <inertia ixx="0.0006497241529" ixy="-2.88560094495e-07" ixz="7.26158980543e-07" iyy="0.00035431768666" iyz="0.000130103098394" izz="0.000674307517909"/>
    </inertial>
    <visual>
      <origin rpy="0 0 0" xyz="0 0 0"/>
      <geometry>
        <mesh filename="package://canopies_description/meshes/arm/arm_right_6_link.STL"/>
      </geometry>
      <material name="">
        <color rgba="0.752941176470588 0.752941176470588 0.752941176470588 1"/>
      </material>
    </visual>
    <collision>
      <origin rpy="0 0 0" xyz="0 0 0"/>
      <geometry>
        <mesh filename="package://canopies_description/meshes/arm/arm_right_6_link_convex.STL"/>
      </geometry>
    </collision>
  </link>
  <joint name="arm_right_6_joint" type="revolute">
    <origin rpy="1.57079225562289 0 3.14159265358979" xyz="0 -0.0394965876541469 -0.165050003051757"/>
    <parent link="arm_right_5_link"/>
    <child link="arm_right_6_link"/>
    <axis xyz="0 0 1"/>
    <limit effort="50" lower="-2.1562" upper="2.1562" velocity="1.95"/>
    <safety_controller k_position="20" k_velocity="20" soft_lower_limit="-2.0862" soft_upper_limit="2.0862"/>
  </joint>
  <link name="arm_right_7_link">
    <inertial>
      <origin rpy="0 0 0" xyz="8.56652769554156E-12 1.39648292929451E-11 0.00740178372048539"/>
      <mass value="0.04645419506"/>
      <inertia ixx="1.50415963926e-05" ixy="1.85363213141e-15" ixz="1.20426857767e-14" iyy="1.5041596398e-05" iyz="-2.32028280159e-14" izz="1.40885078823e-05"/>
    </inertial>
    <visual>
      <origin rpy="0 0 0" xyz="0 0 0"/>
      <geometry>
        <mesh filename="package://canopies_description/meshes/arm/arm_right_7_link.STL"/>
      </geometry>
      <material name="">
        <color rgba="0.752941176470588 0.752941176470588 0.752941176470588 1"/>
      </material>
    </visual>
    <collision>
      <origin rpy="0 0 0" xyz="0 0 0"/>
      <geometry>
        <mesh filename="package://canopies_description/meshes/arm/arm_right_7_link_convex.STL"/>
      </geometry>
    </collision>
  </link>
  <joint name="arm_right_7_joint" type="revolute">
    <origin rpy="0 1.57079225564058 1.57079632319904" xyz="0 -0.146000162750523 0.0390015522533293"/>
    <parent link="arm_right_6_link"/>
    <child link="arm_right_7_link"/>
    <axis xyz="0 0 -1"/>
    <limit effort="50" lower="-2.5044" upper="2.5044" velocity="1.95"/>
    <safety_controller k_position="20" k_velocity="20" soft_lower_limit="-2.4344" soft_upper_limit="2.4344"/>
  </joint>
  <!-- Gazebo tags -->
  <gazebo reference="arm_right_1_link">
    <mu1>0.9</mu1>
    <mu2>0.9</mu2>
    <material>Gazebo/DarkGrey</material>
  </gazebo>
  <gazebo reference="arm_right_2_link">
    <mu1>0.9</mu1>
    <mu2>0.9</mu2>
    <material>Gazebo/DarkGrey</material>
  </gazebo>
  <gazebo reference="arm_right_3_link">
    <mu1>0.9</mu1>
    <mu2>0.9</mu2>
    <material>Gazebo/DarkGrey</material>
  </gazebo>
  <gazebo reference="arm_right_4_link">
    <mu1>0.9</mu1>
    <mu2>0.9</mu2>
    <material>Gazebo/DarkGrey</material>
  </gazebo>
  <gazebo reference="arm_right_5_link">
    <mu1>0.9</mu1>
    <mu2>0.9</mu2>
    <material>Gazebo/DarkGrey</material>
  </gazebo>
  <gazebo reference="arm_right_6_link">
    <mu1>0.9</mu1>
    <mu2>0.9</mu2>
    <material>Gazebo/DarkGrey</material>
  </gazebo>
  <gazebo reference="arm_right_7_link">
    <mu1>0.9</mu1>
    <mu2>0.9</mu2>
    <material>Gazebo/DarkGrey</material>
  </gazebo>
  <gazebo reference="arm_right_1_joint">
    <implicitSpringDamper>1</implicitSpringDamper>
  </gazebo>
  <gazebo reference="arm_right_2_joint">
    <implicitSpringDamper>1</implicitSpringDamper>
  </gazebo>
  <gazebo reference="arm_right_3_joint">
    <implicitSpringDamper>1</implicitSpringDamper>
  </gazebo>
  <gazebo reference="arm_right_4_joint">
    <implicitSpringDamper>1</implicitSpringDamper>
  </gazebo>
  <gazebo reference="arm_right_5_joint">
    <implicitSpringDamper>1</implicitSpringDamper>
  </gazebo>
  <gazebo reference="arm_right_6_joint">
    <implicitSpringDamper>1</implicitSpringDamper>
  </gazebo>
  <gazebo reference="arm_right_7_joint">
    <implicitSpringDamper>1</implicitSpringDamper>
  </gazebo>
  <transmission name="arm_right_1_trans">
    <type>sea_transmissions/SeaSimpleTransmission</type>
    <!--transmission_interface/SeaTransmission-->
    <actuator name="arm_right_1_motor">
      </actuator>
    <joint name="arm_right_1_joint">
      <hardwareInterface>hardware_interface/PositionJointInterface</hardwareInterface>
      <hardwareInterface>hardware_interface/EffortJointInterface</hardwareInterface>
      <hardwareInterface>hardware_interface/VelocityJointInterface</hardwareInterface>
      <hardwareInterface>hardware_interface/JointStateInterface</hardwareInterface>
    </joint>
  </transmission>
  <transmission name="arm_right_2_trans">
    <type>sea_transmissions/SeaSimpleTransmission</type>
    <!--transmission_interface/SeaTransmission-->
    <actuator name="arm_right_2_motor">
      </actuator>
    <joint name="arm_right_2_joint">
      <hardwareInterface>hardware_interface/PositionJointInterface</hardwareInterface>
      <hardwareInterface>hardware_interface/EffortJointInterface</hardwareInterface>
      <hardwareInterface>hardware_interface/VelocityJointInterface</hardwareInterface>
      <hardwareInterface>hardware_interface/JointStateInterface</hardwareInterface>
    </joint>
  </transmission>
  <transmission name="arm_right_3_trans">
    <type>sea_transmissions/SeaSimpleTransmission</type>
    <!--transmission_interface/SeaTransmission-->
    <actuator name="arm_right_3_motor">
      </actuator>
    <joint name="arm_right_3_joint">
      <hardwareInterface>hardware_interface/PositionJointInterface</hardwareInterface>
      <hardwareInterface>hardware_interface/EffortJointInterface</hardwareInterface>
      <hardwareInterface>hardware_interface/VelocityJointInterface</hardwareInterface>
      <hardwareInterface>hardware_interface/JointStateInterface</hardwareInterface>
    </joint>
  </transmission>
  <transmission name="arm_right_4_trans">
    <type>sea_transmissions/SeaSimpleTransmission</type>
    <!--transmission_interface/SeaTransmission-->
    <actuator name="arm_right_4_motor">
      </actuator>
    <joint name="arm_right_4_joint">
      <hardwareInterface>hardware_interface/PositionJointInterface</hardwareInterface>
      <hardwareInterface>hardware_interface/EffortJointInterface</hardwareInterface>
      <hardwareInterface>hardware_interface/VelocityJointInterface</hardwareInterface>
      <hardwareInterface>hardware_interface/JointStateInterface</hardwareInterface>
    </joint>
  </transmission>
  <transmission name="arm_right_5_trans">
    <type>sea_transmissions/SeaSimpleTransmission</type>
    <!--transmission_interface/SeaTransmission-->
    <actuator name="arm_right_5_motor">
      </actuator>
    <joint name="arm_right_5_joint">
      <hardwareInterface>hardware_interface/PositionJointInterface</hardwareInterface>
      <hardwareInterface>hardware_interface/EffortJointInterface</hardwareInterface>
      <hardwareInterface>hardware_interface/VelocityJointInterface</hardwareInterface>
      <hardwareInterface>hardware_interface/JointStateInterface</hardwareInterface>
    </joint>
  </transmission>
  <transmission name="arm_right_6_trans">
    <type>sea_transmissions/SeaSimpleTransmission</type>
    <!--transmission_interface/SeaTransmission-->
    <actuator name="arm_right_6_motor">
      </actuator>
    <joint name="arm_right_6_joint">
      <hardwareInterface>hardware_interface/PositionJointInterface</hardwareInterface>
      <hardwareInterface>hardware_interface/EffortJointInterface</hardwareInterface>
      <hardwareInterface>hardware_interface/VelocityJointInterface</hardwareInterface>
      <hardwareInterface>hardware_interface/JointStateInterface</hardwareInterface>
    </joint>
  </transmission>
  <transmission name="arm_right_7_trans">
    <type>sea_transmissions/SeaSimpleTransmission</type>
    <!--transmission_interface/SeaTransmission-->
    <actuator name="arm_right_7_motor">
      </actuator>
    <joint name="arm_right_7_joint">
      <hardwareInterface>hardware_interface/PositionJointInterface</hardwareInterface>
      <hardwareInterface>hardware_interface/EffortJointInterface</hardwareInterface>
      <hardwareInterface>hardware_interface/VelocityJointInterface</hardwareInterface>
      <hardwareInterface>hardware_interface/JointStateInterface</hardwareInterface>
    </joint>
  </transmission>
  <link name="arm_left_1_link">
    <inertial>
      <origin rpy="0 0 0" xyz="0.0132498641167896 -0.104643958422056 -0.0313627278802192"/>
      <mass value="0.876973685013"/>
      <inertia ixx="0.00185306620323" ixy="8.35651442121e-05" ixz="2.56198592188e-05" iyy="0.000602091018667" iyz="-0.00031537020198" izz="0.00165640369006"/>
    </inertial>
    <visual>
      <origin rpy="0 0 0" xyz="0 0 0"/>
      <geometry>
        <mesh filename="package://canopies_description/meshes/arm/arm_left_1_link.STL"/>
      </geometry>
      <material name="">
        <color rgba="0.752941176470588 0.752941176470588 0.752941176470588 1"/>
      </material>
    </visual>
    <collision>
      <origin rpy="0 0 0" xyz="0 0 0"/>
      <geometry>
        <mesh filename="package://canopies_description/meshes/arm/arm_left_1_link_convex.STL"/>
      </geometry>
    </collision>
  </link>
  <joint name="arm_left_1_joint" type="revolute">
    <origin rpy="0 0 3.14159265358979" xyz="0.181558781082121 0.203000000000049 -0.0441000000002132"/>
    <parent link="torso_lift_link"/>
    <child link="arm_left_1_link"/>
    <axis xyz="0 0 -1"/>
    <limit effort="50" lower="-0.848" upper="1.5639" velocity="1.95"/>
    <safety_controller k_position="20" k_velocity="20" soft_lower_limit="-0.778" soft_upper_limit="1.4939"/>
  </joint>
  <link name="arm_left_2_link">
    <inertial>
      <origin rpy="0 0 0" xyz="0.103405641765166 -8.46115248007706E-05 0.0406059744723872"/>
      <mass value="0.794071310034"/>
      <inertia ixx="0.000785583237145" ixy="-2.0052022231e-07" ixz="-0.000281390136283" iyy="0.00123739549319" iyz="-9.50161622259e-07" izz="0.00128756739474"/>
    </inertial>
    <visual>
      <origin rpy="0 0 0" xyz="0 0 0"/>
      <geometry>
        <mesh filename="package://canopies_description/meshes/arm/arm_left_2_link.STL"/>
      </geometry>
      <material name="">
        <color rgba="0.752941176470588 0.752941176470588 0.752941176470588 1"/>
      </material>
    </visual>
    <collision>
      <origin rpy="0 0 0" xyz="0 0 0"/>
      <geometry>
        <mesh filename="package://canopies_description/meshes/arm/arm_left_2_link_convex.STL"/>
      </geometry>
    </collision>
  </link>
  <joint name="arm_left_2_joint" type="revolute">
    <origin rpy="1.5707963267949 0 -1.57079632679489" xyz="0.0482999996185309 -0.129999999999996 -0.0399999999999899"/>
    <parent link="arm_left_1_link"/>
    <child link="arm_left_2_link"/>
    <axis xyz="0 0 -1"/>
    <limit effort="50" lower="-1.5922" upper="1.5922" velocity="1.95"/>
    <safety_controller k_position="20" k_velocity="20" soft_lower_limit="-1.5222" soft_upper_limit="1.5222"/>
  </joint>
  <link name="arm_left_3_link">
    <inertial>
      <origin rpy="0 0 0" xyz="0.0136377329525594 0.0149533114219013 0.130010591854119"/>
      <mass value="0.926307323067"/>
      <inertia ixx="0.00268729618779" ixy="5.93138944713e-06" ixz="6.98081651e-05" iyy="0.0022624306041" iyz="0.000217390694395" izz="0.000728199500067"/>
    </inertial>
    <visual>
      <origin rpy="0 0 0" xyz="0 0 0"/>
      <geometry>
        <mesh filename="package://canopies_description/meshes/arm/arm_left_3_link.STL"/>
      </geometry>
      <material name="">
        <color rgba="0.752941176470588 0.752941176470588 0.752941176470588 1"/>
      </material>
    </visual>
    <collision>
      <origin rpy="0 0 0" xyz="0 0 0"/>
      <geometry>
        <mesh filename="package://canopies_description/meshes/arm/arm_left_3_link_convex.STL"/>
      </geometry>
    </collision>
  </link>
  <joint name="arm_left_3_joint" type="revolute">
    <origin rpy="0 1.5707963267949 0" xyz="0.154945006346297 0 0.0500038538537954"/>
    <parent link="arm_left_2_link"/>
    <child link="arm_left_3_link"/>
    <axis xyz="0 0 1"/>
    <limit effort="50" lower="-2.53135" upper="2.53135" velocity="1.95"/>
    <safety_controller k_position="20" k_velocity="20" soft_lower_limit="-2.46135" soft_upper_limit="2.46135"/>
  </joint>
  <link name="arm_left_4_link">
    <inertial>
      <origin rpy="0 0 0" xyz="0.0270943216353722 -0.0988821520517052 0.0405150394017644"/>
      <mass value="0.82292797291"/>
      <inertia ixx="0.00134281613791" ixy="0.000105745458534" ixz="8.84774161323e-05" iyy="0.000825129978916" iyz="0.000306718405566" izz="0.00139879333095"/>
    </inertial>
    <visual>
      <origin rpy="0 0 0" xyz="0 0 0"/>
      <geometry>
        <mesh filename="package://canopies_description/meshes/arm/arm_left_4_link.STL"/>
      </geometry>
      <material name="">
        <color rgba="0.752941176470588 0.752941176470588 0.752941176470588 1"/>
      </material>
    </visual>
    <collision>
      <origin rpy="0 0 0" xyz="0 0 0"/>
      <geometry>
        <mesh filename="package://canopies_description/meshes/arm/arm_left_4_link_convex.STL"/>
      </geometry>
    </collision>
  </link>
  <joint name="arm_left_4_joint" type="revolute">
    <origin rpy="-1.5707963267949 -0.436332316595644 1.5707963267949" xyz="0.049993121155 0.0199999999949542 0.165099999970051"/>
    <parent link="arm_left_3_link"/>
    <child link="arm_left_4_link"/>
    <axis xyz="0 0 -1"/>
    <limit effort="50" lower="-2.41302" upper="1.60868" velocity="1.95"/>
    <safety_controller k_position="20" k_velocity="20" soft_lower_limit="-2.34302" soft_upper_limit="1.53868"/>
  </joint>
  <link name="arm_left_5_link">
    <inertial>
      <origin rpy="0 0 0" xyz="0.00742954024751451 -1.40628349447613E-05 0.120207299344661"/>
      <mass value="0.748930343342"/>
      <inertia ixx="0.0018690373313" ixy="3.45792389611e-08" ixz="-2.00308700454e-05" iyy="0.00164479378146" iyz="1.43900052018e-07" izz="0.000476519597805"/>
    </inertial>
    <visual>
      <origin rpy="0 0 0" xyz="0 0 0"/>
      <geometry>
        <mesh filename="package://canopies_description/meshes/arm/arm_left_5_link.STL"/>
      </geometry>
      <material name="">
        <color rgba="0.752941176470588 0.752941176470588 0.752941176470588 1"/>
      </material>
    </visual>
    <collision>
      <origin rpy="0 0 0" xyz="0 0 0"/>
      <geometry>
        <mesh filename="package://canopies_description/meshes/arm/arm_left_5_link_convex.STL"/>
      </geometry>
    </collision>
  </link>
  <joint name="arm_left_5_joint" type="revolute">
    <origin rpy="1.13446401019926 1.5707963267949 0" xyz="0.0473796784810662 -0.148930079020028 0.0500006723402904"/>
    <parent link="arm_left_4_link"/>
    <child link="arm_left_5_link"/>
    <axis xyz="0 0 1"/>
    <limit effort="50" lower="-2.54185" upper="2.54185" velocity="1.95"/>
    <safety_controller k_position="20" k_velocity="20" soft_lower_limit="-2.47185" soft_upper_limit="2.47185"/>
  </joint>
  <link name="arm_left_6_link">
    <inertial>
      <origin rpy="0 0 0" xyz="-0.097397015740831 -7.60509099821949E-05 0.0319703400106361"/>
      <mass value="0.574499982762"/>
      <inertia ixx="0.000336830706146" ixy="2.54868794955e-07" ixz="0.000130149113719" iyy="0.000640156728274" iyz="-1.91674636839e-07" izz="0.000665608290534"/>
    </inertial>
    <visual>
      <origin rpy="0 0 0" xyz="0 0 0"/>
      <geometry>
        <mesh filename="package://canopies_description/meshes/arm/arm_left_6_link.STL"/>
      </geometry>
      <material name="">
        <color rgba="0.752941176470588 0.752941176470588 0.752941176470588 1"/>
      </material>
    </visual>
    <collision>
      <origin rpy="0 0 0" xyz="0 0 0"/>
      <geometry>
        <mesh filename="package://canopies_description/meshes/arm/arm_left_6_link_convex.STL"/>
      </geometry>
    </collision>
  </link>
  <joint name="arm_left_6_joint" type="revolute">
    <origin rpy="3.14159265358979 1.5707963267949 0" xyz="0.0394965876541543 0 0.165050003051757"/>
    <parent link="arm_left_5_link"/>
    <child link="arm_left_6_link"/>
    <axis xyz="0 0 -1"/>
    <limit effort="50" lower="-2.1562" upper="2.1562" velocity="1.95"/>
    <safety_controller k_position="20" k_velocity="20" soft_lower_limit="-2.0862" soft_upper_limit="2.0862"/>
  </joint>
  <link name="arm_left_7_link">
    <inertial>
      <origin rpy="0 0 0" xyz="7.21433329742283E-12 -1.40316647190275E-11 -0.00771079747828263"/>
      <mass value="0.04645419506"/>
      <inertia ixx="1.50415963926e-05" ixy="1.85363213141e-15" ixz="1.20426857767e-14" iyy="1.5041596398e-05" iyz="-2.32028280159e-14" izz="1.40885078823e-05"/>
    </inertial>
    <visual>
      <origin rpy="0 0 0" xyz="0 0 0"/>
      <geometry>
        <mesh filename="package://canopies_description/meshes/arm/arm_left_7_link.STL"/>
      </geometry>
      <material name="">
        <color rgba="0.752941176470588 0.752941176470588 0.752941176470588 1"/>
      </material>
    </visual>
    <collision>
      <origin rpy="0 0 0" xyz="0 0 0"/>
      <geometry>
        <mesh filename="package://canopies_description/meshes/arm/arm_left_7_link_convex.STL"/>
      </geometry>
    </collision>
  </link>
  <joint name="arm_left_7_joint" type="revolute">
    <origin rpy="3.14159265358979 1.57079225564058 0" xyz="-0.146000003967285 0 0.0390021466447858"/>
    <parent link="arm_left_6_link"/>
    <child link="arm_left_7_link"/>
    <axis xyz="0 0 1"/>
    <limit effort="50" lower="-2.5044" upper="2.5044" velocity="1.95"/>
    <safety_controller k_position="20" k_velocity="20" soft_lower_limit="-2.4344" soft_upper_limit="2.4344"/>
  </joint>
  <!-- Gazebo tags -->
  <gazebo reference="arm_left_1_link">
    <mu1>0.9</mu1>
    <mu2>0.9</mu2>
    <material>Gazebo/DarkGrey</material>
  </gazebo>
  <gazebo reference="arm_left_2_link">
    <mu1>0.9</mu1>
    <mu2>0.9</mu2>
    <material>Gazebo/DarkGrey</material>
  </gazebo>
  <gazebo reference="arm_left_3_link">
    <mu1>0.9</mu1>
    <mu2>0.9</mu2>
    <material>Gazebo/DarkGrey</material>
  </gazebo>
  <gazebo reference="arm_left_4_link">
    <mu1>0.9</mu1>
    <mu2>0.9</mu2>
    <material>Gazebo/DarkGrey</material>
  </gazebo>
  <gazebo reference="arm_left_5_link">
    <mu1>0.9</mu1>
    <mu2>0.9</mu2>
    <material>Gazebo/DarkGrey</material>
  </gazebo>
  <gazebo reference="arm_left_6_link">
    <mu1>0.9</mu1>
    <mu2>0.9</mu2>
    <material>Gazebo/DarkGrey</material>
  </gazebo>
  <gazebo reference="arm_left_7_link">
    <mu1>0.9</mu1>
    <mu2>0.9</mu2>
    <material>Gazebo/DarkGrey</material>
  </gazebo>
  <gazebo reference="arm_left_1_joint">
    <implicitSpringDamper>1</implicitSpringDamper>
  </gazebo>
  <gazebo reference="arm_left_2_joint">
    <implicitSpringDamper>1</implicitSpringDamper>
  </gazebo>
  <gazebo reference="arm_left_3_joint">
    <implicitSpringDamper>1</implicitSpringDamper>
  </gazebo>
  <gazebo reference="arm_left_4_joint">
    <implicitSpringDamper>1</implicitSpringDamper>
  </gazebo>
  <gazebo reference="arm_left_5_joint">
    <implicitSpringDamper>1</implicitSpringDamper>
  </gazebo>
  <gazebo reference="arm_left_6_joint">
    <implicitSpringDamper>1</implicitSpringDamper>
  </gazebo>
  <gazebo reference="arm_left_7_joint">
    <implicitSpringDamper>1</implicitSpringDamper>
  </gazebo>
  <transmission name="arm_left_1_trans">
    <type>sea_transmissions/SeaSimpleTransmission</type>
    <!--transmission_interface/SeaTransmission-->
    <actuator name="arm_left_1_motor">
      </actuator>
    <joint name="arm_left_1_joint">
      <hardwareInterface>hardware_interface/PositionJointInterface</hardwareInterface>
      <hardwareInterface>hardware_interface/EffortJointInterface</hardwareInterface>
      <hardwareInterface>hardware_interface/VelocityJointInterface</hardwareInterface>
      <hardwareInterface>hardware_interface/JointStateInterface</hardwareInterface>
    </joint>
  </transmission>
  <transmission name="arm_left_2_trans">
    <type>sea_transmissions/SeaSimpleTransmission</type>
    <!--transmission_interface/SeaTransmission-->
    <actuator name="arm_left_2_motor">
      </actuator>
    <joint name="arm_left_2_joint">
      <hardwareInterface>hardware_interface/PositionJointInterface</hardwareInterface>
      <hardwareInterface>hardware_interface/EffortJointInterface</hardwareInterface>
      <hardwareInterface>hardware_interface/VelocityJointInterface</hardwareInterface>
      <hardwareInterface>hardware_interface/JointStateInterface</hardwareInterface>
    </joint>
  </transmission>
  <transmission name="arm_left_3_trans">
    <type>sea_transmissions/SeaSimpleTransmission</type>
    <!--transmission_interface/SeaTransmission-->
    <actuator name="arm_left_3_motor">
      </actuator>
    <joint name="arm_left_3_joint">
      <hardwareInterface>hardware_interface/PositionJointInterface</hardwareInterface>
      <hardwareInterface>hardware_interface/EffortJointInterface</hardwareInterface>
      <hardwareInterface>hardware_interface/VelocityJointInterface</hardwareInterface>
      <hardwareInterface>hardware_interface/JointStateInterface</hardwareInterface>
    </joint>
  </transmission>
  <transmission name="arm_left_4_trans">
    <type>sea_transmissions/SeaSimpleTransmission</type>
    <!--transmission_interface/SeaTransmission-->
    <actuator name="arm_left_4_motor">
      </actuator>
    <joint name="arm_left_4_joint">
      <hardwareInterface>hardware_interface/PositionJointInterface</hardwareInterface>
      <hardwareInterface>hardware_interface/EffortJointInterface</hardwareInterface>
      <hardwareInterface>hardware_interface/VelocityJointInterface</hardwareInterface>
      <hardwareInterface>hardware_interface/JointStateInterface</hardwareInterface>
    </joint>
  </transmission>
  <transmission name="arm_left_5_trans">
    <type>sea_transmissions/SeaSimpleTransmission</type>
    <!--transmission_interface/SeaTransmission-->
    <actuator name="arm_left_5_motor">
      </actuator>
    <joint name="arm_left_5_joint">
      <hardwareInterface>hardware_interface/PositionJointInterface</hardwareInterface>
      <hardwareInterface>hardware_interface/EffortJointInterface</hardwareInterface>
      <hardwareInterface>hardware_interface/VelocityJointInterface</hardwareInterface>
      <hardwareInterface>hardware_interface/JointStateInterface</hardwareInterface>
    </joint>
  </transmission>
  <transmission name="arm_left_6_trans">
    <type>sea_transmissions/SeaSimpleTransmission</type>
    <!--transmission_interface/SeaTransmission-->
    <actuator name="arm_left_6_motor">
      </actuator>
    <joint name="arm_left_6_joint">
      <hardwareInterface>hardware_interface/PositionJointInterface</hardwareInterface>
      <hardwareInterface>hardware_interface/EffortJointInterface</hardwareInterface>
      <hardwareInterface>hardware_interface/VelocityJointInterface</hardwareInterface>
      <hardwareInterface>hardware_interface/JointStateInterface</hardwareInterface>
    </joint>
  </transmission>
  <transmission name="arm_left_7_trans">
    <type>sea_transmissions/SeaSimpleTransmission</type>
    <!--transmission_interface/SeaTransmission-->
    <actuator name="arm_left_7_motor">
      </actuator>
    <joint name="arm_left_7_joint">
      <hardwareInterface>hardware_interface/PositionJointInterface</hardwareInterface>
      <hardwareInterface>hardware_interface/EffortJointInterface</hardwareInterface>
      <hardwareInterface>hardware_interface/VelocityJointInterface</hardwareInterface>
      <hardwareInterface>hardware_interface/JointStateInterface</hardwareInterface>
    </joint>
  </transmission>
  <material name="camera_right_d435_aluminum">
    <color rgba="0.5 0.5 0.5 1"/>
  </material>
  <!-- camera body, with origin at bottom screw mount -->
  <joint name="camera_right_d435_joint" type="fixed">
    <origin rpy="0.0 0.0 0.0" xyz="0.0 0.0 0.0"/>
    <parent link="sliding_camera_right_link"/>
    <child link="camera_right_d435_bottom_screw_frame"/>
  </joint>
  <link name="camera_right_d435_bottom_screw_frame"/>
  <joint name="camera_right_d435_link_joint" type="fixed">
    <origin rpy="0 0 0" xyz="0.0106 0.0175 0.0125"/>
    <parent link="camera_right_d435_bottom_screw_frame"/>
    <child link="camera_right_d435_link"/>
  </joint>
  <link name="camera_right_d435_link">
    <visual>
      <!-- the mesh origin is at front plate in between the two infrared camera axes -->
      <origin rpy="1.57079632679 0 1.57079632679" xyz="0.0043 -0.0175 0"/>
      <geometry>
        <mesh filename="package://realsense2_description/meshes/d435.dae"/>
      </geometry>
    </visual>
    <collision>
      <origin rpy="0 0 0" xyz="0 -0.0175 0"/>
      <geometry>
        <box size="0.02505 0.09 0.025"/>
      </geometry>
    </collision>
    <inertial>
      <!-- The following are not reliable values, and should not be used for modeling -->
      <mass value="0.072"/>
      <origin xyz="0 0 0"/>
      <inertia ixx="0.003881243" ixy="0.0" ixz="0.0" iyy="0.000498940" iyz="0.0" izz="0.003879257"/>
    </inertial>
  </link>
  <!-- camera depth joints and links -->
  <joint name="camera_right_d435_depth_joint" type="fixed">
    <origin rpy="0 0 0" xyz="0 0 0"/>
    <parent link="camera_right_d435_link"/>
    <child link="camera_right_d435_depth_frame"/>
  </joint>
  <link name="camera_right_d435_depth_frame"/>
  <joint name="camera_right_d435_depth_optical_joint" type="fixed">
    <origin rpy="-1.57079632679 0 -1.57079632679" xyz="0 0 0"/>
    <parent link="camera_right_d435_depth_frame"/>
    <child link="camera_right_d435_depth_optical_frame"/>
  </joint>
  <link name="camera_right_d435_depth_optical_frame"/>
  <!-- camera left IR joints and links -->
  <joint name="camera_right_d435_infra1_joint" type="fixed">
    <origin rpy="0 0 0" xyz="0 0.0 0"/>
    <parent link="camera_right_d435_link"/>
    <child link="camera_right_d435_infra1_frame"/>
  </joint>
  <link name="camera_right_d435_infra1_frame"/>
  <joint name="camera_right_d435_infra1_optical_joint" type="fixed">
    <origin rpy="-1.57079632679 0 -1.57079632679" xyz="0 0 0"/>
    <parent link="camera_right_d435_infra1_frame"/>
    <child link="camera_right_d435_infra1_optical_frame"/>
  </joint>
  <link name="camera_right_d435_infra1_optical_frame"/>
  <!-- camera right IR joints and links -->
  <joint name="camera_right_d435_infra2_joint" type="fixed">
    <origin rpy="0 0 0" xyz="0 -0.05 0"/>
    <parent link="camera_right_d435_link"/>
    <child link="camera_right_d435_infra2_frame"/>
  </joint>
  <link name="camera_right_d435_infra2_frame"/>
  <joint name="camera_right_d435_infra2_optical_joint" type="fixed">
    <origin rpy="-1.57079632679 0 -1.57079632679" xyz="0 0 0"/>
    <parent link="camera_right_d435_infra2_frame"/>
    <child link="camera_right_d435_infra2_optical_frame"/>
  </joint>
  <link name="camera_right_d435_infra2_optical_frame"/>
  <!-- camera color joints and links -->
  <joint name="camera_right_d435_color_joint" type="fixed">
    <origin rpy="0 0 0" xyz="0 0.015 0"/>
    <parent link="camera_right_d435_link"/>
    <child link="camera_right_d435_color_frame"/>
  </joint>
  <link name="camera_right_d435_color_frame"/>
  <joint name="camera_right_d435_color_optical_joint" type="fixed">
    <origin rpy="-1.57079632679 0 -1.57079632679" xyz="0 0 0"/>
    <parent link="camera_right_d435_color_frame"/>
    <child link="camera_right_d435_color_optical_frame"/>
  </joint>
  <link name="camera_right_d435_color_optical_frame"/>
  <gazebo reference="camera_right_d435_link">
    <self_collide>0</self_collide>
    <enable_wind>0</enable_wind>
    <kinematic>0</kinematic>
    <gravity>1</gravity>
    <!--<mu>1</mu>-->
    <mu2>1</mu2>
    <fdir1>0 0 0</fdir1>
    <!--<slip1>0</slip1>
      <slip2>0</slip2>-->
    <kp>1e+13</kp>
    <kd>1</kd>
    <!--<max_vel>0.01</max_vel>
      <min_depth>0</min_depth>-->
    <sensor name="camera_right_d435color" type="camera">
      <camera name="camera_right_d435">
        <horizontal_fov>1.21125850088</horizontal_fov>
        <image>
          <width>640</width>
          <height>480</height>
          <format>RGB_INT8</format>
        </image>
        <clip>
          <near>0.1</near>
          <far>100</far>
        </clip>
        <noise>
          <type>gaussian</type>
          <mean>0.0</mean>
          <stddev>0.007</stddev>
        </noise>
      </camera>
      <always_on>1</always_on>
      <update_rate>30</update_rate>
      <visualize>1</visualize>
    </sensor>
    <sensor name="camera_right_d435ired1" type="camera">
      <camera name="camera_right_d435">
        <horizontal_fov>1.4870205227</horizontal_fov>
        <image>
          <width>1280</width>
          <height>720</height>
          <format>L_INT8</format>
        </image>
        <clip>
          <near>0.1</near>
          <far>100</far>
        </clip>
        <noise>
          <type>gaussian</type>
          <mean>0.0</mean>
          <stddev>0.05</stddev>
        </noise>
      </camera>
      <always_on>1</always_on>
      <update_rate>90</update_rate>
      <visualize>0</visualize>
    </sensor>
    <sensor name="camera_right_d435ired2" type="camera">
      <camera name="camera_right_d435">
        <horizontal_fov>1.4870205227</horizontal_fov>
        <image>
          <width>1280</width>
          <height>720</height>
          <format>L_INT8</format>
        </image>
        <clip>
          <near>0.1</near>
          <far>100</far>
        </clip>
        <noise>
          <type>gaussian</type>
          <mean>0.0</mean>
          <stddev>0.05</stddev>
        </noise>
      </camera>
      <always_on>1</always_on>
      <update_rate>90</update_rate>
      <visualize>0</visualize>
    </sensor>
    <sensor name="camera_right_d435depth" type="depth">
      <camera name="camera_right_d435">
        <horizontal_fov>1.4870205227</horizontal_fov>
        <image>
          <width>1280</width>
          <height>720</height>
        </image>
        <clip>
          <near>0.1</near>
          <far>100</far>
        </clip>
        <noise>
          <type>gaussian</type>
          <mean>0.0</mean>
          <stddev>0.100</stddev>
        </noise>
      </camera>
      <always_on>1</always_on>
      <update_rate>90</update_rate>
      <visualize>0</visualize>
    </sensor>
  </gazebo>
  <gazebo>
    <plugin filename="librealsense_gazebo_plugin.so" name="camera_right_d435">
      <prefix>camera_right_d435</prefix>
      <depthUpdateRate>30.0</depthUpdateRate>
      <colorUpdateRate>30.0</colorUpdateRate>
      <infraredUpdateRate>30.0</infraredUpdateRate>
      <depthTopicName>depth/image_raw</depthTopicName>
      <depthCameraInfoTopicName>depth/camera_info</depthCameraInfoTopicName>
      <colorTopicName>color/image_raw</colorTopicName>
      <colorCameraInfoTopicName>color/camera_info</colorCameraInfoTopicName>
      <infrared1TopicName>infra1/image_raw</infrared1TopicName>
      <infrared1CameraInfoTopicName>infra1/camera_info</infrared1CameraInfoTopicName>
      <infrared2TopicName>infra2/image_raw</infrared2TopicName>
      <infrared2CameraInfoTopicName>infra2/camera_info</infrared2CameraInfoTopicName>
      <colorOpticalframeName>camera_right_d435_color_optical_frame</colorOpticalframeName>
      <depthOpticalframeName>camera_right_d435_depth_optical_frame</depthOpticalframeName>
      <infrared1OpticalframeName>camera_right_d435_infra1_ir_optical_frame</infrared1OpticalframeName>
      <infrared2OpticalframeName>camera_right_d435_infra2_ir_optical_frame</infrared2OpticalframeName>
      <rangeMinDepth>0.2</rangeMinDepth>
      <rangeMaxDepth>10.0</rangeMaxDepth>
      <pointCloud>True</pointCloud>
      <pointCloudTopicName>depth/color/points</pointCloudTopicName>
      <pointCloudCutoff>0.25</pointCloudCutoff>
      <pointCloudCutoffMax>9.0</pointCloudCutoffMax>
    </plugin>
  </gazebo>
  <!-- GRIPPER -->
  <link name="base_gripper_right_link">
    <inertial>
      <origin rpy="0 0 0" xyz="-0.000800676543599457 0.000473514175096567 0.0433873268088167"/>
      <mass value="0.541999169536226"/>
      <inertia ixx="0.000301490971818317" ixy="1.75689502966857E-06" ixz="-3.19430552225728E-06" iyy="0.000367415088227513" iyz="-4.07947845633224E-06" izz="0.000444887114559986"/>
    </inertial>
    <visual>
      <origin rpy="-1.5708 -1.5708 0" xyz="0 0 0.0482"/>
      <geometry>
        <mesh filename="package://canopies_description/meshes/end-effector/base_gripper_link.STL"/>
      </geometry>
      <material name="">
        <color rgba="0.894117647058823 0.913725490196078 0.929411764705882 1"/>
      </material>
    </visual>
    <collision>
      <origin rpy="-1.5708 -1.5708 0" xyz="0 0 0.0485"/>
      <geometry>
        <mesh filename="package://canopies_description/meshes/end-effector/base_gripper_link.STL"/>
      </geometry>
    </collision>
  </link>
  <joint name="base_gripper_right_joint" type="fixed">
    <origin rpy="0 3.1415 0." xyz="0 0 0.001"/>
    <parent link="arm_right_7_link"/>
    <child link="base_gripper_right_link"/>
  </joint>
  <link name="inner_finger_1_right_link">
    <inertial>
      <origin rpy="0 0 0" xyz="1.04083408558608E-17 0.0441364442468319 -0.00969447527298418"/>
      <mass value="0.0325097389503491"/>
      <inertia ixx="2.13868037871617E-05" ixy="-1.58818677610181E-21" ixz="2.8117435355803E-23" iyy="1.14588284120502E-06" iyz="-2.49432669215837E-06" izz="2.08353808944892E-05"/>
    </inertial>
    <visual>
      <origin rpy="0 0 0" xyz="0 0 0"/>
      <geometry>
        <mesh filename="package://canopies_description/meshes/end-effector/left_inner_finger_link.STL"/>
      </geometry>
      <material name="">
        <color rgba="0.894117647058823 0.913725490196078 0.929411764705882 1"/>
      </material>
    </visual>
    <collision>
      <origin rpy="0 0 0" xyz="0 0 0"/>
      <geometry>
        <mesh filename="package://canopies_description/meshes/end-effector/left_inner_finger_link.STL"/>
      </geometry>
    </collision>
  </link>
  <joint name="inner_finger_1_right_joint" type="revolute">
    <origin rpy="1.5708 -0.2618 -3.1416" xyz="0.014 0.011 0.07885"/>
    <parent link="base_gripper_right_link"/>
    <child link="inner_finger_1_right_link"/>
    <axis xyz="0 0 1"/>
    <limit effort="100" lower="-0.23" upper="-0.0" velocity="100"/>
  </joint>
  <link name="fingertip_1_right_link">
    <inertial>
      <origin rpy="0 0 0" xyz="0.000851919851254511 0.0103104379943489 0.00410562585765633"/>
      <mass value="0.010358106060689"/>
      <inertia ixx="8.41417491098856E-07" ixy="-2.04324825572577E-07" ixz="1.05084170012449E-08" iyy="4.29037545121468E-07" iyz="7.60054592015762E-09" izz="1.09853472040319E-06"/>
    </inertial>
    <visual>
      <origin rpy="-1.57 0 0" xyz="0 0 0.0093"/>
      <geometry>
        <mesh filename="package://canopies_description/meshes/end-effector/left_fingertip_link.STL"/>
      </geometry>
      <material name="">
        <color rgba="1 0.752941176470588 1 1"/>
      </material>
    </visual>
    <collision>
      <origin rpy="-1.57 0 0" xyz="0 0 0.0093"/>
      <geometry>
        <mesh filename="package://canopies_description/meshes/end-effector/left_fingertip_link.STL"/>
      </geometry>
    </collision>
  </link>
  <joint name="fingertip_1_right_joint" type="revolute">
    <origin rpy="0 0 -0.30" xyz="0.00087405 0.084996 -0.008"/>
    <parent link="inner_finger_1_right_link"/>
    <child link="fingertip_1_right_link"/>
    <axis xyz="0 0 -1"/>
    <limit effort="100" lower="-0.2" upper="0.2" velocity="100"/>
    <mimic joint="inner_finger_1_right_joint" multiplier="1" offset="0"/>
  </joint>
  <gazebo>
    <plugin filename="libroboticsgroup_gazebo_mimic_joint_plugin.so" name="left_inner_finger_rightmimic_joint_plugin">
      <joint>inner_finger_1_right_joint</joint>
      <mimicJoint>fingertip_1_right_joint</mimicJoint>
      <multiplier>1.0</multiplier>
      <offset>0.0</offset>
      <sensitiveness>0.0</sensitiveness>
      <!-- if absolute difference between setpoint and process value is below this threshold, do nothing; 0.0 = disable [rad] -->
      <maxEffort>0.05</maxEffort>
      <!-- only taken into account if has_pid:=true [Nm] -->
      <robotNamespace/>
    </plugin>
  </gazebo>
  <link name="outer_finger_1_right_link">
    <inertial>
      <origin rpy="0 0 0" xyz="1.38777878078145E-17 0.0435280890450747 0.00203448329089162"/>
      <mass value="0.0129836486868957"/>
      <inertia ixx="8.15797963155731E-06" ixy="8.04019555401543E-22" ixz="2.73397570688282E-23" iyy="1.28087017228676E-07" iyz="1.83547933975566E-08" izz="8.20938955146781E-06"/>
    </inertial>
    <visual>
      <origin rpy="0 0 0" xyz="0 0 0"/>
      <geometry>
        <mesh filename="package://canopies_description/meshes/end-effector/left_outer_finger_link.STL"/>
      </geometry>
      <material name="">
        <color rgba="0.894117647058823 0.913725490196078 0.929411764705882 1"/>
      </material>
    </visual>
    <collision>
      <origin rpy="0 0 0" xyz="0 0 0"/>
      <geometry>
        <mesh filename="package://canopies_description/meshes/end-effector/left_outer_finger_link.STL"/>
      </geometry>
    </collision>
  </link>
  <joint name="outer_finger_1_right_joint" type="revolute">
    <origin rpy="1.5708 -0.2618 3.1416" xyz="0.028823 -0.002 0.074318"/>
    <parent link="base_gripper_right_link"/>
    <child link="outer_finger_1_right_link"/>
    <axis xyz="0 0 -1"/>
    <limit effort="100" lower="-0.2" upper="0.2" velocity="100"/>
    <mimic joint="inner_finger_1_right_joint" multiplier="-1" offset="0"/>
  </joint>
  <gazebo>
    <plugin filename="libroboticsgroup_gazebo_mimic_joint_plugin.so" name="left_inner_finger_rightmimic_joint_plugin">
      <joint>inner_finger_1_right_joint</joint>
      <mimicJoint>outer_finger_1_right_joint</mimicJoint>
      <multiplier>-1.0</multiplier>
      <offset>0.0</offset>
      <sensitiveness>0.0</sensitiveness>
      <!-- if absolute difference between setpoint and process value is below this threshold, do nothing; 0.0 = disable [rad] -->
      <maxEffort>0.05</maxEffort>
      <!-- only taken into account if has_pid:=true [Nm] -->
      <robotNamespace/>
    </plugin>
  </gazebo>
  <link name="inner_finger_2_right_link">
    <inertial>
      <origin rpy="0 0 0" xyz="0.0646047030783166 0.0315172908864769 0.00330552472701581"/>
      <mass value="0.032509738950349"/>
      <inertia ixx="1.63265735506671E-05" ixy="-8.76457586759864E-06" ixz="-1.24716334607985E-06" iyy="6.2061130776996E-06" iyz="-2.16015028074637E-06" izz="2.08353808944891E-05"/>
    </inertial>
    <visual>
      <origin rpy="0 0 0.52" xyz="-0.041 -0.014 -0.013"/>
      <geometry>
        <mesh filename="package://canopies_description/meshes/end-effector/right_inner_finger_link.STL"/>
      </geometry>
      <material name="">
        <color rgba="0.894117647058823 0.913725490196078 0.929411764705882 1"/>
      </material>
    </visual>
    <collision>
      <origin rpy="0 0 0.52" xyz="-0.041 -0.014 -0.013"/>
      <geometry>
        <mesh filename="package://canopies_description/meshes/end-effector/right_inner_finger_link.STL"/>
      </geometry>
    </collision>
  </link>
  <joint name="inner_finger_2_right_joint" type="revolute">
    <origin rpy="1.5708 0.2618 -3.1416" xyz="-0.014 0.011 0.07885"/>
    <parent link="base_gripper_right_link"/>
    <child link="inner_finger_2_right_link"/>
    <axis xyz="0 0 -1"/>
    <limit effort="100" lower="-0.2" upper="0.2" velocity="100"/>
    <mimic joint="inner_finger_1_right_joint" multiplier="1" offset="0.0"/>
  </joint>
  <gazebo>
    <plugin filename="libroboticsgroup_gazebo_mimic_joint_plugin.so" name="left_inner_finger_rightmimic_joint_plugin">
      <joint>inner_finger_1_right_joint</joint>
      <mimicJoint>inner_finger_2_right_joint</mimicJoint>
      <multiplier>1.0</multiplier>
      <offset>0.0</offset>
      <sensitiveness>0.0</sensitiveness>
      <!-- if absolute difference between setpoint and process value is below this threshold, do nothing; 0.0 = disable [rad] -->
      <maxEffort>0.05</maxEffort>
      <!-- only taken into account if has_pid:=true [Nm] -->
      <robotNamespace/>
    </plugin>
  </gazebo>
  <link name="fingertip_2_right_link">
    <inertial>
      <origin rpy="0 0 0" xyz="-0.00086444427228092 0.0128877023644735 0.00547726816629734"/>
      <mass value="0.0103952358496456"/>
      <inertia ixx="1.07064504824949E-06" ixy="1.91949725747789E-07" ixz="2.15992027261561E-08" iyy="6.5050694240894E-07" iyz="-9.65608509756539E-08" izz="1.25351597607521E-06"/>
    </inertial>
    <visual>
      <origin rpy="-1.57 0 0" xyz="0 0 0.0093"/>
      <geometry>
        <mesh filename="package://canopies_description/meshes/end-effector/right_fingertip_link.STL"/>
      </geometry>
      <material name="">
        <color rgba="1 0.752941176470588 1 1"/>
      </material>
    </visual>
    <collision>
      <origin rpy="-1.57 0 0" xyz="0 0 0.0093"/>
      <geometry>
        <mesh filename="package://canopies_description/meshes/end-effector/right_fingertip_link.STL"/>
      </geometry>
    </collision>
  </link>
  <joint name="fingertip_2_right_joint" type="revolute">
    <origin rpy="0 0 0.19" xyz="0 0.087 -0.008"/>
    <parent link="inner_finger_2_right_link"/>
    <child link="fingertip_2_right_link"/>
    <axis xyz="0 0 -1"/>
    <limit effort="100" lower="-0.2" upper="0.2" velocity="100"/>
    <mimic joint="inner_finger_1_right_joint" multiplier="-1" offset="0"/>
  </joint>
  <gazebo>
    <plugin filename="libroboticsgroup_gazebo_mimic_joint_plugin.so" name="left_inner_finger_rightmimic_joint_plugin">
      <joint>inner_finger_1_right_joint</joint>
      <mimicJoint>fingertip_2_right_joint</mimicJoint>
      <multiplier>-1.0</multiplier>
      <offset>0.0</offset>
      <sensitiveness>0.0</sensitiveness>
      <!-- if absolute difference between setpoint and process value is below this threshold, do nothing; 0.0 = disable [rad] -->
      <maxEffort>0.05</maxEffort>
      <!-- only taken into account if has_pid:=true [Nm] -->
      <robotNamespace/>
    </plugin>
  </gazebo>
  <link name="outer_finger_2_right_link">
    <inertial>
      <origin rpy="0 0 0" xyz="-3.46944695195361E-18 0.0425000000000001 0.003"/>
      <mass value="0.0133083962040813"/>
      <inertia ixx="8.72551168654838E-06" ixy="-8.92693317067227E-21" ixz="2.37408275306099E-23" iyy="1.3138146792651E-07" iyz="-7.42678128662845E-23" izz="8.77704277725041E-06"/>
    </inertial>
    <visual>
      <origin rpy="0 0 0" xyz="0 0 0"/>
      <geometry>
        <mesh filename="package://canopies_description/meshes/end-effector/right_outer_finger_link.STL"/>
      </geometry>
      <material name="">
        <color rgba="0.894117647058823 0.913725490196078 0.929411764705882 1"/>
      </material>
    </visual>
    <collision>
      <origin rpy="0 0 0" xyz="0 0 0"/>
      <geometry>
        <mesh filename="package://canopies_description/meshes/end-effector/right_outer_finger_link.STL"/>
      </geometry>
    </collision>
  </link>
  <joint name="outer_finger_2_right_joint" type="revolute">
    <origin rpy="1.5708 0.2618 -3.1416" xyz="-0.028823 -0.003 0.074318"/>
    <parent link="base_gripper_right_link"/>
    <child link="outer_finger_2_right_link"/>
    <axis xyz="0 0 -1"/>
    <limit effort="100" lower="-0.2" upper="0.2" velocity="100"/>
    <mimic joint="inner_finger_1_right_joint" multiplier="1" offset="0.0"/>
  </joint>
  <gazebo>
    <plugin filename="libroboticsgroup_gazebo_mimic_joint_plugin.so" name="left_inner_finger_rightmimic_joint_plugin">
      <joint>inner_finger_1_right_joint</joint>
      <mimicJoint>outer_finger_2_right_joint</mimicJoint>
      <multiplier>1.0</multiplier>
      <offset>0.0</offset>
      <sensitiveness>0.0</sensitiveness>
      <!-- if absolute difference between setpoint and process value is below this threshold, do nothing; 0.0 = disable [rad] -->
      <maxEffort>0.05</maxEffort>
      <!-- only taken into account if has_pid:=true [Nm] -->
      <robotNamespace/>
    </plugin>
  </gazebo>
  <!-- Camera and its relative position to the gripper -->
  <link name="bracelet_right_link">
    <inertial>
      <origin rpy="0 0 0" xyz="2.79734083848452E-09 0.042751821136237 0.0281127266298947"/>
      <mass value="0.00498877703130037"/>
      <inertia ixx="6.95604652222796E-07" ixy="7.08999729894727E-14" ixz="-2.84614044091492E-15" iyy="7.52972200134102E-07" iyz="1.99784544055453E-16" izz="1.53735636966001E-07"/>
    </inertial>
    <visual>
      <origin rpy="0 0 0" xyz="0 0 0"/>
      <geometry>
        <mesh filename="package://canopies_description/meshes/end-effector/camera_rotational_link.STL"/>
      </geometry>
      <material name="">
        <color rgba="0.298039215686275 0.298039215686275 0.298039215686275 1"/>
      </material>
    </visual>
    <collision>
      <origin rpy="0 0 0" xyz="0 0 0"/>
      <geometry>
        <mesh filename="package://canopies_description/meshes/end-effector/camera_rotational_link.STL"/>
      </geometry>
    </collision>
  </link>
  <joint name="bracelet_right_joint" type="fixed">
    <origin rpy="0 0 0" xyz="0 0 0"/>
    <parent link="base_gripper_right_link"/>
    <child link="bracelet_right_link"/>
  </joint>
  <link name="sliding_camera_right_link">
    <inertial>
      <origin rpy="0 0 0" xyz="0.00191415786419463 0.000899730089904842 0.0103578716883767"/>
      <mass value="0.045942703958924"/>
      <inertia ixx="2.49330078505231E-05" ixy="9.43998542256713E-08" ixz="9.3926537239295E-07" iyy="8.19626949652857E-06" iyz="-9.45103591650873E-09" izz="2.88263143775324E-05"/>
    </inertial>
    <visual>
      <origin rpy="0 0 0" xyz="0 0 0"/>
      <geometry>
        <mesh filename="package://canopies_description/meshes/end-effector/sliding_camera_link.STL"/>
      </geometry>
      <material name="">
        <color rgba="1 1 1 1"/>
      </material>
    </visual>
    <collision>
      <origin rpy="0 0 0" xyz="0 0 0"/>
      <geometry>
        <mesh filename="package://canopies_description/meshes/end-effector/sliding_camera_link.STL"/>
      </geometry>
    </collision>
  </link>
  <joint name="sliding_camera_right_joint" type="fixed">
    <origin rpy="-1.5708 -1.5708 0" xyz="0 0.05352 -0.032425"/>
    <parent link="bracelet_right_link"/>
    <child link="sliding_camera_right_link"/>
  </joint>
  <transmission name="gripper_right_trans">
    <type>transmission_interface/SimpleTransmission</type>
    <actuator name="gripper_right_motor">
      <mechanicalReduction>1.0</mechanicalReduction>
    </actuator>
    <joint name="inner_finger_1_right_joint">
      <hardwareInterface>hardware_interface/PositionJointInterface</hardwareInterface>
      <hardwareInterface>hardware_interface/EffortJointInterface</hardwareInterface>
      <hardwareInterface>hardware_interface/JointStateInterface</hardwareInterface>
    </joint>
  </transmission>
  <material name="camera_left_d435_aluminum">
    <color rgba="0.5 0.5 0.5 1"/>
  </material>
  <!-- camera body, with origin at bottom screw mount -->
  <joint name="camera_left_d435_joint" type="fixed">
    <origin rpy="0.0 0.0 0.0" xyz="0.0 0.0 0.0"/>
    <parent link="sliding_camera_left_link"/>
    <child link="camera_left_d435_bottom_screw_frame"/>
  </joint>
  <link name="camera_left_d435_bottom_screw_frame"/>
  <joint name="camera_left_d435_link_joint" type="fixed">
    <origin rpy="0 0 0" xyz="0.0106 0.0175 0.0125"/>
    <parent link="camera_left_d435_bottom_screw_frame"/>
    <child link="camera_left_d435_link"/>
  </joint>
  <link name="camera_left_d435_link">
    <visual>
      <!-- the mesh origin is at front plate in between the two infrared camera axes -->
      <origin rpy="1.57079632679 0 1.57079632679" xyz="0.0043 -0.0175 0"/>
      <geometry>
        <mesh filename="package://realsense2_description/meshes/d435.dae"/>
      </geometry>
    </visual>
    <collision>
      <origin rpy="0 0 0" xyz="0 -0.0175 0"/>
      <geometry>
        <box size="0.02505 0.09 0.025"/>
      </geometry>
    </collision>
    <inertial>
      <!-- The following are not reliable values, and should not be used for modeling -->
      <mass value="0.072"/>
      <origin xyz="0 0 0"/>
      <inertia ixx="0.003881243" ixy="0.0" ixz="0.0" iyy="0.000498940" iyz="0.0" izz="0.003879257"/>
    </inertial>
  </link>
  <!-- camera depth joints and links -->
  <joint name="camera_left_d435_depth_joint" type="fixed">
    <origin rpy="0 0 0" xyz="0 0 0"/>
    <parent link="camera_left_d435_link"/>
    <child link="camera_left_d435_depth_frame"/>
  </joint>
  <link name="camera_left_d435_depth_frame"/>
  <joint name="camera_left_d435_depth_optical_joint" type="fixed">
    <origin rpy="-1.57079632679 0 -1.57079632679" xyz="0 0 0"/>
    <parent link="camera_left_d435_depth_frame"/>
    <child link="camera_left_d435_depth_optical_frame"/>
  </joint>
  <link name="camera_left_d435_depth_optical_frame"/>
  <!-- camera left IR joints and links -->
  <joint name="camera_left_d435_infra1_joint" type="fixed">
    <origin rpy="0 0 0" xyz="0 0.0 0"/>
    <parent link="camera_left_d435_link"/>
    <child link="camera_left_d435_infra1_frame"/>
  </joint>
  <link name="camera_left_d435_infra1_frame"/>
  <joint name="camera_left_d435_infra1_optical_joint" type="fixed">
    <origin rpy="-1.57079632679 0 -1.57079632679" xyz="0 0 0"/>
    <parent link="camera_left_d435_infra1_frame"/>
    <child link="camera_left_d435_infra1_optical_frame"/>
  </joint>
  <link name="camera_left_d435_infra1_optical_frame"/>
  <!-- camera right IR joints and links -->
  <joint name="camera_left_d435_infra2_joint" type="fixed">
    <origin rpy="0 0 0" xyz="0 -0.05 0"/>
    <parent link="camera_left_d435_link"/>
    <child link="camera_left_d435_infra2_frame"/>
  </joint>
  <link name="camera_left_d435_infra2_frame"/>
  <joint name="camera_left_d435_infra2_optical_joint" type="fixed">
    <origin rpy="-1.57079632679 0 -1.57079632679" xyz="0 0 0"/>
    <parent link="camera_left_d435_infra2_frame"/>
    <child link="camera_left_d435_infra2_optical_frame"/>
  </joint>
  <link name="camera_left_d435_infra2_optical_frame"/>
  <!-- camera color joints and links -->
  <joint name="camera_left_d435_color_joint" type="fixed">
    <origin rpy="0 0 0" xyz="0 0.015 0"/>
    <parent link="camera_left_d435_link"/>
    <child link="camera_left_d435_color_frame"/>
  </joint>
  <link name="camera_left_d435_color_frame"/>
  <joint name="camera_left_d435_color_optical_joint" type="fixed">
    <origin rpy="-1.57079632679 0 -1.57079632679" xyz="0 0 0"/>
    <parent link="camera_left_d435_color_frame"/>
    <child link="camera_left_d435_color_optical_frame"/>
  </joint>
  <link name="camera_left_d435_color_optical_frame"/>
  <gazebo reference="camera_left_d435_link">
    <self_collide>0</self_collide>
    <enable_wind>0</enable_wind>
    <kinematic>0</kinematic>
    <gravity>1</gravity>
    <!--<mu>1</mu>-->
    <mu2>1</mu2>
    <fdir1>0 0 0</fdir1>
    <!--<slip1>0</slip1>
      <slip2>0</slip2>-->
    <kp>1e+13</kp>
    <kd>1</kd>
    <!--<max_vel>0.01</max_vel>
      <min_depth>0</min_depth>-->
    <sensor name="camera_left_d435color" type="camera">
      <camera name="camera_left_d435">
        <horizontal_fov>1.21125850088</horizontal_fov>
        <image>
          <width>640</width>
          <height>480</height>
          <format>RGB_INT8</format>
        </image>
        <clip>
          <near>0.1</near>
          <far>100</far>
        </clip>
        <noise>
          <type>gaussian</type>
          <mean>0.0</mean>
          <stddev>0.007</stddev>
        </noise>
      </camera>
      <always_on>1</always_on>
      <update_rate>30</update_rate>
      <visualize>1</visualize>
    </sensor>
    <sensor name="camera_left_d435ired1" type="camera">
      <camera name="camera_left_d435">
        <horizontal_fov>1.4870205227</horizontal_fov>
        <image>
          <width>1280</width>
          <height>720</height>
          <format>L_INT8</format>
        </image>
        <clip>
          <near>0.1</near>
          <far>100</far>
        </clip>
        <noise>
          <type>gaussian</type>
          <mean>0.0</mean>
          <stddev>0.05</stddev>
        </noise>
      </camera>
      <always_on>1</always_on>
      <update_rate>90</update_rate>
      <visualize>0</visualize>
    </sensor>
    <sensor name="camera_left_d435ired2" type="camera">
      <camera name="camera_left_d435">
        <horizontal_fov>1.4870205227</horizontal_fov>
        <image>
          <width>1280</width>
          <height>720</height>
          <format>L_INT8</format>
        </image>
        <clip>
          <near>0.1</near>
          <far>100</far>
        </clip>
        <noise>
          <type>gaussian</type>
          <mean>0.0</mean>
          <stddev>0.05</stddev>
        </noise>
      </camera>
      <always_on>1</always_on>
      <update_rate>90</update_rate>
      <visualize>0</visualize>
    </sensor>
    <sensor name="camera_left_d435depth" type="depth">
      <camera name="camera_left_d435">
        <horizontal_fov>1.4870205227</horizontal_fov>
        <image>
          <width>1280</width>
          <height>720</height>
        </image>
        <clip>
          <near>0.1</near>
          <far>100</far>
        </clip>
        <noise>
          <type>gaussian</type>
          <mean>0.0</mean>
          <stddev>0.100</stddev>
        </noise>
      </camera>
      <always_on>1</always_on>
      <update_rate>90</update_rate>
      <visualize>0</visualize>
    </sensor>
  </gazebo>
  <gazebo>
    <plugin filename="librealsense_gazebo_plugin.so" name="camera_left_d435">
      <prefix>camera_left_d435</prefix>
      <depthUpdateRate>30.0</depthUpdateRate>
      <colorUpdateRate>30.0</colorUpdateRate>
      <infraredUpdateRate>30.0</infraredUpdateRate>
      <depthTopicName>depth/image_raw</depthTopicName>
      <depthCameraInfoTopicName>depth/camera_info</depthCameraInfoTopicName>
      <colorTopicName>color/image_raw</colorTopicName>
      <colorCameraInfoTopicName>color/camera_info</colorCameraInfoTopicName>
      <infrared1TopicName>infra1/image_raw</infrared1TopicName>
      <infrared1CameraInfoTopicName>infra1/camera_info</infrared1CameraInfoTopicName>
      <infrared2TopicName>infra2/image_raw</infrared2TopicName>
      <infrared2CameraInfoTopicName>infra2/camera_info</infrared2CameraInfoTopicName>
      <colorOpticalframeName>camera_left_d435_color_optical_frame</colorOpticalframeName>
      <depthOpticalframeName>camera_left_d435_depth_optical_frame</depthOpticalframeName>
      <infrared1OpticalframeName>camera_left_d435_infra1_ir_optical_frame</infrared1OpticalframeName>
      <infrared2OpticalframeName>camera_left_d435_infra2_ir_optical_frame</infrared2OpticalframeName>
      <rangeMinDepth>0.2</rangeMinDepth>
      <rangeMaxDepth>10.0</rangeMaxDepth>
      <pointCloud>True</pointCloud>
      <pointCloudTopicName>depth/color/points</pointCloudTopicName>
      <pointCloudCutoff>0.25</pointCloudCutoff>
      <pointCloudCutoffMax>9.0</pointCloudCutoffMax>
    </plugin>
  </gazebo>
  <!-- GRIPPER -->
  <link name="base_gripper_left_link">
    <inertial>
      <origin rpy="0 0 0" xyz="-0.000800676543599457 0.000473514175096567 0.0433873268088167"/>
      <mass value="0.541999169536226"/>
      <inertia ixx="0.000301490971818317" ixy="1.75689502966857E-06" ixz="-3.19430552225728E-06" iyy="0.000367415088227513" iyz="-4.07947845633224E-06" izz="0.000444887114559986"/>
    </inertial>
    <visual>
      <origin rpy="-1.5708 -1.5708 0" xyz="0 0 0.0482"/>
      <geometry>
        <mesh filename="package://canopies_description/meshes/end-effector/base_gripper_link.STL"/>
      </geometry>
      <material name="">
        <color rgba="0.894117647058823 0.913725490196078 0.929411764705882 1"/>
      </material>
    </visual>
    <collision>
      <origin rpy="-1.5708 -1.5708 0" xyz="0 0 0.0485"/>
      <geometry>
        <mesh filename="package://canopies_description/meshes/end-effector/base_gripper_link.STL"/>
      </geometry>
    </collision>
  </link>
  <joint name="base_gripper_left_joint" type="fixed">
    <origin rpy="0 0 -1.117359787" xyz="0 0 -0.001"/>
    <parent link="arm_left_7_link"/>
    <child link="base_gripper_left_link"/>
  </joint>
  <link name="inner_finger_1_left_link">
    <inertial>
      <origin rpy="0 0 0" xyz="1.04083408558608E-17 0.0441364442468319 -0.00969447527298418"/>
      <mass value="0.0325097389503491"/>
      <inertia ixx="2.13868037871617E-05" ixy="-1.58818677610181E-21" ixz="2.8117435355803E-23" iyy="1.14588284120502E-06" iyz="-2.49432669215837E-06" izz="2.08353808944892E-05"/>
    </inertial>
    <visual>
      <origin rpy="0 0 0" xyz="0 0 0"/>
      <geometry>
        <mesh filename="package://canopies_description/meshes/end-effector/left_inner_finger_link.STL"/>
      </geometry>
      <material name="">
        <color rgba="0.894117647058823 0.913725490196078 0.929411764705882 1"/>
      </material>
    </visual>
    <collision>
      <origin rpy="0 0 0" xyz="0 0 0"/>
      <geometry>
        <mesh filename="package://canopies_description/meshes/end-effector/left_inner_finger_link.STL"/>
      </geometry>
    </collision>
  </link>
  <joint name="inner_finger_1_left_joint" type="revolute">
    <origin rpy="1.5708 -0.2618 -3.1416" xyz="0.014 0.011 0.07885"/>
    <parent link="base_gripper_left_link"/>
    <child link="inner_finger_1_left_link"/>
    <axis xyz="0 0 1"/>
    <limit effort="100" lower="-0.23" upper="-0.0" velocity="100"/>
  </joint>
  <link name="fingertip_1_left_link">
    <inertial>
      <origin rpy="0 0 0" xyz="0.000851919851254511 0.0103104379943489 0.00410562585765633"/>
      <mass value="0.010358106060689"/>
      <inertia ixx="8.41417491098856E-07" ixy="-2.04324825572577E-07" ixz="1.05084170012449E-08" iyy="4.29037545121468E-07" iyz="7.60054592015762E-09" izz="1.09853472040319E-06"/>
    </inertial>
    <visual>
      <origin rpy="-1.57 0 0" xyz="0 0 0.0093"/>
      <geometry>
        <mesh filename="package://canopies_description/meshes/end-effector/left_fingertip_link.STL"/>
      </geometry>
      <material name="">
        <color rgba="1 0.752941176470588 1 1"/>
      </material>
    </visual>
    <collision>
      <origin rpy="-1.57 0 0" xyz="0 0 0.0093"/>
      <geometry>
        <mesh filename="package://canopies_description/meshes/end-effector/left_fingertip_link.STL"/>
      </geometry>
    </collision>
  </link>
  <joint name="fingertip_1_left_joint" type="revolute">
    <origin rpy="0 0 -0.30" xyz="0.00087405 0.084996 -0.008"/>
    <parent link="inner_finger_1_left_link"/>
    <child link="fingertip_1_left_link"/>
    <axis xyz="0 0 -1"/>
    <limit effort="100" lower="-0.2" upper="0.2" velocity="100"/>
    <mimic joint="inner_finger_1_left_joint" multiplier="1" offset="0"/>
  </joint>
  <gazebo>
    <plugin filename="libroboticsgroup_gazebo_mimic_joint_plugin.so" name="left_inner_finger_leftmimic_joint_plugin">
      <joint>inner_finger_1_left_joint</joint>
      <mimicJoint>fingertip_1_left_joint</mimicJoint>
      <multiplier>1.0</multiplier>
      <offset>0.0</offset>
      <sensitiveness>0.0</sensitiveness>
      <!-- if absolute difference between setpoint and process value is below this threshold, do nothing; 0.0 = disable [rad] -->
      <maxEffort>0.05</maxEffort>
      <!-- only taken into account if has_pid:=true [Nm] -->
      <robotNamespace/>
    </plugin>
  </gazebo>
  <link name="outer_finger_1_left_link">
    <inertial>
      <origin rpy="0 0 0" xyz="1.38777878078145E-17 0.0435280890450747 0.00203448329089162"/>
      <mass value="0.0129836486868957"/>
      <inertia ixx="8.15797963155731E-06" ixy="8.04019555401543E-22" ixz="2.73397570688282E-23" iyy="1.28087017228676E-07" iyz="1.83547933975566E-08" izz="8.20938955146781E-06"/>
    </inertial>
    <visual>
      <origin rpy="0 0 0" xyz="0 0 0"/>
      <geometry>
        <mesh filename="package://canopies_description/meshes/end-effector/left_outer_finger_link.STL"/>
      </geometry>
      <material name="">
        <color rgba="0.894117647058823 0.913725490196078 0.929411764705882 1"/>
      </material>
    </visual>
    <collision>
      <origin rpy="0 0 0" xyz="0 0 0"/>
      <geometry>
        <mesh filename="package://canopies_description/meshes/end-effector/left_outer_finger_link.STL"/>
      </geometry>
    </collision>
  </link>
  <joint name="outer_finger_1_left_joint" type="revolute">
    <origin rpy="1.5708 -0.2618 3.1416" xyz="0.028823 -0.002 0.074318"/>
    <parent link="base_gripper_left_link"/>
    <child link="outer_finger_1_left_link"/>
    <axis xyz="0 0 -1"/>
    <limit effort="100" lower="-0.2" upper="0.2" velocity="100"/>
    <mimic joint="inner_finger_1_left_joint" multiplier="-1" offset="0"/>
  </joint>
  <gazebo>
    <plugin filename="libroboticsgroup_gazebo_mimic_joint_plugin.so" name="left_inner_finger_leftmimic_joint_plugin">
      <joint>inner_finger_1_left_joint</joint>
      <mimicJoint>outer_finger_1_left_joint</mimicJoint>
      <multiplier>-1.0</multiplier>
      <offset>0.0</offset>
      <sensitiveness>0.0</sensitiveness>
      <!-- if absolute difference between setpoint and process value is below this threshold, do nothing; 0.0 = disable [rad] -->
      <maxEffort>0.05</maxEffort>
      <!-- only taken into account if has_pid:=true [Nm] -->
      <robotNamespace/>
    </plugin>
  </gazebo>
  <link name="inner_finger_2_left_link">
    <inertial>
      <origin rpy="0 0 0" xyz="0.0646047030783166 0.0315172908864769 0.00330552472701581"/>
      <mass value="0.032509738950349"/>
      <inertia ixx="1.63265735506671E-05" ixy="-8.76457586759864E-06" ixz="-1.24716334607985E-06" iyy="6.2061130776996E-06" iyz="-2.16015028074637E-06" izz="2.08353808944891E-05"/>
    </inertial>
    <visual>
      <origin rpy="0 0 0.52" xyz="-0.041 -0.014 -0.013"/>
      <geometry>
        <mesh filename="package://canopies_description/meshes/end-effector/right_inner_finger_link.STL"/>
      </geometry>
      <material name="">
        <color rgba="0.894117647058823 0.913725490196078 0.929411764705882 1"/>
      </material>
    </visual>
    <collision>
      <origin rpy="0 0 0.52" xyz="-0.041 -0.014 -0.013"/>
      <geometry>
        <mesh filename="package://canopies_description/meshes/end-effector/right_inner_finger_link.STL"/>
      </geometry>
    </collision>
  </link>
  <joint name="inner_finger_2_left_joint" type="revolute">
    <origin rpy="1.5708 0.2618 -3.1416" xyz="-0.014 0.011 0.07885"/>
    <parent link="base_gripper_left_link"/>
    <child link="inner_finger_2_left_link"/>
    <axis xyz="0 0 -1"/>
    <limit effort="100" lower="-0.2" upper="0.2" velocity="100"/>
    <mimic joint="inner_finger_1_left_joint" multiplier="1" offset="0.0"/>
  </joint>
  <gazebo>
    <plugin filename="libroboticsgroup_gazebo_mimic_joint_plugin.so" name="left_inner_finger_leftmimic_joint_plugin">
      <joint>inner_finger_1_left_joint</joint>
      <mimicJoint>inner_finger_2_left_joint</mimicJoint>
      <multiplier>1.0</multiplier>
      <offset>0.0</offset>
      <sensitiveness>0.0</sensitiveness>
      <!-- if absolute difference between setpoint and process value is below this threshold, do nothing; 0.0 = disable [rad] -->
      <maxEffort>0.05</maxEffort>
      <!-- only taken into account if has_pid:=true [Nm] -->
      <robotNamespace/>
    </plugin>
  </gazebo>
  <link name="fingertip_2_left_link">
    <inertial>
      <origin rpy="0 0 0" xyz="-0.00086444427228092 0.0128877023644735 0.00547726816629734"/>
      <mass value="0.0103952358496456"/>
      <inertia ixx="1.07064504824949E-06" ixy="1.91949725747789E-07" ixz="2.15992027261561E-08" iyy="6.5050694240894E-07" iyz="-9.65608509756539E-08" izz="1.25351597607521E-06"/>
    </inertial>
    <visual>
      <origin rpy="-1.57 0 0" xyz="0 0 0.0093"/>
      <geometry>
        <mesh filename="package://canopies_description/meshes/end-effector/right_fingertip_link.STL"/>
      </geometry>
      <material name="">
        <color rgba="1 0.752941176470588 1 1"/>
      </material>
    </visual>
    <collision>
      <origin rpy="-1.57 0 0" xyz="0 0 0.0093"/>
      <geometry>
        <mesh filename="package://canopies_description/meshes/end-effector/right_fingertip_link.STL"/>
      </geometry>
    </collision>
  </link>
  <joint name="fingertip_2_left_joint" type="revolute">
    <origin rpy="0 0 0.19" xyz="0 0.087 -0.008"/>
    <parent link="inner_finger_2_left_link"/>
    <child link="fingertip_2_left_link"/>
    <axis xyz="0 0 -1"/>
    <limit effort="100" lower="-0.2" upper="0.2" velocity="100"/>
    <mimic joint="inner_finger_1_left_joint" multiplier="-1" offset="0"/>
  </joint>
  <gazebo>
    <plugin filename="libroboticsgroup_gazebo_mimic_joint_plugin.so" name="left_inner_finger_leftmimic_joint_plugin">
      <joint>inner_finger_1_left_joint</joint>
      <mimicJoint>fingertip_2_left_joint</mimicJoint>
      <multiplier>-1.0</multiplier>
      <offset>0.0</offset>
      <sensitiveness>0.0</sensitiveness>
      <!-- if absolute difference between setpoint and process value is below this threshold, do nothing; 0.0 = disable [rad] -->
      <maxEffort>0.05</maxEffort>
      <!-- only taken into account if has_pid:=true [Nm] -->
      <robotNamespace/>
    </plugin>
  </gazebo>
  <link name="outer_finger_2_left_link">
    <inertial>
      <origin rpy="0 0 0" xyz="-3.46944695195361E-18 0.0425000000000001 0.003"/>
      <mass value="0.0133083962040813"/>
      <inertia ixx="8.72551168654838E-06" ixy="-8.92693317067227E-21" ixz="2.37408275306099E-23" iyy="1.3138146792651E-07" iyz="-7.42678128662845E-23" izz="8.77704277725041E-06"/>
    </inertial>
    <visual>
      <origin rpy="0 0 0" xyz="0 0 0"/>
      <geometry>
        <mesh filename="package://canopies_description/meshes/end-effector/right_outer_finger_link.STL"/>
      </geometry>
      <material name="">
        <color rgba="0.894117647058823 0.913725490196078 0.929411764705882 1"/>
      </material>
    </visual>
    <collision>
      <origin rpy="0 0 0" xyz="0 0 0"/>
      <geometry>
        <mesh filename="package://canopies_description/meshes/end-effector/right_outer_finger_link.STL"/>
      </geometry>
    </collision>
  </link>
  <joint name="outer_finger_2_left_joint" type="revolute">
    <origin rpy="1.5708 0.2618 -3.1416" xyz="-0.028823 -0.003 0.074318"/>
    <parent link="base_gripper_left_link"/>
    <child link="outer_finger_2_left_link"/>
    <axis xyz="0 0 -1"/>
    <limit effort="100" lower="-0.2" upper="0.2" velocity="100"/>
    <mimic joint="inner_finger_1_left_joint" multiplier="1" offset="0.0"/>
  </joint>
  <gazebo>
    <plugin filename="libroboticsgroup_gazebo_mimic_joint_plugin.so" name="left_inner_finger_leftmimic_joint_plugin">
      <joint>inner_finger_1_left_joint</joint>
      <mimicJoint>outer_finger_2_left_joint</mimicJoint>
      <multiplier>1.0</multiplier>
      <offset>0.0</offset>
      <sensitiveness>0.0</sensitiveness>
      <!-- if absolute difference between setpoint and process value is below this threshold, do nothing; 0.0 = disable [rad] -->
      <maxEffort>0.05</maxEffort>
      <!-- only taken into account if has_pid:=true [Nm] -->
      <robotNamespace/>
    </plugin>
  </gazebo>
  <!-- Camera and its relative position to the gripper -->
  <link name="bracelet_left_link">
    <inertial>
      <origin rpy="0 0 0" xyz="2.79734083848452E-09 0.042751821136237 0.0281127266298947"/>
      <mass value="0.00498877703130037"/>
      <inertia ixx="6.95604652222796E-07" ixy="7.08999729894727E-14" ixz="-2.84614044091492E-15" iyy="7.52972200134102E-07" iyz="1.99784544055453E-16" izz="1.53735636966001E-07"/>
    </inertial>
    <visual>
      <origin rpy="0 0 0" xyz="0 0 0"/>
      <geometry>
        <mesh filename="package://canopies_description/meshes/end-effector/camera_rotational_link.STL"/>
      </geometry>
      <material name="">
        <color rgba="0.298039215686275 0.298039215686275 0.298039215686275 1"/>
      </material>
    </visual>
    <collision>
      <origin rpy="0 0 0" xyz="0 0 0"/>
      <geometry>
        <mesh filename="package://canopies_description/meshes/end-effector/camera_rotational_link.STL"/>
      </geometry>
    </collision>
  </link>
  <joint name="bracelet_left_joint" type="fixed">
    <origin rpy="0 0 0" xyz="0 0 0"/>
    <parent link="base_gripper_left_link"/>
    <child link="bracelet_left_link"/>
  </joint>
  <link name="sliding_camera_left_link">
    <inertial>
      <origin rpy="0 0 0" xyz="0.00191415786419463 0.000899730089904842 0.0103578716883767"/>
      <mass value="0.045942703958924"/>
      <inertia ixx="2.49330078505231E-05" ixy="9.43998542256713E-08" ixz="9.3926537239295E-07" iyy="8.19626949652857E-06" iyz="-9.45103591650873E-09" izz="2.88263143775324E-05"/>
    </inertial>
    <visual>
      <origin rpy="0 0 0" xyz="0 0 0"/>
      <geometry>
        <mesh filename="package://canopies_description/meshes/end-effector/sliding_camera_link.STL"/>
      </geometry>
      <material name="">
        <color rgba="1 1 1 1"/>
      </material>
    </visual>
    <collision>
      <origin rpy="0 0 0" xyz="0 0 0"/>
      <geometry>
        <mesh filename="package://canopies_description/meshes/end-effector/sliding_camera_link.STL"/>
      </geometry>
    </collision>
  </link>
  <joint name="sliding_camera_left_joint" type="fixed">
    <origin rpy="-1.5708 -1.5708 0" xyz="0 0.05352 -0.032425"/>
    <parent link="bracelet_left_link"/>
    <child link="sliding_camera_left_link"/>
  </joint>
  <transmission name="gripper_left_trans">
    <type>transmission_interface/SimpleTransmission</type>
    <actuator name="gripper_left_motor">
      <mechanicalReduction>1.0</mechanicalReduction>
    </actuator>
    <joint name="inner_finger_1_left_joint">
      <hardwareInterface>hardware_interface/PositionJointInterface</hardwareInterface>
      <hardwareInterface>hardware_interface/EffortJointInterface</hardwareInterface>
      <hardwareInterface>hardware_interface/JointStateInterface</hardwareInterface>
    </joint>
  </transmission>
  <material name="head_camera_aluminum">
    <color rgba="0.5 0.5 0.5 1"/>
  </material>
  <!-- camera body, with origin at bottom screw mount -->
  <joint name="head_camera_joint" type="fixed">
    <origin rpy="0.0 0.0 0.0" xyz="0.0 0.0 0.0"/>
    <parent link="head_camera_base_link"/>
    <child link="head_camera_bottom_screw_frame"/>
  </joint>
  <link name="head_camera_bottom_screw_frame"/>
  <joint name="head_camera_link_joint" type="fixed">
    <origin rpy="0 0 0" xyz="0.0106 0.0175 0.0125"/>
    <parent link="head_camera_bottom_screw_frame"/>
    <child link="head_camera_link"/>
  </joint>
  <link name="head_camera_link">
    <visual>
      <!-- the mesh origin is at front plate in between the two infrared camera axes -->
      <origin rpy="1.57079632679 0 1.57079632679" xyz="0.0043 -0.0175 0"/>
      <geometry>
        <mesh filename="package://realsense2_description/meshes/d435.dae"/>
      </geometry>
    </visual>
    <collision>
      <origin rpy="0 0 0" xyz="0 -0.0175 0"/>
      <geometry>
        <box size="0.02505 0.09 0.025"/>
      </geometry>
    </collision>
    <inertial>
      <!-- The following are not reliable values, and should not be used for modeling -->
      <mass value="0.072"/>
      <origin xyz="0 0 0"/>
      <inertia ixx="0.003881243" ixy="0.0" ixz="0.0" iyy="0.000498940" iyz="0.0" izz="0.003879257"/>
    </inertial>
  </link>
  <!-- camera depth joints and links -->
  <joint name="head_camera_depth_joint" type="fixed">
    <origin rpy="0 0 0" xyz="0 0 0"/>
    <parent link="head_camera_link"/>
    <child link="head_camera_depth_frame"/>
  </joint>
  <link name="head_camera_depth_frame"/>
  <joint name="head_camera_depth_optical_joint" type="fixed">
    <origin rpy="-1.57079632679 0 -1.57079632679" xyz="0 0 0"/>
    <parent link="head_camera_depth_frame"/>
    <child link="head_camera_depth_optical_frame"/>
  </joint>
  <link name="head_camera_depth_optical_frame"/>
  <!-- camera left IR joints and links -->
  <joint name="head_camera_infra1_joint" type="fixed">
    <origin rpy="0 0 0" xyz="0 0.0 0"/>
    <parent link="head_camera_link"/>
    <child link="head_camera_infra1_frame"/>
  </joint>
  <link name="head_camera_infra1_frame"/>
  <joint name="head_camera_infra1_optical_joint" type="fixed">
    <origin rpy="-1.57079632679 0 -1.57079632679" xyz="0 0 0"/>
    <parent link="head_camera_infra1_frame"/>
    <child link="head_camera_infra1_optical_frame"/>
  </joint>
  <link name="head_camera_infra1_optical_frame"/>
  <!-- camera right IR joints and links -->
  <joint name="head_camera_infra2_joint" type="fixed">
    <origin rpy="0 0 0" xyz="0 -0.05 0"/>
    <parent link="head_camera_link"/>
    <child link="head_camera_infra2_frame"/>
  </joint>
  <link name="head_camera_infra2_frame"/>
  <joint name="head_camera_infra2_optical_joint" type="fixed">
    <origin rpy="-1.57079632679 0 -1.57079632679" xyz="0 0 0"/>
    <parent link="head_camera_infra2_frame"/>
    <child link="head_camera_infra2_optical_frame"/>
  </joint>
  <link name="head_camera_infra2_optical_frame"/>
  <!-- camera color joints and links -->
  <joint name="head_camera_color_joint" type="fixed">
    <origin rpy="0 0 0" xyz="0 0.015 0"/>
    <parent link="head_camera_link"/>
    <child link="head_camera_color_frame"/>
  </joint>
  <link name="head_camera_color_frame"/>
  <joint name="head_camera_color_optical_joint" type="fixed">
    <origin rpy="-1.57079632679 0 -1.57079632679" xyz="0 0 0"/>
    <parent link="head_camera_color_frame"/>
    <child link="head_camera_color_optical_frame"/>
  </joint>
  <link name="head_camera_color_optical_frame"/>
  <gazebo reference="head_camera_link">
    <self_collide>0</self_collide>
    <enable_wind>0</enable_wind>
    <kinematic>0</kinematic>
    <gravity>1</gravity>
    <!--<mu>1</mu>-->
    <mu2>1</mu2>
    <fdir1>0 0 0</fdir1>
    <!--<slip1>0</slip1>
      <slip2>0</slip2>-->
    <kp>1e+13</kp>
    <kd>1</kd>
    <!--<max_vel>0.01</max_vel>
      <min_depth>0</min_depth>-->
    <sensor name="head_cameracolor" type="camera">
      <camera name="head_camera">
        <horizontal_fov>1.21125850088</horizontal_fov>
        <image>
          <width>640</width>
          <height>480</height>
          <format>RGB_INT8</format>
        </image>
        <clip>
          <near>0.1</near>
          <far>100</far>
        </clip>
        <noise>
          <type>gaussian</type>
          <mean>0.0</mean>
          <stddev>0.007</stddev>
        </noise>
      </camera>
      <always_on>1</always_on>
      <update_rate>30</update_rate>
      <visualize>1</visualize>
    </sensor>
    <sensor name="head_cameraired1" type="camera">
      <camera name="head_camera">
        <horizontal_fov>1.4870205227</horizontal_fov>
        <image>
          <width>1280</width>
          <height>720</height>
          <format>L_INT8</format>
        </image>
        <clip>
          <near>0.1</near>
          <far>100</far>
        </clip>
        <noise>
          <type>gaussian</type>
          <mean>0.0</mean>
          <stddev>0.05</stddev>
        </noise>
      </camera>
      <always_on>1</always_on>
      <update_rate>90</update_rate>
      <visualize>0</visualize>
    </sensor>
    <sensor name="head_cameraired2" type="camera">
      <camera name="head_camera">
        <horizontal_fov>1.4870205227</horizontal_fov>
        <image>
          <width>1280</width>
          <height>720</height>
          <format>L_INT8</format>
        </image>
        <clip>
          <near>0.1</near>
          <far>100</far>
        </clip>
        <noise>
          <type>gaussian</type>
          <mean>0.0</mean>
          <stddev>0.05</stddev>
        </noise>
      </camera>
      <always_on>1</always_on>
      <update_rate>90</update_rate>
      <visualize>0</visualize>
    </sensor>
    <sensor name="head_cameradepth" type="depth">
      <camera name="head_camera">
        <horizontal_fov>1.4870205227</horizontal_fov>
        <image>
          <width>1280</width>
          <height>720</height>
        </image>
        <clip>
          <near>0.1</near>
          <far>100</far>
        </clip>
        <noise>
          <type>gaussian</type>
          <mean>0.0</mean>
          <stddev>0.100</stddev>
        </noise>
      </camera>
      <always_on>1</always_on>
      <update_rate>90</update_rate>
      <visualize>0</visualize>
    </sensor>
  </gazebo>
  <gazebo>
    <plugin filename="librealsense_gazebo_plugin.so" name="head_camera">
      <prefix>head_camera</prefix>
      <depthUpdateRate>30.0</depthUpdateRate>
      <colorUpdateRate>30.0</colorUpdateRate>
      <infraredUpdateRate>30.0</infraredUpdateRate>
      <depthTopicName>depth/image_raw</depthTopicName>
      <depthCameraInfoTopicName>depth/camera_info</depthCameraInfoTopicName>
      <colorTopicName>color/image_raw</colorTopicName>
      <colorCameraInfoTopicName>color/camera_info</colorCameraInfoTopicName>
      <infrared1TopicName>infra1/image_raw</infrared1TopicName>
      <infrared1CameraInfoTopicName>infra1/camera_info</infrared1CameraInfoTopicName>
      <infrared2TopicName>infra2/image_raw</infrared2TopicName>
      <infrared2CameraInfoTopicName>infra2/camera_info</infrared2CameraInfoTopicName>
      <colorOpticalframeName>head_camera_color_optical_frame</colorOpticalframeName>
      <depthOpticalframeName>head_camera_depth_optical_frame</depthOpticalframeName>
      <infrared1OpticalframeName>head_camera_infra1_ir_optical_frame</infrared1OpticalframeName>
      <infrared2OpticalframeName>head_camera_infra2_ir_optical_frame</infrared2OpticalframeName>
      <rangeMinDepth>0.2</rangeMinDepth>
      <rangeMaxDepth>10.0</rangeMaxDepth>
      <pointCloud>True</pointCloud>
      <pointCloudTopicName>depth/color/points</pointCloudTopicName>
      <pointCloudCutoff>0.25</pointCloudCutoff>
      <pointCloudCutoffMax>9.0</pointCloudCutoffMax>
    </plugin>
  </gazebo>
  <link name="head_1_link">
    <inertial>
      <origin rpy="0 0 0" xyz="-0.00227212440222749 -0.000214576966496169 0.0427574532849163"/>
      <mass value="0.461098369550764"/>
      <inertia ixx="0.000908187580055504" ixy="1.29814956957997E-06" ixz="-1.23800994528056E-05" iyy="0.000788455519612357" iyz="5.43478523879669E-06" izz="0.000544808155380873"/>
    </inertial>
    <visual>
      <origin rpy="0 0 0" xyz="0 0 0"/>
      <geometry>
        <mesh filename="package://canopies_description/meshes/head/head_1_link.STL"/>
      </geometry>
      <material name="">
        <color rgba="0.894117647058823 0.913725490196078 0.929411764705882 1"/>
      </material>
    </visual>
    <collision>
      <origin rpy="0 0 0" xyz="0 0 0"/>
      <geometry>
        <mesh filename="package://canopies_description/meshes/head/head_1_link_convex.STL"/>
      </geometry>
    </collision>
  </link>
  <joint name="head_1_joint" type="revolute">
    <origin rpy="0 0 0" xyz="0.19805 0 -0.017"/>
    <parent link="torso_lift_link"/>
    <child link="head_1_link"/>
    <axis xyz="0 0 1"/>
    <limit effort="5.197" lower="-1.308996939" upper="1.308996939" velocity="3.0"/>
    <dynamics damping="0.5" friction="1.0"/>
    <safety_controller k_position="20" k_velocity="20" soft_lower_limit="-1.308996939" soft_upper_limit="1.308996939"/>
  </joint>
  <link name="head_2_link">
    <inertial>
      <origin rpy="0 0 0" xyz="0.0253815180111981 0.0375513384242796 -0.00355803448386626"/>
      <mass value="0.411032492605717"/>
      <inertia ixx="0.0018692724356324" ixy="-0.000266869511659131" ixz="4.82085794346606E-06" iyy="0.0016523847215072" iyz="-1.68746863299374E-07" izz="0.000991473690297453"/>
    </inertial>
    <visual>
      <origin rpy="0 0 0" xyz="0 0 0"/>
      <geometry>
        <mesh filename="package://canopies_description/meshes/head/head_2_link.STL"/>
      </geometry>
      <material name="">
        <color rgba="0.792156862745098 0.819607843137255 0.933333333333333 1"/>
      </material>
    </visual>
    <collision>
      <origin rpy="0 0 0" xyz="0 0 0"/>
      <geometry>
        <mesh filename="package://canopies_description/meshes/head/head_2_link_convex.STL"/>
      </geometry>
    </collision>
  </link>
  <joint name="head_2_joint" type="revolute">
    <origin rpy="1.5708 0 0" xyz="0.005 0 0.086"/>
    <parent link="head_1_link"/>
    <child link="head_2_link"/>
    <axis xyz="0 0 1"/>
    <limit effort="2.77" lower="-1.0471975512" upper="0.785398163397" velocity="3.0"/>
    <dynamics damping="0.5" friction="1.0"/>
    <safety_controller k_position="20" k_velocity="20" soft_lower_limit="-1.0471975512" soft_upper_limit="0.785398163397"/>
  </joint>
  <!-- Camera Frame -->
  <link name="head_camera_base_link">
    <inertial>
      <origin rpy="0 0 0" xyz="-0.0911841668491683 0.00499050102872186 -0.103796229221887"/>
      <mass value="1.6035675247705"/>
      <inertia ixx="0.0112777696100121" ixy="4.66329633506238E-05" ixz="-0.00237085729249898" iyy="0.0117868583715947" iyz="-4.62980817151922E-05" izz="0.0052459737110999"/>
    </inertial>
    <visual>
      <origin rpy="0 0 0" xyz="0 0 0"/>
      <geometry>
        <box size="0.01 0.01 0.01"/>
      </geometry>
      <material name="">
        <color rgba="1 1 1 1"/>
      </material>
    </visual>
    <collision>
      <origin rpy="0 0 0" xyz="0 0 0"/>
      <geometry>
        <box size="0.01 0.01 0.01"/>
      </geometry>
    </collision>
  </link>
  <joint name="head_camera_base_joint" type="fixed">
    <origin rpy="-1.5708 0 0" xyz="0.08911 0.0575 0.004"/>
    <parent link="head_2_link"/>
    <child link="head_camera_base_link"/>
    <axis xyz="0 0 0"/>
  </joint>
  <transmission name="head_1_trans">
    <type>transmission_interface/SimpleTransmission</type>
    <actuator name="head_1_motor">
      <mechanicalReduction>1.0</mechanicalReduction>
    </actuator>
    <joint name="head_1_joint">
      <hardwareInterface>hardware_interface/PositionJointInterface</hardwareInterface>
      <hardwareInterface>hardware_interface/VelocityJointInterface</hardwareInterface>
      <hardwareInterface>hardware_interface/EffortJointInterface</hardwareInterface>
      <hardwareInterface>hardware_interface/JointStateInterface</hardwareInterface>
    </joint>
  </transmission>
  <transmission name="head_2_trans">
    <type>transmission_interface/SimpleTransmission</type>
    <actuator name="head_2_motor">
      <mechanicalReduction>1.0</mechanicalReduction>
    </actuator>
    <joint name="head_2_joint">
      <hardwareInterface>hardware_interface/PositionJointInterface</hardwareInterface>
      <hardwareInterface>hardware_interface/VelocityJointInterface</hardwareInterface>
      <hardwareInterface>hardware_interface/EffortJointInterface</hardwareInterface>
      <hardwareInterface>hardware_interface/JointStateInterface</hardwareInterface>
    </joint>
  </transmission>
</robot>
