<robot name="human_36dof_ISB_model">
    <material name="body_color">
        <texture />
        <color rgba="0.005 0.005 0.005 0.6" />
    </material>
    <material name="Black">
        <texture />
        <color rgba="0 0 0 1" />
    </material>
    <link name="base_link" />
    <link name="left_clavicle" />
    <link name="left_foot">
        <inertial>
            <mass value="1.212" />
            <origin xyz="0.0744792 -0.0295246 -0.00504441" rpy="0 -0 0" />
            <inertia ixx="0.0023786" ixy="0.00343617" ixz="0.00013254" iyy="0.0131596" iyz="-0.000180508" izz="0.0139264" />
        </inertial>
        <visual>
            <origin xyz="-0.05 -0.055 0.075" rpy="0 1.57 0" />
            <geometry>
		<mesh filename="package://human_urdf/meshes/foot_mesh.STL" scale="0.0060 0.0060 0.0060"/>
                <!--<box size="0.03 0.085239 0.06" />-->
            </geometry>
            <material name="body_color">
                <texture />
                <color rgba="0 1 1 0.5" />
            </material>
        </visual>
    </link>
    <link name="left_foot_COM">
        <visual>
            <origin xyz="0 0 0" rpy="0 -0 0" />
            <geometry>
                <sphere radius="0.008" />
            </geometry>
            <material name="Black">
                <texture />
                <color rgba="1 0 0 1" />
            </material>
        </visual>
    </link>
    <link name="left_foot_virtual" />
    <link name="left_hand">
        <inertial>
            <mass value="0.606" />
            <origin xyz="0.0069896 -0.0715155 -0.00639292" rpy="0 -0 0" />
            <inertia ixx="0.00476249" ixy="0.000516024" ixz="-7.19892e-05" iyy="0.000690167" iyz="-0.000453179" izz="0.00450976" />
        </inertial>
        <visual>
            <origin xyz="-0.06 -0.15 0.165" rpy="0 1.57 0" />
            <geometry>
		<mesh filename="package://human_urdf/meshes/hand_mesh.STL" scale="0.0060 0.0060 0.0060"/>
                <!--<box size="0.03 0.085239 0.06" />-->
            </geometry>
            <material name="body_color">
                <texture />
                <color rgba="0 1 1 0.5" />
            </material>
        </visual>
    </link>
    <link name="left_hand_COM">
        <visual>
            <origin xyz="0 0 0" rpy="0 -0 0" />
            <geometry>
                <sphere radius="0.008" />
            </geometry>
            <material name="Black">
                <texture />
                <color rgba="1 0 0 1" />
            </material>
        </visual>
    </link>
    <link name="left_hand_virtual" />
    <link name="left_lowerarm">
        <inertial>
            <mass value="1.717" />
            <origin xyz="-0.00392629 -0.125943 -0.00332224" rpy="0 -0 0" />
            <inertia ixx="0.0395325" ixy="0.000153331" ixz="-3.80587e-05" iyy="0.00194052" iyz="-0.000781064" izz="0.03954" />
        </inertial>
        <visual>
            <origin xyz="0.052 -0.26 -0.17" rpy="0.0 -1.57 0" />
            <geometry>
                <mesh filename="package://human_urdf/meshes/lowerarm_mesh.STL" scale="0.0060 0.0060 0.0060"/>
            </geometry>
            <material name="body_color">
                <texture />
                <color rgba="0 1 1 0.5" />
            </material>
        </visual>
    </link>
    <link name="left_lowerarm_COM">
        <visual>
            <origin xyz="0 0 0" rpy="0 -0 0" />
            <geometry>
                <sphere radius="0.008" />
            </geometry>
            <material name="Black">
                <texture />
                <color rgba="1 0 0 1" />
            </material>
        </visual>
    </link>
    <link name="left_lowerarm_virtual" >
        <visual>
	<origin xyz="-0.15 -0.04 -0.035" rpy="0 0 0" />
            <geometry>
		<mesh filename="package://human_urdf/meshes/elbow_mesh.STL" scale="0.0055 0.0055 0.0055"/>
            </geometry>
            <material name="body_color">
                <texture />
                <color rgba="0 1 1 0.5" />
            </material>
        </visual>
    </link>
    <link name="left_lowerleg">
        <inertial>
            <mass value="4.848" />
            <origin xyz="-0.0221901 -0.189541 -0.00323606" rpy="0 -0 0" />
            <inertia ixx="0.255448" ixy="-0.0187326" ixz="-0.000762565" iyy="0.0127989" iyz="-0.00463134" izz="0.257784" />
        </inertial>
        <visual>
            <origin xyz="-0.06 -0.43 0.08" rpy="0.0 1.57 0" />
            <geometry>
                <mesh filename="package://human_urdf/meshes/lowerleg_mesh.STL" scale="0.0063 0.0065 0.007"/>
            </geometry>
            <material name="body_color">
                <texture />
                <color rgba="0 1 1 0.5" />
            </material>        </visual>
    </link>
    <link name="left_lowerleg_COM">
        <visual>
            <origin xyz="0 0 0" rpy="0 -0 0" />
            <geometry>
                <sphere radius="0.008" />
            </geometry>
            <material name="Black">
                <texture />
                <color rgba="1 0 0 1" />
            </material>
        </visual>
    </link>
    <link name="left_upperarm">
        <inertial>
            <mass value="2.424" />
            <origin xyz="0.00532073 -0.142477 0.00916348" rpy="0 -0 0" />
            <inertia ixx="0.0672227" ixy="0.0023671" ixz="-0.000308807" iyy="0.00385162" iyz="-0.000414708" izz="0.0683374" />
        </inertial>
        <visual>
            <origin xyz="0.06 -0.29 -0.175" rpy="0.0 -1.57 0" />
            <geometry>
                <mesh filename="package://human_urdf/meshes/upperarm_mesh.STL" scale="0.0063 0.0060 0.007"/>
            </geometry>
            <material name="body_color"/>

        </visual>
    </link>
    <link name="left_upperarm_COM">
        <visual>
            <origin xyz="0 0 0" rpy="0 -0 0" />
            <geometry>
                <sphere radius="0.008" />
            </geometry>
            <material name="Black">
                <texture />
                <color rgba="1 0 0 1" />
            </material>
        </visual>
    </link>
    <link name="left_upperarm_virtual_1" >
        <visual>
	<origin xyz="-0.16 -0.045 -0.045" rpy="0 0 0" />
            <geometry>
		<mesh filename="package://human_urdf/meshes/shoulder_mesh.STL" scale="0.0055 0.0055 0.0055"/>
            </geometry>
            <material name="body_color">
                <texture />
                <color rgba="0 1 1 0.5" />
            </material>
        </visual>
    </link>
    <link name="left_upperarm_virtual_2" />
    <link name="left_upperleg">
        <inertial>
            <mass value="12.423" />
            <origin xyz="-0.0189076 -0.197838 0.0152183" rpy="0 -0 0" />
            <inertia ixx="0.711301" ixy="-0.0335241" ixz="0.00251781" iyy="0.0667629" iyz="0.0244568" izz="0.728452" />
        </inertial>
        <visual>
            <origin xyz="-0.1 -0.42 0.085" rpy="0.0 1.57 0" />
            <geometry>
                <mesh filename="package://human_urdf/meshes/upperleg_mesh.STL" scale="0.0063 0.0065 0.007"/>
            </geometry>
            <material name="body_color">
                <texture />
                <color rgba="0 1 1 0.5" />
            </material>
        </visual>
    </link>
    <link name="left_upperleg_COM">
        <visual>
            <origin xyz="0 0 0" rpy="0 -0 0" />
            <geometry>
                <sphere radius="0.008" />
            </geometry>
            <material name="Black">
                <texture />
                <color rgba="1 0 0 1" />
            </material>
        </visual>
    </link>
    <link name="left_upperleg_virtual_1"/>


    <link name="left_upperleg_virtual_2" >
        <visual>
            <origin xyz="-0.04 -0.48 0.080" rpy="0.0 1.57 0" />
            <geometry>
                <mesh filename="package://human_urdf/meshes/knee_mesh.STL" scale="0.006 0.006 0.006"/>
            </geometry>
            <material name="body_color">
                <texture />
                <color rgba="0 1 1 0.5" />
            </material>
        </visual>
     </link>
    <link name="middle_abdomen">
        <inertial>
            <mass value="2.929" />
            <origin xyz="0.0283742 -0.0581993 -0.00532016" rpy="0 -0 0" />
            <inertia ixx="0.0322027" ixy="0.00575797" ixz="0.000716207" iyy="0.0356021" iyz="-0.000716587" izz="0.0244595" />
        </inertial>
        <visual>
            <origin xyz="-0.06 -0.065 -0.085" rpy="0 -0 0" />
            <geometry>
		<mesh filename="package://human_urdf/meshes/abdomen_mesh.STL" scale="0.0055 0.0055 0.0055"/>
                <!--<box size="0.15 0.161217 0.198658" />-->
            </geometry>
            <material name="body_color">
                <texture />
                <color rgba="0 1 1 0.5" />
            </material>
        </visual>
    </link>
    <link name="middle_abdomen_COM">
        <visual>
            <origin xyz="0 0 0" rpy="0 -0 0" />
            <geometry>
                <sphere radius="0.008" />
            </geometry>
            <material name="Black">
                <texture />
                <color rgba="1 0 0 1" />
            </material>
        </visual>
    </link>
    <link name="middle_abdomen_virtual" />
    <link name="middle_abdomen_virtual_2" />
    <link name="middle_head">
        <inertial>
            <mass value="6.767" />
            <origin xyz="0.0059346 0.158454 0.00029673" rpy="0 -0 0" />
            <inertia ixx="0.223528" ixy="-0.00344387" ixz="0.000226414" iyy="0.0345585" iyz="0.000218072" izz="0.2274" />
        </inertial>
        <visual>
	    <origin xyz="-0.07 0.04 0.09" rpy="0 1.57 0" />
            <geometry>
		<mesh filename="package://human_urdf/meshes/head_mesh.STL" scale="0.0055 0.0055 0.0055"/>
            </geometry>
            <material name="body_color">
                <texture />
                <color rgba="0.2 0.2 0.2 0.5" />
            </material>
        </visual>
    </link>
    <link name="middle_head_COM">
        <visual>
            <origin xyz="0 0 0" rpy="0 -0 0" />
            <geometry>
                <sphere radius="0.008" />
            </geometry>
            <material name="Black">
                <texture />
                <color rgba="1 0 0 1" />
            </material>
        </visual>
    </link>
    <link name="middle_head_virtual_1">
        <visual>
	    <origin xyz="-0.03 -0.01 -0.045" rpy="0 0.0 0" />
            <geometry>
		<mesh filename="package://human_urdf/meshes/neck_mesh.STL" scale="0.005 0.005 0.005"/>
            </geometry>
            <material name="body_color">
                <texture />
                <color rgba="0.2 0.2 0.2 0.7" />
            </material>
        </visual>
    </link>
    <link name="middle_head_virtual_2" />
    <link name="middle_pelvis">
        <inertial>
            <mass value="14.342" />
            <origin xyz="-0.00019845 -0.0285768 -0.00059535" rpy="0 -0 0" />
            <inertia ixx="0.158628" ixy="0.00805211" ixz="0.00203167" iyy="0.158664" iyz="0.000659713" izz="0.141848" />
        </inertial>
        <visual>
	    <origin xyz="-0.08 -0.13 0.125" rpy="0 1.57 0" />
            <geometry>
		<mesh filename="package://human_urdf/meshes/pelvis_mesh.STL" scale="0.006 0.0055 0.0055"/>
            </geometry>
            <material name="body_color">
                <texture />
                <color rgba="0 1 1 0.5" />
            </material>
        </visual>
    </link>
    <link name="middle_pelvis_COM">
        <visual>
            <origin xyz="0 0 0" rpy="0 -0 0" />
            <geometry>
                <sphere radius="0.008" />
            </geometry>
            <material name="Black">
                <texture />
                <color rgba="1 0 0 1" />
            </material>
        </visual>
    </link>
    <link name="middle_thorax">
        <inertial>
            <mass value="30.704" />
            <origin xyz="0 -0.197937 -0.00142657" rpy="0 -0 0" />
            <inertia ixx="1.89192" ixy="0.047255" ixz="0.000390537" iyy="0.425357" iyz="-0.00515509" izz="1.70909" />
        </inertial>
        <visual>
            <! -- <origin xyz="0.024 -0.178321 0" rpy="0 -0 0" /> -->
	    <origin xyz="-0.11 -0.32 0.13" rpy="0 1.57 0" />
            <geometry>
		<!--<box size="0.15 0.356643 0.329994" />-->
		<mesh filename="package://human_urdf/meshes/torso_mesh.STL" scale="0.0065 0.0065 0.0065"/>
            </geometry>
            <material name="body_color">
                <texture />
                <color rgba="0.2 0.2 0.2 0.2" />
            </material>
        </visual>
    </link>
    <link name="middle_thorax_COM">
        <visual>
            <origin xyz="0 0 0" rpy="0 -0 0" />
            <geometry>
                <sphere radius="0.008" />
            </geometry>
            <material name="Black">
                <texture />
                <color rgba="1 0 0 1" />
            </material>
        </visual>
    </link>
    <link name="middle_thorax_virtual_1" />
    <link name="middle_thorax_virtual_2" />
    <link name="middle_thorax_virtual_3" />
    <link name="right_clavicle" />
    <link name="right_foot">
        <inertial>
            <mass value="1.212" />
            <origin xyz="0.0744792 -0.0295246 0.00504441" rpy="0 0.0 0" />
            <inertia ixx="0.0023786" ixy="0.00343617" ixz="-0.00013254" iyy="0.0131596" iyz="0.000180508" izz="0.0139264" />
        </inertial>
        <visual>
            <origin xyz="-0.05 -0.055 0.065" rpy="0 1.57 0" />
            <geometry>
		<mesh filename="package://human_urdf/meshes/foot_mesh.STL" scale="0.0060 0.0060 0.0060"/>
                <!--<box size="0.03 0.085239 0.06" />-->
            </geometry>
            <material name="body_color">
                <texture />
                <color rgba="0 1 1 0.5" />
            </material>
        </visual>
    </link>
    <link name="right_foot_COM">
        <visual>
            <origin xyz="0 0 0" rpy="0 -0 0" />
            <geometry>
                <sphere radius="0.008" />
            </geometry>
            <material name="Black">
                <texture />
                <color rgba="1 0 0 1" />
            </material>
        </visual>
    </link>
    <link name="right_foot_virtual" />
    <link name="right_hand">
        <inertial>
            <mass value="0.606" />
            <origin xyz="0.0069896 -0.0715155 0.00639292" rpy="0 -0 0" />
            <inertia ixx="0.00476249" ixy="0.000516024" ixz="7.19892e-05" iyy="0.000690167" iyz="0.000453179" izz="0.00450976" />
        </inertial>
        <visual>
            <origin xyz="0.06 -0.15 -0.165" rpy="0 -1.57 0" />
            <geometry>
		<mesh filename="package://human_urdf/meshes/hand_mesh.STL" scale="0.0060 0.0060 0.0060"/>
                <!--<box size="0.03 0.085239 0.06" />-->
            </geometry>
            <material name="body_color">
                <texture />
                <color rgba="0 1 1 0.5" />
            </material>
        </visual>
    </link>
    <link name="right_hand_COM">
        <visual>
            <origin xyz="0 0 0" rpy="0 -0 0" />
            <geometry>
                <sphere radius="0.008" />
            </geometry>
            <material name="Black">
                <texture />
                <color rgba="1 0 0 1" />
            </material>
        </visual>
    </link>
    <link name="right_hand_virtual" />
    <link name="right_lowerarm">
        <inertial>
            <mass value="1.717" />
            <origin xyz="-0.00392629 -0.125943 0.00332224" rpy="0 -0 0" />
            <inertia ixx="0.0395325" ixy="0.000153331" ixz="3.80587e-05" iyy="0.00194052" iyz="0.000781064" izz="0.03954" />
        </inertial>
        <visual>
            <origin xyz="0.052 -0.26 -0.17" rpy="0.0 -1.57 0" />
            <geometry>
                <mesh filename="package://human_urdf/meshes/lowerarm_mesh.STL" scale="0.0060 0.0060 0.0060"/>
            </geometry>
            <material name="body_color">
                <texture />
                <color rgba="0 1 1 0.5" />
            </material>
        </visual>
    </link>
    <link name="right_lowerarm_COM">
        <visual>
            <origin xyz="0 0 0" rpy="0 -0 0" />
            <geometry>
                <sphere radius="0.008" />
            </geometry>
            <material name="Black">
                <texture />
                <color rgba="1 0 0 1" />
            </material>
        </visual>
    </link>
    <link name="right_lowerarm_virtual">
        <visual>
	<origin xyz="-0.15 -0.04 -0.035" rpy="0 0 0" />
            <geometry>
		<mesh filename="package://human_urdf/meshes/elbow_mesh.STL" scale="0.0055 0.0055 0.0055"/>
            </geometry>
            <material name="body_color">
                <texture />
                <color rgba="0 1 1 0.5" />
            </material>
        </visual>
    </link>
    <link name="right_lowerleg">
        <inertial>
            <mass value="4.848" />
            <origin xyz="-0.0221901 -0.189541 0.00323606" rpy="0 -0 0" />
            <inertia ixx="0.255448" ixy="-0.0187326" ixz="0.000762565" iyy="0.0127989" iyz="0.00463134" izz="0.257784" />
        </inertial>
        <visual>
            <origin xyz="-0.06 -0.43 0.07" rpy="0.0 1.57 0" />
            <geometry>
                <mesh filename="package://human_urdf/meshes/lowerleg_mesh.STL" scale="0.0063 0.0065 0.007"/>
            </geometry>
            <material name="body_color">
                <texture />
                <color rgba="0 1 1 0.5" />
            </material>
        </visual>
    </link>
    <link name="right_lowerleg_COM">
        <visual>
            <origin xyz="0 0 0" rpy="0 -0 0" />
            <geometry>
                <sphere radius="0.008" />
            </geometry>
            <material name="Black">
                <texture />
                <color rgba="1 0 0 1" />
            </material>
        </visual>
    </link>
    <link name="right_upperarm">
        <inertial>
            <mass value="2.424" />
            <origin xyz="0.00532073 -0.142477 -0.00916348" rpy="0 -0 0" />
            <inertia ixx="0.0672227" ixy="0.0023671" ixz="0.000308807" iyy="0.00385162" iyz="0.000414708" izz="0.0683374" />
        </inertial>
        <visual>
            <origin xyz="0.06 -0.29 -0.18" rpy="0.0 -1.57 0" />
            <geometry>
                <mesh filename="package://human_urdf/meshes/upperarm_mesh.STL" scale="0.0063 0.0060 0.007"/>
            </geometry>
            <material name="body_color">
                <texture />
                <color rgba="0 1 1 0.5" />
            </material>
        </visual>
    </link>
    <link name="right_upperarm_COM">
        <visual>
            <origin xyz="0 0 0" rpy="0 -0 0" />
            <geometry>
                <sphere radius="0.008" />
            </geometry>
            <material name="Black">
                <texture />
                <color rgba="1 0 0 1" />
            </material>
        </visual>
    </link>
    <link name="right_upperarm_virtual_1">
        <visual>
	<origin xyz="-0.15 -0.04 -0.05" rpy="0 0 0" />
            <geometry>
		<mesh filename="package://human_urdf/meshes/shoulder_mesh.STL" scale="0.0055 0.0055 0.0055"/>
            </geometry>
            <material name="body_color">
                <texture />
                <color rgba="0 1 1 0.5" />
            </material>
        </visual>
   </link>
    <link name="right_upperarm_virtual_2" />
    <link name="right_upperleg">
        <inertial>
            <mass value="12.423" />
            <origin xyz="-0.0189076 -0.197838 -0.0152183" rpy="0 0.0 0" />
            <inertia ixx="0.711301" ixy="-0.0335241" ixz="-0.00251781" iyy="0.0667629" iyz="-0.0244568" izz="0.728452" />
        </inertial>
        <visual>
            <origin xyz="-0.1 -0.42 0.07" rpy="0.0 1.57 0" />
            <geometry>
                <mesh filename="package://human_urdf/meshes/upperleg_mesh.STL" scale="0.0063 0.0065 0.007"/>
            </geometry>
            <material name="body_color">
                <texture />
                <color rgba="0 1 1 0.5" />
            </material>
        </visual>
    </link>
    <link name="right_upperleg_COM">
        <visual>
            <origin xyz="0 0 0" rpy="0 -0 0" />
            <geometry>
                <sphere radius="0.008" />
            </geometry>
            <material name="Black">
                <texture />
                <color rgba="1 0 0 1" />
            </material>
        </visual>
    </link>
    <link name="right_upperleg_virtual_1"/>

    <link name="right_upperleg_virtual_2" >
        <visual>
            <origin xyz="-0.04 -0.48 0.07" rpy="0.0 1.57 0" />
            <geometry>
                <mesh filename="package://human_urdf/meshes/knee_mesh.STL" scale="0.006 0.006 0.006"/>
            </geometry>
            <material name="body_color">
                <texture />
                <color rgba="0 1 1 0.5" />
            </material>
        </visual>
    </link>
    <joint name="base_to_pelvis_free_joint" type="fixed">
        <origin xyz="0 0 0" rpy="1.5708 -0 0" />
        <parent link="base_link" />
        <child link="middle_pelvis" />
    </joint>
    <joint name="left_ankle_X" type="revolute">
        <origin xyz="0 0 0" rpy="0 -0 0" />
        <axis xyz="-1 0 0" />
        <parent link="left_foot_virtual" />
        <child link="left_foot" />
        <limit effort="0" velocity="0" lower="-3.14" upper="3.14" />
    </joint>
    <joint name="left_ankle_Z" type="revolute">
        <origin xyz="0 -0.462294 0" rpy="0 -0 0" />
        <axis xyz="0 0 1" />
        <parent link="left_lowerleg" />
        <child link="left_foot_virtual" />
        <limit effort="0" velocity="0" lower="-3.14" upper="3.14" />
    </joint>
    <joint name="left_clavicle_joint_X" type="revolute">
        <origin xyz="0 0 0" rpy="0 -0 0" />
        <axis xyz="1 0 0" />
        <parent link="middle_thorax" />
        <child link="left_clavicle" />
        <limit effort="0" velocity="0" lower="-3.14" upper="3.14" />
    </joint>
    <joint name="left_elbow_Y" type="revolute">
        <origin xyz="0 0 0" rpy="0 -0 0" />
        <axis xyz="0 -1 0" />
        <parent link="left_lowerarm_virtual" />
        <child link="left_lowerarm" />
        <limit effort="0" velocity="0" lower="-3.14" upper="3.14" />
    </joint>
    <joint name="left_elbow_Z" type="revolute">
        <origin xyz="0 -0.295596 0" rpy="0 -0 0" />
        <axis xyz="0 0 1" />
        <parent link="left_upperarm" />
        <child link="left_lowerarm_virtual" />
        <limit effort="0" velocity="0" lower="-3.14" upper="3.14" />
    </joint>
    <joint name="left_foot_COM_joint" type="fixed">
        <origin xyz="0.0744792 -0.0295246 -0.00504441" rpy="0 -0 0" />
        <axis xyz="0 0 0" />
        <parent link="left_foot" />
        <child link="left_foot_COM" />
    </joint>
    <joint name="left_hand_COM_joint" type="fixed">
        <origin xyz="0.0069896 -0.0715155 -0.00639292" rpy="0 -0 0" />
        <axis xyz="0 0 0" />
        <parent link="left_hand" />
        <child link="left_hand_COM" />
    </joint>
    <joint name="left_hip_X" type="revolute">
        <origin xyz="0 0 0" rpy="0 -0 0" />
        <axis xyz="-1 0 0" />
        <parent link="left_upperleg_virtual_1" />
        <child link="left_upperleg_virtual_2" />
        <limit effort="0" velocity="0" lower="-3.14" upper="3.14" />
    </joint>
    <joint name="left_hip_Y" type="revolute">
        <origin xyz="0 0 0" rpy="0 -0 0" />
        <axis xyz="0 -1 0" />
        <parent link="left_upperleg_virtual_2" />
        <child link="left_upperleg" />
        <limit effort="0" velocity="0" lower="-3.14" upper="3.14" />
    </joint>
    <joint name="left_hip_Z" type="revolute">
        <origin xyz="0.057645 -0.080892 -0.086373" rpy="0 -0 0" />
        <axis xyz="0 0 1" />
        <parent link="middle_pelvis" />
        <child link="left_upperleg_virtual_1" />
        <limit effort="0" velocity="0" lower="-3.14" upper="3.14" />
    </joint>
    <joint name="left_knee" type="revolute">
        <origin xyz="0 -0.46116 0" rpy="0 -0 0" />
        <axis xyz="0 0 -1" />
        <parent link="left_upperleg" />
        <child link="left_lowerleg" />
        <limit effort="0" velocity="0" lower="-3.14" upper="3.14" />
    </joint>
    <joint name="left_lowerarm_COM_joint" type="fixed">
        <origin xyz="-0.00392629 -0.125943 -0.00332224" rpy="0 -0 0" />
        <axis xyz="0 0 0" />
        <parent link="left_lowerarm" />
        <child link="left_lowerarm_COM" />
    </joint>
    <joint name="left_lowerleg_COM_joint" type="fixed">
        <origin xyz="-0.0221901 -0.189541 -0.00323606" rpy="0 -0 0" />
        <axis xyz="0 0 0" />
        <parent link="left_lowerleg" />
        <child link="left_lowerleg_COM" />
    </joint>
    <joint name="left_shoulder_X" type="revolute">
        <origin xyz="0 0 0" rpy="0 -0 0" />
        <axis xyz="-1 0 0" />
        <parent link="left_upperarm_virtual_1" />
        <child link="left_upperarm_virtual_2" />
        <limit effort="0" velocity="0" lower="-3.14" upper="3.14" />
    </joint>
    <joint name="left_shoulder_Y" type="revolute">
        <origin xyz="0.008694 -0.078624 -0.219996" rpy="0 -0 0" />
        <axis xyz="0 -1 0" />
        <parent link="left_clavicle" />
        <child link="left_upperarm_virtual_1" />
        <limit effort="0" velocity="0" lower="-3.14" upper="3.14" />
    </joint>
    <joint name="left_shoulder_Z" type="revolute">
        <origin xyz="0 0 0" rpy="0 -0 0" />
        <axis xyz="0 0 1" />
        <parent link="left_upperarm_virtual_2" />
        <child link="left_upperarm" />
        <limit effort="0" velocity="0" lower="-3.14" upper="3.14" />
    </joint>
    <joint name="left_upperarm_COM_joint" type="fixed">
        <origin xyz="0.00532073 -0.142477 0.00916348" rpy="0 -0 0" />
        <axis xyz="0 0 0" />
        <parent link="left_upperarm" />
        <child link="left_upperarm_COM" />
    </joint>
    <joint name="left_upperleg_COM_joint" type="fixed">
        <origin xyz="-0.0189076 -0.197838 0.0152183" rpy="0 -0 0" />
        <axis xyz="0 0 0" />
        <parent link="left_upperleg" />
        <child link="left_upperleg_COM" />
    </joint>
    <joint name="left_wrist_X" type="revolute">
        <origin xyz="0 0 0" rpy="0 -0 0" />
        <axis xyz="-1 0 0" />
        <parent link="left_hand_virtual" />
        <child link="left_hand" />
        <limit effort="0" velocity="0" lower="-3.14" upper="3.14" />
    </joint>
    <joint name="left_wrist_Z" type="revolute">
        <origin xyz="0 -0.302022 0" rpy="0 -0 0" />
        <axis xyz="0 0 1" />
        <parent link="left_lowerarm" />
        <child link="left_hand_virtual" />
        <limit effort="0" velocity="0" lower="-3.14" upper="3.14" />
    </joint>
    <joint name="middle_abdomen_COM_joint" type="fixed">
        <origin xyz="0.0283742 -0.0581993 -0.00532016" rpy="0 -0 0" />
        <axis xyz="0 0 0" />
        <parent link="middle_abdomen" />
        <child link="middle_abdomen_COM" />
    </joint>
    <joint name="middle_abdomen_base_frame" type="fixed">
        <origin xyz="0 0.161217 0" rpy="0 -0 0" />
        <axis xyz="0 0 0" />
        <parent link="middle_abdomen_virtual_2" />
        <child link="middle_abdomen" />
    </joint>
    <joint name="middle_cervical_X" type="revolute">
        <origin xyz="0 0 0" rpy="0 -0 0" />
        <axis xyz="1 0 0" />
        <parent link="middle_head_virtual_1" />
        <child link="middle_head_virtual_2" />
        <limit effort="0" velocity="0" lower="-3.14" upper="3.14" />
    </joint>
    <joint name="middle_cervical_Y" type="revolute">
        <origin xyz="0 0 0" rpy="0 -0 0" />
        <axis xyz="0 1 0" />
        <parent link="middle_head_virtual_2" />
        <child link="middle_head" />
        <limit effort="0" velocity="0" lower="-3.14" upper="3.14" />
    </joint>
    <joint name="middle_cervical_Z" type="revolute">
        <origin xyz="0 0 0" rpy="0 -0 0" />
        <axis xyz="0 0 1" />
        <parent link="middle_thorax" />
        <child link="middle_head_virtual_1" />
        <limit effort="0" velocity="0" lower="-3.14" upper="3.14" />
    </joint>
    <joint name="middle_head_COM_joint" type="fixed">
        <origin xyz="0.0059346 0.158454 0.00029673" rpy="0 -0 0" />
        <axis xyz="0 0 0" />
        <parent link="middle_head" />
        <child link="middle_head_COM" />
    </joint>
    <joint name="middle_lumbar_X" type="revolute">
        <origin xyz="0 0 0" rpy="0 -0 0" />
        <axis xyz="1 0 0" />
        <parent link="middle_abdomen_virtual" />
        <child link="middle_abdomen_virtual_2" />
        <limit effort="0" velocity="0" lower="-3.14" upper="3.14" />
    </joint>
    <joint name="middle_lumbar_Z" type="revolute">
        <origin xyz="0 0 0" rpy="0 -0 0" />
        <axis xyz="0 0 1" />
        <parent link="middle_pelvis" />
        <child link="middle_abdomen_virtual" />
        <limit effort="0" velocity="0" lower="-3.14" upper="3.14" />
    </joint>
    <joint name="middle_pelvis_COM_joint" type="fixed">
        <origin xyz="-0.00019845 -0.0285768 -0.00059535" rpy="0 -0 0" />
        <axis xyz="0 0 0" />
        <parent link="middle_pelvis" />
        <child link="middle_pelvis_COM" />
    </joint>
    <joint name="middle_thoracic_X" type="revolute">
        <origin xyz="0 0 0" rpy="0 -0 0" />
        <axis xyz="1 0 0" />
        <parent link="middle_thorax_virtual_1" />
        <child link="middle_thorax_virtual_2" />
        <limit effort="0" velocity="0" lower="-3.14" upper="3.14" />
    </joint>
    <joint name="middle_thoracic_Y" type="revolute">
        <origin xyz="0 0 0" rpy="0 -0 0" />
        <axis xyz="0 1 0" />
        <parent link="middle_thorax_virtual_2" />
        <child link="middle_thorax_virtual_3" />
        <limit effort="0" velocity="0" lower="-3.14" upper="3.14" />
    </joint>
    <joint name="middle_thoracic_Z" type="revolute">
        <origin xyz="0 0 0" rpy="0 -0 0" />
        <axis xyz="0 0 1" />
        <parent link="middle_abdomen" />
        <child link="middle_thorax_virtual_1" />
        <limit effort="0" velocity="0" lower="-3.14" upper="3.14" />
    </joint>
    <joint name="middle_thorax_COM_joint" type="fixed">
        <origin xyz="0 -0.197937 -0.00142657" rpy="0 -0 0" />
        <axis xyz="0 0 0" />
        <parent link="middle_thorax" />
        <child link="middle_thorax_COM" />
    </joint>
    <joint name="middle_thorax_base_frame" type="fixed">
        <origin xyz="0 0.356643 0" rpy="0 -0 0" />
        <axis xyz="0 0 0" />
        <parent link="middle_thorax_virtual_3" />
        <child link="middle_thorax" />
    </joint>
    <joint name="right_ankle_X" type="revolute">
        <origin xyz="0 0 0" rpy="0 -0 0" />
        <axis xyz="1 0 0" />
        <parent link="right_foot_virtual" />
        <child link="right_foot" />
        <limit effort="0" velocity="0" lower="-3.14" upper="3.14" />
    </joint>
    <joint name="right_ankle_Z" type="revolute">
        <origin xyz="0 -0.462294 0" rpy="0 -0 0" />
        <axis xyz="0 0 1" />
        <parent link="right_lowerleg" />
        <child link="right_foot_virtual" />
        <limit effort="0" velocity="0" lower="-3.14" upper="3.14" />
    </joint>
    <joint name="right_clavicle_joint_X" type="revolute">
        <origin xyz="0 0 0" rpy="0 -0 0" />
        <axis xyz="-1 0 0" />
        <parent link="middle_thorax" />
        <child link="right_clavicle" />
        <limit effort="0" velocity="0" lower="-3.14" upper="3.14" />
    </joint>
    <joint name="right_elbow_Y" type="revolute">
        <origin xyz="0 0 0" rpy="0 -0 0" />
        <axis xyz="0 1 0" />
        <parent link="right_lowerarm_virtual" />
        <child link="right_lowerarm" />
        <limit effort="0" velocity="0" lower="-3.14" upper="3.14" />
    </joint>
    <joint name="right_elbow_Z" type="revolute">
        <origin xyz="0 -0.295596 0" rpy="0 -0 0" />
        <axis xyz="0 0 1" />
        <parent link="right_upperarm" />
        <child link="right_lowerarm_virtual" />
        <limit effort="0" velocity="0" lower="-3.14" upper="3.14" />
    </joint>
    <joint name="right_foot_COM_joint" type="fixed">
        <origin xyz="0.0744792 -0.0295246 0.00504441" rpy="0 -0 0" />
        <axis xyz="0 0 0" />
        <parent link="right_foot" />
        <child link="right_foot_COM" />
    </joint>
    <joint name="right_hand_COM_joint" type="fixed">
        <origin xyz="0.0069896 -0.0715155 0.00639292" rpy="0 -0 0" />
        <axis xyz="0 0 0" />
        <parent link="right_hand" />
        <child link="right_hand_COM" />
    </joint>
    <joint name="right_hip_X" type="revolute">
        <origin xyz="0 0 0" rpy="0 -0 0" />
        <axis xyz="1 0 0" />
        <parent link="right_upperleg_virtual_1" />
        <child link="right_upperleg_virtual_2" />
        <limit effort="0" velocity="0" lower="-3.14" upper="3.14" />
    </joint>
    <joint name="right_hip_Y" type="revolute">
        <origin xyz="0 0 0" rpy="0 -0 0" />
        <axis xyz="0 1 0" />
        <parent link="right_upperleg_virtual_2" />
        <child link="right_upperleg" />
        <limit effort="0" velocity="0" lower="-3.14" upper="3.14" />
    </joint>
    <joint name="right_hip_Z" type="revolute">
        <origin xyz="0.057645 -0.080892 0.086373" rpy="0 -0 0" />
        <axis xyz="0 0 1" />
        <parent link="middle_pelvis" />
        <child link="right_upperleg_virtual_1" />
        <limit effort="0" velocity="0" lower="-3.14" upper="3.14" />
    </joint>
    <joint name="right_knee" type="revolute">
        <origin xyz="0 -0.46116 0" rpy="0 -0 0" />
        <axis xyz="0 0 -1" />
        <parent link="right_upperleg" />
        <child link="right_lowerleg" />
        <limit effort="0" velocity="0" lower="-3.14" upper="3.14" />
    </joint>
    <joint name="right_lowerarm_COM_joint" type="fixed">
        <origin xyz="-0.00392629 -0.125943 0.00332224" rpy="0 -0 0" />
        <axis xyz="0 0 0" />
        <parent link="right_lowerarm" />
        <child link="right_lowerarm_COM" />
    </joint>
    <joint name="right_lowerleg_COM_joint" type="fixed">
        <origin xyz="-0.0221901 -0.189541 0.00323606" rpy="0 -0 0" />
        <axis xyz="0 0 0" />
        <parent link="right_lowerleg" />
        <child link="right_lowerleg_COM" />
    </joint>
    <joint name="right_shoulder_X" type="revolute">
        <origin xyz="0 0 0" rpy="0 -0 0" />
        <axis xyz="1 0 0" />
        <parent link="right_upperarm_virtual_1" />
        <child link="right_upperarm_virtual_2" />
        <limit effort="0" velocity="0" lower="-3.14" upper="3.14" />
    </joint>
    <joint name="right_shoulder_Y" type="revolute">
        <origin xyz="0.008694 -0.078624 0.219996" rpy="0 -0 0" />
        <axis xyz="0 1 0" />
        <parent link="right_clavicle" />
        <child link="right_upperarm_virtual_1" />
        <limit effort="0" velocity="0" lower="-3.14" upper="3.14" />
    </joint>
    <joint name="right_shoulder_Z" type="revolute">
        <origin xyz="0 0 0" rpy="0 -0 0" />
        <axis xyz="0 0 1" />
        <parent link="right_upperarm_virtual_2" />
        <child link="right_upperarm" />
        <limit effort="0" velocity="0" lower="-3.14" upper="3.14" />
    </joint>
    <joint name="right_upperarm_COM_joint" type="fixed">
        <origin xyz="0.00532073 -0.142477 -0.00916348" rpy="0 -0 0" />
        <axis xyz="0 0 0" />
        <parent link="right_upperarm" />
        <child link="right_upperarm_COM" />
    </joint>
    <joint name="right_upperleg_COM_joint" type="fixed">
        <origin xyz="-0.0189076 -0.197838 -0.0152183" rpy="0 -0 0" />
        <axis xyz="0 0 0" />
        <parent link="right_upperleg" />
        <child link="right_upperleg_COM" />
    </joint>
    <joint name="right_wrist_X" type="revolute">
        <origin xyz="0 0 0" rpy="0 -0 0" />
        <axis xyz="1 0 0" />
        <parent link="right_hand_virtual" />
        <child link="right_hand" />
        <limit effort="0" velocity="0" lower="-3.14" upper="3.14" />
    </joint>
    <joint name="right_wrist_Z" type="revolute">
        <origin xyz="0 -0.302022 0" rpy="0 -0 0" />
        <axis xyz="0 0 1" />
        <parent link="right_lowerarm" />
        <child link="right_hand_virtual" />
        <limit effort="0" velocity="0" lower="-3.14" upper="3.14" />
    </joint>
</robot>
