<robot name="human_36dof_ISB_model">
    <material name="Cyan">
        <texture />
        <color rgba="0 1 1 0.5" />
    </material>
    <material name="Red">
        <texture />
        <color rgba="1 0 0 1" />
    </material>
    <link name="base_link" />
    <link name="human_abdomen">
        <inertial>
            <mass value="2.32" />
            <origin xyz="0.0262724 -0.0538883 -0.00492608" rpy="0 -0 0" />
            <inertia ixx="0.0218682" ixy="0.00391013" ixz="0.000486362" iyy="0.0241767" iyz="-0.00048662" izz="0.01661" />
        </inertial>
        <visual>
            <origin xyz="0 -0.0746375 0" rpy="0 -0 0" />
            <geometry>
                <box size="0.15 0.149275 0.15995" />
            </geometry>
            <material name="Cyan">
                <texture />
                <color rgba="0 1 1 0.5" />
            </material>
        </visual>
    </link>
    <link name="human_abdomen_COM">
        <visual>
            <origin xyz="0 0 0" rpy="0 -0 0" />
            <geometry>
                <sphere radius="0.015" />
            </geometry>
            <material name="Red">
                <texture />
                <color rgba="1 0 0 1" />
            </material>
        </visual>
    </link>
    <link name="human_abdomen_virtual_1" />
    <link name="human_abdomen_virtual_2" />
    <link name="human_head">
        <inertial>
            <mass value="5.36" />
            <origin xyz="0.005495 0.146716 0.00027475" rpy="0 -0 0" />
            <inertia ixx="0.151794" ixy="-0.00233867" ixz="0.000153753" iyy="0.023468" iyz="0.000148088" izz="0.154423" />
        </inertial>
        <visual>
            <origin xyz="0 0.0686875 0" rpy="0 -0 0" />
            <geometry>
                <sphere radius="0.0755563" />
            </geometry>
            <material name="Cyan">
                <texture />
                <color rgba="0 1 1 0.5" />
            </material>
        </visual>
    </link>
    <link name="human_head_COM">
        <visual>
            <origin xyz="0 0 0" rpy="0 -0 0" />
            <geometry>
                <sphere radius="0.015" />
            </geometry>
            <material name="Red">
                <texture />
                <color rgba="1 0 0 1" />
            </material>
        </visual>
    </link>
    <link name="human_head_virtual_1" />
    <link name="human_head_virtual_2" />
    <link name="human_left_clavicle" />
    <link name="human_left_foot">
        <inertial>
            <mass value="0.96" />
            <origin xyz="0.0689623 -0.0273376 -0.00467075" rpy="0 -0 0" />
            <inertia ixx="0.00161526" ixy="0.00233344" ixz="9.00053e-05" iyy="0.0089364" iyz="-0.00012258" izz="0.00945717" />
        </inertial>
        <visual>
            <origin xyz="0.0686875 -0.015 0" rpy="0 -0 0" />
            <geometry>
                <box size="0.137375 0.03 0.08" />
            </geometry>
            <material name="Cyan">
                <texture />
                <color rgba="0 1 1 0.5" />
            </material>
        </visual>
    </link>
    <link name="human_left_foot_COM">
        <visual>
            <origin xyz="0 0 0" rpy="0 -0 0" />
            <geometry>
                <sphere radius="0.015" />
            </geometry>
            <material name="Red">
                <texture />
                <color rgba="1 0 0 1" />
            </material>
        </visual>
    </link>
    <link name="human_left_foot_virtual_1" />
    <link name="human_left_hand">
        <inertial>
            <mass value="0.48" />
            <origin xyz="0.00647185 -0.0662181 -0.00591937" rpy="0 -0 0" />
            <inertia ixx="0.00323412" ixy="0.000350421" ixz="-4.88864e-05" iyy="0.000468679" iyz="-0.000307745" izz="0.00306249" />
        </inertial>
        <visual>
            <origin xyz="0 -0.0394625 0" rpy="0 -0 0" />
            <geometry>
                <box size="0.03 0.078925 0.06" />
            </geometry>
            <material name="Cyan">
                <texture />
                <color rgba="0 1 1 0.5" />
            </material>
        </visual>
    </link>
    <link name="human_left_hand_COM">
        <visual>
            <origin xyz="0 0 0" rpy="0 -0 0" />
            <geometry>
                <sphere radius="0.015" />
            </geometry>
            <material name="Red">
                <texture />
                <color rgba="1 0 0 1" />
            </material>
        </visual>
    </link>
    <link name="human_left_hand_virtual_1" />
    <link name="human_left_lowerarm">
        <inertial>
            <mass value="1.36" />
            <origin xyz="-0.00363545 -0.116614 -0.00307615" rpy="0 -0 0" />
            <inertia ixx="0.0268457" ixy="0.000104124" ixz="-2.58449e-05" iyy="0.00131777" iyz="-0.000530405" izz="0.0268508" />
        </inertial>
        <visual>
            <origin xyz="0 -0.139825 0" rpy="1.5708 -0 0" />
            <geometry>
                <cylinder radius="0.025" length="0.27965" />
            </geometry>
            <material name="Cyan">
                <texture />
                <color rgba="0 1 1 0.5" />
            </material>
        </visual>
    </link>
    <link name="human_left_lowerarm_COM">
        <visual>
            <origin xyz="0 0 0" rpy="0 -0 0" />
            <geometry>
                <sphere radius="0.015" />
            </geometry>
            <material name="Red">
                <texture />
                <color rgba="1 0 0 1" />
            </material>
        </visual>
    </link>
    <link name="human_left_lowerarm_virtual_1" />
    <link name="human_left_lowerleg">
        <inertial>
            <mass value="3.84" />
            <origin xyz="-0.0205464 -0.175501 -0.00299635" rpy="0 -0 0" />
            <inertia ixx="0.17347" ixy="-0.0127209" ixz="-0.000517843" iyy="0.00869146" iyz="-0.00314505" izz="0.175056" />
        </inertial>
        <visual>
            <origin xyz="0 -0.214025 0" rpy="1.5708 -0 0" />
            <geometry>
                <cylinder radius="0.04" length="0.42805" />
            </geometry>
            <material name="Cyan">
                <texture />
                <color rgba="0 1 1 0.5" />
            </material>
        </visual>
    </link>
    <link name="human_left_lowerleg_COM">
        <visual>
            <origin xyz="0 0 0" rpy="0 -0 0" />
            <geometry>
                <sphere radius="0.015" />
            </geometry>
            <material name="Red">
                <texture />
                <color rgba="1 0 0 1" />
            </material>
        </visual>
    </link>
    <link name="human_left_upperarm">
        <inertial>
            <mass value="1.92" />
            <origin xyz="0.0049266 -0.131923 0.0084847" rpy="0 -0 0" />
            <inertia ixx="0.0456496" ixy="0.00160745" ixz="-0.000209705" iyy="0.00261556" iyz="-0.00028162" izz="0.0464066" />
        </inertial>
        <visual>
            <origin xyz="0 -0.13685 0" rpy="1.5708 -0 0" />
            <geometry>
                <cylinder radius="0.035" length="0.2737" />
            </geometry>
            <material name="Cyan">
                <texture />
                <color rgba="0 1 1 0.5" />
            </material>
        </visual>
    </link>
    <link name="human_left_upperarm_COM">
        <visual>
            <origin xyz="0 0 0" rpy="0 -0 0" />
            <geometry>
                <sphere radius="0.015" />
            </geometry>
            <material name="Red">
                <texture />
                <color rgba="1 0 0 1" />
            </material>
        </visual>
    </link>
    <link name="human_left_upperarm_virtual_1" />
    <link name="human_left_upperarm_virtual_2" />
    <link name="human_left_upperleg">
        <inertial>
            <mass value="9.84" />
            <origin xyz="-0.017507 -0.183183 0.014091" rpy="0 -0 0" />
            <inertia ixx="0.48303" ixy="-0.0227656" ixz="0.00170979" iyy="0.0453373" iyz="0.0166081" izz="0.494678" />
        </inertial>
        <visual>
            <origin xyz="0 -0.2135 0" rpy="1.5708 -0 0" />
            <geometry>
                <cylinder radius="0.05" length="0.427" />
            </geometry>
            <material name="Cyan">
                <texture />
                <color rgba="0 1 1 0.5" />
            </material>
        </visual>
    </link>
    <link name="human_left_upperleg_COM">
        <visual>
            <origin xyz="0 0 0" rpy="0 -0 0" />
            <geometry>
                <sphere radius="0.015" />
            </geometry>
            <material name="Red">
                <texture />
                <color rgba="1 0 0 1" />
            </material>
        </visual>
    </link>
    <link name="human_left_upperleg_virtual_1" />
    <link name="human_left_upperleg_virtual_2" />
    <link name="human_pelvis">
        <inertial>
            <mass value="11.36" />
            <origin xyz="-0.00018375 -0.02646 -0.00055125" rpy="0 -0 0" />
            <inertia ixx="0.107721" ixy="0.00546803" ixz="0.00137966" iyy="0.107746" iyz="0.000447998" izz="0.096326" />
        </inertial>
        <visual>
            <origin xyz="0 -0.0459375 0" rpy="0 -0 0" />
            <geometry>
                <box size="0.15 0.091875 0.25995" />
            </geometry>
            <material name="Cyan">
                <texture />
                <color rgba="0 1 1 0.5" />
            </material>
        </visual>
    </link>
    <link name="human_pelvis_COM">
        <visual>
            <origin xyz="0 0 0" rpy="0 -0 0" />
            <geometry>
                <sphere radius="0.015" />
            </geometry>
            <material name="Red">
                <texture />
                <color rgba="1 0 0 1" />
            </material>
        </visual>
    </link>
    <link name="human_right_clavicle" />
    <link name="human_right_foot">
        <inertial>
            <mass value="0.96" />
            <origin xyz="0.0689623 -0.0273376 0.00467075" rpy="0 -0 0" />
            <inertia ixx="0.00161526" ixy="0.00233344" ixz="-9.00053e-05" iyy="0.0089364" iyz="0.00012258" izz="0.00945717" />
        </inertial>
        <visual>
            <origin xyz="0.0686875 -0.015 0" rpy="0 -0 0" />
            <geometry>
                <box size="0.137375 0.03 0.08" />
            </geometry>
            <material name="Cyan">
                <texture />
                <color rgba="0 1 1 0.5" />
            </material>
        </visual>
    </link>
    <link name="human_right_foot_COM">
        <visual>
            <origin xyz="0 0 0" rpy="0 -0 0" />
            <geometry>
                <sphere radius="0.015" />
            </geometry>
            <material name="Red">
                <texture />
                <color rgba="1 0 0 1" />
            </material>
        </visual>
    </link>
    <link name="human_right_foot_virtual_1" />
    <link name="human_right_hand">
        <inertial>
            <mass value="0.48" />
            <origin xyz="0.00647185 -0.0662181 0.00591937" rpy="0 -0 0" />
            <inertia ixx="0.00323412" ixy="0.000350421" ixz="4.88864e-05" iyy="0.000468679" iyz="0.000307745" izz="0.00306249" />
        </inertial>
        <visual>
            <origin xyz="0 -0.0394625 0" rpy="0 -0 0" />
            <geometry>
                <box size="0.03 0.078925 0.06" />
            </geometry>
            <material name="Cyan">
                <texture />
                <color rgba="0 1 1 0.5" />
            </material>
        </visual>
    </link>
    <link name="human_right_hand_COM">
        <visual>
            <origin xyz="0 0 0" rpy="0 -0 0" />
            <geometry>
                <sphere radius="0.015" />
            </geometry>
            <material name="Red">
                <texture />
                <color rgba="1 0 0 1" />
            </material>
        </visual>
    </link>
    <link name="human_right_hand_virtual_1" />
    <link name="human_right_lowerarm">
        <inertial>
            <mass value="1.36" />
            <origin xyz="-0.00363545 -0.116614 0.00307615" rpy="0 -0 0" />
            <inertia ixx="0.0268457" ixy="0.000104124" ixz="2.58449e-05" iyy="0.00131777" iyz="0.000530405" izz="0.0268508" />
        </inertial>
        <visual>
            <origin xyz="0 -0.139825 0" rpy="1.5708 -0 0" />
            <geometry>
                <cylinder radius="0.025" length="0.27965" />
            </geometry>
            <material name="Cyan">
                <texture />
                <color rgba="0 1 1 0.5" />
            </material>
        </visual>
    </link>
    <link name="human_right_lowerarm_COM">
        <visual>
            <origin xyz="0 0 0" rpy="0 -0 0" />
            <geometry>
                <sphere radius="0.015" />
            </geometry>
            <material name="Red">
                <texture />
                <color rgba="1 0 0 1" />
            </material>
        </visual>
    </link>
    <link name="human_right_lowerarm_virtual_1" />
    <link name="human_right_lowerleg">
        <inertial>
            <mass value="3.84" />
            <origin xyz="-0.0205464 -0.175501 0.00299635" rpy="0 -0 0" />
            <inertia ixx="0.17347" ixy="-0.0127209" ixz="0.000517843" iyy="0.00869146" iyz="0.00314505" izz="0.175056" />
        </inertial>
        <visual>
            <origin xyz="0 -0.214025 0" rpy="1.5708 -0 0" />
            <geometry>
                <cylinder radius="0.04" length="0.42805" />
            </geometry>
            <material name="Cyan">
                <texture />
                <color rgba="0 1 1 0.5" />
            </material>
        </visual>
    </link>
    <link name="human_right_lowerleg_COM">
        <visual>
            <origin xyz="0 0 0" rpy="0 -0 0" />
            <geometry>
                <sphere radius="0.015" />
            </geometry>
            <material name="Red">
                <texture />
                <color rgba="1 0 0 1" />
            </material>
        </visual>
    </link>
    <link name="human_right_upperarm">
        <inertial>
            <mass value="1.92" />
            <origin xyz="0.0049266 -0.131923 -0.0084847" rpy="0 -0 0" />
            <inertia ixx="0.0456496" ixy="0.00160745" ixz="0.000209705" iyy="0.00261556" iyz="0.00028162" izz="0.0464066" />
        </inertial>
        <visual>
            <origin xyz="0 -0.13685 0" rpy="1.5708 -0 0" />
            <geometry>
                <cylinder radius="0.035" length="0.2737" />
            </geometry>
            <material name="Cyan">
                <texture />
                <color rgba="0 1 1 0.5" />
            </material>
        </visual>
    </link>
    <link name="human_right_upperarm_COM">
        <visual>
            <origin xyz="0 0 0" rpy="0 -0 0" />
            <geometry>
                <sphere radius="0.015" />
            </geometry>
            <material name="Red">
                <texture />
                <color rgba="1 0 0 1" />
            </material>
        </visual>
    </link>
    <link name="human_right_upperarm_virtual_1" />
    <link name="human_right_upperarm_virtual_2" />
    <link name="human_right_upperleg">
        <inertial>
            <mass value="9.84" />
            <origin xyz="-0.017507 -0.183183 -0.014091" rpy="0 -0 0" />
            <inertia ixx="0.48303" ixy="-0.0227656" ixz="-0.00170979" iyy="0.0453373" iyz="-0.0166081" izz="0.494678" />
        </inertial>
        <visual>
            <origin xyz="0 -0.2135 0" rpy="1.5708 -0 0" />
            <geometry>
                <cylinder radius="0.05" length="0.427" />
            </geometry>
            <material name="Cyan">
                <texture />
                <color rgba="0 1 1 0.5" />
            </material>
        </visual>
    </link>
    <link name="human_right_upperleg_COM">
        <visual>
            <origin xyz="0 0 0" rpy="0 -0 0" />
            <geometry>
                <sphere radius="0.015" />
            </geometry>
            <material name="Red">
                <texture />
                <color rgba="1 0 0 1" />
            </material>
        </visual>
    </link>
    <link name="human_right_upperleg_virtual_1" />
    <link name="human_right_upperleg_virtual_2" />
    <link name="human_thorax">
        <inertial>
            <mass value="24.32" />
            <origin xyz="0 -0.183275 -0.0013209" rpy="0 -0 0" />
            <inertia ixx="1.28477" ixy="0.0320899" ixz="0.000265206" iyy="0.288852" iyz="-0.00350072" izz="1.16061" />
        </inertial>
        <visual>
            <origin xyz="0 -0.165112 0" rpy="0 -0 0" />
            <geometry>
                <box size="0.15 0.330225 0.3374" />
            </geometry>
            <material name="Cyan">
                <texture />
                <color rgba="0 1 1 0.5" />
            </material>
        </visual>
    </link>
    <link name="human_thorax_COM">
        <visual>
            <origin xyz="0 0 0" rpy="0 -0 0" />
            <geometry>
                <sphere radius="0.015" />
            </geometry>
            <material name="Red">
                <texture />
                <color rgba="1 0 0 1" />
            </material>
        </visual>
    </link>
    <link name="human_thorax_virtual_1" />
    <link name="human_thorax_virtual_2" />
    <link name="human_thorax_virtual_3" />
    <joint name="base_link_to_human_pelvis_fixed" type="fixed">
        <origin xyz="0 0 0" rpy="1.5708 -0 0" />
        <axis xyz="0 0 0" />
        <parent link="base_link" />
        <child link="human_pelvis" />
    </joint>
    <joint name="human_abdomen_COM" type="fixed">
        <origin xyz="0.0262724 -0.0538883 -0.00492608" rpy="0 -0 0" />
        <axis xyz="0 0 0" />
        <parent link="human_abdomen" />
        <child link="human_abdomen_COM" />
        <limit effort="0" velocity="0" lower="0" upper="0" />
    </joint>
    <joint name="human_abdomen_fixed" type="fixed">
        <origin xyz="0 0.149275 0" rpy="0 -0 0" />
        <axis xyz="0 0 0" />
        <parent link="human_abdomen_virtual_2" />
        <child link="human_abdomen" />
    </joint>
    <joint name="human_cervical_X" type="revolute">
        <origin xyz="0 0 0" rpy="0 -0 0" />
        <axis xyz="1 0 0" />
        <parent link="human_head_virtual_1" />
        <child link="human_head_virtual_2" />
        <limit effort="0" velocity="0" lower="-1.0472" upper="1.0472" />
    </joint>
    <joint name="human_cervical_Y" type="revolute">
        <origin xyz="0 0 0" rpy="0 -0 0" />
        <axis xyz="0 1 0" />
        <parent link="human_head_virtual_2" />
        <child link="human_head" />
        <limit effort="0" velocity="0" lower="-1.5708" upper="1.5708" />
    </joint>
    <joint name="human_cervical_Z" type="revolute">
        <origin xyz="0 0 0" rpy="0 -0 0" />
        <axis xyz="0 0 1" />
        <parent link="human_thorax" />
        <child link="human_head_virtual_1" />
        <limit effort="0" velocity="0" lower="-1.5708" upper="1.5708" />
    </joint>
    <joint name="human_head_COM" type="fixed">
        <origin xyz="0.005495 0.146716 0.00027475" rpy="0 -0 0" />
        <axis xyz="0 0 0" />
        <parent link="human_head" />
        <child link="human_head_COM" />
        <limit effort="0" velocity="0" lower="0" upper="0" />
    </joint>
    <joint name="human_left_ankle_X" type="revolute">
        <origin xyz="0 0 0" rpy="0 -0 0" />
        <axis xyz="-1 0 0" />
        <parent link="human_left_foot_virtual_1" />
        <child link="human_left_foot" />
        <limit effort="0" velocity="0" lower="0" upper="0.785398" />
    </joint>
    <joint name="human_left_ankle_Z" type="revolute">
        <origin xyz="0 -0.42805 0" rpy="0 -0 0" />
        <axis xyz="0 0 1" />
        <parent link="human_left_lowerleg" />
        <child link="human_left_foot_virtual_1" />
        <limit effort="0" velocity="0" lower="-1.0472" upper="0.392699" />
    </joint>
    <joint name="human_left_clavicle_joint_X" type="revolute">
        <origin xyz="0 0 0" rpy="0 -0 0" />
        <axis xyz="1 0 0" />
        <parent link="human_thorax" />
        <child link="human_left_clavicle" />
        <limit effort="0" velocity="0" lower="-1.0472" upper="0.314159" />
    </joint>
    <joint name="human_left_elbow_Y" type="revolute">
        <origin xyz="0 0 0" rpy="0 -0 0" />
        <axis xyz="0 -1 0" />
        <parent link="human_left_lowerarm_virtual_1" />
        <child link="human_left_lowerarm" />
        <limit effort="0" velocity="0" lower="-1.5708" upper="1.5708" />
    </joint>
    <joint name="human_left_elbow_Z" type="revolute">
        <origin xyz="0 -0.2737 0" rpy="0 -0 0" />
        <axis xyz="0 0 1" />
        <parent link="human_left_upperarm" />
        <child link="human_left_lowerarm_virtual_1" />
        <limit effort="0" velocity="0" lower="0" upper="2.74889" />
    </joint>
    <joint name="human_left_foot_COM" type="fixed">
        <origin xyz="0.0689623 -0.0273376 -0.00467075" rpy="0 -0 0" />
        <axis xyz="0 0 0" />
        <parent link="human_left_foot" />
        <child link="human_left_foot_COM" />
        <limit effort="0" velocity="0" lower="0" upper="0" />
    </joint>
    <joint name="human_left_hand_COM" type="fixed">
        <origin xyz="0.00647185 -0.0662181 -0.00591937" rpy="0 -0 0" />
        <axis xyz="0 0 0" />
        <parent link="human_left_hand" />
        <child link="human_left_hand_COM" />
        <limit effort="0" velocity="0" lower="0" upper="0" />
    </joint>
    <joint name="human_left_hip_X" type="revolute">
        <origin xyz="0 0 0" rpy="0 -0 0" />
        <axis xyz="-1 0 0" />
        <parent link="human_left_upperleg_virtual_1" />
        <child link="human_left_upperleg_virtual_2" />
        <limit effort="0" velocity="0" lower="-0.392699" upper="1.5708" />
    </joint>
    <joint name="human_left_hip_Y" type="revolute">
        <origin xyz="0 0 0" rpy="0 -0 0" />
        <axis xyz="0 -1 0" />
        <parent link="human_left_upperleg_virtual_2" />
        <child link="human_left_upperleg" />
        <limit effort="0" velocity="0" lower="-1.5708" upper="1.5708" />
    </joint>
    <joint name="human_left_hip_Z" type="revolute">
        <origin xyz="0.053375 -0.0749 -0.079975" rpy="0 -0 0" />
        <axis xyz="0 0 1" />
        <parent link="human_pelvis" />
        <child link="human_left_upperleg_virtual_1" />
        <limit effort="0" velocity="0" lower="-0.785398" upper="3.14159" />
    </joint>
    <joint name="human_left_knee_Z" type="revolute">
        <origin xyz="0 -0.427 0" rpy="0 -0 0" />
        <axis xyz="0 0 -1" />
        <parent link="human_left_upperleg" />
        <child link="human_left_lowerleg" />
        <limit effort="0" velocity="0" lower="0" upper="2.74889" />
    </joint>
    <joint name="human_left_lowerarm_COM" type="fixed">
        <origin xyz="-0.00363545 -0.116614 -0.00307615" rpy="0 -0 0" />
        <axis xyz="0 0 0" />
        <parent link="human_left_lowerarm" />
        <child link="human_left_lowerarm_COM" />
        <limit effort="0" velocity="0" lower="0" upper="0" />
    </joint>
    <joint name="human_left_lowerleg_COM" type="fixed">
        <origin xyz="-0.0205464 -0.175501 -0.00299635" rpy="0 -0 0" />
        <axis xyz="0 0 0" />
        <parent link="human_left_lowerleg" />
        <child link="human_left_lowerleg_COM" />
        <limit effort="0" velocity="0" lower="0" upper="0" />
    </joint>
    <joint name="human_left_shoulder_X" type="revolute">
        <origin xyz="0 0 0" rpy="0 -0 0" />
        <axis xyz="-1 0 0" />
        <parent link="human_left_upperarm_virtual_1" />
        <child link="human_left_upperarm_virtual_2" />
        <limit effort="0" velocity="0" lower="-3.14159" upper="1.0472" />
    </joint>
    <joint name="human_left_shoulder_Y" type="revolute">
        <origin xyz="0.00805 -0.0728 -0.2037" rpy="0 -0 0" />
        <axis xyz="0 -1 0" />
        <parent link="human_left_clavicle" />
        <child link="human_left_upperarm_virtual_1" />
        <limit effort="0" velocity="0" lower="-2.0944" upper="0.392699" />
    </joint>
    <joint name="human_left_shoulder_Z" type="revolute">
        <origin xyz="0 0 0" rpy="0 -0 0" />
        <axis xyz="0 0 1" />
        <parent link="human_left_upperarm_virtual_2" />
        <child link="human_left_upperarm" />
        <limit effort="0" velocity="0" lower="-1.5708" upper="3.14159" />
    </joint>
    <joint name="human_left_upperarm_COM" type="fixed">
        <origin xyz="0.0049266 -0.131923 0.0084847" rpy="0 -0 0" />
        <axis xyz="0 0 0" />
        <parent link="human_left_upperarm" />
        <child link="human_left_upperarm_COM" />
        <limit effort="0" velocity="0" lower="0" upper="0" />
    </joint>
    <joint name="human_left_upperleg_COM" type="fixed">
        <origin xyz="-0.017507 -0.183183 0.014091" rpy="0 -0 0" />
        <axis xyz="0 0 0" />
        <parent link="human_left_upperleg" />
        <child link="human_left_upperleg_COM" />
        <limit effort="0" velocity="0" lower="0" upper="0" />
    </joint>
    <joint name="human_left_wrist_X" type="revolute">
        <origin xyz="0 0 0" rpy="0 -0 0" />
        <axis xyz="-1 0 0" />
        <parent link="human_left_hand_virtual_1" />
        <child link="human_left_hand" />
        <limit effort="0" velocity="0" lower="-0.785398" upper="0.785398" />
    </joint>
    <joint name="human_left_wrist_Z" type="revolute">
        <origin xyz="0 -0.27965 0" rpy="0 -0 0" />
        <axis xyz="0 0 1" />
        <parent link="human_left_lowerarm" />
        <child link="human_left_hand_virtual_1" />
        <limit effort="0" velocity="0" lower="-1.5708" upper="1.5708" />
    </joint>
    <joint name="human_lumbar_X" type="revolute">
        <origin xyz="0 0 0" rpy="0 -0 0" />
        <axis xyz="1 0 0" />
        <parent link="human_abdomen_virtual_1" />
        <child link="human_abdomen_virtual_2" />
        <limit effort="0" velocity="0" lower="-0.785398" upper="0.785398" />
    </joint>
    <joint name="human_lumbar_Z" type="revolute">
        <origin xyz="0 0 0" rpy="0 -0 0" />
        <axis xyz="0 0 1" />
        <parent link="human_pelvis" />
        <child link="human_abdomen_virtual_1" />
        <limit effort="0" velocity="0" lower="-3.14159" upper="0.785398" />
    </joint>
    <joint name="human_pelvis_COM" type="fixed">
        <origin xyz="-0.00018375 -0.02646 -0.00055125" rpy="0 -0 0" />
        <axis xyz="0 0 0" />
        <parent link="human_pelvis" />
        <child link="human_pelvis_COM" />
        <limit effort="0" velocity="0" lower="0" upper="0" />
    </joint>
    <joint name="human_right_ankle_X" type="revolute">
        <origin xyz="0 0 0" rpy="0 -0 0" />
        <axis xyz="1 0 0" />
        <parent link="human_right_foot_virtual_1" />
        <child link="human_right_foot" />
        <limit effort="0" velocity="0" lower="0" upper="0.785398" />
    </joint>
    <joint name="human_right_ankle_Z" type="revolute">
        <origin xyz="0 -0.42805 0" rpy="0 -0 0" />
        <axis xyz="0 0 1" />
        <parent link="human_right_lowerleg" />
        <child link="human_right_foot_virtual_1" />
        <limit effort="0" velocity="0" lower="-1.0472" upper="0.392699" />
    </joint>
    <joint name="human_right_clavicle_joint_X" type="revolute">
        <origin xyz="0 0 0" rpy="0 -0 0" />
        <axis xyz="-1 0 0" />
        <parent link="human_thorax" />
        <child link="human_right_clavicle" />
        <limit effort="0" velocity="0" lower="-1.0472" upper="0.314159" />
    </joint>
    <joint name="human_right_elbow_Y" type="revolute">
        <origin xyz="0 0 0" rpy="0 -0 0" />
        <axis xyz="0 1 0" />
        <parent link="human_right_lowerarm_virtual_1" />
        <child link="human_right_lowerarm" />
        <limit effort="0" velocity="0" lower="-1.5708" upper="1.5708" />
    </joint>
    <joint name="human_right_elbow_Z" type="revolute">
        <origin xyz="0 -0.2737 0" rpy="0 -0 0" />
        <axis xyz="0 0 1" />
        <parent link="human_right_upperarm" />
        <child link="human_right_lowerarm_virtual_1" />
        <limit effort="0" velocity="0" lower="0" upper="2.74889" />
    </joint>
    <joint name="human_right_foot_COM" type="fixed">
        <origin xyz="0.0689623 -0.0273376 0.00467075" rpy="0 -0 0" />
        <axis xyz="0 0 0" />
        <parent link="human_right_foot" />
        <child link="human_right_foot_COM" />
        <limit effort="0" velocity="0" lower="0" upper="0" />
    </joint>
    <joint name="human_right_hand_COM" type="fixed">
        <origin xyz="0.00647185 -0.0662181 0.00591937" rpy="0 -0 0" />
        <axis xyz="0 0 0" />
        <parent link="human_right_hand" />
        <child link="human_right_hand_COM" />
        <limit effort="0" velocity="0" lower="0" upper="0" />
    </joint>
    <joint name="human_right_hip_X" type="revolute">
        <origin xyz="0 0 0" rpy="0 -0 0" />
        <axis xyz="1 0 0" />
        <parent link="human_right_upperleg_virtual_1" />
        <child link="human_right_upperleg_virtual_2" />
        <limit effort="0" velocity="0" lower="-0.392699" upper="1.5708" />
    </joint>
    <joint name="human_right_hip_Y" type="revolute">
        <origin xyz="0 0 0" rpy="0 -0 0" />
        <axis xyz="0 1 0" />
        <parent link="human_right_upperleg_virtual_2" />
        <child link="human_right_upperleg" />
        <limit effort="0" velocity="0" lower="-1.5708" upper="1.5708" />
    </joint>
    <joint name="human_right_hip_Z" type="revolute">
        <origin xyz="0.053375 -0.0749 0.079975" rpy="0 -0 0" />
        <axis xyz="0 0 1" />
        <parent link="human_pelvis" />
        <child link="human_right_upperleg_virtual_1" />
        <limit effort="0" velocity="0" lower="-0.785398" upper="3.14159" />
    </joint>
    <joint name="human_right_knee_Z" type="revolute">
        <origin xyz="0 -0.427 0" rpy="0 -0 0" />
        <axis xyz="0 0 -1" />
        <parent link="human_right_upperleg" />
        <child link="human_right_lowerleg" />
        <limit effort="0" velocity="0" lower="0" upper="2.74889" />
    </joint>
    <joint name="human_right_lowerarm_COM" type="fixed">
        <origin xyz="-0.00363545 -0.116614 0.00307615" rpy="0 -0 0" />
        <axis xyz="0 0 0" />
        <parent link="human_right_lowerarm" />
        <child link="human_right_lowerarm_COM" />
        <limit effort="0" velocity="0" lower="0" upper="0" />
    </joint>
    <joint name="human_right_lowerleg_COM" type="fixed">
        <origin xyz="-0.0205464 -0.175501 0.00299635" rpy="0 -0 0" />
        <axis xyz="0 0 0" />
        <parent link="human_right_lowerleg" />
        <child link="human_right_lowerleg_COM" />
        <limit effort="0" velocity="0" lower="0" upper="0" />
    </joint>
    <joint name="human_right_shoulder_X" type="revolute">
        <origin xyz="0 0 0" rpy="0 -0 0" />
        <axis xyz="1 0 0" />
        <parent link="human_right_upperarm_virtual_1" />
        <child link="human_right_upperarm_virtual_2" />
        <limit effort="0" velocity="0" lower="-3.14159" upper="1.0472" />
    </joint>
    <joint name="human_right_shoulder_Y" type="revolute">
        <origin xyz="0.00805 -0.0728 0.2037" rpy="0 -0 0" />
        <axis xyz="0 1 0" />
        <parent link="human_right_clavicle" />
        <child link="human_right_upperarm_virtual_1" />
        <limit effort="0" velocity="0" lower="-2.0944" upper="0.392699" />
    </joint>
    <joint name="human_right_shoulder_Z" type="revolute">
        <origin xyz="0 0 0" rpy="0 -0 0" />
        <axis xyz="0 1 0" />
        <parent link="human_right_upperarm_virtual_2" />
        <child link="human_right_upperarm" />
        <limit effort="0" velocity="0" lower="-1.5708" upper="3.14159" />
    </joint>
    <joint name="human_right_upperarm_COM" type="fixed">
        <origin xyz="0.0049266 -0.131923 -0.0084847" rpy="0 -0 0" />
        <axis xyz="0 0 0" />
        <parent link="human_right_upperarm" />
        <child link="human_right_upperarm_COM" />
        <limit effort="0" velocity="0" lower="0" upper="0" />
    </joint>
    <joint name="human_right_upperleg_COM" type="fixed">
        <origin xyz="-0.017507 -0.183183 -0.014091" rpy="0 -0 0" />
        <axis xyz="0 0 0" />
        <parent link="human_right_upperleg" />
        <child link="human_right_upperleg_COM" />
        <limit effort="0" velocity="0" lower="0" upper="0" />
    </joint>
    <joint name="human_right_wrist_X" type="revolute">
        <origin xyz="0 0 0" rpy="0 -0 0" />
        <axis xyz="1 0 0" />
        <parent link="human_right_hand_virtual_1" />
        <child link="human_right_hand" />
        <limit effort="0" velocity="0" lower="-0.785398" upper="0.785398" />
    </joint>
    <joint name="human_right_wrist_Z" type="revolute">
        <origin xyz="0 -0.27965 0" rpy="0 -0 0" />
        <axis xyz="0 0 1" />
        <parent link="human_right_lowerarm" />
        <child link="human_right_hand_virtual_1" />
        <limit effort="0" velocity="0" lower="-1.5708" upper="1.5708" />
    </joint>
    <joint name="human_thoracic_X" type="revolute">
        <origin xyz="0 0 0" rpy="0 -0 0" />
        <axis xyz="1 0 0" />
        <parent link="human_thorax_virtual_1" />
        <child link="human_thorax_virtual_2" />
        <limit effort="0" velocity="0" lower="-1.0472" upper="1.0472" />
    </joint>
    <joint name="human_thoracic_Y" type="revolute">
        <origin xyz="0 0 0" rpy="0 -0 0" />
        <axis xyz="0 1 0" />
        <parent link="human_thorax_virtual_2" />
        <child link="human_thorax_virtual_3" />
        <limit effort="0" velocity="0" lower="-1.0472" upper="1.0472" />
    </joint>
    <joint name="human_thoracic_Z" type="revolute">
        <origin xyz="0 0 0" rpy="0 -0 0" />
        <axis xyz="0 0 1" />
        <parent link="human_abdomen" />
        <child link="human_thorax_virtual_1" />
        <limit effort="0" velocity="0" lower="-1.0472" upper="0.392699" />
    </joint>
    <joint name="human_thorax_COM" type="fixed">
        <origin xyz="0 -0.183275 -0.0013209" rpy="0 -0 0" />
        <axis xyz="0 0 0" />
        <parent link="human_thorax" />
        <child link="human_thorax_COM" />
        <limit effort="0" velocity="0" lower="0" upper="0" />
    </joint>
    <joint name="human_thorax_fixed" type="fixed">
        <origin xyz="0 0.330225 0" rpy="0 -0 0" />
        <axis xyz="0 0 0" />
        <parent link="human_thorax_virtual_3" />
        <child link="human_thorax" />
    </joint>
</robot>
