<robot name="human_36dof_ISB_model">
    <material name="body_color">
        <texture />
        <color rgba="0.005 0.005 0.005 0.6" />
    </material>
    <material name="Black">
        <texture />
        <color rgba="0 0 0 1" />
    </material>
    <link name="base_link" />
    <link name="middle_abdomen">
        <inertial>
            <mass value="2.32" />
            <origin xyz="0.0262724 -0.0538883 -0.00492608" rpy="0 -0 0" />
            <inertia ixx="0.0218682" ixy="0.00391013" ixz="0.000486362" iyy="0.0241767" iyz="-0.00048662" izz="0.01661" />
        </inertial>
	    <visual>
            <origin xyz="-0.06 -0.065 -0.085" rpy="0 -0 0" />
            <geometry>
		        <mesh filename="package://human_urdf/meshes/abdomen_mesh.STL" scale="0.0055 0.0055 0.0055"/>
                <!--<box size="0.15 0.161217 0.198658" />-->
            </geometry>
            <material name="body_color">
                <texture />
                <color rgba="0 1 1 0.5" />
            </material>
        </visual>
    </link>
    <link name="middle_abdomen_COM">
        <visual>
            <origin xyz="0 0 0" rpy="0 -0 0" />
            <geometry>
                <sphere radius="0.008" />
            </geometry>
            <material name="Black">
                <texture />
                <color rgba="1 0 0 1" />
            </material>
        </visual>
    </link>
    <link name="middle_abdomen_virtual" />
    <link name="middle_abdomen_virtual_2" />
    <link name="middle_head">
        <inertial>
            <mass value="5.36" />
            <origin xyz="0.005495 0.146716 0.00027475" rpy="0 -0 0" />
            <inertia ixx="0.151794" ixy="-0.00233867" ixz="0.000153753" iyy="0.023468" iyz="0.000148088" izz="0.154423" />
        </inertial>
        <visual>
	        <origin xyz="-0.07 0.04 0.09" rpy="0 1.57 0" />
            <geometry>
		        <mesh filename="package://human_urdf/meshes/head_mesh.STL" scale="0.0055 0.0055 0.0055"/>
            </geometry>
            <material name="body_color">
                <texture />
                <color rgba="0.2 0.2 0.2 0.5" />
            </material>
        </visual>
    </link>
    <link name="middle_head_COM">
        <visual>
            <origin xyz="0 0 0" rpy="0 -0 0" />
            <geometry>
                <sphere radius="0.008" />
            </geometry>
            <material name="Black">
                <texture />
                <color rgba="1 0 0 1" />
            </material>
        </visual>
    </link>
    <link name="middle_head_virtual" >
    <visual>
	    <origin xyz="-0.03 -0.01 -0.045" rpy="0 0.0 0" />
            <geometry>
		<mesh filename="package://human_urdf/meshes/neck_mesh.STL" scale="0.005 0.005 0.005"/>
            </geometry>
            <material name="body_color">
                <texture />
                <color rgba="0.2 0.2 0.2 0.7" />
            </material>
        </visual>
    </link>
    <link name="middle_head_virtual_2" />
    <link name="left_clavicle" />
    <link name="left_foot">
        <inertial>
            <mass value="0.96" />
            <origin xyz="0.0689623 -0.0273376 -0.00467075" rpy="0 -0 0" />
            <inertia ixx="0.00161526" ixy="0.00233344" ixz="9.00053e-05" iyy="0.0089364" iyz="-0.00012258" izz="0.00945717" />
        </inertial>
        <visual>
            <origin xyz="-0.05 -0.055 0.075" rpy="0 1.57 0" />
            <geometry>
		        <mesh filename="package://human_urdf/meshes/foot_mesh.STL" scale="0.0060 0.0060 0.0060"/>
                <!--<box size="0.03 0.085239 0.06" />-->
            </geometry>
            <material name="body_color">
                <texture />
                <color rgba="0 1 1 0.5" />
            </material>
        </visual>
    </link>
    <link name="left_foot_COM">
        <visual>
            <origin xyz="0 0 0" rpy="0 -0 0" />
            <geometry>
                <sphere radius="0.008" />
            </geometry>
            <material name="Black">
                <texture />
                <color rgba="1 0 0 1" />
            </material>
        </visual>
    </link>
    <link name="left_foot_virtual" />
    <link name="left_hand">
        <inertial>
            <mass value="0.48" />
            <origin xyz="0.00647185 -0.0662181 -0.00591937" rpy="0 -0 0" />
            <inertia ixx="0.00323412" ixy="0.000350421" ixz="-4.88864e-05" iyy="0.000468679" iyz="-0.000307745" izz="0.00306249" />
        </inertial>
        <visual>
            <origin xyz="-0.06 -0.15 0.165" rpy="0 1.57 0" />
            <geometry>
		        <mesh filename="package://human_urdf/meshes/hand_mesh.STL" scale="0.0060 0.0060 0.0060"/>
                <!--<box size="0.03 0.085239 0.06" />-->
            </geometry>
            <material name="body_color">
                <texture />
                <color rgba="0 1 1 0.5" />
            </material>
        </visual>
    </link>
    <link name="left_hand_COM">
        <visual>
            <origin xyz="0 0 0" rpy="0 -0 0" />
            <geometry>
                <sphere radius="0.008" />
            </geometry>
            <material name="Black">
                <texture />
                <color rgba="1 0 0 1" />
            </material>
        </visual>
    </link>
    <link name="left_hand_virtual" />
    <link name="left_lowerarm">
        <inertial>
            <mass value="1.36" />
            <origin xyz="-0.00363545 -0.116614 -0.00307615" rpy="0 -0 0" />
            <inertia ixx="0.0268457" ixy="0.000104124" ixz="-2.58449e-05" iyy="0.00131777" iyz="-0.000530405" izz="0.0268508" />
        </inertial>
        <visual>
            <origin xyz="0.052 -0.26 -0.17" rpy="0.0 -1.57 0" />
            <geometry>
                <mesh filename="package://human_urdf/meshes/lowerarm_mesh.STL" scale="0.0060 0.0060 0.0060"/>
            </geometry>
            <material name="body_color">
                <texture />
                <color rgba="0 1 1 0.5" />
            </material>
        </visual>
    </link>
    <link name="left_lowerarm_COM">
        <visual>
            <origin xyz="0 0 0" rpy="0 -0 0" />
            <geometry>
                <sphere radius="0.008" />
            </geometry>
            <material name="Black">
                <texture />
                <color rgba="1 0 0 1" />
            </material>
        </visual>
    </link>
    <link name="left_lowerarm_virtual">
	    <visual>
	        <origin xyz="-0.15 -0.04 -0.035" rpy="0 0 0" />
            <geometry>
		        <mesh filename="package://human_urdf/meshes/elbow_mesh.STL" scale="0.0055 0.0055 0.0055"/>
            </geometry>
            <material name="body_color">
                <texture />
                <color rgba="0 1 1 0.5" />
            </material>
        </visual>
    </link>
    <link name="left_lowerleg">
        <inertial>
            <mass value="3.84" />
            <origin xyz="-0.0205464 -0.175501 -0.00299635" rpy="0 -0 0" />
            <inertia ixx="0.17347" ixy="-0.0127209" ixz="-0.000517843" iyy="0.00869146" iyz="-0.00314505" izz="0.175056" />
        </inertial>
        <visual>
            <origin xyz="-0.06 -0.43 0.08" rpy="0.0 1.57 0" />
            <geometry>
                <mesh filename="package://human_urdf/meshes/lowerleg_mesh.STL" scale="0.0063 0.0065 0.007"/>
            </geometry>
            <material name="body_color">
                <texture />
                <color rgba="0 1 1 0.5" />
            </material>
	    </visual>
    </link>
    <link name="left_lowerleg_COM">
        <visual>
            <origin xyz="0 0 0" rpy="0 -0 0" />
            <geometry>
                <sphere radius="0.008" />
            </geometry>
            <material name="Black">
                <texture />
                <color rgba="1 0 0 1" />
            </material>
        </visual>
    </link>
    <link name="left_upperarm">
        <inertial>
            <mass value="1.92" />
            <origin xyz="0.0049266 -0.131923 0.0084847" rpy="0 -0 0" />
            <inertia ixx="0.0456496" ixy="0.00160745" ixz="-0.000209705" iyy="0.00261556" iyz="-0.00028162" izz="0.0464066" />
        </inertial>
        <visual>
            <origin xyz="0.06 -0.29 -0.175" rpy="0.0 -1.57 0" />
            <geometry>
                <mesh filename="package://human_urdf/meshes/upperarm_mesh.STL" scale="0.0063 0.0060 0.007"/>
            </geometry>
            <material name="body_color"/>
        </visual>
    </link>
    <link name="left_upperarm_COM">
        <visual>
            <origin xyz="0 0 0" rpy="0 -0 0" />
            <geometry>
                <sphere radius="0.008" />
            </geometry>
            <material name="Black">
                <texture />
                <color rgba="1 0 0 1" />
            </material>
        </visual>
    </link>
    <link name="left_upperarm_virtual">
	    <visual>
	        <origin xyz="-0.16 -0.045 -0.045" rpy="0 0 0" />
            <geometry>
		        <mesh filename="package://human_urdf/meshes/shoulder_mesh.STL" scale="0.0055 0.0055 0.0055"/>
            </geometry>
            <material name="body_color">
                <texture />
                <color rgba="0 1 1 0.5" />
            </material>
        </visual>
    </link>
    <link name="left_upperarm_virtual_2" />
    <link name="left_upperleg">
        <inertial>
            <mass value="9.84" />
            <origin xyz="-0.017507 -0.183183 0.014091" rpy="0 -0 0" />
            <inertia ixx="0.48303" ixy="-0.0227656" ixz="0.00170979" iyy="0.0453373" iyz="0.0166081" izz="0.494678" />
        </inertial>
        <visual>
            <origin xyz="-0.1 -0.42 0.085" rpy="0.0 1.57 0" />
            <geometry>
                <mesh filename="package://human_urdf/meshes/upperleg_mesh.STL" scale="0.0063 0.0065 0.007"/>
            </geometry>
            <material name="body_color">
                <texture />
                <color rgba="0 1 1 0.5" />
            </material>
        </visual>
    </link>
    <link name="left_upperleg_COM">
        <visual>
            <origin xyz="0 0 0" rpy="0 -0 0" />
            <geometry>
                <sphere radius="0.008" />
            </geometry>
            <material name="Black">
                <texture />
                <color rgba="1 0 0 1" />
            </material>
        </visual>
    </link>
    <link name="left_upperleg_virtual" />
    <link name="left_upperleg_virtual_2">
	    <visual>
            <origin xyz="-0.04 -0.48 0.080" rpy="0.0 1.57 0" />
            <geometry>
                <mesh filename="package://human_urdf/meshes/knee_mesh.STL" scale="0.006 0.006 0.006"/>
            </geometry>
            <material name="body_color">
                <texture />
                <color rgba="0 1 1 0.5" />
            </material>
        </visual>
    </link>
    <link name="middle_pelvis">
        <inertial>
            <mass value="11.36" />
            <origin xyz="-0.00018375 -0.02646 -0.00055125" rpy="0 -0 0" />
            <inertia ixx="0.107721" ixy="0.00546803" ixz="0.00137966" iyy="0.107746" iyz="0.000447998" izz="0.096326" />
        </inertial>
        <visual>
	        <origin xyz="-0.08 -0.13 0.125" rpy="0 1.57 0" />
            <geometry>
		        <mesh filename="package://human_urdf/meshes/pelvis_mesh.STL" scale="0.006 0.0055 0.0055"/>
            </geometry>
            <material name="body_color">
                <texture />
                <color rgba="0 1 1 0.5" />
            </material>
        </visual>
    </link>
    <link name="middle_pelvis_COM">
        <visual>
            <origin xyz="0 0 0" rpy="0 -0 0" />
            <geometry>
                <sphere radius="0.008" />
            </geometry>
            <material name="Black">
                <texture />
                <color rgba="1 0 0 1" />
            </material>
        </visual>
    </link>
    <link name="right_clavicle" />
    <link name="right_foot">
        <inertial>
            <mass value="0.96" />
            <origin xyz="0.0689623 -0.0273376 0.00467075" rpy="0 -0 0" />
            <inertia ixx="0.00161526" ixy="0.00233344" ixz="-9.00053e-05" iyy="0.0089364" iyz="0.00012258" izz="0.00945717" />
        </inertial>
        <visual>
            <origin xyz="-0.05 -0.055 0.065" rpy="0 1.57 0" />
            <geometry>
		        <mesh filename="package://human_urdf/meshes/foot_mesh.STL" scale="0.0060 0.0060 0.0060"/>
                <!--<box size="0.03 0.085239 0.06" />-->
            </geometry>
            <material name="body_color">
                <texture />
                <color rgba="0 1 1 0.5" />
            </material>
        </visual>
    </link>
    <link name="right_foot_COM">
        <visual>
            <origin xyz="0 0 0" rpy="0 -0 0" />
            <geometry>
                <sphere radius="0.008" />
            </geometry>
            <material name="Black">
                <texture />
                <color rgba="1 0 0 1" />
            </material>
        </visual>
    </link>
    <link name="right_foot_virtual" />
    <link name="right_hand">
        <inertial>
            <mass value="0.48" />
            <origin xyz="0.00647185 -0.0662181 0.00591937" rpy="0 -0 0" />
            <inertia ixx="0.00323412" ixy="0.000350421" ixz="4.88864e-05" iyy="0.000468679" iyz="0.000307745" izz="0.00306249" />
        </inertial>
        <visual>
            <origin xyz="0.06 -0.15 -0.165" rpy="0 -1.57 0" />
            <geometry>
		        <mesh filename="package://human_urdf/meshes/hand_mesh.STL" scale="0.0060 0.0060 0.0060"/>
                <!--<box size="0.03 0.085239 0.06" />-->
            </geometry>
            <material name="body_color">
                <texture />
                <color rgba="0 1 1 0.5" />
            </material>
        </visual>
    </link>
    <link name="right_hand_COM">
        <visual>
            <origin xyz="0 0 0" rpy="0 -0 0" />
            <geometry>
                <sphere radius="0.008" />
            </geometry>
            <material name="Black">
                <texture />
                <color rgba="1 0 0 1" />
            </material>
        </visual>
    </link>
    <link name="right_hand_virtual" />
    <link name="right_lowerarm">
        <inertial>
            <mass value="1.36" />
            <origin xyz="-0.00363545 -0.116614 0.00307615" rpy="0 -0 0" />
            <inertia ixx="0.0268457" ixy="0.000104124" ixz="2.58449e-05" iyy="0.00131777" iyz="0.000530405" izz="0.0268508" />
        </inertial>
        <visual>
            <origin xyz="0.052 -0.26 -0.17" rpy="0.0 -1.57 0" />
            <geometry>
                <mesh filename="package://human_urdf/meshes/lowerarm_mesh.STL" scale="0.0060 0.0060 0.0060"/>
            </geometry>
            <material name="body_color">
                <texture />
                <color rgba="0 1 1 0.5" />
            </material>
        </visual>
    </link>
    <link name="right_lowerarm_COM">
        <visual>
            <origin xyz="0 0 0" rpy="0 -0 0" />
            <geometry>
                <sphere radius="0.008" />
            </geometry>
            <material name="Black">
                <texture />
                <color rgba="1 0 0 1" />
            </material>
        </visual>
    </link>
    <link name="right_lowerarm_virtual">
        <visual>
	        <origin xyz="-0.15 -0.04 -0.035" rpy="0 0 0" />
            <geometry>
		        <mesh filename="package://human_urdf/meshes/elbow_mesh.STL" scale="0.0055 0.0055 0.0055"/>
            </geometry>
            <material name="body_color">
                <texture />
                <color rgba="0 1 1 0.5" />
            </material>
        </visual>
    </link>
    <link name="right_lowerleg">
        <inertial>
            <mass value="3.84" />
            <origin xyz="-0.0205464 -0.175501 0.00299635" rpy="0 -0 0" />
            <inertia ixx="0.17347" ixy="-0.0127209" ixz="0.000517843" iyy="0.00869146" iyz="0.00314505" izz="0.175056" />
        </inertial>
        <visual>
            <origin xyz="-0.06 -0.43 0.07" rpy="0.0 1.57 0" />
            <geometry>
                <mesh filename="package://human_urdf/meshes/lowerleg_mesh.STL" scale="0.0063 0.0065 0.007"/>
            </geometry>
            <material name="body_color">
                <texture />
                <color rgba="0 1 1 0.5" />
            </material>
        </visual>
    </link>
    <link name="right_lowerleg_COM">
        <visual>
            <origin xyz="0 0 0" rpy="0 -0 0" />
            <geometry>
                <sphere radius="0.008" />
            </geometry>
            <material name="Black">
                <texture />
                <color rgba="1 0 0 1" />
            </material>
        </visual>
    </link>
    <link name="right_upperarm">
        <inertial>
            <mass value="1.92" />
            <origin xyz="0.0049266 -0.131923 -0.0084847" rpy="0 -0 0" />
            <inertia ixx="0.0456496" ixy="0.00160745" ixz="0.000209705" iyy="0.00261556" iyz="0.00028162" izz="0.0464066" />
        </inertial>
        <visual>
            <origin xyz="0.06 -0.29 -0.18" rpy="0.0 -1.57 0" />
            <geometry>
                <mesh filename="package://human_urdf/meshes/upperarm_mesh.STL" scale="0.0063 0.0060 0.007"/>
            </geometry>
            <material name="body_color">
                <texture />
                <color rgba="0 1 1 0.5" />
            </material>
        </visual>
    </link>
    <link name="right_upperarm_COM">
        <visual>
            <origin xyz="0 0 0" rpy="0 -0 0" />
            <geometry>
                <sphere radius="0.008" />
            </geometry>
            <material name="Black">
                <texture />
                <color rgba="1 0 0 1" />
            </material>
        </visual>
    </link>
    <link name="right_upperarm_virtual">
        <visual>
	        <origin xyz="-0.15 -0.04 -0.05" rpy="0 0 0" />
            <geometry>
		        <mesh filename="package://human_urdf/meshes/shoulder_mesh.STL" scale="0.0055 0.0055 0.0055"/>
            </geometry>
            <material name="body_color">
                <texture />
                <color rgba="0 1 1 0.5" />
            </material>
        </visual>
    </link>
   <link name="right_upperarm_virtual_2" />
    <link name="right_upperleg">
        <inertial>
            <mass value="12.423" />
            <origin xyz="-0.0189076 -0.197838 -0.0152183" rpy="0 0.0 0" />
            <inertia ixx="0.711301" ixy="-0.0335241" ixz="-0.00251781" iyy="0.0667629" iyz="-0.0244568" izz="0.728452" />
        </inertial>
        <visual>
            <origin xyz="-0.1 -0.42 0.07" rpy="0.0 1.57 0" />
            <geometry>
                <mesh filename="package://human_urdf/meshes/upperleg_mesh.STL" scale="0.0063 0.0065 0.007"/>
            </geometry>
            <material name="body_color">
                <texture />
                <color rgba="0 1 1 0.5" />
            </material>
        </visual>
    </link>
    <link name="right_upperleg_COM">
        <visual>
            <origin xyz="0 0 0" rpy="0 -0 0" />
            <geometry>
                <sphere radius="0.008" />
            </geometry>
            <material name="Black">
                <texture />
                <color rgba="1 0 0 1" />
            </material>
        </visual>
    </link>
    <link name="right_upperleg_virtual" />
    <link name="right_upperleg_virtual_2">
        <visual>
            <origin xyz="-0.04 -0.48 0.07" rpy="0.0 1.57 0" />
            <geometry>
                <mesh filename="package://human_urdf/meshes/knee_mesh.STL" scale="0.006 0.006 0.006"/>
            </geometry>
            <material name="body_color">
                <texture />
                <color rgba="0 1 1 0.5" />
            </material>
        </visual>
    </link>
    <link name="middle_thorax">
        <inertial>
            <mass value="24.32" />
            <origin xyz="0 -0.183275 -0.0013209" rpy="0 -0 0" />
            <inertia ixx="1.28477" ixy="0.0320899" ixz="0.000265206" iyy="0.288852" iyz="-0.00350072" izz="1.16061" />
        </inertial>
        <visual>
            <! -- <origin xyz="0.024 -0.178321 0" rpy="0 -0 0" /> -->
	    <origin xyz="-0.11 -0.32 0.13" rpy="0 1.57 0" />
            <geometry>
		        <!--<box size="0.15 0.356643 0.329994" />-->
		        <mesh filename="package://human_urdf/meshes/torso_mesh.STL" scale="0.0065 0.0065 0.0065"/>
            </geometry>
            <material name="body_color">
                <texture />
                <color rgba="0.2 0.2 0.2 0.2" />
            </material>
        </visual>
    </link>
    <link name="middle_thorax_COM">
        <visual>
            <origin xyz="0 0 0" rpy="0 -0 0" />
            <geometry>
                <sphere radius="0.008" />
            </geometry>
            <material name="Black">
                <texture />
                <color rgba="1 0 0 1" />
            </material>
        </visual>
    </link>
    <link name="middle_thorax_virtual" />
    <link name="middle_thorax_virtual_2" />
    <link name="middle_thorax_virtual_3" />
    <joint name="base_to_pelvis_fixed_joint" type="fixed">
        <origin xyz="0 0 0" rpy="1.5708 -0 0" />
        <axis xyz="0 0 0" />
        <parent link="base_link" />
        <child link="middle_pelvis" />
    </joint>
    <joint name="middle_abdomen_COM_joint" type="fixed">
        <origin xyz="0.0262724 -0.0538883 -0.00492608" rpy="0 -0 0" />
        <axis xyz="0 0 0" />
        <parent link="middle_abdomen" />
        <child link="middle_abdomen_COM" />
        <limit effort="0" velocity="0" lower="0" upper="0" />
    </joint>
    <joint name="middle_abdomen_base_frame" type="fixed">
        <origin xyz="0 0.149275 0" rpy="0 -0 0" />
        <axis xyz="0 0 0" />
        <parent link="middle_abdomen_virtual_2" />
        <child link="middle_abdomen" />
    </joint>
    <joint name="middle_cervical_X" type="revolute">
        <origin xyz="0 0 0" rpy="0 -0 0" />
        <axis xyz="1 0 0" />
        <parent link="middle_head_virtual" />
        <child link="middle_head_virtual_2" />
        <limit effort="0" velocity="0" lower="-1.0472" upper="1.0472" />
    </joint>
    <joint name="middle_cervical_Y" type="revolute">
        <origin xyz="0 0 0" rpy="0 -0 0" />
        <axis xyz="0 1 0" />
        <parent link="middle_head_virtual_2" />
        <child link="middle_head" />
        <limit effort="0" velocity="0" lower="-1.5708" upper="1.5708" />
    </joint>
    <joint name="middle_cervical_Z" type="revolute">
        <origin xyz="0 0 0" rpy="0 -0 0" />
        <axis xyz="0 0 1" />
        <parent link="middle_thorax" />
        <child link="middle_head_virtual" />
        <limit effort="0" velocity="0" lower="-1.5708" upper="1.5708" />
    </joint>
    <joint name="middle_head_COM_joint" type="fixed">
        <origin xyz="0.005495 0.146716 0.00027475" rpy="0 -0 0" />
        <axis xyz="0 0 0" />
        <parent link="middle_head" />
        <child link="middle_head_COM" />
        <limit effort="0" velocity="0" lower="0" upper="0" />
    </joint>
    <joint name="left_ankle_X" type="revolute">
        <origin xyz="0 0 0" rpy="0 -0 0" />
        <axis xyz="-1 0 0" />
        <parent link="left_foot_virtual" />
        <child link="left_foot" />
        <limit effort="0" velocity="0" lower="0" upper="0.785398" />
    </joint>
    <joint name="left_ankle_Z" type="revolute">
        <origin xyz="0 -0.42805 0" rpy="0 -0 0" />
        <axis xyz="0 0 1" />
        <parent link="left_lowerleg" />
        <child link="left_foot_virtual" />
        <limit effort="0" velocity="0" lower="-1.0472" upper="0.392699" />
    </joint>
    <joint name="left_clavicle_joint_X" type="revolute">
        <origin xyz="0 0 0" rpy="0 -0 0" />
        <axis xyz="1 0 0" />
        <parent link="middle_thorax" />
        <child link="left_clavicle" />
        <limit effort="0" velocity="0" lower="-1.0472" upper="0.314159" />
    </joint>
    <joint name="left_elbow_Y" type="revolute">
        <origin xyz="0 0 0" rpy="0 -0 0" />
        <axis xyz="0 -1 0" />
        <parent link="left_lowerarm_virtual" />
        <child link="left_lowerarm" />
        <limit effort="0" velocity="0" lower="-1.5708" upper="1.5708" />
    </joint>
    <joint name="left_elbow_Z" type="revolute">
        <origin xyz="0 -0.2737 0" rpy="0 -0 0" />
        <axis xyz="0 0 1" />
        <parent link="left_upperarm" />
        <child link="left_lowerarm_virtual" />
        <limit effort="0" velocity="0" lower="0" upper="2.74889" />
    </joint>
    <joint name="left_foot_COM_joint" type="fixed">
        <origin xyz="0.0689623 -0.0273376 -0.00467075" rpy="0 -0 0" />
        <axis xyz="0 0 0" />
        <parent link="left_foot" />
        <child link="left_foot_COM" />
        <limit effort="0" velocity="0" lower="0" upper="0" />
    </joint>
    <joint name="left_hand_COM_joint" type="fixed">
        <origin xyz="0.00647185 -0.0662181 -0.00591937" rpy="0 -0 0" />
        <axis xyz="0 0 0" />
        <parent link="left_hand" />
        <child link="left_hand_COM" />
        <limit effort="0" velocity="0" lower="0" upper="0" />
    </joint>
    <joint name="left_hip_X" type="revolute">
        <origin xyz="0 0 0" rpy="0 -0 0" />
        <axis xyz="-1 0 0" />
        <parent link="left_upperleg_virtual" />
        <child link="left_upperleg_virtual_2" />
        <limit effort="0" velocity="0" lower="-0.392699" upper="1.5708" />
    </joint>
    <joint name="left_hip_Y" type="revolute">
        <origin xyz="0 0 0" rpy="0 -0 0" />
        <axis xyz="0 -1 0" />
        <parent link="left_upperleg_virtual_2" />
        <child link="left_upperleg" />
        <limit effort="0" velocity="0" lower="-1.5708" upper="1.5708" />
    </joint>
    <joint name="left_hip_Z" type="revolute">
        <origin xyz="0.053375 -0.0749 -0.079975" rpy="0 -0 0" />
        <axis xyz="0 0 1" />
        <parent link="middle_pelvis" />
        <child link="left_upperleg_virtual" />
        <limit effort="0" velocity="0" lower="-0.785398" upper="3.14159" />
    </joint>
    <joint name="left_knee" type="revolute">
        <origin xyz="0 -0.427 0" rpy="0 -0 0" />
        <axis xyz="0 0 -1" />
        <parent link="left_upperleg" />
        <child link="left_lowerleg" />
        <limit effort="0" velocity="0" lower="0" upper="2.74889" />
    </joint>
    <joint name="left_lowerarm_COM_joint" type="fixed">
        <origin xyz="-0.00363545 -0.116614 -0.00307615" rpy="0 -0 0" />
        <axis xyz="0 0 0" />
        <parent link="left_lowerarm" />
        <child link="left_lowerarm_COM" />
        <limit effort="0" velocity="0" lower="0" upper="0" />
    </joint>
    <joint name="left_lowerleg_COM_joint" type="fixed">
        <origin xyz="-0.0205464 -0.175501 -0.00299635" rpy="0 -0 0" />
        <axis xyz="0 0 0" />
        <parent link="left_lowerleg" />
        <child link="left_lowerleg_COM" />
        <limit effort="0" velocity="0" lower="0" upper="0" />
    </joint>
    <joint name="left_shoulder_X" type="revolute">
        <origin xyz="0 0 0" rpy="0 -0 0" />
        <axis xyz="-1 0 0" />
        <parent link="left_upperarm_virtual" />
        <child link="left_upperarm_virtual_2" />
        <limit effort="0" velocity="0" lower="-3.14159" upper="1.0472" />
    </joint>
    <joint name="left_shoulder_Y" type="revolute">
        <origin xyz="0.00805 -0.0728 -0.2037" rpy="0 -0 0" />
        <axis xyz="0 -1 0" />
        <parent link="left_clavicle" />
        <child link="left_upperarm_virtual" />
        <limit effort="0" velocity="0" lower="-2.0944" upper="0.392699" />
    </joint>
    <joint name="left_shoulder_Z" type="revolute">
        <origin xyz="0 0 0" rpy="0 -0 0" />
        <axis xyz="0 0 1" />
        <parent link="left_upperarm_virtual_2" />
        <child link="left_upperarm" />
        <limit effort="0" velocity="0" lower="-1.5708" upper="3.14159" />
    </joint>
    <joint name="left_upperarm_COM_joint" type="fixed">
        <origin xyz="0.0049266 -0.131923 0.0084847" rpy="0 -0 0" />
        <axis xyz="0 0 0" />
        <parent link="left_upperarm" />
        <child link="left_upperarm_COM" />
        <limit effort="0" velocity="0" lower="0" upper="0" />
    </joint>
    <joint name="left_upperleg_COM_joint" type="fixed">
        <origin xyz="-0.017507 -0.183183 0.014091" rpy="0 -0 0" />
        <axis xyz="0 0 0" />
        <parent link="left_upperleg" />
        <child link="left_upperleg_COM" />
        <limit effort="0" velocity="0" lower="0" upper="0" />
    </joint>
    <joint name="left_wrist_X" type="revolute">
        <origin xyz="0 0 0" rpy="0 -0 0" />
        <axis xyz="-1 0 0" />
        <parent link="left_hand_virtual" />
        <child link="left_hand" />
        <limit effort="0" velocity="0" lower="-0.785398" upper="0.785398" />
    </joint>
    <joint name="left_wrist_Z" type="revolute">
        <origin xyz="0 -0.27965 0" rpy="0 -0 0" />
        <axis xyz="0 0 1" />
        <parent link="left_lowerarm" />
        <child link="left_hand_virtual" />
        <limit effort="0" velocity="0" lower="-1.5708" upper="1.5708" />
    </joint>
    <joint name="middle_lumbar_X" type="revolute">
        <origin xyz="0 0 0" rpy="0 -0 0" />
        <axis xyz="1 0 0" />
        <parent link="middle_abdomen_virtual" />
        <child link="middle_abdomen_virtual_2" />
        <limit effort="0" velocity="0" lower="-0.785398" upper="0.785398" />
    </joint>
    <joint name="middle_lumbar_Z" type="revolute">
        <origin xyz="0 0 0" rpy="0 -0 0" />
        <axis xyz="0 0 1" />
        <parent link="middle_pelvis" />
        <child link="middle_abdomen_virtual" />
        <limit effort="0" velocity="0" lower="-3.14159" upper="0.785398" />
    </joint>
    <joint name="middle_pelvis_COM_joint" type="fixed">
        <origin xyz="-0.00018375 -0.02646 -0.00055125" rpy="0 -0 0" />
        <axis xyz="0 0 0" />
        <parent link="middle_pelvis" />
        <child link="middle_pelvis_COM" />
        <limit effort="0" velocity="0" lower="0" upper="0" />
    </joint>
    <joint name="right_ankle_X" type="revolute">
        <origin xyz="0 0 0" rpy="0 -0 0" />
        <axis xyz="1 0 0" />
        <parent link="right_foot_virtual" />
        <child link="right_foot" />
        <limit effort="0" velocity="0" lower="0" upper="0.785398" />
    </joint>
    <joint name="right_ankle_Z" type="revolute">
        <origin xyz="0 -0.42805 0" rpy="0 -0 0" />
        <axis xyz="0 0 1" />
        <parent link="right_lowerleg" />
        <child link="right_foot_virtual" />
        <limit effort="0" velocity="0" lower="-1.0472" upper="0.392699" />
    </joint>
    <joint name="right_clavicle_joint_X" type="revolute">
        <origin xyz="0 0 0" rpy="0 -0 0" />
        <axis xyz="-1 0 0" />
        <parent link="middle_thorax" />
        <child link="right_clavicle" />
        <limit effort="0" velocity="0" lower="-1.0472" upper="0.314159" />
    </joint>
    <joint name="right_elbow_Y" type="revolute">
        <origin xyz="0 0 0" rpy="0 -0 0" />
        <axis xyz="0 1 0" />
        <parent link="right_lowerarm_virtual" />
        <child link="right_lowerarm" />
        <limit effort="0" velocity="0" lower="-1.5708" upper="1.5708" />
    </joint>
    <joint name="right_elbow_Z" type="revolute">
        <origin xyz="0 -0.2737 0" rpy="0 -0 0" />
        <axis xyz="0 0 1" />
        <parent link="right_upperarm" />
        <child link="right_lowerarm_virtual" />
        <limit effort="0" velocity="0" lower="0" upper="2.74889" />
    </joint>
    <joint name="right_foot_COM_joint" type="fixed">
        <origin xyz="0.0689623 -0.0273376 0.00467075" rpy="0 -0 0" />
        <axis xyz="0 0 0" />
        <parent link="right_foot" />
        <child link="right_foot_COM" />
        <limit effort="0" velocity="0" lower="0" upper="0" />
    </joint>
    <joint name="right_hand_COM_joint" type="fixed">
        <origin xyz="0.00647185 -0.0662181 0.00591937" rpy="0 -0 0" />
        <axis xyz="0 0 0" />
        <parent link="right_hand" />
        <child link="right_hand_COM" />
        <limit effort="0" velocity="0" lower="0" upper="0" />
    </joint>
    <joint name="right_hip_X" type="revolute">
        <origin xyz="0 0 0" rpy="0 -0 0" />
        <axis xyz="1 0 0" />
        <parent link="right_upperleg_virtual" />
        <child link="right_upperleg_virtual_2" />
        <limit effort="0" velocity="0" lower="-0.392699" upper="1.5708" />
    </joint>
    <joint name="right_hip_Y" type="revolute">
        <origin xyz="0 0 0" rpy="0 -0 0" />
        <axis xyz="0 1 0" />
        <parent link="right_upperleg_virtual_2" />
        <child link="right_upperleg" />
        <limit effort="0" velocity="0" lower="-1.5708" upper="1.5708" />
    </joint>
    <joint name="right_hip_Z" type="revolute">
        <origin xyz="0.053375 -0.0749 0.079975" rpy="0 -0 0" />
        <axis xyz="0 0 1" />
        <parent link="middle_pelvis" />
        <child link="right_upperleg_virtual" />
        <limit effort="0" velocity="0" lower="-0.785398" upper="3.14159" />
    </joint>
    <joint name="right_knee" type="revolute">
        <origin xyz="0 -0.427 0" rpy="0 -0 0" />
        <axis xyz="0 0 -1" />
        <parent link="right_upperleg" />
        <child link="right_lowerleg" />
        <limit effort="0" velocity="0" lower="0" upper="2.74889" />
    </joint>
    <joint name="right_lowerarm_COM_joint" type="fixed">
        <origin xyz="-0.00363545 -0.116614 0.00307615" rpy="0 -0 0" />
        <axis xyz="0 0 0" />
        <parent link="right_lowerarm" />
        <child link="right_lowerarm_COM" />
        <limit effort="0" velocity="0" lower="0" upper="0" />
    </joint>
    <joint name="right_lowerleg_COM_joint" type="fixed">
        <origin xyz="-0.0205464 -0.175501 0.00299635" rpy="0 -0 0" />
        <axis xyz="0 0 0" />
        <parent link="right_lowerleg" />
        <child link="right_lowerleg_COM" />
        <limit effort="0" velocity="0" lower="0" upper="0" />
    </joint>
    <joint name="right_shoulder_X" type="revolute">
        <origin xyz="0 0 0" rpy="0 -0 0" />
        <axis xyz="1 0 0" />
        <parent link="right_upperarm_virtual" />
        <child link="right_upperarm_virtual_2" />
        <limit effort="0" velocity="0" lower="-3.14159" upper="1.0472" />
    </joint>
    <joint name="right_shoulder_Y" type="revolute">
        <origin xyz="0.00805 -0.0728 0.2037" rpy="0 -0 0" />
        <axis xyz="0 1 0" />
        <parent link="right_clavicle" />
        <child link="right_upperarm_virtual" />
        <limit effort="0" velocity="0" lower="-2.0944" upper="0.392699" />
    </joint>
    <joint name="right_shoulder_Z" type="revolute">
        <origin xyz="0 0 0" rpy="0 -0 0" />
        <axis xyz="0 0 1" />
        <parent link="right_upperarm_virtual_2" />
        <child link="right_upperarm" />
        <limit effort="0" velocity="0" lower="-1.5708" upper="3.14159" />
    </joint>
    <joint name="right_upperarm_COM_joint" type="fixed">
        <origin xyz="0.0049266 -0.131923 -0.0084847" rpy="0 -0 0" />
        <axis xyz="0 0 0" />
        <parent link="right_upperarm" />
        <child link="right_upperarm_COM" />
        <limit effort="0" velocity="0" lower="0" upper="0" />
    </joint>
    <joint name="right_upperleg_COM_joint" type="fixed">
        <origin xyz="-0.017507 -0.183183 -0.014091" rpy="0 -0 0" />
        <axis xyz="0 0 0" />
        <parent link="right_upperleg" />
        <child link="right_upperleg_COM" />
        <limit effort="0" velocity="0" lower="0" upper="0" />
    </joint>
    <joint name="right_wrist_X" type="revolute">
        <origin xyz="0 0 0" rpy="0 -0 0" />
        <axis xyz="1 0 0" />
        <parent link="right_hand_virtual" />
        <child link="right_hand" />
        <limit effort="0" velocity="0" lower="-0.785398" upper="0.785398" />
    </joint>
    <joint name="right_wrist_Z" type="revolute">
        <origin xyz="0 -0.27965 0" rpy="0 -0 0" />
        <axis xyz="0 0 1" />
        <parent link="right_lowerarm" />
        <child link="right_hand_virtual" />
        <limit effort="0" velocity="0" lower="-1.5708" upper="1.5708" />
    </joint>
    <joint name="middle_thoracic_X" type="revolute">
        <origin xyz="0 0 0" rpy="0 -0 0" />
        <axis xyz="1 0 0" />
        <parent link="middle_thorax_virtual" />
        <child link="middle_thorax_virtual_2" />
        <limit effort="0" velocity="0" lower="-1.0472" upper="1.0472" />
    </joint>
    <joint name="middle_thoracic_Y" type="revolute">
        <origin xyz="0 0 0" rpy="0 -0 0" />
        <axis xyz="0 1 0" />
        <parent link="middle_thorax_virtual_2" />
        <child link="middle_thorax_virtual_3" />
        <limit effort="0" velocity="0" lower="-1.0472" upper="1.0472" />
    </joint>
    <joint name="middle_thoracic_Z" type="revolute">
        <origin xyz="0 0 0" rpy="0 -0 0" />
        <axis xyz="0 0 1" />
        <parent link="middle_abdomen" />
        <child link="middle_thorax_virtual" />
        <limit effort="0" velocity="0" lower="-1.0472" upper="0.392699" />
    </joint>
    <joint name="middle_thorax_COM_joint" type="fixed">
        <origin xyz="0 -0.183275 -0.0013209" rpy="0 -0 0" />
        <axis xyz="0 0 0" />
        <parent link="middle_thorax" />
        <child link="middle_thorax_COM" />
        <limit effort="0" velocity="0" lower="0" upper="0" />
    </joint>
    <joint name="middle_thorax_base_frame" type="fixed">
        <origin xyz="0 0.330225 0" rpy="0 -0 0" />
        <axis xyz="0 0 0" />
        <parent link="middle_thorax_virtual_3" />
        <child link="middle_thorax" />
    </joint>
</robot>
