<robot name="human_39dof_ISB_model">
    <material name="body_color">
        <texture />
        <color rgba="0.005 0.005 0.005 0.6" />
    </material>
    <material name="Black">
        <texture />
        <color rgba="0 0 0 1" />
    </material>
    <link name="base_link">
        <inertial>
            <mass value="1e-6"/>
            <inertia ixx="1e-6" ixy="1e-6" ixz="1e-6" iyy="1e-6" iyz="1e-6" izz="1e-6"/>
        </inertial>
    </link>
    <joint name="left_hip_Z" type="revolute">
        <origin xyz="0.055 -0.077 -0.083" rpy="0 -0 0" />
        <axis xyz="0 0 1" />
        <parent link="base_link" />
        <child link="left_upperleg_virtual" />
        <limit effort="0" velocity="0" lower="-0.785398" upper="3.14159" />
    </joint>
    <link name="left_upperleg_virtual" />
    <joint name="left_hip_X" type="revolute">
        <origin xyz="0 0 0" rpy="0 -0 0" />
        <axis xyz="1 0 0" />
        <parent link="left_upperleg_virtual" />
        <child link="left_upperleg_virtual_2" />
        <limit effort="0" velocity="0" lower="-0.392699" upper="1.5708" />
    </joint>
    <link name="left_upperleg_virtual_2">
	    <visual>
            <origin xyz="-0.04 -0.48 0.080" rpy="0.0 1.57 0" />
            <geometry>
                <mesh filename="package://human_description/meshes/knee_mesh.STL" scale="0.006 0.006 0.006" />
            </geometry>
            <material name="body_color">
                <texture />
                <color rgba="0 1 1 0.5" />
            </material>
        </visual>
    </link>
    <joint name="left_hip_Y" type="revolute">
        <origin xyz="0 0 0" rpy="0 -0 0" />
        <axis xyz="0 1 0" />
        <parent link="left_upperleg_virtual_2" />
        <child link="left_upperleg" />
        <limit effort="0" velocity="0" lower="-1.5708" upper="1.5708" />
    </joint>
    <link name="left_upperleg">
        <inertial>
            <mass value="8.84" />
            <origin xyz="-0.017 -0.18 0.014" rpy="0 -0 0" />
            <inertia ixx="0.131144" ixy="0.007641" ixz="-0.000624" iyy="0.035086" iyz="-0.007641" izz="0.140344" />
        </inertial>
        <visual>
            <origin xyz="-0.1 -0.42 0.085" rpy="0.0 1.57 0" />
            <geometry>
                <mesh filename="package://human_description/meshes/upperleg_mesh.STL" scale="0.0063 0.0065 0.007" />
            </geometry>
            <material name="body_color">
                <texture />
                <color rgba="0 1 1 0.5" />
            </material>
        </visual>
    </link>
    <joint name="left_knee" type="revolute">
        <origin xyz="0.0 -0.42 0.0" rpy="0 -0 0" />
        <axis xyz="0 0 -1" />
        <parent link="left_upperleg" />
        <child link="left_lowerleg" />
        <limit effort="0" velocity="0" lower="0" upper="2.74889" />
    </joint>
    <link name="left_lowerleg">
        <inertial>
            <mass value="3.45" />
            <origin xyz="-0.02 -0.173 0.003" rpy="0 -0 0" />
            <inertia ixx="0.04794" ixy="-0.000978" ixz="-0.000245" iyy="0.006115" iyz="0.001529" izz="0.04794" />
        </inertial>
        <visual>
            <origin xyz="-0.06 -0.43 0.08" rpy="0.0 1.57 0" />
            <geometry>
                <mesh filename="package://human_description/meshes/lowerleg_mesh.STL" scale="0.0063 0.0065 0.007" />
            </geometry>
            <material name="body_color">
                <texture />
                <color rgba="0 1 1 0.5" />
            </material>
	    </visual>
    </link>
    <joint name="left_ankle_Z" type="revolute">
        <origin xyz="0.0 -0.421 0.0" rpy="0 -0 0" />
        <axis xyz="0 0 1" />
        <parent link="left_lowerleg" />
        <child link="left_foot_virtual" />
        <limit effort="0" velocity="0" lower="-0.392699" upper="1.0472" />
    </joint>
    <link name="left_foot_virtual" />
    <joint name="left_ankle_X" type="revolute">
        <origin xyz="0 0 0" rpy="0 -0 0" />
        <axis xyz="-1 0 0" />
        <parent link="left_foot_virtual" />
        <child link="left_foot" />
        <limit effort="0" velocity="0" lower="0" upper="0.785398" />
    </joint>
    <link name="left_foot">
        <inertial>
            <mass value="0.86" />
            <origin xyz="0.068 -0.027 0.005" rpy="0 -0 0" />
            <inertia ixx="0.000787" ixy="0.00046" ixz="-0.000174" iyy="0.00373" iyz="0.0" izz="0.003531" />
        </inertial>
        <visual>
            <origin xyz="-0.05 -0.055 0.075" rpy="0 1.57 0" />
            <geometry>
		        <mesh filename="package://human_description/meshes/foot_mesh.STL" scale="0.0060 0.0060 0.0060" />

            </geometry>
            <material name="body_color">
                <texture />
                <color rgba="0 1 1 0.5" />
            </material>
        </visual>
    </link>
    <joint name="middle_lumbar_Z" type="revolute">
        <origin xyz="0.0 0.0 0.0" rpy="0 -0 0" />
        <axis xyz="0 0 -1" />
        <parent link="base_link" />
        <child link="middle_pelvis_virtual" />
        <limit effort="0" velocity="0" lower="-3.14159" upper="0.785398" />
    </joint>
    <link name="middle_pelvis_virtual" />
    <joint name="middle_lumbar_X" type="revolute">
        <origin xyz="0 0 0" rpy="0 -0 0" />
        <axis xyz="1 0 0" />
        <parent link="middle_pelvis_virtual" />
        <child link="middle_pelvis" />
        <limit effort="0" velocity="0" lower="-0.785398" upper="0.785398" />
    </joint>
    <link name="middle_pelvis">
        <inertial>
            <mass value="10.21" />
            <origin xyz="0.003 -0.025 -0.001" rpy="0 -0 0" />
            <inertia ixx="0.086248" ixy="-0.005284" ixz="-0.001218" iyy="0.094999" iyz="-0.000541" izz="0.076305" />
        </inertial>
        <visual>
	        <origin xyz="-0.08 -0.13 0.125" rpy="0 1.57 0" />
            <geometry>
		        <mesh filename="package://human_description/meshes/pelvis_mesh.STL" scale="0.006 0.0055 0.0055" />
            </geometry>
            <material name="body_color">
                <texture />
                <color rgba="0 1 1 0.5" />
            </material>
        </visual>
    </link>
    <joint name="middle_abdomen_Z" type="revolute">
        <origin xyz="0.0 0.092 0.0" rpy="0 -0 0" />
        <axis xyz="0 0 -1" />
        <parent link="middle_pelvis" />
        <child link="middle_abdomen_virtual" />
        <limit effort="0" velocity="0" lower="-1.0472" upper="0.392699" />
    </joint>
    <link name="middle_abdomen_virtual" />
    <joint name="middle_abdomen_X" type="revolute">
        <origin xyz="0 0 0" rpy="0 -0 0" />
        <axis xyz="1 0 0" />
        <parent link="middle_abdomen_virtual" />
        <child link="middle_abdomen_virtual_2" />
        <limit effort="0" velocity="0" lower="-1.0472" upper="1.0472" />
    </joint>
    <link name="middle_abdomen_virtual_2" />
    <joint name="middle_abdomen_Y" type="revolute">
        <origin xyz="0 0 0" rpy="0 -0 0" />
        <axis xyz="0 1 0" />
        <parent link="middle_abdomen_virtual_2" />
        <child link="middle_abdomen" />
        <limit effort="0" velocity="0" lower="-1.0472" upper="1.0472" />
    </joint>
    <link name="middle_abdomen">
        <inertial>
            <mass value="1.94" />
            <origin xyz="-0.005 0.084 -0.0" rpy="0 -0 0" />
            <inertia ixx="0.04316" ixy="0.001303" ixz="1.6e-05" iyy="0.002514" iyz="-6.4e-05" izz="0.043382" />
        </inertial>
	    <visual>
            <origin xyz="-0.06 0.04 -0.085" rpy="0 -0 0" />
            <geometry>
		        <mesh filename="package://human_description/meshes/abdomen_mesh.STL" scale="0.0055 0.0055 0.0055" />

            </geometry>
            <material name="body_color">
                <texture />
                <color rgba="0 1 1 0.5" />
            </material>
        </visual>
    </link>
    <joint name="middle_thoracic_Z" type="revolute">
        <origin xyz="0.0 0.144 0.0" rpy="0 -0 0" />
        <axis xyz="0 0 -1" />
        <parent link="middle_pelvis" />
        <child link="middle_thorax_virtual" />
        <limit effort="0" velocity="0" lower="-1.0472" upper="0.392699" />
    </joint>
    <link name="middle_thorax_virtual" />
    <joint name="middle_thoracic_X" type="revolute">
        <origin xyz="0 0 0" rpy="0 -0 0" />
        <axis xyz="1 0 0" />
        <parent link="middle_thorax_virtual" />
        <child link="middle_thorax_virtual_2" />
        <limit effort="0" velocity="0" lower="-1.0472" upper="1.0472" />
    </joint>
    <link name="middle_thorax_virtual_2" />
    <joint name="middle_thoracic_Y" type="revolute">
        <origin xyz="0 0 0" rpy="0 -0 0" />
        <axis xyz="0 1 0" />
        <parent link="middle_thorax_virtual_2" />
        <child link="middle_thorax" />
        <limit effort="0" velocity="0" lower="-1.0472" upper="1.0472" />
    </joint>
    <link name="middle_thorax">
        <inertial>
            <mass value="21.86" />
            <origin xyz="-0.011 0.185 -0.001" rpy="0 -0 0" />
            <inertia ixx="2.386661" ixy="0.072074" ixz="0.00089" iyy="0.139031" iyz="-0.003559" izz="2.398896" />
        </inertial>
        <visual>
	    <origin xyz="-0.11 0 0.13" rpy="0 1.57 0" />
            <geometry>

		        <mesh filename="package://human_description/meshes/torso_mesh.STL" scale="0.0065 0.0065 0.0065" />
            </geometry>
            <material name="body_color">
                <texture />
                <color rgba="0.2 0.2 0.2 0.2" />
            </material>
        </visual>
    </link>
    <joint name="middle_cervical_Z" type="revolute">
        <origin xyz="0.0 0.319 0.0" rpy="0 -0 0" />
        <axis xyz="0 0 -1" />
        <parent link="middle_thorax" />
        <child link="middle_head_virtual" />
        <limit effort="0" velocity="0" lower="-1.5708" upper="1.5708" />
    </joint>
    <link name="middle_head_virtual">
    <visual>
	    <origin xyz="-0.03 -0.01 -0.045" rpy="0 0.0 0" />
            <geometry>
		<mesh filename="package://human_description/meshes/neck_mesh.STL" scale="0.005 0.005 0.005" />
            </geometry>
            <material name="body_color">
                <texture />
                <color rgba="0.2 0.2 0.2 0.7" />
            </material>
        </visual>
    </link>
    <joint name="middle_cervical_X" type="revolute">
        <origin xyz="0 0 0" rpy="0 -0 0" />
        <axis xyz="1 0 0" />
        <parent link="middle_head_virtual" />
        <child link="middle_head_virtual_2" />
        <limit effort="0" velocity="0" lower="-1.0472" upper="1.0472" />
    </joint>
    <link name="middle_head_virtual_2" />
    <joint name="middle_cervical_Y" type="revolute">
        <origin xyz="0 0 0" rpy="0 -0 0" />
        <axis xyz="0 1 0" />
        <parent link="middle_head_virtual_2" />
        <child link="middle_head" />
        <limit effort="0" velocity="0" lower="-1.5708" upper="1.5708" />
    </joint>
    <link name="middle_head">
        <inertial>
            <mass value="4.82" />
            <origin xyz="-0.015 0.132 0.0" rpy="0 -0 0" />
            <inertia ixx="0.026018" ixy="-0.002193" ixz="-0.000108" iyy="0.016921" iyz="0.000244" izz="0.029483" />
        </inertial>
        <visual>
	        <origin xyz="-0.07 0.04 0.09" rpy="0 1.57 0" />
            <geometry>
		        <mesh filename="package://human_description/meshes/head_mesh.STL" scale="0.0055 0.0055 0.0055" />
            </geometry>
            <material name="body_color">
                <texture />
                <color rgba="0.2 0.2 0.2 0.5" />
            </material>
        </visual>
    </link>
    <joint name="left_clavicle_joint_X" type="revolute">
        <origin xyz="0.0 0.319 0.0" rpy="0 -0 0" />
        <axis xyz="1 0 0" />
        <parent link="middle_thorax" />
        <child link="left_clavicle" />
        <limit effort="0" velocity="0" lower="-1.0472" upper="0.314159" />
    </joint>
    <link name="left_clavicle">
        <inertial>
            <mass value="0.15600" />
            <origin xyz="-0.011096 0.00637 0.05417" rpy="0 -0 0" />
            <inertia ixx="0.00024" ixy="-0.00002" ixz="-0.00007" iyy="0.00026" iyz="0.00005" izz="0.00004" />
        </inertial>
    </link>
    <joint name="left_shoulder_Z" type="revolute">
        <origin xyz="0.008 -0.075 -0.211" rpy="0 -0 0" />
        <axis xyz="0 0 1" />
        <parent link="left_clavicle" />
        <child link="left_upperarm_virtual" />
        <limit effort="0" velocity="0" lower="-2.0944" upper="0.392699" />
    </joint>
    <link name="left_upperarm_virtual">
	    <visual>
	        <origin xyz="-0.16 -0.045 -0.045" rpy="0 0 0" />
            <geometry>
		        <mesh filename="package://human_description/meshes/shoulder_mesh.STL" scale="0.0055 0.0055 0.0055" />
            </geometry>
            <material name="body_color">
                <texture />
                <color rgba="0 1 1 0.5" />
            </material>
        </visual>
    </link>
    <joint name="left_shoulder_X" type="revolute">
        <origin xyz="0 0 0" rpy="0 -0 0" />
        <axis xyz="1 0 0" />
        <parent link="left_upperarm_virtual" />
        <child link="left_upperarm_virtual_2" />
        <limit effort="0" velocity="0" lower="-3.14159" upper="1.0472" />
    </joint>
    <link name="left_upperarm_virtual_2" />
    <joint name="left_shoulder_Y" type="revolute">
        <origin xyz="0 0 0" rpy="0 -0 0" />
        <axis xyz="0 1 0" />
        <parent link="left_upperarm_virtual_2" />
        <child link="left_upperarm" />
        <limit effort="0" velocity="0" lower="-1.5708" upper="3.14159" />
    </joint>
    <link name="left_upperarm">
        <inertial>
            <mass value="1.73" />
            <origin xyz="0.004 -0.119 -0.007" rpy="0 -0 0" />
            <inertia ixx="0.0115" ixy="0.000431" ixz="0.000299" iyy="0.002345" iyz="4.8e-05" izz="0.012253" />
        </inertial>
        <visual>
            <origin xyz="-0.065 -0.27 0.18" rpy="0.0 1.57 0" />
            <geometry>
                <mesh filename="package://human_description/meshes/upperarm_mesh.STL" scale="0.0063 0.0060 0.007" />
            </geometry>
            <material name="body_color" />
        </visual>
    </link>
    <joint name="left_elbow_Z" type="revolute">
        <origin xyz="0.0 -0.263 0.0" rpy="0 -0 0" />
        <axis xyz="0 0 1" />
        <parent link="left_upperarm" />
        <child link="left_lowerarm_virtual" />
        <limit effort="0" velocity="0" lower="0" upper="2.74889" />
    </joint>
    <link name="left_lowerarm_virtual">
	    <visual>
	        <origin xyz="-0.15 -0.04 -0.035" rpy="0 0 0" />
            <geometry>
		        <mesh filename="package://human_description/meshes/elbow_mesh.STL" scale="0.0055 0.0055 0.0055" />
            </geometry>
            <material name="body_color">
                <texture />
                <color rgba="0 1 1 0.5" />
            </material>
        </visual>
    </link>
    <joint name="left_elbow_Y" type="revolute">
        <origin xyz="0 0 0" rpy="0 -0 0" />
        <axis xyz="0 -1 0" />
        <parent link="left_lowerarm_virtual" />
        <child link="left_lowerarm" />
        <limit effort="0" velocity="0" lower="-1.5708" upper="1.5708" />
    </joint>
    <link name="left_lowerarm">
        <inertial>
            <mass value="1.22" />
            <origin xyz="0.003 -0.115 0.004" rpy="0 -0 0" />
            <inertia ixx="0.007233" ixy="8.3e-05" ixz="3.7e-05" iyy="0.001116" iyz="-0.00059" izz="0.006726" />
        </inertial>
        <visual>
            <origin xyz="0.052 -0.26 -0.17" rpy="0.0 -1.57 0" />
            <geometry>
                <mesh filename="package://human_description/meshes/lowerarm_mesh.STL" scale="0.0060 0.0060 0.0060" />
            </geometry>
            <material name="body_color">
                <texture />
                <color rgba="0 1 1 0.5" />
            </material>
        </visual>
    </link>
    <joint name="left_wrist_Z" type="revolute">
        <origin xyz="0.0 -0.275 0.0" rpy="0 -0 0" />
        <axis xyz="0 0 1" />
        <parent link="left_lowerarm" />
        <child link="left_hand_virtual" />
        <limit effort="0" velocity="0" lower="-1.5708" upper="1.5708" />
    </joint>
    <link name="left_hand_virtual" />
    <joint name="left_wrist_X" type="revolute">
        <origin xyz="0 0 0" rpy="0 -0 0" />
        <axis xyz="-1 0 0" />
        <parent link="left_hand_virtual" />
        <child link="left_hand" />
        <limit effort="0" velocity="0" lower="-0.785398" upper="0.785398" />
    </joint>
    <link name="left_hand">
        <inertial>
            <mass value="0.43" />
            <origin xyz="0.015 -0.154 0.014" rpy="0 -0 0" />
            <inertia ixx="0.005417" ixy="0.000705" ixz="0.000328" iyy="0.002102" iyz="-0.000582" izz="0.004565" />
        </inertial>
        <visual>
            <origin xyz="0.17 -0.17 0.055" rpy="0 3.14 0" />
            <geometry>
		        <mesh filename="package://human_description/meshes/hand_mesh.STL" scale="0.0060 0.0060 0.0060" />

            </geometry>
            <material name="body_color">
                <texture />
                <color rgba="0 1 1 0.5" />
            </material>
        </visual>
    </link>
    <joint name="right_clavicle_joint_X" type="revolute">
        <origin xyz="0.0 0.319 0.0" rpy="0 -0 0" />
        <axis xyz="-1 0 0" />
        <parent link="middle_thorax" />
        <child link="right_clavicle" />
        <limit effort="0" velocity="0" lower="-0.392699" upper="1.0472" />
    </joint>
    <link name="right_clavicle">
        <inertial>
            <mass value="0.15600" />
            <origin xyz="-0.011096 0.00637 0.05417" rpy="0 -0 0" />
            <inertia ixx="0.00024" ixy="-0.00002" ixz="-0.00007" iyy="0.00026" iyz="0.00005" izz="0.00004" />
        </inertial>
    </link>
    <joint name="right_shoulder_Z" type="revolute">
        <origin xyz="0.008 -0.075 0.211" rpy="0 -0 0" />
        <axis xyz="0 0 1" />
        <parent link="right_clavicle" />
        <child link="right_upperarm_virtual" />
        <limit effort="0" velocity="0" lower="-2.0944" upper="0.392699" />
    </joint>
    <link name="right_upperarm_virtual">
        <visual>
	        <origin xyz="-0.15 -0.04 -0.05" rpy="0 0 0" />
            <geometry>
		        <mesh filename="package://human_description/meshes/shoulder_mesh.STL" scale="0.0055 0.0055 0.0055" />
            </geometry>
            <material name="body_color">
                <texture />
                <color rgba="0 1 1 0.5" />
            </material>
        </visual>
    </link>
    <joint name="right_shoulder_X" type="revolute">
        <origin xyz="0 0 0" rpy="0 -0 0" />
        <axis xyz="-1 0 0" />
        <parent link="right_upperarm_virtual" />
        <child link="right_upperarm_virtual_2" />
        <limit effort="0" velocity="0" lower="-3.14159" upper="1.0472" />
    </joint>
    <link name="right_upperarm_virtual_2" />
    <joint name="right_shoulder_Y" type="revolute">
        <origin xyz="0 0 0" rpy="0 -0 0" />
        <axis xyz="0 -1 0" />
        <parent link="right_upperarm_virtual_2" />
        <child link="right_upperarm" />
        <limit effort="0" velocity="0" lower="-1.5708" upper="3.14159" />
    </joint>
    <link name="right_upperarm">
        <inertial>
            <mass value="1.73" />
            <origin xyz="0.004 -0.119 -0.007" rpy="0 -0 0" />
            <inertia ixx="0.0115" ixy="0.000431" ixz="0.000299" iyy="0.002345" iyz="4.8e-05" izz="0.012253" />
        </inertial>
        <visual>
            <origin xyz="-0.065 -0.27 0.18" rpy="0.0 1.57 0" />
            <geometry>
                <mesh filename="package://human_description/meshes/upperarm_mesh.STL" scale="0.0063 0.0060 0.007" />
            </geometry>
            <material name="body_color">
                <texture />
                <color rgba="0 1 1 0.5" />
            </material>
        </visual>
    </link>
    <joint name="right_elbow_Z" type="revolute">
        <origin xyz="0.0 -0.263 0.0" rpy="0 -0 0" />
        <axis xyz="0 0 1" />
        <parent link="right_upperarm" />
        <child link="right_lowerarm_virtual" />
        <limit effort="0" velocity="0" lower="0" upper="2.74889" />
    </joint>
    <link name="right_lowerarm_virtual">
        <visual>
	        <origin xyz="-0.15 -0.04 -0.035" rpy="0 0 0" />
            <geometry>
		        <mesh filename="package://human_description/meshes/elbow_mesh.STL" scale="0.0055 0.0055 0.0055" />
            </geometry>
            <material name="body_color">
                <texture />
                <color rgba="0 1 1 0.5" />
            </material>
        </visual>
    </link>
    <joint name="right_elbow_Y" type="revolute">
        <origin xyz="0 0 0" rpy="0 -0 0" />
        <axis xyz="0 1 0" />
        <parent link="right_lowerarm_virtual" />
        <child link="right_lowerarm" />
        <limit effort="0" velocity="0" lower="-1.5708" upper="1.5708" />
    </joint>
    <link name="right_lowerarm">
        <inertial>
            <mass value="1.22" />
            <origin xyz="0.003 -0.115 0.004" rpy="0 -0 0" />
            <inertia ixx="0.007233" ixy="8.3e-05" ixz="3.7e-05" iyy="0.001116" iyz="-0.00059" izz="0.006726" />
        </inertial>
        <visual>
            <origin xyz="0.052 -0.26 -0.17" rpy="0.0 -1.57 0" />
            <geometry>
                <mesh filename="package://human_description/meshes/lowerarm_mesh.STL" scale="0.0060 0.0060 0.0060" />
            </geometry>
            <material name="body_color">
                <texture />
                <color rgba="0 1 1 0.5" />
            </material>
        </visual>
    </link>
    <joint name="right_wrist_Z" type="revolute">
        <origin xyz="0.0 -0.275 0.0" rpy="0 -0 0" />
        <axis xyz="0 0 1" />
        <parent link="right_lowerarm" />
        <child link="right_hand_virtual" />
        <limit effort="0" velocity="0" lower="-1.5708" upper="1.5708" />
    </joint>
    <link name="right_hand_virtual" />
    <joint name="right_wrist_X" type="revolute">
        <origin xyz="0 0 0" rpy="0 -0 0" />
        <axis xyz="1 0 0" />
        <parent link="right_hand_virtual" />
        <child link="right_hand" />
        <limit effort="0" velocity="0" lower="-0.785398" upper="0.785398" />
    </joint>
    <link name="right_hand">
        <inertial>
            <mass value="0.43" />
            <origin xyz="0.015 -0.154 0.014" rpy="0 -0 0" />
            <inertia ixx="0.005417" ixy="0.000705" ixz="0.000328" iyy="0.002102" iyz="-0.000582" izz="0.004565" />
        </inertial>
        <visual>
            <origin xyz="0.17 -0.17 0.055" rpy="0 3.14 0" />
            <geometry>
		        <mesh filename="package://human_description/meshes/hand_mesh.STL" scale="0.0060 0.0060 0.0060" />

            </geometry>
            <material name="body_color">
                <texture />
                <color rgba="0 1 1 0.5" />
            </material>
        </visual>
    </link>
    <joint name="right_hip_Z" type="revolute">
        <origin xyz="0.055 -0.077 0.083" rpy="0 -0 0" />
        <axis xyz="0 0 1" />
        <parent link="base_link" />
        <child link="right_upperleg_virtual" />
        <limit effort="0" velocity="0" lower="-0.785398" upper="3.14159" />
    </joint>
    <link name="right_upperleg_virtual" />
    <joint name="right_hip_X" type="revolute">
        <origin xyz="0 0 0" rpy="0 -0 0" />
        <axis xyz="-1 0 0" />
        <parent link="right_upperleg_virtual" />
        <child link="right_upperleg_virtual_2" />
        <limit effort="0" velocity="0" lower="-0.392699" upper="1.5708" />
    </joint>
    <link name="right_upperleg_virtual_2">
        <visual>
            <origin xyz="-0.04 -0.48 0.07" rpy="0.0 1.57 0" />
            <geometry>
                <mesh filename="package://human_description/meshes/knee_mesh.STL" scale="0.006 0.006 0.006" />
            </geometry>
            <material name="body_color">
                <texture />
                <color rgba="0 1 1 0.5" />
            </material>
        </visual>
    </link>
    <joint name="right_hip_Y" type="revolute">
        <origin xyz="0 0 0" rpy="0 -0 0" />
        <axis xyz="0 -1 0" />
        <parent link="right_upperleg_virtual_2" />
        <child link="right_upperleg" />
        <limit effort="0" velocity="0" lower="-1.5708" upper="1.5708" />
    </joint>
    <link name="right_upperleg">
        <inertial>
            <mass value="8.84" />
            <origin xyz="-0.017 -0.18 0.014" rpy="0 -0 0" />
            <inertia ixx="0.131144" ixy="0.007641" ixz="-0.000624" iyy="0.035086" iyz="-0.007641" izz="0.140344" />
        </inertial>
        <visual>
            <origin xyz="-0.1 -0.42 0.07" rpy="0.0 1.57 0" />
            <geometry>
                <mesh filename="package://human_description/meshes/upperleg_mesh.STL" scale="0.0063 0.0065 0.007" />
            </geometry>
            <material name="body_color">
                <texture />
                <color rgba="0 1 1 0.5" />
            </material>
        </visual>
    </link>
    <joint name="right_knee" type="revolute">
        <origin xyz="0.0 -0.42 0.0" rpy="0 -0 0" />
        <axis xyz="0 0 -1" />
        <parent link="right_upperleg" />
        <child link="right_lowerleg" />
        <limit effort="0" velocity="0" lower="0" upper="2.74889" />
    </joint>
    <link name="right_lowerleg">
        <inertial>
            <mass value="3.45" />
            <origin xyz="-0.02 -0.173 0.003" rpy="0 -0 0" />
            <inertia ixx="0.04794" ixy="-0.000978" ixz="-0.000245" iyy="0.006115" iyz="0.001529" izz="0.04794" />
        </inertial>
        <visual>
            <origin xyz="-0.06 -0.43 0.07" rpy="0.0 1.57 0" />
            <geometry>
                <mesh filename="package://human_description/meshes/lowerleg_mesh.STL" scale="0.0063 0.0065 0.007" />
            </geometry>
            <material name="body_color">
                <texture />
                <color rgba="0 1 1 0.5" />
            </material>
        </visual>
    </link>
    <joint name="right_ankle_Z" type="revolute">
        <origin xyz="0.0 -0.421 0.0" rpy="0 -0 0" />
        <axis xyz="0 0 1" />
        <parent link="right_lowerleg" />
        <child link="right_foot_virtual" />
        <limit effort="0" velocity="0" lower="-1.0472" upper="0.392699" />
    </joint>
    <link name="right_foot_virtual" />
    <joint name="right_ankle_X" type="revolute">
        <origin xyz="0 0 0" rpy="0 -0 0" />
        <axis xyz="1 0 0" />
        <parent link="right_foot_virtual" />
        <child link="right_foot" />
        <limit effort="0" velocity="0" lower="0" upper="0.785398" />
    </joint>
    <link name="right_foot">
        <inertial>
            <mass value="0.86" />
            <origin xyz="0.068 -0.027 0.005" rpy="0 -0 0" />
            <inertia ixx="0.000787" ixy="0.00046" ixz="-0.000174" iyy="0.00373" iyz="0.0" izz="0.003531" />
        </inertial>
        <visual>
            <origin xyz="-0.05 -0.055 0.065" rpy="0 1.57 0" />
            <geometry>
		        <mesh filename="package://human_description/meshes/foot_mesh.STL" scale="0.0060 0.0060 0.0060" />

            </geometry>
            <material name="body_color">
                <texture />
                <color rgba="0 1 1 0.5" />
            </material>
        </visual>
    </link>
</robot>
